Workbook
Name ac_type: [1]ref_link!$A$2:$A$4
Name AMP_LIST: #REF!
Name AMP_NAME: #REF!
Name Bangkok: INDIRECT('[2]Address Code'!$N$2)
Name client_type: [1]ref_link!$A$27:$A$28
Name DD_OD: [1]ref_link!$N$2:$N$111
Name DD_TP: [1]ref_link!$O$2:$O$23
Name Factor_MED: [1]MED!$E$4:$H$135
Name Factor_SI: [1]F5Sum_Insured!$D$4:$E$6814
Name Factor_TPBI_Occu: [1]F8TPBI_O!$C$4:$G$68
Name Factor_TPBI_Person: [1]F7TPBI_P!$C$4:$G$207
Name Factor_TPPD: [1]F9TPPD!$C$4:$G$283
Name Factor_Veh_Age: [1]F4_VAge!$C$4:$D$147
Name Factor_Veh_Capacity: [1]F2_VCap_Seat!$C$4:$H$32
Name Factor_Veh_Group: [1]F6Vehicle_Group!$B$4:$E$21
Name Factor_Veh_Usage: [1]F1_VUsage!$D$4:$E$56
Name fleet: [1]ref_link!$A$31:$A$32
Name Garage: [1]ref_link!$E$2:$E$4
Name Group: [1]ref_link!$A$6:$A$11
Name language: [1]ref_link!$A$22:$A$24
Name Loan_type: [3]Rate!$O$3:$O$4
Name MED: [1]ref_link!$M$2:$M$8
Name MV: [1]ref_link!$C$2:$C$31
Name NCB: [1]ref_link!$A$14:$A$19
Name province: [1]ref_link!$E$7:$E$32
Name PRV_LIST: #REF!
Name PRV_NAME: #REF!
Name risk: [1]ref_link!$G$28:$G$31
Name TableProvinces: [4]Province!$A$2:$A$78
Name TPBI_PO: [1]ref_link!$K$2:$K$6
Name TPBI_PP: [1]ref_link!$J$2:$J$21
Name TPPD: [1]ref_link!$L$2:$L$25
Name TUM_NAME: #REF!
Name VCC: [1]ref_link!$K$29:$K$67
Name veh_body_type_lnk: [5]ref_link!$G$1:$H$25
Name veh_code: [1]ref_link!$G$2:$G$21

Sheet Sheet1
A1: Motor Code | B1: Brand | C1: Model | D1: Brand&Model | E1: Yeargroup | F1: Engine | G1: SI
A2: 110 | B2: Ford | C2: Everest | D2: =B2&" "&C2 -> Ford Everest | E2: 2006 | F2: 2500 | G2: 140000
A3: 110 | B3: Ford | C3: Everest | D3: =B3&" "&C3 -> Ford Everest | E3: 2006 | F3: 2500 | G3: 150,000
A4: 110 | B4: Ford | C4: Everest | D4: =B4&" "&C4 -> Ford Everest | E4: 2006 | F4: 2500 | G4: 160,000
A5: 110 | B5: Ford | C5: Everest | D5: =B5&" "&C5 -> Ford Everest | E5: 2006 | F5: 2500 | G5: 170,000
A6: 110 | B6: Ford | C6: Everest | D6: =B6&" "&C6 -> Ford Everest | E6: 2006 | F6: 2500 | G6: 180,000
A7: 110 | B7: Ford | C7: Everest | D7: =B7&" "&C7 -> Ford Everest | E7: 2006 | F7: 2500 | G7: 190,000
A8: 110 | B8: Ford | C8: Everest | D8: =B8&" "&C8 -> Ford Everest | E8: 2006 | F8: 2500 | G8: 200,000
A9: 110 | B9: Ford | C9: Everest | D9: =B9&" "&C9 -> Ford Everest | E9: 2006 | F9: 2500 | G9: 210,000
A10: 320 | B10: Isuzu | C10: D-Max | D10: =B10&" "&C10 -> Isuzu D-Max | E10: 2006 | F10: ไม่เกิน 4 ตัน | G10: 130000
A11: 320 | B11: Isuzu | C11: D-Max | D11: =B11&" "&C11 -> Isuzu D-Max | E11: 2006 | F11: ไม่เกิน 4 ตัน | G11: 140,000
A12: 320 | B12: Isuzu | C12: D-Max | D12: =B12&" "&C12 -> Isuzu D-Max | E12: 2006 | F12: ไม่เกิน 4 ตัน | G12: 150,000
A13: 320 | B13: Isuzu | C13: D-Max | D13: =B13&" "&C13 -> Isuzu D-Max | E13: 2006 | F13: ไม่เกิน 4 ตัน | G13: 160,000
A14: 320 | B14: Isuzu | C14: D-Max | D14: =B14&" "&C14 -> Isuzu D-Max | E14: 2006 | F14: ไม่เกิน 4 ตัน | G14: 170,000
A15: 320 | B15: Isuzu | C15: D-Max | D15: =B15&" "&C15 -> Isuzu D-Max | E15: 2006 | F15: ไม่เกิน 4 ตัน | G15: 180,000
A16: 320 | B16: Isuzu | C16: D-Max | D16: =B16&" "&C16 -> Isuzu D-Max | E16: 2006 | F16: ไม่เกิน 4 ตัน | G16: 190,000
A17: 320 | B17: Isuzu | C17: D-Max | D17: =B17&" "&C17 -> Isuzu D-Max | E17: 2006 | F17: ไม่เกิน 4 ตัน | G17: 200,000
A18: 320 | B18: Isuzu | C18: D-Max | D18: =B18&" "&C18 -> Isuzu D-Max | E18: 2006 | F18: ไม่เกิน 4 ตัน | G18: 210,000
D19: =B19&" "&C19
D20: =B20&" "&C20
D21: =B21&" "&C21
D22: =B22&" "&C22
D23: =B23&" "&C23
D24: =B24&" "&C24
D25: =B25&" "&C25
D26: =B26&" "&C26
D27: =B27&" "&C27
D28: =B28&" "&C28
D29: =B29&" "&C29
D30: =B30&" "&C30
... D103: =B103&" "&C103

Sheet Sheet4
A2: 1 | B2: มกราคม | C2: 2568
A3: 2 | B3: กุมภาพันธ์ | C3: 2567
A4: 3 | B4: มีนาคม | C4: 2566
A5: 4 | B5: เมษายน | C5: 2565
A6: 5 | B6: พฤษภาคม | C6: 2564
A7: 6 | B7: มิถุนายน | C7: 2563
A8: 7 | B8: กรกฎาคม | C8: 2562
A9: 8 | B9: สิงหาคม | C9: 2561
A10: 9 | B10: กันยายน | C10: 2560
A11: 10 | B11: ตุลาคม | C11: 2559
A12: 11 | B12: พฤศจิกายน | C12: 2558
A13: 12 | B13: ธันวาคม | C13: 2557
A14: 13 | C14: 2556
A15: 14 | C15: 2555
A16: 15 | C16: 2554
A17: 16 | C17: 2553
A18: 17 | C18: 2552
A19: 18 | C19: 2551
A20: 19 | C20: 2550
A21: 20 | C21: 2549
A22: 21 | C22: 2548
A23: 22 | C23: 2547
A24: 23 | C24: 2546
A25: 24 | C25: 2545
... A32: 31 | C32: 2538
C33: 2537
C34: 2536
C35: 2535
C36: 2534
C37: 2533
C38: 2532
C39: 2531
C40: 2530
C41: 2529
C42: 2528
C43: 2527
C44: 2526
... C90: 2480

Sheet 01 แคนเซอร์ อีซี่ แคร์_v0104
A6: ใบเสนอขายประกันภัย
D7: โครงการ | E7: : | F7: ประกันโรคมะเร็ง ซีไอเอ็มบี ไทย แคนเซอร์ อีซี่ แคร์
D9: เรียนเสนอ คุณ | E9: : | F9: คุณปัฐญา บ้านหมู่
D10: อายุ | E10: : | F10: =ROUNDDOWN(YEARFRAC((TODAY()),(DATE($L$10-543,VLOOKUP($K$10,Month!$B$2:$C$13,2,0),$J$10))),0) -> 39 | G10: ปี | H10: วัน/เดือน/ปี เกิด | J10: 22 | K10: กุมภาพันธ์ | L10: 2530
D11: แผนประกัน | E11: : | F11: แผน 500,000
D12: ระยะเวลาชำระเบี้ย | E12: : | F12: 1 ปี | G12: ระยะเวลาคุ้มครอง | I12: 1 ปี (รับประกันอายุ 1 ปี - 60 ปี ต่ออายุได้ถึง 99 ปี)
D13: เบี้ยประกันต่อปี | E13: : | F13: =VLOOKUP(IF($F$10<1,"",IF($F$10<35,"1-34",IF($F$10>34,$F$10,""))),'Rate Cancer'!$A$16:$I$42,MATCH(F11,'Rate Cancer'!$G$15:$I$15,0)+6,0) -> 5628 | G13: บาท | H13: =IFERROR(F13,"อายุไม่อยู่ในกฏเกณฑ์การรับประกัน1-60ปี") -> 5628
B16: ผลประโยชน์ความคุ้มครอง
B17: ผลประโยชน์ความคุ้มครองประกันโรคมะเร็ง บริษัทจะจ่ายไม่เกินตามความคุ้มครองที่ระบุในตารางผลประโยชน์
B19: กรณีตรวจพบโรคมะเร็ง ก่อนระยะลุกลาม หรือลุกลาม (ไม่รวมมะเร็งผิวหนัง) | K19: =VLOOKUP(B19,'Rate Cancer'!$A$3:$I$12,MATCH('01 แคนเซอร์ อีซี่ แคร์_v0104'!$F$11,'Rate Cancer'!$G$2:$I$2,0)+6,0) -> 500000 | L19: บาท
B20: กรณีตรวจพบโรคมะเร็งผิวหนัง | K20: =VLOOKUP(B20,'Rate Cancer'!$A$3:$I$12,MATCH('01 แคนเซอร์ อีซี่ แคร์_v0104'!$F$11,'Rate Cancer'!$G$2:$I$2,0)+6,0) -> 50000 | L20: บาท
B21: ค่ารักษาพยาบาล สำหรับ การทำเคมีบำบัด/รังสีรักษา/การผ่าตัด (1) จ่ายตามจริง สูงสุดต่อครั้งไม่เกิน | K21: =VLOOKUP(B21,'Rate Cancer'!$A$3:$I$12,MATCH('01 แคนเซอร์ อีซี่ แคร์_v0104'!$F$11,'Rate Cancer'!$G$2:$I$2,0)+6,0) -> 300000 | L21: บาท
B22: กรณีการตรวจวินิจฉัยซ้ำ ( Second Opinion ) (2) | K22: =VLOOKUP(B22,'Rate Cancer'!$A$3:$I$12,MATCH('01 แคนเซอร์ อีซี่ แคร์_v0104'!$F$11,'Rate Cancer'!$G$2:$I$2,0)+6,0) -> 10000 | L22: บาท
B23: ค่าใช้จ่ายในการเดินทาง ต่อครั้ง (สูงสุด 10 ครั้ง)(3) | K23: =VLOOKUP(B23,'Rate Cancer'!$A$3:$I$12,MATCH('01 แคนเซอร์ อีซี่ แคร์_v0104'!$F$11,'Rate Cancer'!$G$2:$I$2,0)+6,0) -> 500 | L23: บาท
B26: การจ่ายผลประโยชน์ข้างต้น จะต้องไม่เกินจำนวนเงินผลประโยชน์สูงสุดที่ระบุไว้ในตารางกรมธรรม์
B27: คุณสมบัติของผู้เอาประกันภัยไม่ประกอบอาชีพดังต่อไปนี้ คนที่ทํางานในโรงงานผลิตแบตเตอรี่ โรงงานผลิตถ่านไฟฉาย เหมืองนิกเกิล โรงงานไฟฟ้านิวเคลียร์
B28: โรงงานทีใช้กัมมันตภาพรังษีในการผลิต โรงงานปิโตรเลียม งานที่เกี่ยวกับฝุ่นละอองจากถ่านหินและน้ำมัน ฝุ่นแร่ใยหิน(Asbestos)
C29: A1 : ท่านเคยมีกรมธรรม์ประกันอุบัติเหตุหรือประกันสุขภาพหรือไม่
C30: £ เคยมี £ ไม่เคยมี กรุณาดำเนินการในข้อ A2
C31: A2 : ข้าพเจ้า ........................................................ รับทราบ และมีความเข้าใจในผลิตภัณฑ์และได้รับการอธิบายจากพนักงานอย่างเข้าใจดีแล้ว
B32: หมายเหตุ
C33: 1. แผนประกันโรคมะเร็ง ซีไอเอ็มบี ไทย แคนเซอร์ อีซี่ แคร์ เป็นชื่อทางการตลาด ส่วนในกรมธรรม์จะเป็นชื่อแบบประกัน "ประกันภัยโรคมะเร็ง"
C34: 2. แผนประกันโรคมะเร็ง ซีไอเอ็มบี ไทย แคนเซอร์ อีซี่ แคร์ เป็นผลิตภัณฑ์ประกันภัยมิใช่ผลิตภัณฑ์เงินฝาก
C35: 3. การนำส่งเบี้ยประกันภัยเป็นหน้าที่ของผู้เอาประกันภัย การที่นายหน้าประกันวินาศภัยเก็บเบี้ยประกันภัยเป็นการให้บริการเท่านั้น
C36: โดยศึกษาข้อมูลเพิ่มเติมได้จากคู่มือผู้เอาประกันภัย
C37: 4. การรับประกันภัยขึ้นอยู่กับเงื่อนไข และกฏเกณฑ์การพิจารณารับประกันภัยของ บริษัท ซมโปะ ประกันภัย (ประเทศไทย) จำกัด (มหาชน)
C38: 5. วิธีการชำระเบี้ย สำหรับการสมัครทำประกันภัยใหม่และปีต่ออายุ ดังนี้ เงินสด เช็ค บัตรเครดิต
C39: 6. ผู้เอาประกันภัยสามารถนำเบี้ยประกันภัยสุขภาพตามที่จ่ายจริง แต่ไม่เกิน 25,000 บาท ทั้งนี้เมื่อรวมกับเบี้ยประกันชีวิตทุกกรมธรรม์มาใช้สิทธิลดหย่อน
C40: ภาษีสูงสุดไม่เกินปีละ 100,000 บาท โดยเป็นไปตามกฎเกณฑ์ของกรมสรรพากร (ตามประกาศอธิบดีกรมสรรพากรเกี่ยวกับภาษีเงินได้ฉบับที่ 383)
C41: 7. ระยะเวลาเอาประกันภัย 1 ปี โดยสามารถต่ออายุกรมธรรม์ตามเงื่อนไขสัญญา จนถึงระยะเวลาชำระเบี้ยประกันภัยที่ระบุไว้ข้างต้น
C42: 8. เบี้ยประกันภัยข้างต้นแตกต่างตามช่วงอายุ และแผนความคุ้มครองของผู้ขอเอาประกันภัย ทั้งนี้ขึ้นอยู่กับกฎเกณฑ์ของบริษัท
C43: 9. เบี้ยประกันภัยสำหรับปีต่ออายุอาจเปลี่ยนแปลงได้ตามกฎเกณฑ์ของบริษัท
C44: 10. สงวนสิทธิ์ซื้อได้สูงสุดไม่เกิน 2 ฉบับต่อคน (หากซื้อมากกว่า 2 ฉบับ บริษัทฯจะคืนเบี้ยประกันภัยสําหรับแผนประกันภัยที่ไม่คุ้มครองนั้นให้ทั้งหมดเต็มจํานวน)
... C58: สำหรับ "การไปและกลับรวมกันในแต่ละครั้ง ตามที่ระบุไว้ในตารางกรมธรรม์ประกันภัย"
B59: เสนอโดยนายหน้า | G59: เลขที่ใบอนุญาตนายหน้าประกันวินาศภัย
B60: ธนาคารซีไอเอ็มบีไทย สาขา | I60: วัน/เวลาเสนอขาย_____________________
B62: ข้าพเจ้าได้ทราบและเข้าใจข้อความข้างต้นเป็นอย่างดีโดยตลอดแล้ว เห็นว่าถูกต้องตรงตามเจตนารมณ์และความประสงค์ของข้าพเจ้าทุกประการ
B63: ลงชื่อผู้ขอเอาประกัน___________________________เบอร์โทร______________________วันที่__________________
C64: ( )
B66: (ก) ข้อมูลในเอกสารนี้เป็นเพียงข้อมูลเบื้องต้นเพื่อประกอบการขายเท่านั้น ลูกค้าควรศึกษาข้อมูลเพิ่มเติม เรื่องความคุ้มครอง ข้อกำหนด เงื่อนไข ข้อยกเว้น และผลประโยชน์จากกรมธรรม์ประกันภัย
...

Sheet 02 PA แคร์พลัส_v0104
A6: ใบเสนอขายประกันภัย
D7: แบบประกันภัย | E7: : | F7: ประกันอุบัติเหตุ ซีไอเอ็มบี ไทย พีเอ แคร์พลัส
D9: เรียนเสนอ คุณ | E9: :
D11: อายุ | E11: : | F11: =ROUNDDOWN(YEARFRAC(TODAY(),DATE($L$11-543,VLOOKUP($K$11,Month!$B$2:$C$13,2,0),$J$11)),0) -> 60 | G11: ปี | H11: วัน/เดือน/ปี เกิด | J11: 22 | K11: เมษายน | L11: 2509
D12: แผนประกัน | E12: : | F12: แผน 1,000,000
D13: ระยะเวลาชำระเบี้ย | E13: : | F13: 1 ปี | G13: ระยะเวลาคุ้มครอง | I13: 1 ปี (รับประกันอายุ 16 ปี - 60 ปี ต่ออายุได้ถึง 70 ปี)
D14: เบี้ยประกันต่อปี | E14: : | F14: =VLOOKUP($F$11,'Rate PA'!A14:C59,MATCH(F12,'Rate PA'!A14:C14,0),0) -> 3970 | G14: บาท | H14: =IFERROR(F14,"อายุไม่อยู่ในกฏเกณฑ์การรับประกัน16-60ปี") -> 3970
B17: ผลประโยชน์ความคุ้มครอง
B18: บริษัทจะจ่ายผลประโยชน์ความคุ้มครองไม่เกินที่ระบุในตารางผลประโยชน์
B20: 1.การเสียชีวิต สูญเสียอวัยวะ สายตาหรือทุพพลภาพถาวรสิ้นเชิงจากอุบัติเหตุทั่วไป | J20: สูงสุดไม่เกิน | K20: =VLOOKUP(B20,'Rate PA'!$A$2:$C$12,MATCH($F$12,'Rate PA'!$A$1:$C$1,0),0) -> 1000000 | L20: บาท
B21: 2.การเสียชีวิต สูญเสียอวัยวะ สายตาหรือทุพพลภาพถาวรสิ้นเชิงจากการถูกฆาตกรรมหรือถูกทําร้ายร่างกาย | J21: สูงสุดไม่เกิน | K21: =K20 -> 1000000 | L21: บาท
B22: 3.การเสียชีวิต สูญเสียอวัยวะ สายตาหรือทุพพลภาพถาวรสิ้นเชิงขณะขับขี่หรือโดยสารรถจักรยานยนต์ | J22: สูงสุดไม่เกิน | K22: =VLOOKUP(B22,'Rate PA'!$A$2:$C$12,MATCH($F$12,'Rate PA'!$A$1:$C$1,0),0) -> 200000 | L22: บาท
B23: 4.การเสียชีวิต การสูญเสียอวัยวะ สายตา หรือทุพพลภาพถาวรสิ้นเชิง
B24: - จากอุบัติเหตุขณะโดยสารยานขนส่งสาธารณะ ทางบก ทางน้ำ ทางอากาศ (1) | J24: สูงสุดไม่เกิน | K24: =K21*2 -> 2000000 | L24: บาท
B25: - จากอุบัติเหตุขณะอยู่ในอาคารสาธารณะและลิฟท์ขนส่งสาธารณะ (2)
B26: 5.การรักษาพยาบาลกรณีเกิดจากอุบัติเหตุในแต่ละครั้งจ่ายตามจริง | J26: สูงสุดไม่เกิน | K26: =VLOOKUP(B26,'Rate PA'!$A$2:$C$12,MATCH($F$12,'Rate PA'!$A$1:$C$1,0),0) -> 30000 | L26: บาท
B27: 6.ค่าชดเชยรายได้ระหว่างการเข้ารักษาตัวในโรงพยาบาล อันเนื่องมาจากการบาดเจ็บจากอุบัติเหตุ | J27: วันละ | K27: =VLOOKUP(B27,'Rate PA'!$A$2:$C$12,MATCH($F$12,'Rate PA'!$A$1:$C$1,0),0) -> 1000 | L27: บาท
B28: ( สูงสุด 30 วัน ต่ออุบัติเหตุในแต่ละครั้ง)
B29: 7.ค่าปลงศพ กรณีเสียชีวิตเนื่องจากการเจ็บป่วย และอุบัติเหตุ | K29: =VLOOKUP(B29,'Rate PA'!$A$2:$C$12,MATCH($F$12,'Rate PA'!$A$1:$C$1,0),0) -> 50000 | L29: บาท
B31: คุณสมบัติของผู้เอาประกันภัยไม่ประกอบอาชีพดังต่อไปนี้ คนงานก่อสร้าง , มอเตอร์ไซด์รับจ้าง , พนักงานรับ/ส่งเอกสาร ,
B32: ลูกเรือประมง , พนักงานดับเพลิง , ทหาร , ตํารวจ, ทนายความ, หมอ, พยาบาล และเจ้าหน้าที่สาธารณะสุขที่เกี่ยวข้องกับการรักษาพยาบาล
C33: A1 : ท่านเคยมีกรมธรรม์ประกันอุบัติเหตุหรือประกันสุขภาพหรือไม่
C34: £ เคยมี £ ไม่เคยมี กรุณาดำเนินการในข้อ A2
C35: A2 : ข้าพเจ้า ........................................................ รับทราบ และมีความเข้าใจในผลิตภัณฑ์และได้รับการอธิบายจากพนักงานอย่างเข้าใจดีแล้ว
B37: การเสียชีวิต การสูญเสียอวัยวะ สายตา หรือทุพพลภาพถาวรสิ้นเชิงจากอุบัติเหตุทั่วไป (อบ.1) | M37: - เคยมี | N37: .
B38: บริษัทฯ จะจ่ายค่าทดแทนเพียงรายการที่สูงสุดรายการเดียว ดังนี้
B39: - การเสียชีวิต 100% ของจำนวนเงินเอาประกันภัย
B40: - การทุพพลภาพถาวรสิ้นเชิง 100% ของจำนวนเงินเอาประกันภัย
B41: - การสูญเสียมือ หรือเท้า หรือสายตาทั้ง 2 ข้าง 100% ของจำนวนเงินเอาประกันภัย
B42: - การสูญเสียมือ 1 ข้างและเท้า 1 ข้าง 100% ของจำนวนเงินเอาประกันภัย
B43: - การสูญเสียมือ 1 ข้างและสายตา 1 ข้าง 100% ของจำนวนเงินเอาประกันภัย
B44: - การสูญเสียเท้า 1 ข้างและสายตา 1 ข้าง 100% ของจำนวนเงินเอาประกันภัย
B45: - การสูญเสียมือ 1 ข้าง หรือเท้า 1 ข้าง หรือ สายตา 1 ข้าง 60% ของจำนวนเงินเอาประกันภัย
B46: (1) อุบัติเหตุในขณะโดยสารยานขนส่งสาธารณะ หมายถึง ยานพาหนะทางบก ทางน้ำ หรือทางอากาศ โดยผู้ขับขี่ที่มีใบอนุญาตและ
B47: ดำเนินการโดยผู้ได้รับอนุญาตตามกฎหมายให้ดำเนินการขนส่งผู้โดยสารที่ชำระค่าโดยสารและมีกำหนดการปฏิบัติงานตามเส้นทางและตารางประจำ
B48: โดยเกิดขึ้นในขณะกำลังขึ้นหรือกำลังลง หรืออยู่ในยานขนส่งสาธารณะในฐานะผู้โดยสารที่ชำระค่าโดยสาร
B49: (2) อุบัติเหตุสาธารณะ หมายถึง ขณะผู้เอาประกันภัยอยู่ในอาคารสาธารณะของรัฐหรือเอกชน ในเวลาที่เปิดให้บริการแก่บุคคลทั่วไป และเกิดไฟไหม้รวมถึงการกระโดดหนีไฟเพื่อรักษาชีวิต
... B51: รวมถึงขณะผู้เอาประกันภัยเป็นผู้โดยสารและเกิดอุบัติเหตุขึ้น รถไฟ รถไฟลอยฟ้า รถไฟฟ้าใต้ดิน รถโดยสารขนส่งมวลชน รถโดยสารบริษัทขนส่ง รวมทั้งรถตู้ขนส่งมวลชน
C52: ลูกค้าสามารถขอยกเลิกกรมธรรม์ได้ภายใน 15 วัน นับจากวันที่ผู้ซื้อประกันภัยได้รับกรมธรรม์แล้ว
C53: หากเกินกำหนดระยะเวลาดังกล่าว บริษัทจะคืนเบี้ยประกันภัยหลังจากหักเบี้ยประกันภัยสำหรับระยะเวลาที่กรมธรรม์ประกันภัยฉบับนี้ได้ใช้บังคับมาแล้วออก
...

Sheet 03 เฮลธ์  แคร์ พลัส
A6: ใบเสนอขายประกันภัย
D7: โครงการ | E7: : | F7: ประกันสุขภาพ ซีไอเอ็มบี ไทย เฮลธ์ แคร์ พลัส
D9: เรียนเสนอ คุณ | E9: :
D11: อายุ | E11: : | F11: =ROUNDDOWN(YEARFRAC(TODAY(),DATE($M$11-543,VLOOKUP($L$11,Month!$B$2:$C$13,2,0),$K$11)),0) -> 31 | G11: ปี | H11: วัน/เดือน/ปี เกิด | K11: 29 | L11: ธันวาคม | M11: 2537
D12: แผนประกัน | E12: : | F12: แผน 100,000 | I12: กรณีผู้ขอเอาประกันภัยมีอายุมากกว่า 60 ปีขึ้นไป โปรดดำเนินการในข้อ A2 ด้านล่าง
D13: ระยะเวลาชำระเบี้ย | E13: : | F13: 1 ปี | G13: ระยะเวลาคุ้มครอง | I13: 1 ปี (รับประกันอายุ 18 ปี - 65 ปี ต่ออายุได้ถึง 70 ปี)
D14: เบี้ยประกันต่อปี | E14: : | F14: =VLOOKUP(IF($F$11<18,"<18",IF($F$11<26,"18-25",IF($F$11<31,"26-30",IF($F$11<36,"31-35",IF($F$11<41,"36-40",IF($F$11<46,"41-45",IF($F$11<51,"46-50",IF($F$11<56,"51-55",IF($F$11<61,"56-60",IF($F$11<66,"61-65",IF($F$11>70,">70",""))))))))))),'Rate Health'!$J$35:$AD$45,MATCH('03 เฮลธ์ แคร์ พลัส'!$F$12,'Rate Health'!$K$34:$AD$34,0)+1,0) -> 8500 | G14: บาท | H14: =IFERROR(F14,"อายุไม่อยู่ในกฏเกณฑ์การรับประกัน18-65ปี") -> 8500
B17: ผลประโยชน์ความคุ้มครอง
B18: บริษัทจะจ่ายผลประโยชน์ความคุ้มครอง ตามที่จ่ายจริง แต่ไม่เกินที่ระบุในตารางผลประโยชน์ ต่อการบาดเจ็บหรือการเจ็บป่วยแต่ละครั้ง
B20: ผลประโยชน์สูงสุดต่อการเข้าพักรักษาตัวเป็นผู้ป่วยในครั้งใดครั้งหนึ่ง (1) | L20: =VLOOKUP(F12,'Rate Health'!$AG$4:$AH$23,2,0) -> 100000 | M20: บาท
B21: หมวด 1. ค่าห้อง และค่าอาหาร ค่าบริการในโรงพยาบาล (ผู้ป่วยใน) ต่อการเข้าพักรักษาตัวจากการบาดเจ็บหรือการเจ็บป่วยครั้งใดครั้งหนึ่ง ต่อวัน
C22: - ค่าห้องทั่วไป และค่าอาหาร ค่าบริการในโรงพยาบาล ต่อการเข้าพักรักษาเป็นผู้ป่วยในครั้งใดครั้งหนึ่ง ต่อวัน สูงสุดไม่เกิน 30 วัน | L22: =VLOOKUP(L20,'Rate Health'!$AH$4:$AI$23,2,0) -> 1000 | M22: บาท
C23: - ค่าห้องผู้ป่วยวิกฤติ (Intensive Care Inpatient Room) ค่าอาหาร ค่าบริการในโรงพยาบาล ต่อวัน สูงสุดไม่เกิน 15 วัน | L23: =L22*2 -> 2000 | M23: บาท
C24: และเมื่อรวมกับห้องผู้ป่วยปกติแล้ว ไม่เกิน 30 วัน
B25: หมวด 2. ค่าบริการทางการแพทย์เพื่อการตรวจวินิจฉัยหรือบำบัดรักษา ค่าบริการโลหิตและส่วนประกอบของโลหิต
B26: ค่าบริการทางการพยาบาล ค่ายา ค่าสารอาหารทางหลอดเลือด และค่าเวชภัณฑ์
C27: 2.1 ค่าบริการทางการแพทย์เพื่อการตรวจวินิจฉัย | L27: จ่ายตามจริง | M27: บาท
C28: 2.2 ค่าบริการทางการแพทย์เพื่อการบำบัดรักษา ค่าบริการโลหิตและส่วนประกอบของโลหิต และค่าบริการทางการพยาบาล
C29: 2.3 ค่ายา ค่าสารอาหารทางหลอดเลือด และค่าเวชภัณฑ์
C30: 2.4 ค่ายา และค่าเวชภัณฑ์สิ้นเปลือง (เวชภัณฑ์ 1) สำหรับกลับบ้าน
B31: หมวด 3. ค่าผู้ประกอบวิชาชีพเวชกรรม (แพทย์) ตรวจรักษา | L31: จ่ายตามจริง | M31: บาท
B32: หมวด 4. ค่ารักษาพยาบาลโดยการผ่าตัด (ศัลยกรรม) และหัตถการ
C33: 4.1 ค่าห้องผ่าตัด และค่าห้องทำหัตถการ | L33: จ่ายตามจริง | M33: บาท
C34: 4.2 ค่ายา ค่าสารอาหารทางหลอดเลือด ค่าเวชภัณฑ์ และค่าอุปกรณ์การผ่าตัดและหัตถการ
C35: 4.3 ค่าผู้ประกอบวิชาชีพเวชกรรม ทำศัลยกรรมและหัตถการ สำหรับแพทย์ทำศัลยกรรม หัตถการ (รวมแพทย์ผู้ช่วยผ่าตัด) (Doctor fee)
C36: 4.4 ค่าผู้ประกอบวิชาชีพเวชกรรม วิสัญญีแพทย์ (Doctor fee)
C37: 4.5 ค่ารักษาพยาบาลโดยการผ่าตัดเปลี่ยนอวัยวะ | L37: 50000 | M37: บาท
B38: หมวด 5. การผ่าตัดใหญ่ที่ไม่ต้องเข้าพักรักษาตัวเป็นผู้ป่วยใน (Day Surgery) (เฉพาะค่าทำศัลยกรรมและหัตถการ) | L38: จ่ายตามจริง | M38: บาท
B39: หมวด 6. ค่าบริการทางการแพทย์เพื่อตรวจวินิจฉัยที่เกี่ยวข้องโดยตรงก่อนและหลังการเข้าพักรักษาตัวเป็นผู้ป่วยใน หรือค่ารักษาพยาบาลผู้ป่วยนอก
B40: ที่ต่อเนื่องที่เกี่ยวข้องโดยตรงหลังการเข้าพักรักษาตัวเป็นผู้ป่วยใน
C41: 6.1 ค่าบริการทางการแพทย์เพื่อการตรวจวินิจฉัยที่เกี่ยวข้องโดยตรงและเกิดขึ้นภายใน 30 วัน ก่อนและหลังการเข้าพักรักษาตัว | L41: จ่ายตามจริง | M41: บาท
C42: 6.2 ค่ารักษาพยาบาลผู้ป่วยนอกหลังการเข้าพักรักษาตัวเป็นผู้ป่วยในต่อครั้ง สำหรับการรักษาพยาบาลต่อเนื่อง ภายใน 30 วัน
C43: หลังจากออกจากการเข้าพักรักษาเป็นผู้ป่วยในครั้งนั้น (ไม่รวมค่าบริการทางการแพทย์เพื่อตรวจวินิจฉัย)
B44: หมวด 7. ค่ารักษาพยาบาลการบาดเจ็บ กรณีผู้ป่วยนอก ภายใน 24 ชั่วโมง ของการเกิดอุบัติเหตุต่อครั้ง | L44: =VLOOKUP(L20,'Rate Health'!$AH$4:$AJ$23,3,0) -> 20000 | M44: บาท
B45: หมวด 8. ค่าเวชศาสตร์ฟื้นฟู หลังการเข้าพักรักษาตัวเป็นผู้ป่วยใน | L45: จ่ายตามจริง | M45: บาท
B46: หมวด 9. ค่าบริการทางการแพทย์เพื่อการบำบัดรักษาโรคไตวายเรื้อรัง โดยการล้างไตผ่านทางเส้นเลือด | L46: 50000 | M46: บาท
B47: ต่อรอบปีกรมธรรม์ประกันภัย
B48: หมวด 10. ค่าบริการทางการแพทย์เพื่อการบำบัดรักษาโรคเนื้องอกหรือมะเร็ง โดยรังสีรักษา รังสีร่วมรักษา | L48: จ่ายตามจริง | M48: บาท
B49: เวชศาสตร์นิวเคลียร์รักษา ต่อรอบปีกรมธรรม์ประกันภัย
B50: หมวด 11. ค่าบริการทางการแพทย์เพื่อการบำบัดรักษาโรคมะเร็ง โดยเคมีบำบัด | L50: จ่ายตามจริง | M50: บาท
...

Sheet 04 โฮม แคร์
A6: ใบเสนอขายประกันภัย
D7: แบบประกันภัย | E7: : | F7: ประกันภัย ซีไอเอ็มบี ไทย โฮม แคร์
D9: เรียนเสนอ คุณ | E9: : | F9: คุณเบญจมาศ ธรรมจรุงวงศ์
D11: แผนประกัน | E11: : | F11: 5 ปี
D12: ระยะเวลาชำระเบี้ย | E12: : | F12: 1 ปี | G12: ระยะเวลาคุ้มครอง | I12: =F11 -> 5 ปี
D13: เบี้ยประกันต่อปี | E13: : | F13: =VLOOKUP(I12,'Rate HC'!A30:E34,5,0) -> 6799.9987 | G13: บาท
B16: ผลประโยชน์ความคุ้มครอง | K16: จำนวนเงินเอาประกันภัย
B17: ความคุ้มครองการประกันอัคคีภัย | K17: (บาท /ต่อปี)
B19: - คุ้มครองการสูญเสียหรือความเสียหายของสิ่งปลูกสร้าง และทรัพย์สินภายในสิ่งปลูกสร้างจาก ไฟไหม้ ฟ้าผ่า ระเบิด ภัยจากการเฉี่ยว และหรือการชนของยานพาหนะหรือสัตว์พาหนะ ภัยอากาศยาน ภัยเนื่องจากน้ำ (ไม่รวมน้ำท่วม) | K19: 500000 | L19: บาท
B20: ขยายความคุ้มครอง
B21: - กลุ่มภัยธรรมชาติ
C22: ภัยจากลมพายุ | K22: 500000 | L22: บาท
C23: ภัยจากแผ่นดินไหว หรือภูเขาไฟระเบิด หรือคลื่นใต้น้า หรือสึนามิ | K23: 500000 | L23: บาท
C24: ภัยจากลูกเห็บ | K24: 500000 | L24: บาท
C25: ภัยจากน้ำท่วม | K25: 50000 | L25: บาท
B26: - ความสูญเสียหรือความเสียหายต่อเครื่องไฟฟ้า | K26: 50000 | L26: บาท
B27: - ค่าใช้จ่ายสำหรับค่าเช่าที่อยู่อาศัยชั่วคราว* วันละ 1,000 บาท และสูงสุดตลอดอายุกรมธรรม์ไม่เกิน | K27: 50000 | L27: บาท
B28: - ความสูญเสียหรือความเสียหายต่อโบราณวัตถุหรือศิลปวัตถุ** สูงสุดตลอดอายุกรมธรรม์ไม่เกิน | K28: 10000 | L28: บาท
B29: - ความสูญเสียหรือความเสียหายต่อทรัพย์สินส่วนบุคคล*** สูงสุดตลอดอายุกรมธรรม์ไม่เกิน | K29: 10000 | L29: บาท
B30: หมวดการประกันภัยโจรกรรม
B31: - ความสูญเสียหรือความเสียหายของทรัพย์สิน ภายในตัวอาคาร อันเกิดจากการลักทรัพย์ ที่ปรากฏร่องรอยงัดแงะ หรือการชิงทรัพย์ หรือการปล้นทรัพย์ รวมถึงความเสียหายต่ออาคาร/ สิ่งปลูกสร้างอันเกิดจากการกระทำที่ได้รับความคุ้มครอง | K31: 50000 | L31: บาท
B32: หมวดการประกันภัยสำหรับเงิน
B33: - ความเสียหายของเงินภายในอาคารสถานที่เอาประกันภัย อันเกิดจากการชิงทรัพย์ ปล้นทรัพย์ และ/หรือ ความเสียหายของเงินภายในตู้นิรภัยหรือห้องนิรภัย อันเกิดจากการการโจรกรรมเงิน | K33: 50000 | L33: บาท
B34: หมวดการประกันภัยกระจก - ความเสียหายที่ทำให้กระจกแตก (ซึ่งไม่รวมถึงการเสียรูปหรือเสียหายนอกจากการร้าวตลอดความหนาของกระจก ความเสียหายที่เกิดในระหว่างการขนส่งหรือติดตั้ง หรือถอดถอน หรือเกี่ยวเนื่องโดยตรง และโดยอ้อมจากอัคคีภีย เป็นต้น) | K34: 50000 | L34: บาท
B35: หมวดความรับผิดต่อบุคคลภายนอก**** - การเสียชีวิต, บาดเจ็บ หรือทรัพย์สินของบุคคลภายนอกเสียหาย สูงสุดตลอดระยะเวลาเอาประกันภัยไม่เกิน | K35: 500000 | L35: บาท
B36: หมวดเงินชดเชยกรณีการเสียชีวิต ของผู้เอาประกันภัย คู่สมรส และ/หรือบุตร
B37: - จากอัคคีภัยและภัยเพิ่ม และจากภัยโจรกรรม ทีเกิดขึ้นภายในสถานทีเอาประกันภัย 100,000 บาท ต่อราย สูงสุด / ครั้งไม่เกิน | K37: 300000 | L37: บาท
B38: บริษัทจะจ่ายทดแทนความเสียหาย ไม่เกินจำนวนเงินเอาประกันภัยที่ระบุในตารางผลประโยชน์ความคุ้มครอง
B39: *ความคุ้มครองค่าเช่าที่อยู่อาศัยชั่วคราว จะชดใช้เป็นจำนวนเงินวันละ 1,000 บาท และสูงสุดตลอดอายุกรมธรรม์ไม่เกิน 50,000 บาท กรณีหากความเสียหายคิดเป็นมูลค่ามากกว่า 50% ของมูลค่าการจัดทดแทนโดยการสร้างขึ้นใหม่ **โบราณวัตถุหรือศิลปวัตถุ เช่น พระเครื่อง พระพุทธรูป ศิลาจารึก รูปปั้น รูปหล่อ ภาพเขียน รูปปั้น เครื่องลายคราม ฯลฯ ***ทรัพย์สินส่วนบุคคล หมายถึง ทรัพย์สินที่พกพาติดตัวได้ เช่น นาฬิกาข้อมือ โทรศัพท์มือถือ บัตรเติมเงินโทรศัพท์ คอมพิวเตอร์แบบกระเป๋าหิ้ว (Notebook) หรือแบบพกพา กล้องถ่ายรูปทุกประเภท กล้องวีดีโอ ฯลฯ ****บุคคลภายนอก ไม่รวมถึง ผู้เอาประกันภัย, ลูกจ้างของผู้เอาประกันภัย ผู้กระทำการแทน, บิดา มารดา บุตร คู่สมรส ญาติ หรือบุคคลที่พักอาศัยอยู่ร่วมกันในสถานที่เอาประกันภัย
C40: A1 : ท่านเคยมีกรมธรรม์ประกันอัคคีภัยหรือประกันภัยทรัพย์สินหรือไม่
C41: £ เคยมี £ ไม่เคยมี กรุณาดำเนินการในข้อ A2
C42: A2 : ข้าพเจ้า ........................................................ รับทราบ และมีความเข้าใจในผลิตภัณฑ์และได้รับการอธิบายจากพนักงานอย่างเข้าใจดีแล้ว
B43: หมายเหตุ
C44: 1. แผนประกันภัย ซีไอเอ็มบี ไทย โฮม แคร์ เป็นชื่อทางการตลาด ส่วนในกรมธรรม์จะเป็นชื่อแบบประกัน "ประกันอัคคีภัย รักษ์บ้าน"
C45: 2. แผนประกันภัย ซีไอเอ็มบี ไทย โฮม แคร์ เป็นผลิตภัณฑ์ประกันภัยมิใช่ผลิตภัณฑ์เงินฝาก
C46: 3. การนำส่งเบี้ยประกันภัยเป็นหน้าที่ของผู้เอาประกันภัย การที่นายหน้าประกันวินาศภัยเก็บเบี้ยประกันภัยเป็นการให้บริการเท่านั้น
C47: โดยศึกษาข้อมูลเพิ่มเติมได้จากคู่มือผู้เอาประกันภัย
C48: 4. การรับประกันภัยและการจ่ายผลประโยชน์ต่างๆ จะเป็นไปตามที่กำหนดไว้ในกรมธรรม์ประกันภัย บมจ. ซมโปะ ประกันภัย (ประเทศไทย)
C49: 5. รับประกันอาคารสิ่งปลูกสร้างอายุไม่เกิน 20 ปี
C50: 6. รับประกันภัยเฉพาะทรัพย์สินที่อยู่ภายในอาคารที่เป็นคอนกรีตล้วน หรือลักษณะตึก (สิ่งปลูกสร้างชั้น 1)
...

Sheet 05,06 กระบะ & SUV ชั้น 1
A9: ใบเสนอขายประกันภัย
A10: =VLOOKUP(B18,Sheet5!A2:B4,2,0) -> ประกันรถยนต์ ซีไอเอ็มบี ไทย มอเตอร์ แคร์ ชั้น 1 (เบี้ยเหมา)
A12: เรียนเสนอ คุณ | B12: คุณ พัทธีรา ชัยอมรธนากิตติ์ | G12: วันที่เริ่มคุ้มครอง | H12: 244529 | I12: วันที่/เดือน/ปี พ.ศ.
A14: ประเภทรถ | ยี่ห้อ / รุ่น | B14: รถกระบะ 4 ประตู | C14: | | D14: Toyota Hilux Revo | G14: ปีจดทะเบียนรถ (พ.ศ.) | H14: 2565 | J14: =YEAR(H12)-H14+1 -> 5 | K14: =IF(B14="รถกระบะ 2 ประตู",320,IF(B14="รถกระบะ 4 ประตู",110,110)) -> 110
A16: เครื่องยนต์/น้ำหนัก | B16: 2400 | G16: ทุนประกันภัย | H16: 570000 | I16: บาท
A18: แบบประกันภัย | B18: มอเตอร์ แคร์ (เบี้ยเหมา) - รถกระบะ | G18: จังหวัดทะเบียนรถ | H18: เลย | J18: =IF(OR(B18="มอเตอร์ แคร์ (เบี้ยเหมา) - รถกระบะ",B18="มอเตอร์ แคร์ (เบี้ยเหมา) - รถเก๋ง SUV"),VLOOKUP(H18,Dropdown_Mapping!$W$1:$X$81,2,0),"") -> UPC | K18: =IF(B18<>"มอเตอร์ แคร์ (เบี้ยเหมา) - รถกระบะ","",IF(MID(D14,1,4)="TOYO","Toyota","Non Toyota")) -> Toyota
A20: ประเภทการซ่อม | B20: ซ่อมอู่ในเครือ | G20: ทะเบียนรถยนต์ | H20: กท 8281
A22: ประเภทประกันภัยรถยนต์
A23: ความคุ้มครอง | G23: จำนวนเงินเอาประกันภัย
A24: ความรับผิดต่อบุคคลภายนอก
A25: ความเสียหายต่อชีวิต ร่างกาย หรืออนามัย (ส่วนเกิน พ.ร.บ.) | G25: =VLOOKUP($B$18&$K$18&$J$18&$J$14&$K$14,'Motor database'!$A$1:$Q$210,$J25,0) -> 500000 | H25: บาท ต่อคน | J25: ='Motor database'!I1 -> 9
G26: =VLOOKUP($B$18&$K$18&$J$18&$J$14&$K$14,'Motor database'!$A$1:$Q$210,$J26,0) -> 10000000 | H26: บาท ต่อครั้ง | J26: ='Motor database'!J1 -> 10
A27: ความเสียหายต่อทรัพย์สิน | G27: =VLOOKUP($B$18&$K$18&$J$18&$J$14&$K$14,'Motor database'!$A$1:$Q$210,$J27,0) -> 5000000 | H27: บาท ต่อครั้ง | J27: ='Motor database'!K1 -> 11
A28: ความเสียหายส่วนแรก ( Deductible ) | G28: ไม่มี
A30: ความเสียหายต่อรถยนต์
A31: ความเสียหายต่อตัวรถยนต์ | G31: =H16 -> 570000 | H31: บาท
A32: รถยนต์สูญหายและไฟไหม้ | G32: =G31 -> 570000 | H32: บาท
A33: ภัยธรรมชาติ ( น้ำท่วม ) | G33: =G32 -> 570000 | H33: บาท
A35: ความคุ้มครองตามเอกสารแนบท้าย
A36: อุบัติเหตุส่วนบุคคล | B36: ="("&VLOOKUP($B$18&$K$18&$J$18&$J$14&$K$14,'Motor database'!$A$1:$Q$210,$K36,0) -> (6 | C36: ผู้โดยสาร 1 ผู้ขับขี่) | G36: =VLOOKUP($B$18&$K$18&$J$18&$J$14&$K$14,'Motor database'!$A$1:$Q$210,$J36,0) -> 200000 | H36: บาท ต่อคน | J36: ='Motor database'!L1 -> 12 | K36: ='Motor database'!P1 -> 16
A37: ค่ารักษาพยาบาล | B37: ="("&VLOOKUP($B$18&$K$18&$J$18&$J$14&$K$14,'Motor database'!$A$1:$Q$210,$K37,0) -> (6 | C37: ผู้โดยสาร 1 ผู้ขับขี่) | G37: =VLOOKUP($B$18&$K$18&$J$18&$J$14&$K$14,'Motor database'!$A$1:$Q$210,$J37,0) -> 300000 | H37: บาท ต่อคน | J37: ='Motor database'!M1 -> 13 | K37: ='Motor database'!P1 -> 16
A38: การประกันตัวผู้ขับขี่ในคดีอาญา | G38: =VLOOKUP($B$18&$K$18&$J$18&$J$14&$K$14,'Motor database'!$A$1:$Q$210,$J38,0) -> 300000 | H38: บาท ต่อครั้ง | J38: ='Motor database'!N1 -> 14
A40: เบี้ยประกันภัยสุทธิ | B40: =VLOOKUP($B$18&$K$18&$J$18&$J$14&$K$14,'Motor database'!$A$1:$Q$210,$J40,0) -> 16755 | C40: บาท | D40: อาการแสตมป์ | E40: =IFERROR(ROUNDUP(B40*0.4%,0),"") -> 68 | F40: บาท | G40: ภาษีมูลค่าเพิ่ม | H40: =IFERROR(ROUND((B40+E40)*7%,2),"") -> 1177.61 | I40: บาท | J40: 6
A42: เบี้ยประกันภัยรวม | B42: =IFERROR(B40+E40+H40,"") -> 18000.61 | D42: บาท
A53: A1 : ท่านเคยมีกรมธรรม์ประกันรถยนต์หรือไม่
A54: £ เคยมี £ ไม่เคยมี กรุณาดำเนินการในข้อ A2
A55: A2 : ข้าพเจ้า ........................................................ รับทราบ และมีความเข้าใจในผลิตภัณฑ์และได้รับการอธิบายจากพนักงานอย่างเข้าใจดีแล้ว
A57: หมายเหตุ/Remarks
A58: 1.แผนประกันรถยนต์ ซีไอเอ็มบี ไทย มอเตอร์ แคร์ ชั้น (เบี้ยเหมา) เป็นชื่อทางการตลาด
A59: ส่วนในกรมธรรม์จะเป็นชื่อแบบประกัน "ประกันภัยรถยนต์ภาคสมัครใจ"
A60: 2. การนำส่งเบี้ยประกันภัยเป็นหน้าที่ของผู้เอาประกันภัย การที่นายหน้าประกันวินาศภัยเก็บเบี้ยประกันภัยเป็นการให้บริการเท่านั้น
A61: โดยศึกษาข้อมูลเพิ่มเติมได้จากคู่มือผู้เอาประกันภัย
A62: 3. การรับประกันภัยและการจ่ายผลประโยชน์ต่างๆ จะเป็นไปตามที่กำหนดไว้ในกรมธรรม์ประกันภัย บมจ. ซมโปะ ประกันภัย (ประเทศไทย)
A63: 4. เอกสารฉบับนี้เป็นเพียงใบเสนอราคาเท่านั้น บริษัทฯขอสงวนสิทธิ์ในการปรับปรุง และเปลี่ยนแปลงค่าเบี้ยประกันภัยรวมถึงการให้ความคุ้มครองใดๆ
A64: ต่อเมื่อบริษัทฯได้ตรวจสอบสภาพรถยนต์ และพิจารณายืนยันการประกันภัยรถยนต์แล้วเท่านั้น
A65: 5. ข้อเสนอประกันภัยรถยนต์นี้มีผลบังคับใช้ 30 วัน นับจากวันที่เสนอเบี้ยประกันภัย
... A74: 13. ฟรี ซมโปะ โรดไซด์ เซอร์วิส บริการช่วยเหลือฉุกเฉินทุกที่ทุกเวลา ตลอด 24 ชั่วโมง โทร. 02-039-5780
A80: เสนอโดยนายหน้า | E80: เลขที่ใบอนุญาตนายหน้าประกันวินาศภัย
A81: ธนาคารซีไอเอ็มบีไทย สาขา | F81: วัน/เวลาเสนอขาย_____________________________
A84: ข้าพเจ้าได้ทราบและเข้าใจข้อความข้างต้นเป็นอย่างดีโดยตลอดแล้ว เห็นว่าถูกต้องตรงตามเจตนารมณ์และความประสงค์ของข้าพเจ้าทุกประการ
...

Sheet 07,08 มอเตอร์ 2+ & 3+
A7: ใบเสนอขายประกันภัย
A8: =VLOOKUP($B$12,Sheet3!$A$2:$B$9,2,0) -> ประกันรถยนต์ ซีไอเอ็มบี ไทย มอเตอร์ แคร์ 2+
A10: เรียนเสนอ คุณ | B10: คุณยวงทอง เริ่มเสริมสุข | G10: วันที่เริ่มคุ้มครอง | H10: 244536 | I10: วัน/เดือน/ปี พ.ศ.
A12: ชื่อผลิตภัณฑ์ | B12: Motor 2+_Sedan for Non Europe car | G12: รหัสรถยนต์ | H12: =VLOOKUP($B$12&$B$18,'Motor database'!$A$1:$Q$42,$J12,0) -> 110 | J12: ='Motor database'!H1 -> 8
A14: ปีจดทะเบียนรถยนต์ (พ.ศ.) | G14: ทะเบียนรถยนต์ | H14: พข 1819 | J14: =YEAR(H10)-B14+1 -> 2570
A16: ประเภทการซ่อม | B16: ซ่อมอู่ในเครือ | G16: เครื่องยนต์/น้ำหนัก
A18: ทุนประกันภัย | B18: 300000 | E18: บาท | G18: เบี้ยประกันภัยสุทธิ | H18: =IF(J14>20,"อายุรถเกิน 20 ปี",VLOOKUP($B$12&B18,'Motor database'!$A$3:$Q$42,4,0)) -> อายุรถเกิน 20 ปี | I18: บาท
A20: ประเภทประกันภัยรถยนต์
A21: ความคุ้มครอง | G21: จำนวนเงินเอาประกันภัย
A22: ความรับผิดต่อบุคคลภายนอก
A23: ความเสียหายต่อชีวิต ร่างกาย หรืออนามัย (ส่วนเกิน พ.ร.บ.) | G23: =VLOOKUP($B$12&$B$18,'Motor database'!$A$1:$Q$42,$J23,0) -> 1000000 | H23: บาท ต่อคน | J23: ='Motor database'!I1 -> 9
G24: =VLOOKUP($B$12&$B$18,'Motor database'!$A$1:$Q$42,$J24,0) -> 10000000 | H24: บาท ต่อครั้ง | J24: ='Motor database'!J1 -> 10
A25: ความเสียหายต่อทรัพย์สิน | G25: =VLOOKUP($B$12&$B$18,'Motor database'!$A$1:$Q$42,$J25,0) -> 1000000 | H25: บาท ต่อครั้ง | J25: ='Motor database'!K1 -> 11
A26: ความเสียหายส่วนแรก ( Deductible ) | G26: ไม่มี
A28: ความเสียหายต่อรถยนต์
A29: ความเสียหายต่อตัวรถยนต์ ( กรณีมีคู่กรณียานพาหนะทางบก ) | G29: =VLOOKUP($B$12,Sheet3!$A$2:$C$9,3,0) -> 300000 | H29: บาท
A30: รถยนต์สูญหายและไฟไหม้ | G30: =VLOOKUP($B$12,Sheet3!$A$2:$D$9,4,0) -> 300000 | H30: บาท
A31: ภัยธรรมชาติ ( น้ำท่วม ) | G31: - | H31: บาท
A33: ความคุ้มครองตามเอกสารแนบท้าย
A34: อุบัติเหตุส่วนบุคคล | B34: ="("&VLOOKUP($B$12&$B$18,'Motor database'!$A$3:$Q$42,$K34,0) -> (6 | C34: ผู้โดยสาร 1 ผู้ขับขี่) | G34: =VLOOKUP($B$12&$B$18,'Motor database'!$A$1:$Q$42,$J34,0) -> 100000 | H34: บาท ต่อคน | J34: ='Motor database'!L1 -> 12 | K34: ='Motor database'!P1 -> 16
A35: ค่ารักษาพยาบาล | B35: ="("&VLOOKUP($B$12&$B$18,'Motor database'!$A$3:$Q$42,$K35,0) -> (6 | C35: ผู้โดยสาร 1 ผู้ขับขี่) | G35: =VLOOKUP($B$12&$B$18,'Motor database'!$A$1:$Q$42,$J35,0) -> 100000 | H35: บาท ต่อคน | J35: ='Motor database'!M1 -> 13 | K35: ='Motor database'!P1 -> 16
A36: การประกันตัวผู้ขับขี่ในคดีอาญา | G36: =VLOOKUP($B$12&$B$18,'Motor database'!$A$1:$Q$42,$J36,0) -> 300000 | H36: บาท ต่อครั้ง | J36: ='Motor database'!N1 -> 14
A38: เบี้ยประกันภัยสุทธิ | B38: =VLOOKUP($B$12&$B$18,'Motor database'!$A$1:$Q$42,$J38,0) -> 8005 | C38: บาท | D38: อาการแสตมป์ | E38: =IFERROR(ROUNDUP(B38*0.4%,0),"") -> 33 | F38: บาท | G38: ภาษีมูลค่าเพิ่ม | H38: =IFERROR(ROUND((B38+E38)*7%,2),"") -> 562.66 | I38: บาท | J38: 6
A40: เบี้ยประกันภัยรวม | B40: =IFERROR(B38+E38+H38,"") -> 8600.66 | D40: บาท
A51: A1 : ท่านเคยมีกรมธรรม์ประกันรถยนต์หรือไม่
A52: £ เคยมี £ ไม่เคยมี กรุณาดำเนินการในข้อ A2
A53: A2 : ข้าพเจ้า ........................................................ รับทราบ และมีความเข้าใจในผลิตภัณฑ์และได้รับการอธิบายจากพนักงานอย่างเข้าใจดีแล้ว
A56: =CONCATENATE(L56,L58) -> 1. แผนประกันรถยนต์ ซีไอเอ็มบี ไทย มอเตอร์ แคร์ 2+ | D56: เป็นชื่อทางการตลาด | L56: 1. แผน
A57: ส่วนในกรมธรรม์จะเป็นชื่อแบบประกัน "ประกันภัยรถยนต์ภาคสมัครใจ"
A58: 2. การนำส่งเบี้ยประกันภัยเป็นหน้าที่ของผู้เอาประกันภัย การที่นายหน้าประกันวินาศภัยเก็บเบี้ยประกันภัยเป็นการให้บริการเท่านั้น | L58: =A8 -> ประกันรถยนต์ ซีไอเอ็มบี ไทย มอเตอร์ แคร์ 2+
A59: โดยศึกษาข้อมูลเพิ่มเติมได้จากคู่มือผู้เอาประกันภัย
A60: 3. การรับประกันภัยและการจ่ายผลประโยชน์ต่างๆ จะเป็นไปตามที่กำหนดไว้ในกรมธรรม์ประกันภัย บมจ. ซมโปะ ประกันภัย (ประเทศไทย)
A61: 4. เอกสารฉบับนี้เป็นเพียงใบเสนอราคาเท่านั้น บริษัทฯขอสงวนสิทธิ์ในการปรับปรุง และเปลี่ยนแปลงค่าเบี้ยประกันภัยรวมถึงการให้ความคุ้มครองใดๆ
A62: ต่อเมื่อบริษัทฯได้ตรวจสอบสภาพรถยนต์ และพิจารณายืนยันการประกันภัยรถยนต์แล้วเท่านั้น
A63: 5. ข้อเสนอประกันภัยรถยนต์นี้มีผลบังคับใช้ 30 วัน นับจากวันที่เสนอเบี้ยประกันภัย
A64: 6. ข้อเสนอประกันภัยรถยนต์นี้ ลูกค้าสามารถเลือกทำประกันด้วยความสมัครใจ และปฏิเสธได้ถ้าหาก ผลประโยชน์ เงื่อนไข ข้อกำหนด ไม่เป็นไปตามความต้องการ
A65: 7. รับประกันภัยอายุรถ 2 - 20 ปี
A66: 8. รับประกันภัยรถใช้ส่วนบุคคลเท่านั้น ไม่ใช้เพื่อการพาณิชย์ รับจ้างหรือให้เช่า
A67: 9. ไม่คุ้มครองอุปกรณ์เสริม และอุปกรณ์ตกแต่งทุกกรณี
A68: 10. เบี้ยประกันภัยข้างต้นรวมส่วนลดกล้อง CCTV และไม่สามารถให้ส่วนลดอื่นๆเพิ่มเติม
...

Sheet Month
B2: มกราคม | C2: 1
B3: กุมภาพันธ์ | C3: 2
B4: มีนาคม | C4: 3
B5: เมษายน | C5: 4
B6: พฤษภาคม | C6: 5
B7: มิถุนายน | C7: 6
B8: กรกฎาคม | C8: 7
B9: สิงหาคม | C9: 8
B10: กันยายน | C10: 9
B11: ตุลาคม | C11: 10
B12: พฤศจิกายน | C12: 11
B13: ธันวาคม | C13: 12

Sheet 05,06 มอเตอร์ แคร์ ชั้น 1 (2)
B1: บริษัท ซมโปะ ประกันภัย (ประเทศไทย) จำกัด (มหาชน)
B2: สำนักงานใหญ่ ชั้น 12, 14 อาคารอับดุลราฮิม เพลซ,
B3: เลขที่ 990 ถนนพระรามที่ 4, แขวงสีลม เขตบางรัก กรุงเทพฯ 10500 โทร 02-119-3000 cs@sompo.co.th
B4: ทะเบียนเลขที่ / เลขประจำตัวผู้เสียภาษีอากร ( Tax ID. No. ) 0107555000287
A6: ใบเสนอขายประกันภัย
A7: ประกันรถยนต์ ซีไอเอ็มบี ไทย มอเตอร์ แคร์ ชั้น 1
A9: เรียนเสนอ คุณ | B9: คุณพัชรี แซ่พุ้น | G9: วันที่เริ่มคุ้มครอง | H9: 242471 | I9: วันที่/เดือน/ปี พ.ศ.
A11: ประเภทรถ | ยี่ห้อ / รุ่น | B11: BMW | C11: | | D11: Z4 | G11: ปีจดทะเบียนรถ (พ.ศ.) | H11: 2019 | J11: =YEAR(H9)-H11+1 -> 545 | K11: =IF(B11="รถกระบะ 2 ประตู",320,IF(B11="รถกระบะ 4 ประตู",110,110)) -> 110
A13: เครื่องยนต์/น้ำหนัก | B13: 2400 | G13: ทุนประกันภัย | H13: Z4 | I13: บาท
A15: แบบประกันภัย | G15: จังหวัดทะเบียนรถ | H15: กรุงเทพมหานคร | J15: =IF(OR(B15="มอเตอร์ แคร์ (เบี้ยเหมา) - รถกระบะ",B15="มอเตอร์ แคร์ (เบี้ยเหมา) - รถเก๋ง SUV"),VLOOKUP(H15,Dropdown_Mapping!$W$1:$X$81,2,0),"") | K15: =IF(B15<>"มอเตอร์ แคร์ (เบี้ยเหมา) - รถกระบะ","",IF(MID(D11,1,4)="TOYO","Toyota","Non Toyota"))
A17: ประเภทการซ่อม | B17: :ซ่อมห้าง | G17: ทะเบียนรถยนต์ | H17: 9กผ72
A19: ประเภทประกันภัยรถยนต์
A20: ความคุ้มครอง | G20: จำนวนเงินเอาประกันภัย
A21: ความรับผิดต่อบุคคลภายนอก
A22: ความเสียหายต่อชีวิต ร่างกาย หรืออนามัย (ส่วนเกิน พ.ร.บ.) | G22: 1000000 | H22: บาท ต่อคน | J22: ='Motor database'!I1 -> 9
G23: 10000000 | H23: บาท ต่อครั้ง | J23: ='Motor database'!J1 -> 10
A24: ความเสียหายต่อทรัพย์สิน | G24: 2500000 | H24: บาท ต่อครั้ง | J24: ='Motor database'!K1 -> 11
A25: ความเสียหายส่วนแรก ( Deductible ) | G25: ไม่มี
A27: ความเสียหายต่อรถยนต์
A28: ความเสียหายต่อตัวรถยนต์ | G28: 2400000 | H28: บาท
A29: รถยนต์สูญหายและไฟไหม้ | G29: =G28 -> 2400000 | H29: บาท
A30: ภัยธรรมชาติ ( น้ำท่วม พายุ ) | G30: =G29 -> 2400000 | H30: บาท
A32: ความคุ้มครองตามเอกสารแนบท้าย
A33: อุบัติเหตุส่วนบุคคล | B33: 1 | C33: ผู้โดยสาร 1 ผู้ขับขี่) | G33: 100000 | H33: บาท ต่อคน | J33: ='Motor database'!L1 -> 12 | K33: ='Motor database'!P1 -> 16
A34: ค่ารักษาพยาบาล | B34: 1 | C34: ผู้โดยสาร 1 ผู้ขับขี่) | G34: 100000 | H34: บาท ต่อคน | J34: ='Motor database'!M1 -> 13 | K34: ='Motor database'!P1 -> 16
A35: การประกันตัวผู้ขับขี่ในคดีอาญา | G35: 300000 | H35: บาท ต่อครั้ง | J35: ='Motor database'!N1 -> 14
A37: เบี้ยประกันภัยสุทธิ | B37: 76698 | C37: บาท | D37: อาการแสตมป์ | E37: =IFERROR(ROUNDUP(B37*0.4%,0),"") -> 307 | F37: บาท | G37: ภาษีมูลค่าเพิ่ม | H37: =IFERROR(ROUND((B37+E37)*7%,2),"") -> 5390.35 | I37: บาท | J37: 6
A39: เบี้ยประกันภัยรวม | B39: =IFERROR(B37+E37+H37,"") -> 82395.35 | D39: บาท
A55: หมายเหตุ/Remarks
A57: =CONCATENATE(L57,L59) -> 1. แผนประกันรถยนต์ ซีไอเอ็มบี ไทย มอเตอร์ แคร์ ชั้น 1 | D57: เป็นชื่อทางการตลาด | L57: 1. แผน
A58: ส่วนในกรมธรรม์จะเป็นชื่อแบบประกัน "ประกันภัยรถยนต์ภาคสมัครใจ"
A59: 2. การนำส่งเบี้ยประกันภัยเป็นหน้าที่ของผู้เอาประกันภัย การที่นายหน้าประกันวินาศภัยเก็บเบี้ยประกันภัยเป็นการให้บริการเท่านั้น | L59: =A7 -> ประกันรถยนต์ ซีไอเอ็มบี ไทย มอเตอร์ แคร์ ชั้น 1
A60: โดยศึกษาข้อมูลเพิ่มเติมได้จากคู่มือผู้เอาประกันภัย
A61: 3. การรับประกันภัยและการจ่ายผลประโยชน์ต่างๆ จะเป็นไปตามที่กำหนดไว้ในกรมธรรม์ประกันภัย บมจ. ซมโปะ ประกันภัย (ประเทศไทย)
A62: 4. เอกสารฉบับนี้เป็นเพียงใบเสนอราคาเท่านั้น บริษัทฯขอสงวนสิทธิ์ในการปรับปรุง และเปลี่ยนแปลงค่าเบี้ยประกันภัยรวมถึงการให้ความคุ้มครองใดๆ
A63: ต่อเมื่อบริษัทฯได้ตรวจสอบสภาพรถยนต์ และพิจารณายืนยันการประกันภัยรถยนต์แล้วเท่านั้น
A64: 5. ข้อเสนอประกันภัยรถยนต์นี้มีผลบังคับใช้ 30 วัน นับจากวันที่เสนอเบี้ยประกันภัย
A65: 6. ข้อเสนอประกันภัยรถยนต์นี้ ลูกค้าสามารถเลือกทำประกันด้วยความสมัครใจ และปฏิเสธได้ถ้าหาก ผลประโยชน์ เงื่อนไข ข้อกำหนด ไม่เป็นไปตามความต้องการ
A66: 7. รับประกันภัยอายุรถ 2 - 20 ปี
A67: 8. รับประกันภัยรถใช้ส่วนบุคคลเท่านั้น ไม่ใช้เพื่อการพาณิชย์ รับจ้างหรือให้เช่า
...

Sheet Sheet3
A2: Motor 2+_Sedan for Non Europe car | B2: ประกันรถยนต์ ซีไอเอ็มบี ไทย มอเตอร์ แคร์ 2+ | C2: ='07,08 มอเตอร์ 2+ & 3+'!$B$18 -> 300000 | D2: ='07,08 มอเตอร์ 2+ & 3+'!$B$18 -> 300000
A3: Motor 2+_Pickup 4 doors | B3: ประกันรถยนต์ ซีไอเอ็มบี ไทย มอเตอร์ แคร์ 2+ | C3: ='07,08 มอเตอร์ 2+ & 3+'!$B$18 -> 300000 | D3: ='07,08 มอเตอร์ 2+ & 3+'!$B$18 -> 300000
A4: Motor 2+_Sedan for Europe car | B4: ประกันรถยนต์ ซีไอเอ็มบี ไทย มอเตอร์ แคร์ 2+ | C4: ='07,08 มอเตอร์ 2+ & 3+'!$B$18 -> 300000 | D4: ='07,08 มอเตอร์ 2+ & 3+'!$B$18 -> 300000
A5: Motor 2+_Pickup 2 doors | B5: ประกันรถยนต์ ซีไอเอ็มบี ไทย มอเตอร์ แคร์ 2+ | C5: ='07,08 มอเตอร์ 2+ & 3+'!$B$18 -> 300000 | D5: ='07,08 มอเตอร์ 2+ & 3+'!$B$18 -> 300000
A6: Motor 3+_Sedan for Non Europe car | B6: ประกันรถยนต์ ซีไอเอ็มบี ไทย มอเตอร์ แคร์ 3+ | C6: ='07,08 มอเตอร์ 2+ & 3+'!$B$18 -> 300000 | D6: -
A7: Motor 3+_Pickup 4 doors | B7: ประกันรถยนต์ ซีไอเอ็มบี ไทย มอเตอร์ แคร์ 3+ | C7: ='07,08 มอเตอร์ 2+ & 3+'!$B$18 -> 300000 | D7: -
A8: Motor 3+_Sedan for Europe car | B8: ประกันรถยนต์ ซีไอเอ็มบี ไทย มอเตอร์ แคร์ 3+ | C8: ='07,08 มอเตอร์ 2+ & 3+'!$B$18 -> 300000 | D8: -
A9: Motor 3+_Pickup 2 doors | B9: ประกันรถยนต์ ซีไอเอ็มบี ไทย มอเตอร์ แคร์ 3+ | C9: ='07,08 มอเตอร์ 2+ & 3+'!$B$18 -> 300000 | D9: -

Sheet Motor database
A1: 1 | B1: =A1+1 -> 2 | C1: =B1+1 -> 3 | D1: =C1+1 -> 4 | E1: =D1+1 -> 5 | F1: =E1+1 -> 6 | G1: =F1+1 -> 7 | H1: =G1+1 -> 8 | I1: =H1+1 -> 9 | ... Q1: =P1+1 -> 17
B2: Product name | C2: SIT Car group | D2: Province | E2: SI | F2: Net Premium | G2: Vehicle year | H2: Vehicle code | I2: TPBI/person | J2: TPBI/accident | K2: TPPD/accident | L2: PA | M2: ME | N2: BB | O2: No. of Driver | P2: No. of Passenger | Q2: No. of Driver + Passenger | W2: Product name | X2: SI
A3: =B3&E3 -> Motor 2+_Sedan for Non Europe car100000 | B3: Motor 2+_Sedan for Non Europe car | E3: 100000 | F3: 7074 | H3: 110 | I3: 1000000 | J3: 10000000 | K3: 1000000 | L3: 100000 | M3: 100000 | N3: 300000 | O3: 1 | P3: 6 | Q3: =SUM(O3:P3) -> 7 | W3: Motor 2+_Sedan for Non Europe car | X3: 100000
A4: =B4&E4 -> Motor 2+_Sedan for Non Europe car150000 | B4: Motor 2+_Sedan for Non Europe car | E4: 150000 | F4: 7260 | H4: 110 | I4: 1000000 | J4: 10000000 | K4: 1000000 | L4: 100000 | M4: 100000 | N4: 300000 | O4: 1 | P4: 6 | Q4: =SUM(O4:P4) -> 7 | W4: Motor 2+_Pickup 4 doors | X4: 150000
A5: =B5&E5 -> Motor 2+_Sedan for Non Europe car200000 | B5: Motor 2+_Sedan for Non Europe car | E5: 200000 | F5: 7540 | H5: 110 | I5: 1000000 | J5: 10000000 | K5: 1000000 | L5: 100000 | M5: 100000 | N5: 300000 | O5: 1 | P5: 6 | Q5: =SUM(O5:P5) -> 7 | W5: Motor 2+_Sedan for Europe car | X5: 200000
A6: =B6&E6 -> Motor 2+_Sedan for Non Europe car250000 | B6: Motor 2+_Sedan for Non Europe car | E6: 250000 | F6: 7726 | H6: 110 | I6: 1000000 | J6: 10000000 | K6: 1000000 | L6: 100000 | M6: 100000 | N6: 300000 | O6: 1 | P6: 6 | Q6: =SUM(O6:P6) -> 7 | W6: Motor 2+_Pickup 2 doors | X6: 250000
A7: =B7&E7 -> Motor 2+_Sedan for Non Europe car300000 | B7: Motor 2+_Sedan for Non Europe car | E7: 300000 | F7: 8005 | H7: 110 | I7: 1000000 | J7: 10000000 | K7: 1000000 | L7: 100000 | M7: 100000 | N7: 300000 | O7: 1 | P7: 6 | Q7: =SUM(O7:P7) -> 7 | W7: Motor 3+_Sedan for Non Europe car | X7: 300000
A8: =B8&E8 -> Motor 2+_Pickup 4 doors100000 | B8: Motor 2+_Pickup 4 doors | E8: 100000 | F8: 7074 | H8: 110 | I8: 1000000 | J8: 10000000 | K8: 1000000 | L8: 100000 | M8: 100000 | N8: 300000 | O8: 1 | P8: 6 | Q8: =SUM(O8:P8) -> 7 | W8: Motor 3+_Pickup 4 doors
A9: =B9&E9 -> Motor 2+_Pickup 4 doors150000 | B9: Motor 2+_Pickup 4 doors | E9: 150000 | F9: 7260 | H9: 110 | I9: 1000000 | J9: 10000000 | K9: 1000000 | L9: 100000 | M9: 100000 | N9: 300000 | O9: 1 | P9: 6 | Q9: =SUM(O9:P9) -> 7 | W9: Motor 3+_Sedan for Europe car
A10: =B10&E10 -> Motor 2+_Pickup 4 doors200000 | B10: Motor 2+_Pickup 4 doors | E10: 200000 | F10: 7540 | H10: 110 | I10: 1000000 | J10: 10000000 | K10: 1000000 | L10: 100000 | M10: 100000 | N10: 300000 | O10: 1 | P10: 6 | Q10: =SUM(O10:P10) -> 7 | W10: Motor 3+_Pickup 2 doors
A11: =B11&E11 -> Motor 2+_Pickup 4 doors250000 | B11: Motor 2+_Pickup 4 doors | E11: 250000 | F11: 7726 | H11: 110 | I11: 1000000 | J11: 10000000 | K11: 1000000 | L11: 100000 | M11: 100000 | N11: 300000 | O11: 1 | P11: 6 | Q11: =SUM(O11:P11) -> 7
A12: =B12&E12 -> Motor 2+_Pickup 4 doors300000 | B12: Motor 2+_Pickup 4 doors | E12: 300000 | F12: 8005 | H12: 110 | I12: 1000000 | J12: 10000000 | K12: 1000000 | L12: 100000 | M12: 100000 | N12: 300000 | O12: 1 | P12: 6 | Q12: =SUM(O12:P12) -> 7
A13: =B13&E13 -> Motor 2+_Sedan for Europe car100000 | B13: Motor 2+_Sedan for Europe car | E13: 100000 | F13: 10146 | H13: 110 | I13: 1000000 | J13: 10000000 | K13: 1000000 | L13: 100000 | M13: 100000 | N13: 300000 | O13: 1 | P13: 6 | Q13: =SUM(O13:P13) -> 7
A14: =B14&E14 -> Motor 2+_Sedan for Europe car150000 | B14: Motor 2+_Sedan for Europe car | E14: 150000 | F14: 11636 | H14: 110 | I14: 1000000 | J14: 10000000 | K14: 1000000 | L14: 100000 | M14: 100000 | N14: 300000 | O14: 1 | P14: 6 | Q14: =SUM(O14:P14) -> 7
A15: =B15&E15 -> Motor 2+_Sedan for Europe car200000 | B15: Motor 2+_Sedan for Europe car | E15: 200000 | F15: 12101 | H15: 110 | I15: 1000000 | J15: 10000000 | K15: 1000000 | L15: 100000 | M15: 100000 | N15: 300000 | O15: 1 | P15: 6 | Q15: =SUM(O15:P15) -> 7
A16: =B16&E16 -> Motor 2+_Sedan for Europe car250000 | B16: Motor 2+_Sedan for Europe car | E16: 250000 | F16: 12566 | H16: 110 | I16: 1000000 | J16: 10000000 | K16: 1000000 | L16: 100000 | M16: 100000 | N16: 300000 | O16: 1 | P16: 6 | Q16: =SUM(O16:P16) -> 7
A17: =B17&E17 -> Motor 2+_Sedan for Europe car300000 | B17: Motor 2+_Sedan for Europe car | E17: 300000 | F17: 13125 | H17: 110 | I17: 1000000 | J17: 10000000 | K17: 1000000 | L17: 100000 | M17: 100000 | N17: 300000 | O17: 1 | P17: 6 | Q17: =SUM(O17:P17) -> 7
A18: =B18&E18 -> Motor 2+_Pickup 2 doors100000 | B18: Motor 2+_Pickup 2 doors | E18: 100000 | F18: 8192 | H18: 320 | I18: 1000000 | J18: 10000000 | K18: 1000000 | L18: 100000 | M18: 100000 | N18: 300000 | O18: 1 | P18: 2 | Q18: =SUM(O18:P18) -> 3
A19: =B19&E19 -> Motor 2+_Pickup 2 doors150000 | B19: Motor 2+_Pickup 2 doors | E19: 150000 | F19: 8378 | H19: 320 | I19: 1000000 | J19: 10000000 | K19: 1000000 | L19: 100000 | M19: 100000 | N19: 300000 | O19: 1 | P19: 2 | Q19: =SUM(O19:P19) -> 3
A20: =B20&E20 -> Motor 2+_Pickup 2 doors200000 | B20: Motor 2+_Pickup 2 doors | E20: 200000 | F20: 8564 | H20: 320 | I20: 1000000 | J20: 10000000 | K20: 1000000 | L20: 100000 | M20: 100000 | N20: 300000 | O20: 1 | P20: 2 | Q20: =SUM(O20:P20) -> 3
A21: =B21&E21 -> Motor 2+_Pickup 2 doors250000 | B21: Motor 2+_Pickup 2 doors | E21: 250000 | F21: 8843 | H21: 320 | I21: 1000000 | J21: 10000000 | K21: 1000000 | L21: 100000 | M21: 100000 | N21: 300000 | O21: 1 | P21: 2 | Q21: =SUM(O21:P21) -> 3
A22: =B22&E22 -> Motor 2+_Pickup 2 doors300000 | B22: Motor 2+_Pickup 2 doors | E22: 300000 | F22: 9308 | H22: 320 | I22: 1000000 | J22: 10000000 | K22: 1000000 | L22: 100000 | M22: 100000 | N22: 300000 | O22: 1 | P22: 2 | Q22: =SUM(O22:P22) -> 3
... A42: =B42&E42 -> Motor 3+_Pickup 2 doors300000 | B42: Motor 3+_Pickup 2 doors | E42: 300000 | F42: 9029 | H42: 320 | I42: 1000000 | J42: 10000000 | K42: 1000000 | L42: 100000 | M42: 100000 | N42: 300000 | O42: 1 | P42: 2 | Q42: =SUM(O42:P42) -> 3
A43: =B43&C43&D43&G43&H43 -> มอเตอร์ แคร์ (เบี้ยเหมา) - รถกระบะNon ToyotaUPC2320 | B43: มอเตอร์ แคร์ (เบี้ยเหมา) - รถกระบะ | C43: Non Toyota | D43: UPC | F43: 14894 | G43: 2 | H43: 320 | I43: 500000 | J43: 10000000 | K43: 2500000 | L43: 200000 | M43: 300000 | N43: 300000 | O43: 1 | P43: 2 | Q43: 3
A44: =B44&C44&D44&G44&H44 -> มอเตอร์ แคร์ (เบี้ยเหมา) - รถกระบะNon ToyotaUPC3320 | B44: มอเตอร์ แคร์ (เบี้ยเหมา) - รถกระบะ | C44: Non Toyota | D44: UPC | F44: 14894 | G44: 3 | H44: 320 | I44: 500000 | J44: 10000000 | K44: 2500000 | L44: 200000 | M44: 300000 | N44: 300000 | O44: 1 | P44: 2 | Q44: 3
A45: =B45&C45&D45&G45&H45 -> มอเตอร์ แคร์ (เบี้ยเหมา) - รถกระบะNon ToyotaUPC4320 | B45: มอเตอร์ แคร์ (เบี้ยเหมา) - รถกระบะ | C45: Non Toyota | D45: UPC | F45: 14894 | G45: 4 | H45: 320 | I45: 500000 | J45: 10000000 | K45: 2500000 | L45: 200000 | M45: 300000 | N45: 300000 | O45: 1 | P45: 2 | Q45: 3
A46: =B46&C46&D46&G46&H46 -> มอเตอร์ แคร์ (เบี้ยเหมา) - รถกระบะNon ToyotaUPC5320 | B46: มอเตอร์ แคร์ (เบี้ยเหมา) - รถกระบะ | C46: Non Toyota | D46: UPC | F46: 14894 | G46: 5 | H46: 320 | I46: 500000 | J46: 10000000 | K46: 2500000 | L46: 200000 | M46: 300000 | N46: 300000 | O46: 1 | P46: 2 | Q46: 3
A47: =B47&C47&D47&G47&H47 -> มอเตอร์ แคร์ (เบี้ยเหมา) - รถกระบะNon ToyotaUPC6320 | B47: มอเตอร์ แคร์ (เบี้ยเหมา) - รถกระบะ | C47: Non Toyota | D47: UPC | F47: 13032 | G47: 6 | H47: 320 | I47: 500000 | J47: 10000000 | K47: 2500000 | L47: 200000 | M47: 300000 | N47: 300000 | O47: 1 | P47: 2 | Q47: 3
A48: =B48&C48&D48&G48&H48 -> มอเตอร์ แคร์ (เบี้ยเหมา) - รถกระบะNon ToyotaUPC7320 | B48: มอเตอร์ แคร์ (เบี้ยเหมา) - รถกระบะ | C48: Non Toyota | D48: UPC | F48: 13032 | G48: 7 | H48: 320 | I48: 500000 | J48: 10000000 | K48: 2500000 | L48: 200000 | M48: 300000 | N48: 300000 | O48: 1 | P48: 2 | Q48: 3
A49: =B49&C49&D49&G49&H49 -> มอเตอร์ แคร์ (เบี้ยเหมา) - รถกระบะNon ToyotaUPC8320 | B49: มอเตอร์ แคร์ (เบี้ยเหมา) - รถกระบะ | C49: Non Toyota | D49: UPC | F49: 13032 | G49: 8 | H49: 320 | I49: 500000 | J49: 10000000 | K49: 2500000 | L49: 200000 | M49: 300000 | N49: 300000 | O49: 1 | P49: 2 | Q49: 3
A50: =B50&C50&D50&G50&H50 -> มอเตอร์ แคร์ (เบี้ยเหมา) - รถกระบะNon ToyotaUPC9320 | B50: มอเตอร์ แคร์ (เบี้ยเหมา) - รถกระบะ | C50: Non Toyota | D50: UPC | F50: 13032 | G50: 9 | H50: 320 | I50: 500000 | J50: 10000000 | K50: 2500000 | L50: 200000 | M50: 300000 | N50: 300000 | O50: 1 | P50: 2 | Q50: 3
A51: =B51&C51&D51&G51&H51 -> มอเตอร์ แคร์ (เบี้ยเหมา) - รถกระบะNon ToyotaUPC10320 | B51: มอเตอร์ แคร์ (เบี้ยเหมา) - รถกระบะ | C51: Non Toyota | D51: UPC | F51: 13032 | G51: 10 | H51: 320 | I51: 500000 | J51: 10000000 | K51: 2500000 | L51: 200000 | M51: 300000 | N51: 300000 | O51: 1 | P51: 2 | Q51: 3
A52: =B52&C52&D52&G52&H52 -> มอเตอร์ แคร์ (เบี้ยเหมา) - รถกระบะNon ToyotaUPC11320 | B52: มอเตอร์ แคร์ (เบี้ยเหมา) - รถกระบะ | C52: Non Toyota | D52: UPC | F52: 13032 | G52: 11 | H52: 320 | I52: 500000 | J52: 10000000 | K52: 2500000 | L52: 200000 | M52: 300000 | N52: 300000 | O52: 1 | P52: 2 | Q52: 3
A53: =B53&C53&D53&G53&H53 -> มอเตอร์ แคร์ (เบี้ยเหมา) - รถกระบะNon ToyotaUPC12320 | B53: มอเตอร์ แคร์ (เบี้ยเหมา) - รถกระบะ | C53: Non Toyota | D53: UPC | F53: 13032 | G53: 12 | H53: 320 | I53: 500000 | J53: 10000000 | K53: 2500000 | L53: 200000 | M53: 300000 | N53: 300000 | O53: 1 | P53: 2 | Q53: 3
A54: =B54&C54&D54&G54&H54 -> มอเตอร์ แคร์ (เบี้ยเหมา) - รถกระบะNon ToyotaUPC13320 | B54: มอเตอร์ แคร์ (เบี้ยเหมา) - รถกระบะ | C54: Non Toyota | D54: UPC | F54: 13032 | G54: 13 | H54: 320 | I54: 500000 | J54: 10000000 | K54: 2500000 | L54: 200000 | M54: 300000 | N54: 300000 | O54: 1 | P54: 2 | Q54: 3
... A154: =B154&C154&D154&G154&H154 -> มอเตอร์ แคร์ (เบี้ยเหมา) - รถกระบะToyotaBMR15110 | B154: มอเตอร์ แคร์ (เบี้ยเหมา) - รถกระบะ | C154: Toyota | D154: BMR | F154: 15359 | G154: 15 | H154: 110 | I154: 500000 | J154: 10000000 | K154: 5000000 | L154: 200000 | M154: 300000 | N154: 300000 | O154: 1 | P154: 6 | Q154: 7
A155: =B155&C155&D155&G155&H155 -> มอเตอร์ แคร์ (เบี้ยเหมา) - รถเก๋ง SUVUPC2110 | B155: มอเตอร์ แคร์ (เบี้ยเหมา) - รถเก๋ง SUV | D155: UPC | F155: 15825 | G155: 2 | H155: 110 | I155: 500000 | J155: 10000000 | K155: 5000000 | L155: 200000 | M155: 300000 | N155: 300000 | O155: 1 | P155: 6 | Q155: 7
A156: =B156&C156&D156&G156&H156 -> มอเตอร์ แคร์ (เบี้ยเหมา) - รถเก๋ง SUVUPC3110 | B156: มอเตอร์ แคร์ (เบี้ยเหมา) - รถเก๋ง SUV | D156: UPC | F156: 15825 | G156: 3 | H156: 110 | I156: 500000 | J156: 10000000 | K156: 5000000 | L156: 200000 | M156: 300000 | N156: 300000 | O156: 1 | P156: 6 | Q156: 7
A157: =B157&C157&D157&G157&H157 -> มอเตอร์ แคร์ (เบี้ยเหมา) - รถเก๋ง SUVUPC4110 | B157: มอเตอร์ แคร์ (เบี้ยเหมา) - รถเก๋ง SUV | D157: UPC | F157: 15825 | G157: 4 | H157: 110 | I157: 500000 | J157: 10000000 | K157: 5000000 | L157: 200000 | M157: 300000 | N157: 300000 | O157: 1 | P157: 6 | Q157: 7
A158: =B158&C158&D158&G158&H158 -> มอเตอร์ แคร์ (เบี้ยเหมา) - รถเก๋ง SUVUPC5110 | B158: มอเตอร์ แคร์ (เบี้ยเหมา) - รถเก๋ง SUV | D158: UPC | F158: 15825 | G158: 5 | H158: 110 | I158: 500000 | J158: 10000000 | K158: 5000000 | L158: 200000 | M158: 300000 | N158: 300000 | O158: 1 | P158: 6 | Q158: 7
...

Sheet Dropdown_Mapping
B1: รถกระบะ 2 ประตู | D1: Ford Everest | F1: รถกระบะ 2 ประตู | G1: Ford Ranger | K1: Ford Everest | L1: 2553 | O1: Ford Everest_2553 | P1: 2500 | S1: Ford Everest_2553_2500 | T1: 180000 | U1: 180000 | V1: 300000 | W1: กระบี่ | X1: UPC | AA1: Ford Ranger | AB1: มอเตอร์ แคร์ (เบี้ยเหมา) - รถกระบะ | AG1: BRAND | AH1: MODEL | AI1: YEARGROUP | AJ1: YEAR_THAI | AK1: AGE | AQ1: BRAND | AR1: MODEL | AS1: YEARGROUP | AT1: YEAR_THAI | AU1: AGE | AV1: ENGINESIZE_PMA | BA1: BRAND | BB1: MODEL | BC1: YEARGROUP | BD1: YEAR_THAI | BE1: AGE | BF1: ENGINESIZE_PMA | BG1: SI | BH1: MIN_SI | BI1: MAX_SI
B2: รถกระบะ 4 ประตู | D2: Ford Ranger | F2: รถกระบะ 2 ประตู | G2: Isuzu D-Max | K2: Ford Everest | L2: 2554 | O2: Ford Everest_2553 | P2: 3000 | S2: Ford Everest_2553_2500 | T2: 190000 | U2: 180000 | V2: 300000 | W2: กรุงเทพมหานคร | X2: BMR | AA2: Ford Everest | AB2: มอเตอร์ แคร์ (เบี้ยเหมา) - รถเก๋ง SUV | AG2: Ford | AH2: Everest | AI2: 2010 | AJ2: 2553 | AK2: 15 | AM2: =AG2&" "&AH2 -> Ford Everest | AN2: =AJ2 -> 2553 | AQ2: Ford | AR2: Everest | AS2: 2010 | AT2: 2553 | AU2: 15 | AV2: 2.5 | AX2: =AQ2&" "&AR2&"_"&AT2 -> Ford Everest_2553 | AY2: =AV2*1000 -> 2500 | BA2: Ford | BB2: Everest | BC2: 2010 | BD2: 2553 | BE2: 15 | BF2: 2.5 | BG2: 180000 | BH2: 180000 | BI2: 300000 | BK2: =BA2&" "&BB2&"_"&BD2&"_"&BF2*1000 -> Ford Everest_2553_2500 | BL2: =BG2 -> 180000 | BM2: =BH2 -> 180000 | BN2: =BI2 -> 300000
B3: รถเก๋ง SUV | D3: Honda CR-V | F3: รถกระบะ 2 ประตู | G3: Mazda BT-50 | K3: Ford Everest | L3: 2555 | O3: Ford Everest_2554 | P3: 2500 | S3: Ford Everest_2553_2500 | T3: 200000 | U3: 180000 | V3: 300000 | W3: กาญจนบุรี | X3: UPC | AA3: Ford Ranger | AG3: Ford | AH3: Everest | AI3: 2011 | AJ3: 2554 | AK3: 14 | AM3: =AG3&" "&AH3 -> Ford Everest | AN3: =AJ3 -> 2554 | AQ3: Ford | AR3: Everest | AS3: 2010 | AT3: 2553 | AU3: 15 | AV3: 3 | AX3: =AQ3&" "&AR3&"_"&AT3 -> Ford Everest_2553 | AY3: =AV3*1000 -> 3000 | BA3: Ford | BB3: Everest | BC3: 2010 | BD3: 2553 | BE3: 15 | BF3: 2.5 | BG3: 190000 | BH3: 180000 | BI3: 300000 | BK3: =BA3&" "&BB3&"_"&BD3&"_"&BF3*1000 -> Ford Everest_2553_2500 | BL3: =BG3 -> 190000 | BM3: =BH3 -> 180000 | BN3: =BI3 -> 300000
D4: Isuzu D-Max | F4: รถกระบะ 2 ประตู | G4: Mazda BT-50 PRO | K4: Ford Everest | L4: 2556 | O4: Ford Everest_2554 | P4: 3000 | S4: Ford Everest_2553_2500 | T4: 210000 | U4: 180000 | V4: 300000 | W4: กาฬสินธุ์ | X4: UPC | AA4: Honda CR-V | AB4: มอเตอร์ แคร์ (เบี้ยเหมา) - รถเก๋ง SUV | AG4: Ford | AH4: Everest | AI4: 2012 | AJ4: 2555 | AK4: 13 | AM4: =AG4&" "&AH4 -> Ford Everest | AN4: =AJ4 -> 2555 | AQ4: Ford | AR4: Everest | AS4: 2011 | AT4: 2554 | AU4: 14 | AV4: 2.5 | AX4: =AQ4&" "&AR4&"_"&AT4 -> Ford Everest_2554 | AY4: =AV4*1000 -> 2500 | BA4: Ford | BB4: Everest | BC4: 2010 | BD4: 2553 | BE4: 15 | BF4: 2.5 | BG4: 200000 | BH4: 180000 | BI4: 300000 | BK4: =BA4&" "&BB4&"_"&BD4&"_"&BF4*1000 -> Ford Everest_2553_2500 | BL4: =BG4 -> 200000 | BM4: =BH4 -> 180000 | BN4: =BI4 -> 300000
D5: Isuzu MU-7 | F5: รถกระบะ 2 ประตู | G5: Mitsubishi Triton | K5: Ford Everest | L5: 2557 | O5: Ford Everest_2555 | P5: 2500 | S5: Ford Everest_2553_2500 | T5: 220000 | U5: 180000 | V5: 300000 | W5: กำแพงเพชร | X5: UPC | AA5: Isuzu D-Max | AB5: มอเตอร์ แคร์ (เบี้ยเหมา) - รถกระบะ | AG5: Ford | AH5: Everest | AI5: 2013 | AJ5: 2556 | AK5: 12 | AM5: =AG5&" "&AH5 -> Ford Everest | AN5: =AJ5 -> 2556 | AQ5: Ford | AR5: Everest | AS5: 2011 | AT5: 2554 | AU5: 14 | AV5: 3 | AX5: =AQ5&" "&AR5&"_"&AT5 -> Ford Everest_2554 | AY5: =AV5*1000 -> 3000 | BA5: Ford | BB5: Everest | BC5: 2010 | BD5: 2553 | BE5: 15 | BF5: 2.5 | BG5: 210000 | BH5: 180000 | BI5: 300000 | BK5: =BA5&" "&BB5&"_"&BD5&"_"&BF5*1000 -> Ford Everest_2553_2500 | BL5: =BG5 -> 210000 | BM5: =BH5 -> 180000 | BN5: =BI5 -> 300000
D6: Isuzu MU-X | F6: รถกระบะ 2 ประตู | G6: Nissan Frontier | K6: Ford Everest | L6: 2558 | O6: Ford Everest_2555 | P6: 3000 | S6: Ford Everest_2553_2500 | T6: 230000 | U6: 180000 | V6: 300000 | W6: ขอนแก่น | X6: UPC | AA6: Isuzu D-Max | AG6: Ford | AH6: Everest | AI6: 2014 | AJ6: 2557 | AK6: 11 | AM6: =AG6&" "&AH6 -> Ford Everest | AN6: =AJ6 -> 2557 | AQ6: Ford | AR6: Everest | AS6: 2012 | AT6: 2555 | AU6: 13 | AV6: 2.5 | AX6: =AQ6&" "&AR6&"_"&AT6 -> Ford Everest_2555 | AY6: =AV6*1000 -> 2500 | BA6: Ford | BB6: Everest | BC6: 2010 | BD6: 2553 | BE6: 15 | BF6: 2.5 | BG6: 220000 | BH6: 180000 | BI6: 300000 | BK6: =BA6&" "&BB6&"_"&BD6&"_"&BF6*1000 -> Ford Everest_2553_2500 | BL6: =BG6 -> 220000 | BM6: =BH6 -> 180000 | BN6: =BI6 -> 300000
D7: Mazda BT-50 | F7: รถกระบะ 2 ประตู | G7: Nissan Frontier Navara | K7: Ford Everest | L7: 2559 | O7: Ford Everest_2556 | P7: 2500 | S7: Ford Everest_2553_2500 | T7: 240000 | U7: 180000 | V7: 300000 | W7: จันทบุรี | X7: UPC | AA7: Isuzu MU-7 | AB7: มอเตอร์ แคร์ (เบี้ยเหมา) - รถเก๋ง SUV | AG7: Ford | AH7: Everest | AI7: 2015 | AJ7: 2558 | AK7: 10 | AM7: =AG7&" "&AH7 -> Ford Everest | AN7: =AJ7 -> 2558 | AQ7: Ford | AR7: Everest | AS7: 2012 | AT7: 2555 | AU7: 13 | AV7: 3 | AX7: =AQ7&" "&AR7&"_"&AT7 -> Ford Everest_2555 | AY7: =AV7*1000 -> 3000 | BA7: Ford | BB7: Everest | BC7: 2010 | BD7: 2553 | BE7: 15 | BF7: 2.5 | BG7: 230000 | BH7: 180000 | BI7: 300000 | BK7: =BA7&" "&BB7&"_"&BD7&"_"&BF7*1000 -> Ford Everest_2553_2500 | BL7: =BG7 -> 230000 | BM7: =BH7 -> 180000 | BN7: =BI7 -> 300000
D8: Mazda BT-50 PRO | F8: รถกระบะ 2 ประตู | G8: Nissan NP 300 Navara | K8: Ford Everest | L8: 2560 | O8: Ford Everest_2556 | P8: 3000 | S8: Ford Everest_2553_2500 | T8: 250000 | U8: 180000 | V8: 300000 | W8: ฉะเชิงเทรา | X8: UPC | AA8: Isuzu MU-X | AB8: มอเตอร์ แคร์ (เบี้ยเหมา) - รถเก๋ง SUV | AG8: Ford | AH8: Everest | AI8: 2016 | AJ8: 2559 | AK8: 9 | AM8: =AG8&" "&AH8 -> Ford Everest | AN8: =AJ8 -> 2559 | AQ8: Ford | AR8: Everest | AS8: 2013 | AT8: 2556 | AU8: 12 | AV8: 2.5 | AX8: =AQ8&" "&AR8&"_"&AT8 -> Ford Everest_2556 | AY8: =AV8*1000 -> 2500 | BA8: Ford | BB8: Everest | BC8: 2010 | BD8: 2553 | BE8: 15 | BF8: 2.5 | BG8: 240000 | BH8: 180000 | BI8: 300000 | BK8: =BA8&" "&BB8&"_"&BD8&"_"&BF8*1000 -> Ford Everest_2553_2500 | BL8: =BG8 -> 240000 | BM8: =BH8 -> 180000 | BN8: =BI8 -> 300000
D9: Mitsubishi Pajero Sport | F9: รถกระบะ 2 ประตู | G9: Suzuki Carry | K9: Ford Everest | L9: 2561 | O9: Ford Everest_2557 | P9: 2500 | S9: Ford Everest_2553_2500 | T9: 260000 | U9: 180000 | V9: 300000 | W9: ชลบุรี | X9: UPC | AA9: Mazda BT-50 | AB9: มอเตอร์ แคร์ (เบี้ยเหมา) - รถกระบะ | AG9: Ford | AH9: Everest | AI9: 2017 | AJ9: 2560 | AK9: 8 | AM9: =AG9&" "&AH9 -> Ford Everest | AN9: =AJ9 -> 2560 | AQ9: Ford | AR9: Everest | AS9: 2013 | AT9: 2556 | AU9: 12 | AV9: 3 | AX9: =AQ9&" "&AR9&"_"&AT9 -> Ford Everest_2556 | AY9: =AV9*1000 -> 3000 | BA9: Ford | BB9: Everest | BC9: 2010 | BD9: 2553 | BE9: 15 | BF9: 2.5 | BG9: 250000 | BH9: 180000 | BI9: 300000 | BK9: =BA9&" "&BB9&"_"&BD9&"_"&BF9*1000 -> Ford Everest_2553_2500 | BL9: =BG9 -> 250000 | BM9: =BH9 -> 180000 | BN9: =BI9 -> 300000
D10: Mitsubishi Triton | F10: รถกระบะ 2 ประตู | G10: Toyota Hilux Revo | K10: Ford Everest | L10: 2562 | O10: Ford Everest_2557 | P10: 3000 | S10: Ford Everest_2553_2500 | T10: 270000 | U10: 180000 | V10: 300000 | W10: ชัยนาท | X10: UPC | AA10: Mazda BT-50 | AG10: Ford | AH10: Everest | AI10: 2018 | AJ10: 2561 | AK10: 7 | AM10: =AG10&" "&AH10 -> Ford Everest | AN10: =AJ10 -> 2561 | AQ10: Ford | AR10: Everest | AS10: 2014 | AT10: 2557 | AU10: 11 | AV10: 2.5 | AX10: =AQ10&" "&AR10&"_"&AT10 -> Ford Everest_2557 | AY10: =AV10*1000 -> 2500 | BA10: Ford | BB10: Everest | BC10: 2010 | BD10: 2553 | BE10: 15 | BF10: 2.5 | BG10: 260000 | BH10: 180000 | BI10: 300000 | BK10: =BA10&" "&BB10&"_"&BD10&"_"&BF10*1000 -> Ford Everest_2553_2500 | BL10: =BG10 -> 260000 | BM10: =BH10 -> 180000 | BN10: =BI10 -> 300000
D11: Nissan Frontier | F11: รถกระบะ 2 ประตู | G11: Toyota Hilux Vigo | K11: Ford Everest | L11: 2563 | O11: Ford Everest_2558 | P11: 2200 | S11: Ford Everest_2553_2500 | T11: 280000 | U11: 180000 | V11: 300000 | W11: ชัยภูมิ | X11: UPC | AA11: Mazda BT-50 PRO | AB11: มอเตอร์ แคร์ (เบี้ยเหมา) - รถกระบะ | AG11: Ford | AH11: Everest | AI11: 2019 | AJ11: 2562 | AK11: 6 | AM11: =AG11&" "&AH11 -> Ford Everest | AN11: =AJ11 -> 2562 | AQ11: Ford | AR11: Everest | AS11: 2014 | AT11: 2557 | AU11: 11 | AV11: 3 | AX11: =AQ11&" "&AR11&"_"&AT11 -> Ford Everest_2557 | AY11: =AV11*1000 -> 3000 | BA11: Ford | BB11: Everest | BC11: 2010 | BD11: 2553 | BE11: 15 | BF11: 2.5 | BG11: 270000 | BH11: 180000 | BI11: 300000 | BK11: =BA11&" "&BB11&"_"&BD11&"_"&BF11*1000 -> Ford Everest_2553_2500 | BL11: =BG11 -> 270000 | BM11: =BH11 -> 180000 | BN11: =BI11 -> 300000
D12: Nissan Frontier Navara | F12: รถกระบะ 4 ประตู | G12: Ford Ranger | K12: Ford Everest | L12: 2564 | O12: Ford Everest_2558 | P12: 2500 | S12: Ford Everest_2553_2500 | T12: 290000 | U12: 180000 | V12: 300000 | W12: ชุมพร | X12: UPC | AA12: Mazda BT-50 PRO | AG12: Ford | AH12: Everest | AI12: 2020 | AJ12: 2563 | AK12: 5 | AM12: =AG12&" "&AH12 -> Ford Everest | AN12: =AJ12 -> 2563 | AQ12: Ford | AR12: Everest | AS12: 2015 | AT12: 2558 | AU12: 10 | AV12: 2.2 | AX12: =AQ12&" "&AR12&"_"&AT12 -> Ford Everest_2558 | AY12: =AV12*1000 -> 2200 | BA12: Ford | BB12: Everest | BC12: 2010 | BD12: 2553 | BE12: 15 | BF12: 2.5 | BG12: 280000 | BH12: 180000 | BI12: 300000 | BK12: =BA12&" "&BB12&"_"&BD12&"_"&BF12*1000 -> Ford Everest_2553_2500 | BL12: =BG12 -> 280000 | BM12: =BH12 -> 180000 | BN12: =BI12 -> 300000
D13: Nissan NP 300 Navara | F13: รถกระบะ 4 ประตู | G13: Isuzu D-Max | K13: Ford Everest | L13: 2565 | O13: Ford Everest_2558 | P13: 3000 | S13: Ford Everest_2553_2500 | T13: 300000 | U13: 180000 | V13: 300000 | W13: เชียงราย | X13: UPC | AA13: Mitsubishi Pajero Sport | AB13: มอเตอร์ แคร์ (เบี้ยเหมา) - รถเก๋ง SUV | AG13: Ford | AH13: Everest | AI13: 2021 | AJ13: 2564 | AK13: 4 | AM13: =AG13&" "&AH13 -> Ford Everest | AN13: =AJ13 -> 2564 | AQ13: Ford | AR13: Everest | AS13: 2015 | AT13: 2558 | AU13: 10 | AV13: 2.5 | AX13: =AQ13&" "&AR13&"_"&AT13 -> Ford Everest_2558 | AY13: =AV13*1000 -> 2500 | BA13: Ford | BB13: Everest | BC13: 2010 | BD13: 2553 | BE13: 15 | BF13: 2.5 | BG13: 290000 | BH13: 180000 | BI13: 300000 | BK13: =BA13&" "&BB13&"_"&BD13&"_"&BF13*1000 -> Ford Everest_2553_2500 | BL13: =BG13 -> 290000 | BM13: =BH13 -> 180000 | BN13: =BI13 -> 300000
D14: Suzuki Carry | F14: รถกระบะ 4 ประตู | G14: Mazda BT-50 | K14: Ford Everest | L14: 2566 | O14: Ford Everest_2558 | P14: 3200 | S14: Ford Everest_2553_3000 | T14: 230000 | U14: 230000 | V14: 320000 | W14: เชียงใหม่ | X14: UPC | AA14: Mitsubishi Triton | AB14: มอเตอร์ แคร์ (เบี้ยเหมา) - รถกระบะ | AG14: Ford | AH14: Everest | AI14: 2022 | AJ14: 2565 | AK14: 3 | AM14: =AG14&" "&AH14 -> Ford Everest | AN14: =AJ14 -> 2565 | AQ14: Ford | AR14: Everest | AS14: 2015 | AT14: 2558 | AU14: 10 | AV14: 3 | AX14: =AQ14&" "&AR14&"_"&AT14 -> Ford Everest_2558 | AY14: =AV14*1000 -> 3000 | BA14: Ford | BB14: Everest | BC14: 2010 | BD14: 2553 | BE14: 15 | BF14: 2.5 | BG14: 300000 | BH14: 180000 | BI14: 300000 | BK14: =BA14&" "&BB14&"_"&BD14&"_"&BF14*1000 -> Ford Everest_2553_2500 | BL14: =BG14 -> 300000 | BM14: =BH14 -> 180000 | BN14: =BI14 -> 300000
D15: Toyota Fortuner | F15: รถกระบะ 4 ประตู | G15: Mazda BT-50 PRO | K15: Ford Ranger | L15: 2553 | O15: Ford Everest_2559 | P15: 2200 | S15: Ford Everest_2553_3000 | T15: 240000 | U15: 230000 | V15: 320000 | W15: ตรัง | X15: UPC | AA15: Mitsubishi Triton | AG15: Ford | AH15: Everest | AI15: 2023 | AJ15: 2566 | AK15: 2 | AM15: =AG15&" "&AH15 -> Ford Everest | AN15: =AJ15 -> 2566 | AQ15: Ford | AR15: Everest | AS15: 2015 | AT15: 2558 | AU15: 10 | AV15: 3.2 | AX15: =AQ15&" "&AR15&"_"&AT15 -> Ford Everest_2558 | AY15: =AV15*1000 -> 3200 | BA15: Ford | BB15: Everest | BC15: 2010 | BD15: 2553 | BE15: 15 | BF15: 3 | BG15: 230000 | BH15: 230000 | BI15: 320000 | BK15: =BA15&" "&BB15&"_"&BD15&"_"&BF15*1000 -> Ford Everest_2553_3000 | BL15: =BG15 -> 230000 | BM15: =BH15 -> 230000 | BN15: =BI15 -> 320000
