Workbook
Name PRV_ALL: [1]List!$H$4:$H$929
Name table: #REF!
Name TableML: #REF!
Name กระบี่: province!$B$2:$B$51
Name กรุงเทพมหานคร: province!$A$2:$A$51
Name กาญจนบุรี: province!$C$2:$C$51
Name กาฬสินธุ์: province!$D$2:$D$51
Name กำแพงเพชร: province!$E$2:$E$51
Name ขอนแก่น: province!$F$2:$F$51
Name จังหวัด: #REF!
Name จังหวัด2: #REF!
Name จันทบุรี: province!$G$2:$G$51
Name ฉะเชิงเทรา: province!$H$2:$H$51
Name ชลบุรี: province!$I$2:$I$51
Name ชัยนาท: province!$J$2:$J$51
Name ชัยภูมิ: province!$K$2:$K$51
Name ชุมพร: province!$L$2:$L$51
Name เชียงราย: province!$M$2:$M$51
Name เชียงใหม่: province!$N$2:$N$51
Name ตรัง: province!$O$2:$O$51
Name ตราด: province!$P$2:$P$51
Name ตาก: province!$Q$2:$Q$51
Name นครนายก: province!$R$2:$R$51
Name นครปฐม: province!$S$2:$S$51
Name นครพนม: province!$T$2:$T$51
Name นครราชสีมา: province!$U$2:$U$51
Name นครศรีธรรมราช: province!$V$2:$V$51
Name นครสวรรค์: province!$W$2:$W$51
Name นนทบุรี: province!$X$2:$X$51
Name นราธิวาส: province!$Y$2:$Y$51
Name น่าน: province!$Z$2:$Z$51
Name บุรีรัมย์: province!$AA$2:$AA$51
Name ปทุมธานี: province!$AB$2:$AB$51
Name ประจวบคีรีขันธ์: province!$AC$2:$AC$51
Name ปราจีนบุรี: province!$AD$2:$AD$51
Name ปัตตานี: province!$AE$2:$AE$51
Name พระนครศรีอยุธยา: province!$AF$2:$AF$51
Name พะเยา: province!$AN$2:$AN$51
Name พังงา: province!$AG$2:$AG$51
Name พัทลุง: province!$AH$2:$AH$51
Name พิจิตร: province!$AI$2:$AI$51
Name พิษณุโลก: province!$AJ$2:$AJ$51
Name เพชรบุรี: province!$AK$2:$AK$51
Name เพชรบูรณ์: province!$AL$2:$AL$51
Name แพร่: province!$AM$2:$AM$51
Name ภูเก็ต: province!$AO$2:$AO$51
Name มหาสารคาม: province!$AP$2:$AP$51
Name มุกดาหาร: province!$AQ$2:$AQ$51
Name เมืองสุรินทร์: #REF!
Name เมืองหนองคาย: #REF!
Name แม่ฮ่องสอน: province!$AR$2:$AR$51
Name ยโสธร: province!$AT$2:$AT$51
Name ยะลา: province!$AS$2:$AS$51
Name ร้อยเอ็ด: province!$AU$2:$AU$51
Name ระนอง: province!$AV$2:$AV$51
Name ระยอง: province!$AW$2:$AW$51
Name ราชบุรี: province!$AX$2:$AX$51
Name ลพบุรี: province!$AY$2:$AY$51
Name ลำปาง: province!$AZ$2:$AZ$51
Name ลำพูน: province!$BA$2:$BA$51

Sheet 1.ลดดอกเบี้ย
B1: ตารางพิจารณาขอลดดอกเบี้ย | F1: v.202608.01 | H1: To be hide
B3: ชื่อลูกค้า | J3: 3Y | K3: 5Y | AV3: * กรอกเฉพาะช่องสีเหลือง
B4: เลข App. | I4: =IFERROR(AD10,0) -> 0 | J4: =SUM(U20:W20) -> 0 | K4: =SUM(U20:Y20) -> 0
B5: อัตราดอกเบี้ย MRR
C7: HL | E7: MP/PP | I7: HL Facility | O7: MP/PP Facility | U7: All Facility | AV7: หมายเหตุ
B8: วงเงิน | I8: =I11/$C$8 -> #DIV/0! | J8: =J11/$C$8 -> #DIV/0! | K8: =K11/$C$8 -> #DIV/0! | L8: =L11/$C$8 -> #DIV/0! | M8: =M11/$C$8 -> #DIV/0! | O8: =O11/$F$8 -> #DIV/0! | P8: =P11/$F$8 -> #DIV/0! | Q8: =Q11/$F$8 -> #DIV/0! | R8: =R11/$F$8 -> #DIV/0! | S8: =S11/$F$8 -> #DIV/0! | AA8: Cumulative | AD8: Check Value | AV8: - ปีที่ 1 ไม่สามารถขอต่ำกว่า 1.44%
B9: ผ่อนชำระ (ปี) | I9: Y1 | J9: Y2 | K9: Y3 | L9: Y4 | M9: Y5 | O9: Y1 | P9: Y2 | Q9: Y3 | R9: Y4 | S9: Y5 | U9: Y1 | V9: Y2 | W9: Y3 | X9: Y4 | Y9: Y5 | AA9: For 3Y | AB9: For 5Y | AD9: =IF(C17="Lock 5Y",AB20,AA20) -> 0 | AV9: - ดอกเบี้ยที่ขออนุมัติ ต้องไม่มีปีไหน
B10: ดอกเบี้ย (เฉลี่ย 3 ปี) | C10: =IFERROR(AVERAGE(D11:D13),"") | E10: =IFERROR(AVERAGE(F11:F13),"") | H10: ENR | I10: =C8*95% -> 0 | J10: =C8*90% -> 0 | K10: =C8*85% -> 0 | L10: =C8*80% -> 0 | M10: =C8*75% -> 0 | O10: =E8*95% -> 0 | P10: =E8*90% -> 0 | Q10: =E8*85% -> 0 | R10: =E8*80% -> 0 | S10: =E8*75% -> 0 | U10: =I10+O10 -> 0 | V10: =J10+P10 -> 0 | W10: =K10+Q10 -> 0 | X10: =L10+R10 -> 0 | Y10: =M10+S10 -> 0 | AD10: =IF(C17="Lock 5Y",1+AB22,1+AA22) -> #DIV/0! | AV10: มากกว่าดอกเบี้ยตามแคมเปญ
B11: ปีที่ 1 | H11: ANR | I11: =AVERAGE(C8,I10) -> 0 | J11: =AVERAGE(I10:J10) -> 0 | K11: =AVERAGE(J10:K10) -> 0 | L11: =AVERAGE(K10:L10) -> 0 | M11: =AVERAGE(L10:M10) -> 0 | O11: =AVERAGE(F8,O10) -> 0 | P11: =AVERAGE(O10:P10) -> 0 | Q11: =AVERAGE(P10:Q10) -> 0 | R11: =AVERAGE(Q10:R10) -> 0 | S11: =AVERAGE(R10:S10) -> 0 | U11: =I11+O11 -> 0 | V11: =J11+P11 -> 0 | W11: =K11+Q11 -> 0 | X11: =L11+R11 -> 0 | Y11: =M11+S11 -> 0 | AV11: อาจจะส่งผลให้ ค่างวดไม่พอตัด
B12: ปีที่ 2 | AE12: ="<"&TEXT(AD18,"0.00%")&" of trigger point" -> #N/A | AH12: >> cannot submit Pricing Deviation | AV12: ชำระยอดดอกเบี้ย
B13: ปีที่ 3 | H13: Revenue | I13: =IFERROR(I11*$D$11,0) -> 0 | J13: =IFERROR(J11*$D$12,0) -> 0 | K13: =IFERROR(K11*$D$13,0) -> 0 | L13: =IFERROR(L11*$D$32,0) -> 0 | M13: =IFERROR(M11*$D$33,0) -> 0 | O13: =O11*$F$11 -> 0 | P13: =P11*$F$12 -> 0 | Q13: =Q11*$F$13 -> 0 | R13: =R11*$F$32 -> 0 | S13: =S11*$F$33 -> 0 | U13: =I13+O13 -> 0 | V13: =J13+P13 -> 0 | W13: =K13+Q13 -> 0 | X13: =L13+R13 -> 0 | Y13: =M13+S13 -> 0 | AA13: =SUM(U13:W13) -> 0 | AB13: =SUM(U13:Y13) -> 0 | AE13: =">="&TEXT(AD18,"0.00%")&" of trigger point" -> #N/A | AH13: >> can submit Pricing Deviation | AV13: - ตารางคำนวณนี้เพื่อเป็นแนวทาง
B14: ปีที่ 4 | H14: COF | I14: =I11*$D$34 -> 0 | J14: =J11*$D$34 -> 0 | K14: =K11*$D$34 -> 0 | L14: =L11*$D$34 -> 0 | M14: =M11*$D$34 -> 0 | O14: =O11*$F$34 -> 0 | P14: =P11*$F$34 -> 0 | Q14: =Q11*$F$34 -> 0 | R14: =R11*$F$34 -> 0 | S14: =S11*$F$34 -> 0 | U14: =I14+O14 -> 0 | V14: =J14+P14 -> 0 | W14: =K14+Q14 -> 0 | X14: =L14+R14 -> 0 | Y14: =M14+S14 -> 0 | AA14: =SUM(U14:W14) -> 0 | AB14: =SUM(U14:Y14) -> 0 | AV14: การนำเสนอดอกเบี้ยเท่านั้น
B15: เบี้ยประกัน MRTA/MLTA | H15: NII | I15: =I13-I14 -> 0 | J15: =J13-J14 -> 0 | K15: =K13-K14 -> 0 | L15: =L13-L14 -> 0 | M15: =M13-M14 -> 0 | O15: =O13-O14 -> 0 | P15: =P13-P14 -> 0 | Q15: =Q13-Q14 -> 0 | R15: =R13-R14 -> 0 | S15: =S13-S14 -> 0 | U15: =I15+O15 -> 0 | V15: =J15+P15 -> 0 | W15: =K15+Q15 -> 0 | X15: =L15+R15 -> 0 | Y15: =M15+S15 -> 0 | AA15: =SUM(U15:W15) -> 0 | AB15: =SUM(U15:Y15) -> 0 | AV15: Product ขอสงวนสิทธิ์ในการ
B16: ยกเว้นค่าจดจำนอง | H16: NOII | I16: =$C$15*34% -> 0 | O16: =$E$15*34% -> 0 | U16: =I16+O16 -> 0 | V16: =J16+P16 -> 0 | W16: =K16+Q16 -> 0 | X16: =L16+R16 -> 0 | Y16: =M16+S16 -> 0 | AA16: =SUM(U16:W16) -> 0 | AB16: =SUM(U16:Y16) -> 0 | AV16: พิจารณาอนุมัติดอกเบี้ยที่เสนอขอ
B17: ผูกสัญญา | H17: CC | I17: =IFERROR(VLOOKUP($C$20,pam!$U$5:$AE$9,pam!$V$12,FALSE)*I11*-1,0) -> 0 | J17: =IFERROR(VLOOKUP($C$20,pam!$U$5:$AE$9,pam!$V$12,FALSE)*J11*-1,0) -> 0 | K17: =IFERROR(VLOOKUP($C$20,pam!$U$5:$AE$9,pam!$V$12,FALSE)*K11*-1,0) -> 0 | L17: =IFERROR(VLOOKUP($C$20,pam!$U$5:$AE$9,pam!$V$12,FALSE)*L11*-1,0) -> 0 | M17: =IFERROR(VLOOKUP($C$20,pam!$U$5:$AE$9,pam!$V$12,FALSE)*M11*-1,0) -> 0 | O17: =O11*$P$28 -> 0 | P17: =P11*$P$28 -> 0 | Q17: =Q11*$P$28 -> 0 | R17: =R11*$P$28 -> 0 | S17: =S11*$P$28 -> 0 | U17: =I17+O17 -> 0 | V17: =J17+P17 -> 0 | W17: =K17+Q17 -> 0 | X17: =L17+R17 -> 0 | Y17: =M17+S17 -> 0 | AA17: =SUM(U17:W17) -> 0 | AB17: =SUM(U17:Y17) -> 0 | AD17: 0 | AE17: =AD18-0.01% -> #N/A | AF17: ไม่สามารถนำเสนอลดดอกเบี้ยได้
B18: แคมเปญ | H18: Commission | I18: =I28*C8 -> 0 | O18: =P29*E8 -> 0 | U18: =I18+O18 -> 0 | V18: =J18+P18 -> 0 | W18: =K18+Q18 -> 0 | X18: =L18+R18 -> 0 | Y18: =M18+S18 -> 0 | AA18: =SUM(U18:W18) -> 0 | AB18: =SUM(U18:Y18) -> 0 | AD18: =AD34 -> #N/A | AF18: สามารถนำเสนอลดดอกเบี้ยได้
B19: รายได้ | H19: OPEX | I19: =IF(IF($C$16="Yes",C8*1%,0)>=100000,100000,IF($C$16="Yes",C8*1%,0)) -> 0 | O19: =IF(IF($E$16="Yes",E8*1%,0)>=100000,100000,IF($E$16="Yes",E8*1%,0)) -> 0 | U19: =I19+O19 -> 0 | V19: =J19+P19 -> 0 | W19: =K19+Q19 -> 0 | X19: =L19+R19 -> 0 | Y19: =M19+S19 -> 0 | AA19: =SUM(U19:W19) -> 0 | AB19: =SUM(U19:Y19) -> 0
B20: Score Grade | H20: PBT | I20: =IFERROR(I15+I16-I17-I18-I19,0) -> 0 | J20: =IFERROR(J15+J16-J17-J18-J19,0) -> 0 | K20: =IFERROR(K15+K16-K17-K18-K19,0) -> 0 | L20: =IFERROR(L15+L16-L17-L18-L19,0) -> 0 | M20: =IFERROR(M15+M16-M17-M18-M19,0) -> 0 | O20: =IFERROR(O15+O16-O17-O18-O19,0) -> 0 | P20: =IFERROR(P15+P16-P17-P18-P19,0) -> 0 | Q20: =IFERROR(Q15+Q16-Q17-Q18-Q19,0) -> 0 | R20: =IFERROR(R15+R16-R17-R18-R19,0) -> 0 | S20: =IFERROR(S15+S16-S17-S18-S19,0) -> 0 | U20: =I20+O20 -> 0 | V20: =J20+P20 -> 0 | W20: =K20+Q20 -> 0 | X20: =L20+R20 -> 0 | Y20: =M20+S20 -> 0 | AA20: =SUM(U20:W20) -> 0 | AB20: =SUM(U20:Y20) -> 0 | AG20: BaseLine | AH20: Lock 3Y | AI20: Lock 5Y
B21: %LTV (รวม MRTA/MLTA) | AD21: Cap Min Rate | AE21: 0.02 | AG21: 1 | AH21: 2 | AI21: 3
B22: หลักประกัน | AA22: =ROUNDDOWN((AA20/3)/AVERAGE($U$11:W$11),4) -> #DIV/0! | AB22: =ROUNDDOWN((AB20/3)/AVERAGE($U$11:Y$11),4) -> #DIV/0! | AD22: Cap Max Loss | AE22: -30000 | AG22: No Ins | AH22: 0.026 | AI22: 0.024
B23: ที่ตั้งหลักประกัน | AG23: Ins | AH23: 0.025 | AI23: 0.023
B24: ช่องทางขาย | AB24: Base line | AD24: 1 | AG24: Index | AH24: =HLOOKUP(C17,AG20:AI21,2,FALSE) -> #N/A
B25: Consent 1.1
B26: ประเภทการผ่อน | E26: เท่ากันทุกเดือน | AB26: Loan Size | AD26: =VLOOKUP(SUM(C8:F8),AF27:AH31,3,TRUE) -> 0.0005 | AF26: LoanSize | AI26: Income | AL26: Campaign | AN26: Collateral | AP26: Location | AR26: LTV
B27: ค่างวดผ่อนชำระ | AB27: Income | AD27: =VLOOKUP(SUM(C19:F19),AI27:AK33,3,TRUE) -> 0.002 | AF27: 0 | AG27: 3000000 | AH27: 0.0005 | AI27: 0 | AJ27: 30000 | AK27: 0.002 | AL27: BT | AM27: 0.0002 | AN27: SingleHouse | AO27: 0.0001 | AP27: BKK&VIC | AQ27: 0.0001 | AR27: 0 | AS27: 0.4999 | AT27: 0.0001
B28: ปีที่ 1 | C28: =IF(C26="เท่ากันทุกเดือน",'Straight-HL'!C10,'Step-HL'!L10) -> 0 | E28: =IF(E26="เท่ากันทุกเดือน",'Straight-MP'!C10,'Step-MP'!L10) -> 0 | H28: %Comm (after var) | I28: =IFERROR(I29*I30,0) -> 0 | O28: MP %CC | P28: 0.011 | AB28: Campaign | AD28: =VLOOKUP(IF(C18<>"",C18,E18),AL27:AM34,2,FALSE) -> #N/A | AF28: =AG27+1 -> 3000001 | AG28: 5000000 | AH28: 0.0003 | AI28: =AJ27+1 -> 30001 | AJ28: 50000 | AK28: 0.0015 | AL28: Focus | AM28: 0.0005 | AN28: TwinHouse | AO28: 0.0001 | AP28: North | AQ28: 0.0005 | AR28: =AS27+0.01% -> 0.5 | AS28: 0.5999 | AT28: 0.0001
B29: ปีที่ 2 | C29: =IF(C26="เท่ากันทุกเดือน",'Straight-HL'!C10,'Step-HL'!L11) -> 0 | E29: =IF(E26="เท่ากันทุกเดือน",'Straight-MP'!C10,'Step-MP'!L11) -> 0 | H29: %Comm | I29: 0.005 | O29: MP %Comm | P29: =IF(E24="DSA",0.5%,0.3%) -> 0.003 | AB29: Collateral | AD29: =VLOOKUP(IF(C22<>"",C22,E22),AN27:AO32,2,FALSE) -> #N/A | AF29: =AG28+1 -> 5000001 | AG29: 7500000 | AH29: 0.0001 | AI29: =AJ28+1 -> 50001 | AJ29: 75000 | AK29: 0.001 | AL29: 2ndHand | AM29: 0.0005 | AN29: TownHouse | AO29: 0.0001 | AP29: NorthEast | AQ29: 0.0005 | AR29: =AS28+0.01% -> 0.6 | AS29: 0.7999 | AT29: 0.0001
B30: ปีที่ 3 | C30: =IF(C26="เท่ากันทุกเดือน",'Straight-HL'!C10,'Step-HL'!L12) -> 0 | E30: =IF(E26="เท่ากันทุกเดือน",'Straight-MP'!C10,'Step-MP'!L12) -> 0 | H30: com variance | I30: =IFERROR(IF((C15/C8)<2%,VLOOKUP(C18,pam!C:E,2,FALSE),VLOOKUP(C18,pam!C:E,3,FALSE)),0) -> 0 | AB30: Location | AD30: =VLOOKUP(IF(C23<>"",C23,E23),AP27:AQ32,2,FALSE) -> #N/A | AF30: =AG29+1 -> 7500001 | AG30: 10000000 | AH30: 0 | AI30: =AJ29+1 -> 75001 | AJ30: 100000 | AK30: 0.0005 | AL30: RBP | AM30: 0.001 | AN30: Condo | AO30: 0.0005 | AP30: East | AQ30: 0.0005 | AR30: =AS29+0.01% -> 0.8 | AS30: 0.8999 | AT30: 0.0001
B31: ปีที่ 4 เป็นต้นไป | C31: =IF(C26="เท่ากันทุกเดือน",'Straight-HL'!C10,'Step-HL'!L13) -> 0 | E31: =IF(E26="เท่ากันทุกเดือน",'Straight-MP'!C10,'Step-MP'!L13) -> 0 | AB31: LTV | AD31: =VLOOKUP(C21,AR27:AT33,3,TRUE) -> 0.0001 | AF31: =AG30+1 -> 10000001 | AH31: 0 | AI31: =AJ30+1 -> 100001 | AJ31: 200000 | AK31: 0.0001 | AL31: PVL | AM31: 0.001 | AN31: ShopHouse | AO31: 0.001 | AP31: South | AQ31: 0.0005 | AR31: =AS30+0.01% -> 0.9 | AS31: 1 | AT31: 0.0001
B32: Retention ปีที่ 4 | D32: =IF(C16="Yes",C10+0.2%,C10) | F32: =IFERROR(E10+0.2%,0) -> 0 | AB32: Total add-on | AD32: =SUM(AD26:AD31) -> #N/A | AI32: =AJ31+1 -> 200001 | AJ32: 500000 | AK32: 0 | AL32: Project | AM32: 0.0015 | AN32: Commercial | AO32: 0.01 | AP32: West | AQ32: 0.0005 | AR32: =AS31+0.01% -> 1.0001 | AS32: 1.4999 | AT32: 0.0001
B33: Retention ปีที่ 5 | D33: =IF(C16="Yes",C10+0.2%,C10) | F33: =IFERROR(E10+0.2%,0) -> 0 | AI33: =AJ32+1 -> 500001 | AK33: 0 | AL33: Other | AM33: 0.002 | AR33: =AS32+0.01% -> 1.5 | AT33: 0.9
B34: COF | D34: =IFERROR(pam!Q21,0) -> 0 | F34: =IFERROR(pam!Q22,0) -> 0 | AB34: Final threshold | AD34: =AD24+AD32 -> #N/A | AL34: MP/PP | AM34: 0.005
B35: NII | D35: =IFERROR(C10-D34,0) -> 0 | F35: =IFERROR(E10-F34,0) -> 0
B41: ผลการพิจารณา | E41: =IFERROR(VLOOKUP($AD$10,$AD$17:$AF$19,3,TRUE),"")

Sheet 2.นำเสนอดอกเบี้ย
A1: ตารางนำเสนอดอกเบี้ย HL | N1: ='1.ลดดอกเบี้ย'!F1 -> v.202608.01
A2: อัตราดอกเบี้ย | C2: Month | F2: ตามมติ | I2: ขออนุมัติในครั้งนี้ | L2: ส่วนต่าง | M2: ดอกเบี้ยคู่แข่ง
A3: MRR = | C3: 1 | D3: - | E3: 12 | I3: ='1.ลดดอกเบี้ย'!C11 -> 0 | K3: ='1.ลดดอกเบี้ย'!D11 -> 0 | N3: โปรดระบุอัตราดอกเบี้ยและโปรโมชั่นคู่แข่ง... | P3: * กรอกเฉพาะช่องสีเหลือง
A4: ='1.ลดดอกเบี้ย'!C5 -> 0 | C4: =E3+1 -> 13 | D4: - | E4: 24 | I4: ='1.ลดดอกเบี้ย'!C12 -> 0 | K4: ='1.ลดดอกเบี้ย'!D12 -> 0
C5: =E4+1 -> 25 | D5: - | E5: 36 | I5: ='1.ลดดอกเบี้ย'!C13 -> 0 | K5: ='1.ลดดอกเบี้ย'!D13 -> 0
C6: 37 | D6: - | E6: For the rest | I6: ='1.ลดดอกเบี้ย'!C14 -> 0 | K6: ='1.ลดดอกเบี้ย'!D14 -> 0
F7: เฉลี่ย 3 ปี | H7: =AVERAGE(H3:H5) -> #DIV/0! | K7: =AVERAGE(K3:K5) -> 0 | L7: =K7-H7 -> #DIV/0!
A9: ชื่อลูกค้า | E9: ='1.ลดดอกเบี้ย'!C3 -> 0 | L9: App No. | N9: ='1.ลดดอกเบี้ย'!C4 -> 0
A10: ช่องทางการขาย | E10: ='1.ลดดอกเบี้ย'!C24 -> 0 | L10: Application Status
A11: ชื่อโครงการ / ชื่อ Developer | K11: ประเภทหลักประกัน
A12: จังหวัดที่ตั้งหลักประกัน | K12: อำเภอของหลักประกัน
A13: แคมเปญสินเชื่อ | E13: ='1.ลดดอกเบี้ย'!C18 -> 0 | K13: ผ่อนชำระ | M13: ='1.ลดดอกเบี้ย'!C9 -> 0 | N13: ปี
A14: วงเงินสินเชื่อ | E14: วงเงิน HL | G14: ='1.ลดดอกเบี้ย'!C8 -> 0 | N14: บาท
A15: วงเงินสินเชื่อ | E15: วงเงิน Insurance | H15: ='1.ลดดอกเบี้ย'!C15 -> 0 | N15: บาท
A16: ประวัติลูกค้า | E16: ผู้กู้หลัก ทำงานที่... ตำแหน่ง... รายได้รวม… อายุงาน... ผู้กู้ร่วม ทำงานที่... ตำแหน่ง... รายได้รวม… อายุงาน...
A17: LTV | H17: DSR | L17: Grade | N17: ='1.ลดดอกเบี้ย'!C20 -> 0
A19: --------------------------------------------------------------------------------------------------------------------------------------------------------------------------------------------------------
A21: ตารางนำเสนอดอกเบี้ย MP | N21: ='1.ลดดอกเบี้ย'!F1 -> v.202608.01
A22: อัตราดอกเบี้ย | C22: Month | F22: ตามมติ | I22: ขออนุมัติในครั้งนี้ | L22: ส่วนต่าง | M22: ดอกเบี้ยคู่แข่ง
A23: MRR = | C23: 1 | D23: - | E23: 12 | I23: ='1.ลดดอกเบี้ย'!E11 -> 0 | K23: ='1.ลดดอกเบี้ย'!F11 -> 0 | N23: โปรดระบุอัตราดอกเบี้ยและโปรโมชั่นคู่แข่ง... | P23: * กรอกเฉพาะช่องสีเหลือง
A24: ='1.ลดดอกเบี้ย'!C5 -> 0 | C24: =E23+1 -> 13 | D24: - | E24: 24 | I24: ='1.ลดดอกเบี้ย'!E12 -> 0 | K24: ='1.ลดดอกเบี้ย'!F12 -> 0
C25: =E24+1 -> 25 | D25: - | E25: 36 | I25: ='1.ลดดอกเบี้ย'!E13 -> 0 | K25: ='1.ลดดอกเบี้ย'!F13 -> 0
C26: 37 | D26: - | E26: For the rest | I26: ='1.ลดดอกเบี้ย'!E14 -> 0 | K26: ='1.ลดดอกเบี้ย'!F14 -> 0
F27: เฉลี่ย 3 ปี | H27: =AVERAGE(H23:H25) -> #DIV/0! | K27: =AVERAGE(K23:K25) -> 0 | L27: =K27-H27 -> #DIV/0!
A29: ชื่อลูกค้า | E29: ='1.ลดดอกเบี้ย'!C3 -> 0 | L29: App No. | N29: ='1.ลดดอกเบี้ย'!C4 -> 0
A30: ช่องทางการขาย | E30: ='1.ลดดอกเบี้ย'!E24 -> 0 | L30: Application Status
A31: ชื่อโครงการ / ชื่อ Developer | K31: ประเภทหลักประกัน
A32: จังหวัดที่ตั้งหลักประกัน | K32: อำเภอของหลักประกัน
A33: แคมเปญสินเชื่อ | E33: Mortgage Power / Property Power | K33: ผ่อนชำระ | M33: ='1.ลดดอกเบี้ย'!E9 -> 0 | N33: ปี
A34: วงเงินสินเชื่อ | E34: วงเงิน MP/PP | H34: ='1.ลดดอกเบี้ย'!E8 -> 0 | N34: บาท
A35: วงเงินสินเชื่อ | E35: วงเงิน Insurance | H35: ='1.ลดดอกเบี้ย'!E15 -> 0 | N35: บาท
A36: ประวัติลูกค้า | E36: ผู้กู้หลัก ทำงานที่... ตำแหน่ง... รายได้รวม… อายุงาน... ผู้กู้ร่วม ทำงานที่... ตำแหน่ง... รายได้รวม… อายุงาน...
A37: LTV | H37: DSR | L37: Grade | N37: ='1.ลดดอกเบี้ย'!E20 -> 0

Sheet ตาราง-HL-เสนอลด
B1: ตารางผ่อนชำระเบื้องต้น HL (อัตราดอกเบี้ยนำเสนอลด)
B2: ชื่อ | C2: ='1.ลดดอกเบี้ย'!C3 -> 0 | G2: ผ่อนชำระ
B3: App No | C3: ='1.ลดดอกเบี้ย'!C4 -> 0 | F3: อัตราดอกเบี้ย | G3: {='1.ลดดอกเบี้ย'!C26:D26} -> 0 | H3: 0
B4: วงเงิน | C4: ='2.นำเสนอดอกเบี้ย'!G14 -> 0 | D4: บาท | E4: ปีที่ 1 | F4: ='2.นำเสนอดอกเบี้ย'!K3 -> 0 | G4: ='1.ลดดอกเบี้ย'!C28 -> 0
B5: ระยะเวลา | C5: ='1.ลดดอกเบี้ย'!C9 -> 0 | D5: ปี | E5: ปีที่ 2 | F5: ='2.นำเสนอดอกเบี้ย'!K4 -> 0 | G5: ='1.ลดดอกเบี้ย'!C29 -> 0 | H5: =SUM(I6:I10)/#REF! -> #REF!
E6: ปีที่ 3 | F6: ='2.นำเสนอดอกเบี้ย'!K5 -> 0 | G6: ='1.ลดดอกเบี้ย'!C30 -> 0 | H6: =F4*12 -> 0
C7: Buffer | D7: 0.01 | E7: ปีที่ 4+ | F7: ='2.นำเสนอดอกเบี้ย'!K6 -> 0 | G7: ='1.ลดดอกเบี้ย'!C31 -> 0 | H7: =F5*12 -> 0
H8: =F6*12 -> 0
H9: =F7*12 -> 0
F10: Int. Yr. 5+ | G10: =F7 -> 0 | H10: =IF(G3="เท่ากันทุกเดือน",'1.ลดดอกเบี้ย'!#REF!,'1.ลดดอกเบี้ย'!C31) -> 0 | I10: =G10*(#REF!-48) -> #REF!
D11: =12*3 -> 36 | E11: =12*5 -> 60 | F11: =12*7 -> 84 | G11: =12*10 -> 120 | H11: =12*30 -> 360 | I11: =12*15 -> 180
D12: 3 Yrs. | E12: 5 Yrs. | F12: 7 Yrs. | G12: 10 Yrs. | H12: 30 Yrs. | I12: 15 Yrs
B13: Total Int. | D13: =SUM($G$20:$G$55) -> 0 | E13: =SUM($G$20:$G$79) -> 0 | F13: =SUM($G$20:$G$103) -> 0 | G13: =SUM($G$20:$G$139) -> 0 | H13: =SUM($G$20:$G$379) -> 0 | I13: =SUM($G$20:$G$199) -> 0
B14: Average O/S | D14: =AVERAGE($D$20:$D$55) -> 0 | E14: =AVERAGE($D$20:$D$79) -> 0 | F14: =AVERAGE($D$20:$D$103) -> 0 | G14: =AVERAGE($D$20:$D$139) -> 0 | H14: =AVERAGE($D$20:$D$379) -> 0 | I14: =AVERAGE($D$20:$D$199) -> 0
B15: EIR | D15: =D13/D14/(D11/12) -> #DIV/0! | E15: =E13/E14/(E11/12) -> #DIV/0! | F15: =F13/F14/(F11/12) -> #DIV/0! | G15: =G13/G14/(G11/12) -> #DIV/0! | H15: =H13/H14/(H11/12) -> #DIV/0! | I15: =I13/I14/(I11/12) -> #DIV/0!
B17: Average | D17: =AVERAGE($C$20:$C$55) -> 0 | E17: =AVERAGE($C$20:$C$79) -> 0 | F17: =AVERAGE($C$20:$C$103) -> 0 | G17: =AVERAGE($C$20:$C$139) -> 0 | H17: =AVERAGE($C$20:$C$379) -> 0 | I17: =AVERAGE(C20:C199) -> 0
B19: เดือน | C19: อัตราดอกเบี้ย | D19: ยอดคงค้าง | E19: ยอดผ่อนชำระ | F19: ยอดเงินต้น | G19: ยอดดอกเบี้ย | H19: ยอดคงค้าง | I19: LTV | O19: Tenor
B20: 1 | C20: =IF(D20>0,$F$4,0) -> 0 | D20: =C4 -> 0 | E20: =G4 -> 0 | F20: =E20-G20 -> 0 | G20: =C20*(D20/365)*30 -> 0 | H20: =IF((D20+G20-E20)<0,0,D20+G20-E20) -> 0 | O20: =IF(H20=0,B20,"n.a.") -> 1
B21: =B20+1 -> 2 | C21: =IF(D21>0,$F$4,0) -> 0 | D21: =H20 -> 0 | E21: =IF(H20<=E20,H20+G21,$G$4) -> 0 | F21: =E21-G21 -> 0 | G21: =C21*(D21/365)*30 -> 0 | H21: =IF((D21+G21-E21)<0,0,D21+G21-E21) -> 0 | O21: =IF(H21=0,B21,"n.a.") -> 2
B22: =B21+1 -> 3 | C22: =IF(D22>0,$F$4,0) -> 0 | D22: =H21 -> 0 | E22: =IF(H21<=E21,H21+G22,$G$4) -> 0 | F22: =E22-G22 -> 0 | G22: =C22*(D22/365)*30 -> 0 | H22: =IF((D22+G22-E22)<0,0,D22+G22-E22) -> 0 | O22: =IF(H22=0,B22,"n.a.") -> 3
B23: =B22+1 -> 4 | C23: =IF(D23>0,$F$4,0) -> 0 | D23: =H22 -> 0 | E23: =IF(H22<=E22,H22+G23,$G$4) -> 0 | F23: =E23-G23 -> 0 | G23: =C23*(D23/365)*30 -> 0 | H23: =IF((D23+G23-E23)<0,0,D23+G23-E23) -> 0 | O23: =IF(H23=0,B23,"n.a.") -> 4
B24: =B23+1 -> 5 | C24: =IF(D24>0,$F$4,0) -> 0 | D24: =H23 -> 0 | E24: =IF(H23<=E23,H23+G24,$G$4) -> 0 | F24: =E24-G24 -> 0 | G24: =C24*(D24/365)*30 -> 0 | H24: =IF((D24+G24-E24)<0,0,D24+G24-E24) -> 0 | O24: =IF(H24=0,B24,"n.a.") -> 5
B25: =B24+1 -> 6 | C25: =IF(D25>0,$F$4,0) -> 0 | D25: =H24 -> 0 | E25: =IF(H24<=E24,H24+G25,$G$4) -> 0 | F25: =E25-G25 -> 0 | G25: =C25*(D25/365)*30 -> 0 | H25: =IF((D25+G25-E25)<0,0,D25+G25-E25) -> 0 | O25: =IF(H25=0,B25,"n.a.") -> 6
B26: =B25+1 -> 7 | C26: =IF(D26>0,$F$4,0) -> 0 | D26: =H25 -> 0 | E26: =IF(H25<=E25,H25+G26,$G$4) -> 0 | F26: =E26-G26 -> 0 | G26: =C26*(D26/365)*30 -> 0 | H26: =IF((D26+G26-E26)<0,0,D26+G26-E26) -> 0 | O26: =IF(H26=0,B26,"n.a.") -> 7
B27: =B26+1 -> 8 | C27: =IF(D27>0,$F$4,0) -> 0 | D27: =H26 -> 0 | E27: =IF(H26<=E26,H26+G27,$G$4) -> 0 | F27: =E27-G27 -> 0 | G27: =C27*(D27/365)*30 -> 0 | H27: =IF((D27+G27-E27)<0,0,D27+G27-E27) -> 0 | O27: =IF(H27=0,B27,"n.a.") -> 8
B28: =B27+1 -> 9 | C28: =IF(D28>0,$F$4,0) -> 0 | D28: =H27 -> 0 | E28: =IF(H27<=E27,H27+G28,$G$4) -> 0 | F28: =E28-G28 -> 0 | G28: =C28*(D28/365)*30 -> 0 | H28: =IF((D28+G28-E28)<0,0,D28+G28-E28) -> 0 | O28: =IF(H28=0,B28,"n.a.") -> 9
B29: =B28+1 -> 10 | C29: =IF(D29>0,$F$4,0) -> 0 | D29: =H28 -> 0 | E29: =IF(H28<=E28,H28+G29,$G$4) -> 0 | F29: =E29-G29 -> 0 | G29: =C29*(D29/365)*30 -> 0 | H29: =IF((D29+G29-E29)<0,0,D29+G29-E29) -> 0 | O29: =IF(H29=0,B29,"n.a.") -> 10
B30: =B29+1 -> 11 | C30: =IF(D30>0,$F$4,0) -> 0 | D30: =H29 -> 0 | E30: =IF(H29<=E29,H29+G30,$G$4) -> 0 | F30: =E30-G30 -> 0 | G30: =C30*(D30/365)*30 -> 0 | H30: =IF((D30+G30-E30)<0,0,D30+G30-E30) -> 0 | O30: =IF(H30=0,B30,"n.a.") -> 11
B31: =B30+1 -> 12 | C31: =IF(D31>0,$F$4,0) -> 0 | D31: =H30 -> 0 | E31: =IF(H30<=E30,H30+G31,$G$4) -> 0 | F31: =E31-G31 -> 0 | G31: =C31*(D31/365)*30 -> 0 | H31: =IF((D31+G31-E31)<0,0,D31+G31-E31) -> 0 | I31: =H31/$D$5 -> #VALUE! | O31: =IF(H31=0,B31,"n.a.") -> 12
B32: =B31+1 -> 13 | C32: =IF(D32>0,$F$5,0) -> 0 | D32: =H31 -> 0 | E32: =IF(H31<=E31,H31+G32,$G$5) -> 0 | F32: =E32-G32 -> 0 | G32: =C32*(D32/365)*30 -> 0 | H32: =IF((D32+G32-E32)<0,0,D32+G32-E32) -> 0 | O32: =IF(H32=0,B32,"n.a.") -> 13
B33: =B32+1 -> 14 | C33: =IF(D33>0,$F$5,0) -> 0 | D33: =H32 -> 0 | E33: =IF(H32<=E32,H32+G33,$G$5) -> 0 | F33: =E33-G33 -> 0 | G33: =C33*(D33/365)*30 -> 0 | H33: =IF((D33+G33-E33)<0,0,D33+G33-E33) -> 0 | O33: =IF(H33=0,B33,"n.a.") -> 14
B34: =B33+1 -> 15 | C34: =IF(D34>0,$F$5,0) -> 0 | D34: =H33 -> 0 | E34: =IF(H33<=E33,H33+G34,$G$5) -> 0 | F34: =E34-G34 -> 0 | G34: =C34*(D34/365)*30 -> 0 | H34: =IF((D34+G34-E34)<0,0,D34+G34-E34) -> 0 | O34: =IF(H34=0,B34,"n.a.") -> 15
B35: =B34+1 -> 16 | C35: =IF(D35>0,$F$5,0) -> 0 | D35: =H34 -> 0 | E35: =IF(H34<=E34,H34+G35,$G$5) -> 0 | F35: =E35-G35 -> 0 | G35: =C35*(D35/365)*30 -> 0 | H35: =IF((D35+G35-E35)<0,0,D35+G35-E35) -> 0 | O35: =IF(H35=0,B35,"n.a.") -> 16
B36: =B35+1 -> 17 | C36: =IF(D36>0,$F$5,0) -> 0 | D36: =H35 -> 0 | E36: =IF(H35<=E35,H35+G36,$G$5) -> 0 | F36: =E36-G36 -> 0 | G36: =C36*(D36/365)*30 -> 0 | H36: =IF((D36+G36-E36)<0,0,D36+G36-E36) -> 0 | O36: =IF(H36=0,B36,"n.a.") -> 17
B37: =B36+1 -> 18 | C37: =IF(D37>0,$F$5,0) -> 0 | D37: =H36 -> 0 | E37: =IF(H36<=E36,H36+G37,$G$5) -> 0 | F37: =E37-G37 -> 0 | G37: =C37*(D37/365)*30 -> 0 | H37: =IF((D37+G37-E37)<0,0,D37+G37-E37) -> 0 | O37: =IF(H37=0,B37,"n.a.") -> 18
B38: =B37+1 -> 19 | C38: =IF(D38>0,$F$5,0) -> 0 | D38: =H37 -> 0 | E38: =IF(H37<=E37,H37+G38,$G$5) -> 0 | F38: =E38-G38 -> 0 | G38: =C38*(D38/365)*30 -> 0 | H38: =IF((D38+G38-E38)<0,0,D38+G38-E38) -> 0 | O38: =IF(H38=0,B38,"n.a.") -> 19
B39: =B38+1 -> 20 | C39: =IF(D39>0,$F$5,0) -> 0 | D39: =H38 -> 0 | E39: =IF(H38<=E38,H38+G39,$G$5) -> 0 | F39: =E39-G39 -> 0 | G39: =C39*(D39/365)*30 -> 0 | H39: =IF((D39+G39-E39)<0,0,D39+G39-E39) -> 0 | O39: =IF(H39=0,B39,"n.a.") -> 20
B40: =B39+1 -> 21 | C40: =IF(D40>0,$F$5,0) -> 0 | D40: =H39 -> 0 | E40: =IF(H39<=E39,H39+G40,$G$5) -> 0 | F40: =E40-G40 -> 0 | G40: =C40*(D40/365)*30 -> 0 | H40: =IF((D40+G40-E40)<0,0,D40+G40-E40) -> 0 | O40: =IF(H40=0,B40,"n.a.") -> 21
B41: =B40+1 -> 22 | C41: =IF(D41>0,$F$5,0) -> 0 | D41: =H40 -> 0 | E41: =IF(H40<=E40,H40+G41,$G$5) -> 0 | F41: =E41-G41 -> 0 | G41: =C41*(D41/365)*30 -> 0 | H41: =IF((D41+G41-E41)<0,0,D41+G41-E41) -> 0 | O41: =IF(H41=0,B41,"n.a.") -> 22
B42: =B41+1 -> 23 | C42: =IF(D42>0,$F$5,0) -> 0 | D42: =H41 -> 0 | E42: =IF(H41<=E41,H41+G42,$G$5) -> 0 | F42: =E42-G42 -> 0 | G42: =C42*(D42/365)*30 -> 0 | H42: =IF((D42+G42-E42)<0,0,D42+G42-E42) -> 0 | O42: =IF(H42=0,B42,"n.a.") -> 23
...

Sheet ตาราง-HL-ตามมติ
B1: ตารางผ่อนชำระเบื้องต้น HL (อัตราดอกเบี้ยตามมติ)
B2: ชื่อ | C2: ='1.ลดดอกเบี้ย'!C3 -> 0 | G2: ผ่อนชำระ
B3: App No | C3: ='1.ลดดอกเบี้ย'!C4 -> 0 | F3: อัตราดอกเบี้ย | G3: {='1.ลดดอกเบี้ย'!C26:D26} -> 0 | H3: 0
B4: วงเงิน | C4: ='2.นำเสนอดอกเบี้ย'!G14 -> 0 | D4: บาท | E4: ปีที่ 1 | F4: ='2.นำเสนอดอกเบี้ย'!H3 -> 0 | G4: ='1.ลดดอกเบี้ย'!C28 -> 0
B5: ระยะเวลา | C5: ='1.ลดดอกเบี้ย'!C9 -> 0 | D5: ปี | E5: ปีที่ 2 | F5: ='2.นำเสนอดอกเบี้ย'!H4 -> 0 | G5: ='1.ลดดอกเบี้ย'!C29 -> 0 | H5: =SUM(I6:I10)/#REF! -> #REF!
E6: ปีที่ 3 | F6: ='2.นำเสนอดอกเบี้ย'!H5 -> 0 | G6: ='1.ลดดอกเบี้ย'!C30 -> 0 | H6: =F4*12 -> 0
C7: Buffer | D7: 0.01 | E7: ปีที่ 4+ | F7: ='2.นำเสนอดอกเบี้ย'!H6 -> 0 | G7: ='1.ลดดอกเบี้ย'!C31 -> 0 | H7: =F5*12 -> 0
H8: =F6*12 -> 0
H9: =F7*12 -> 0
F10: Int. Yr. 5+ | G10: =F7 -> 0 | H10: =IF(G3="เท่ากันทุกเดือน",'1.ลดดอกเบี้ย'!#REF!,'1.ลดดอกเบี้ย'!C31) -> 0 | I10: =G10*(#REF!-48) -> #REF!
D11: =12*3 -> 36 | E11: =12*5 -> 60 | F11: =12*7 -> 84 | G11: =12*10 -> 120 | H11: =12*30 -> 360 | I11: =12*15 -> 180
D12: 3 Yrs. | E12: 5 Yrs. | F12: 7 Yrs. | G12: 10 Yrs. | H12: 30 Yrs. | I12: 15 Yrs
B13: Total Int. | D13: =SUM($G$20:$G$55) -> 0 | E13: =SUM($G$20:$G$79) -> 0 | F13: =SUM($G$20:$G$103) -> 0 | G13: =SUM($G$20:$G$139) -> 0 | H13: =SUM($G$20:$G$379) -> 0 | I13: =SUM($G$20:$G$199) -> 0
B14: Average O/S | D14: =AVERAGE($D$20:$D$55) -> 0 | E14: =AVERAGE($D$20:$D$79) -> 0 | F14: =AVERAGE($D$20:$D$103) -> 0 | G14: =AVERAGE($D$20:$D$139) -> 0 | H14: =AVERAGE($D$20:$D$379) -> 0 | I14: =AVERAGE($D$20:$D$199) -> 0
B15: EIR | D15: =D13/D14/(D11/12) -> #DIV/0! | E15: =E13/E14/(E11/12) -> #DIV/0! | F15: =F13/F14/(F11/12) -> #DIV/0! | G15: =G13/G14/(G11/12) -> #DIV/0! | H15: =H13/H14/(H11/12) -> #DIV/0! | I15: =I13/I14/(I11/12) -> #DIV/0!
B17: Average | D17: =AVERAGE($C$20:$C$55) -> 0 | E17: =AVERAGE($C$20:$C$79) -> 0 | F17: =AVERAGE($C$20:$C$103) -> 0 | G17: =AVERAGE($C$20:$C$139) -> 0 | H17: =AVERAGE($C$20:$C$379) -> 0 | I17: =AVERAGE(C20:C199) -> 0
B19: เดือน | C19: อัตราดอกเบี้ย | D19: ยอดคงค้าง | E19: ยอดผ่อนชำระ | F19: ยอดเงินต้น | G19: ยอดดอกเบี้ย | H19: ยอดคงค้าง | I19: LTV | O19: Tenor
B20: 1 | C20: =IF(D20>0,$F$4,0) -> 0 | D20: =C4 -> 0 | E20: =G4 -> 0 | F20: =E20-G20 -> 0 | G20: =C20*(D20/365)*30 -> 0 | H20: =IF((D20+G20-E20)<0,0,D20+G20-E20) -> 0 | O20: =IF(H20=0,B20,"n.a.") -> 1
B21: =B20+1 -> 2 | C21: =IF(D21>0,$F$4,0) -> 0 | D21: =H20 -> 0 | E21: =IF(H20<=E20,H20+G21,$G$4) -> 0 | F21: =E21-G21 -> 0 | G21: =C21*(D21/365)*30 -> 0 | H21: =IF((D21+G21-E21)<0,0,D21+G21-E21) -> 0 | O21: =IF(H21=0,B21,"n.a.") -> 2
B22: =B21+1 -> 3 | C22: =IF(D22>0,$F$4,0) -> 0 | D22: =H21 -> 0 | E22: =IF(H21<=E21,H21+G22,$G$4) -> 0 | F22: =E22-G22 -> 0 | G22: =C22*(D22/365)*30 -> 0 | H22: =IF((D22+G22-E22)<0,0,D22+G22-E22) -> 0 | O22: =IF(H22=0,B22,"n.a.") -> 3
B23: =B22+1 -> 4 | C23: =IF(D23>0,$F$4,0) -> 0 | D23: =H22 -> 0 | E23: =IF(H22<=E22,H22+G23,$G$4) -> 0 | F23: =E23-G23 -> 0 | G23: =C23*(D23/365)*30 -> 0 | H23: =IF((D23+G23-E23)<0,0,D23+G23-E23) -> 0 | O23: =IF(H23=0,B23,"n.a.") -> 4
B24: =B23+1 -> 5 | C24: =IF(D24>0,$F$4,0) -> 0 | D24: =H23 -> 0 | E24: =IF(H23<=E23,H23+G24,$G$4) -> 0 | F24: =E24-G24 -> 0 | G24: =C24*(D24/365)*30 -> 0 | H24: =IF((D24+G24-E24)<0,0,D24+G24-E24) -> 0 | O24: =IF(H24=0,B24,"n.a.") -> 5
B25: =B24+1 -> 6 | C25: =IF(D25>0,$F$4,0) -> 0 | D25: =H24 -> 0 | E25: =IF(H24<=E24,H24+G25,$G$4) -> 0 | F25: =E25-G25 -> 0 | G25: =C25*(D25/365)*30 -> 0 | H25: =IF((D25+G25-E25)<0,0,D25+G25-E25) -> 0 | O25: =IF(H25=0,B25,"n.a.") -> 6
B26: =B25+1 -> 7 | C26: =IF(D26>0,$F$4,0) -> 0 | D26: =H25 -> 0 | E26: =IF(H25<=E25,H25+G26,$G$4) -> 0 | F26: =E26-G26 -> 0 | G26: =C26*(D26/365)*30 -> 0 | H26: =IF((D26+G26-E26)<0,0,D26+G26-E26) -> 0 | O26: =IF(H26=0,B26,"n.a.") -> 7
B27: =B26+1 -> 8 | C27: =IF(D27>0,$F$4,0) -> 0 | D27: =H26 -> 0 | E27: =IF(H26<=E26,H26+G27,$G$4) -> 0 | F27: =E27-G27 -> 0 | G27: =C27*(D27/365)*30 -> 0 | H27: =IF((D27+G27-E27)<0,0,D27+G27-E27) -> 0 | O27: =IF(H27=0,B27,"n.a.") -> 8
B28: =B27+1 -> 9 | C28: =IF(D28>0,$F$4,0) -> 0 | D28: =H27 -> 0 | E28: =IF(H27<=E27,H27+G28,$G$4) -> 0 | F28: =E28-G28 -> 0 | G28: =C28*(D28/365)*30 -> 0 | H28: =IF((D28+G28-E28)<0,0,D28+G28-E28) -> 0 | O28: =IF(H28=0,B28,"n.a.") -> 9
B29: =B28+1 -> 10 | C29: =IF(D29>0,$F$4,0) -> 0 | D29: =H28 -> 0 | E29: =IF(H28<=E28,H28+G29,$G$4) -> 0 | F29: =E29-G29 -> 0 | G29: =C29*(D29/365)*30 -> 0 | H29: =IF((D29+G29-E29)<0,0,D29+G29-E29) -> 0 | O29: =IF(H29=0,B29,"n.a.") -> 10
B30: =B29+1 -> 11 | C30: =IF(D30>0,$F$4,0) -> 0 | D30: =H29 -> 0 | E30: =IF(H29<=E29,H29+G30,$G$4) -> 0 | F30: =E30-G30 -> 0 | G30: =C30*(D30/365)*30 -> 0 | H30: =IF((D30+G30-E30)<0,0,D30+G30-E30) -> 0 | O30: =IF(H30=0,B30,"n.a.") -> 11
B31: =B30+1 -> 12 | C31: =IF(D31>0,$F$4,0) -> 0 | D31: =H30 -> 0 | E31: =IF(H30<=E30,H30+G31,$G$4) -> 0 | F31: =E31-G31 -> 0 | G31: =C31*(D31/365)*30 -> 0 | H31: =IF((D31+G31-E31)<0,0,D31+G31-E31) -> 0 | I31: =H31/$D$5 -> #VALUE! | O31: =IF(H31=0,B31,"n.a.") -> 12
B32: =B31+1 -> 13 | C32: =IF(D32>0,$F$5,0) -> 0 | D32: =H31 -> 0 | E32: =IF(H31<=E31,H31+G32,$G$5) -> 0 | F32: =E32-G32 -> 0 | G32: =C32*(D32/365)*30 -> 0 | H32: =IF((D32+G32-E32)<0,0,D32+G32-E32) -> 0 | O32: =IF(H32=0,B32,"n.a.") -> 13
B33: =B32+1 -> 14 | C33: =IF(D33>0,$F$5,0) -> 0 | D33: =H32 -> 0 | E33: =IF(H32<=E32,H32+G33,$G$5) -> 0 | F33: =E33-G33 -> 0 | G33: =C33*(D33/365)*30 -> 0 | H33: =IF((D33+G33-E33)<0,0,D33+G33-E33) -> 0 | O33: =IF(H33=0,B33,"n.a.") -> 14
B34: =B33+1 -> 15 | C34: =IF(D34>0,$F$5,0) -> 0 | D34: =H33 -> 0 | E34: =IF(H33<=E33,H33+G34,$G$5) -> 0 | F34: =E34-G34 -> 0 | G34: =C34*(D34/365)*30 -> 0 | H34: =IF((D34+G34-E34)<0,0,D34+G34-E34) -> 0 | O34: =IF(H34=0,B34,"n.a.") -> 15
B35: =B34+1 -> 16 | C35: =IF(D35>0,$F$5,0) -> 0 | D35: =H34 -> 0 | E35: =IF(H34<=E34,H34+G35,$G$5) -> 0 | F35: =E35-G35 -> 0 | G35: =C35*(D35/365)*30 -> 0 | H35: =IF((D35+G35-E35)<0,0,D35+G35-E35) -> 0 | O35: =IF(H35=0,B35,"n.a.") -> 16
B36: =B35+1 -> 17 | C36: =IF(D36>0,$F$5,0) -> 0 | D36: =H35 -> 0 | E36: =IF(H35<=E35,H35+G36,$G$5) -> 0 | F36: =E36-G36 -> 0 | G36: =C36*(D36/365)*30 -> 0 | H36: =IF((D36+G36-E36)<0,0,D36+G36-E36) -> 0 | O36: =IF(H36=0,B36,"n.a.") -> 17
B37: =B36+1 -> 18 | C37: =IF(D37>0,$F$5,0) -> 0 | D37: =H36 -> 0 | E37: =IF(H36<=E36,H36+G37,$G$5) -> 0 | F37: =E37-G37 -> 0 | G37: =C37*(D37/365)*30 -> 0 | H37: =IF((D37+G37-E37)<0,0,D37+G37-E37) -> 0 | O37: =IF(H37=0,B37,"n.a.") -> 18
B38: =B37+1 -> 19 | C38: =IF(D38>0,$F$5,0) -> 0 | D38: =H37 -> 0 | E38: =IF(H37<=E37,H37+G38,$G$5) -> 0 | F38: =E38-G38 -> 0 | G38: =C38*(D38/365)*30 -> 0 | H38: =IF((D38+G38-E38)<0,0,D38+G38-E38) -> 0 | O38: =IF(H38=0,B38,"n.a.") -> 19
B39: =B38+1 -> 20 | C39: =IF(D39>0,$F$5,0) -> 0 | D39: =H38 -> 0 | E39: =IF(H38<=E38,H38+G39,$G$5) -> 0 | F39: =E39-G39 -> 0 | G39: =C39*(D39/365)*30 -> 0 | H39: =IF((D39+G39-E39)<0,0,D39+G39-E39) -> 0 | O39: =IF(H39=0,B39,"n.a.") -> 20
B40: =B39+1 -> 21 | C40: =IF(D40>0,$F$5,0) -> 0 | D40: =H39 -> 0 | E40: =IF(H39<=E39,H39+G40,$G$5) -> 0 | F40: =E40-G40 -> 0 | G40: =C40*(D40/365)*30 -> 0 | H40: =IF((D40+G40-E40)<0,0,D40+G40-E40) -> 0 | O40: =IF(H40=0,B40,"n.a.") -> 21
B41: =B40+1 -> 22 | C41: =IF(D41>0,$F$5,0) -> 0 | D41: =H40 -> 0 | E41: =IF(H40<=E40,H40+G41,$G$5) -> 0 | F41: =E41-G41 -> 0 | G41: =C41*(D41/365)*30 -> 0 | H41: =IF((D41+G41-E41)<0,0,D41+G41-E41) -> 0 | O41: =IF(H41=0,B41,"n.a.") -> 22
B42: =B41+1 -> 23 | C42: =IF(D42>0,$F$5,0) -> 0 | D42: =H41 -> 0 | E42: =IF(H41<=E41,H41+G42,$G$5) -> 0 | F42: =E42-G42 -> 0 | G42: =C42*(D42/365)*30 -> 0 | H42: =IF((D42+G42-E42)<0,0,D42+G42-E42) -> 0 | O42: =IF(H42=0,B42,"n.a.") -> 23
...

Sheet ตาราง-MP-ตามมติ
B1: ตารางผ่อนชำระเบื้องต้น MP (อัตราดอกเบี้ยตามมติ)
B2: ชื่อ | C2: ='1.ลดดอกเบี้ย'!C3 -> 0 | G2: ผ่อนชำระ
B3: App No | C3: ='1.ลดดอกเบี้ย'!C4 -> 0 | F3: อัตราดอกเบี้ย | G3: เท่ากันทุกเดือน
B4: วงเงิน | C4: ='1.ลดดอกเบี้ย'!E8 -> 0 | D4: บาท | E4: ปีที่ 1 | F4: ='2.นำเสนอดอกเบี้ย'!H23 -> 0 | G4: ='1.ลดดอกเบี้ย'!E28 -> 0
B5: ระยะเวลา | C5: ='1.ลดดอกเบี้ย'!E9 -> 0 | D5: ปี | E5: ปีที่ 2 | F5: ='2.นำเสนอดอกเบี้ย'!H24 -> 0 | G5: ='1.ลดดอกเบี้ย'!E29 -> 0 | H5: =SUM(I6:I10)/#REF! -> #REF!
E6: ปีที่ 3 | F6: ='2.นำเสนอดอกเบี้ย'!H25 -> 0 | G6: ='1.ลดดอกเบี้ย'!E30 -> 0 | H6: =F4*12 -> 0
C7: Buffer | D7: 0.01 | E7: ปีที่ 4+ | F7: ='2.นำเสนอดอกเบี้ย'!H26 -> 0 | G7: ='1.ลดดอกเบี้ย'!E31 -> 0 | H7: =F5*12 -> 0
H8: =F6*12 -> 0
H9: =F7*12 -> 0
F10: Int. Yr. 5+ | G10: =F7 -> 0 | H10: =G7 -> 0 | I10: =G10*(#REF!-48) -> #REF!
D11: =12*3 -> 36 | E11: =12*5 -> 60 | F11: =12*7 -> 84 | G11: =12*10 -> 120 | H11: =12*30 -> 360 | I11: =12*15 -> 180
D12: 3 Yrs. | E12: 5 Yrs. | F12: 7 Yrs. | G12: 10 Yrs. | H12: 30 Yrs. | I12: 15 Yrs
B13: Total Int. | D13: =SUM($G$20:$G$55) -> 0 | E13: =SUM($G$20:$G$79) -> 0 | F13: =SUM($G$20:$G$103) -> 0 | G13: =SUM($G$20:$G$139) -> 0 | H13: =SUM($G$20:$G$379) -> 0 | I13: =SUM($G$20:$G$199) -> 0
B14: Average O/S | D14: =AVERAGE($D$20:$D$55) -> 0 | E14: =AVERAGE($D$20:$D$79) -> 0 | F14: =AVERAGE($D$20:$D$103) -> 0 | G14: =AVERAGE($D$20:$D$139) -> 0 | H14: =AVERAGE($D$20:$D$379) -> 0 | I14: =AVERAGE($D$20:$D$199) -> 0
B15: EIR | D15: =D13/D14/(D11/12) -> #DIV/0! | E15: =E13/E14/(E11/12) -> #DIV/0! | F15: =F13/F14/(F11/12) -> #DIV/0! | G15: =G13/G14/(G11/12) -> #DIV/0! | H15: =H13/H14/(H11/12) -> #DIV/0! | I15: =I13/I14/(I11/12) -> #DIV/0!
B17: Average | D17: =AVERAGE($C$20:$C$55) -> 0 | E17: =AVERAGE($C$20:$C$79) -> 0 | F17: =AVERAGE($C$20:$C$103) -> 0 | G17: =AVERAGE($C$20:$C$139) -> 0 | H17: =AVERAGE($C$20:$C$379) -> 0 | I17: =AVERAGE(C20:C199) -> 0
B19: เดือน | C19: อัตราดอกเบี้ย | D19: ยอดคงค้าง | E19: ยอดผ่อนชำระ | F19: ยอดเงินต้น | G19: ยอดดอกเบี้ย | H19: ยอดคงค้าง | I19: LTV | O19: Tenor
B20: 1 | C20: =IF(D20>0,$F$4,0) -> 0 | D20: =C4 -> 0 | E20: =G4 -> 0 | F20: =E20-G20 -> 0 | G20: =C20*(D20/365)*30 -> 0 | H20: =IF((D20+G20-E20)<0,0,D20+G20-E20) -> 0 | O20: =IF(H20=0,B20,"n.a.") -> 1
B21: =B20+1 -> 2 | C21: =IF(D21>0,$F$4,0) -> 0 | D21: =H20 -> 0 | E21: =IF(H20<=E20,H20+G21,$G$4) -> 0 | F21: =E21-G21 -> 0 | G21: =C21*(D21/365)*30 -> 0 | H21: =IF((D21+G21-E21)<0,0,D21+G21-E21) -> 0 | O21: =IF(H21=0,B21,"n.a.") -> 2
B22: =B21+1 -> 3 | C22: =IF(D22>0,$F$4,0) -> 0 | D22: =H21 -> 0 | E22: =IF(H21<=E21,H21+G22,$G$4) -> 0 | F22: =E22-G22 -> 0 | G22: =C22*(D22/365)*30 -> 0 | H22: =IF((D22+G22-E22)<0,0,D22+G22-E22) -> 0 | O22: =IF(H22=0,B22,"n.a.") -> 3
B23: =B22+1 -> 4 | C23: =IF(D23>0,$F$4,0) -> 0 | D23: =H22 -> 0 | E23: =IF(H22<=E22,H22+G23,$G$4) -> 0 | F23: =E23-G23 -> 0 | G23: =C23*(D23/365)*30 -> 0 | H23: =IF((D23+G23-E23)<0,0,D23+G23-E23) -> 0 | O23: =IF(H23=0,B23,"n.a.") -> 4
B24: =B23+1 -> 5 | C24: =IF(D24>0,$F$4,0) -> 0 | D24: =H23 -> 0 | E24: =IF(H23<=E23,H23+G24,$G$4) -> 0 | F24: =E24-G24 -> 0 | G24: =C24*(D24/365)*30 -> 0 | H24: =IF((D24+G24-E24)<0,0,D24+G24-E24) -> 0 | O24: =IF(H24=0,B24,"n.a.") -> 5
B25: =B24+1 -> 6 | C25: =IF(D25>0,$F$4,0) -> 0 | D25: =H24 -> 0 | E25: =IF(H24<=E24,H24+G25,$G$4) -> 0 | F25: =E25-G25 -> 0 | G25: =C25*(D25/365)*30 -> 0 | H25: =IF((D25+G25-E25)<0,0,D25+G25-E25) -> 0 | O25: =IF(H25=0,B25,"n.a.") -> 6
B26: =B25+1 -> 7 | C26: =IF(D26>0,$F$4,0) -> 0 | D26: =H25 -> 0 | E26: =IF(H25<=E25,H25+G26,$G$4) -> 0 | F26: =E26-G26 -> 0 | G26: =C26*(D26/365)*30 -> 0 | H26: =IF((D26+G26-E26)<0,0,D26+G26-E26) -> 0 | O26: =IF(H26=0,B26,"n.a.") -> 7
B27: =B26+1 -> 8 | C27: =IF(D27>0,$F$4,0) -> 0 | D27: =H26 -> 0 | E27: =IF(H26<=E26,H26+G27,$G$4) -> 0 | F27: =E27-G27 -> 0 | G27: =C27*(D27/365)*30 -> 0 | H27: =IF((D27+G27-E27)<0,0,D27+G27-E27) -> 0 | O27: =IF(H27=0,B27,"n.a.") -> 8
B28: =B27+1 -> 9 | C28: =IF(D28>0,$F$4,0) -> 0 | D28: =H27 -> 0 | E28: =IF(H27<=E27,H27+G28,$G$4) -> 0 | F28: =E28-G28 -> 0 | G28: =C28*(D28/365)*30 -> 0 | H28: =IF((D28+G28-E28)<0,0,D28+G28-E28) -> 0 | O28: =IF(H28=0,B28,"n.a.") -> 9
B29: =B28+1 -> 10 | C29: =IF(D29>0,$F$4,0) -> 0 | D29: =H28 -> 0 | E29: =IF(H28<=E28,H28+G29,$G$4) -> 0 | F29: =E29-G29 -> 0 | G29: =C29*(D29/365)*30 -> 0 | H29: =IF((D29+G29-E29)<0,0,D29+G29-E29) -> 0 | O29: =IF(H29=0,B29,"n.a.") -> 10
B30: =B29+1 -> 11 | C30: =IF(D30>0,$F$4,0) -> 0 | D30: =H29 -> 0 | E30: =IF(H29<=E29,H29+G30,$G$4) -> 0 | F30: =E30-G30 -> 0 | G30: =C30*(D30/365)*30 -> 0 | H30: =IF((D30+G30-E30)<0,0,D30+G30-E30) -> 0 | O30: =IF(H30=0,B30,"n.a.") -> 11
B31: =B30+1 -> 12 | C31: =IF(D31>0,$F$4,0) -> 0 | D31: =H30 -> 0 | E31: =IF(H30<=E30,H30+G31,$G$4) -> 0 | F31: =E31-G31 -> 0 | G31: =C31*(D31/365)*30 -> 0 | H31: =IF((D31+G31-E31)<0,0,D31+G31-E31) -> 0 | I31: =H31/$D$5 -> #VALUE! | O31: =IF(H31=0,B31,"n.a.") -> 12
B32: =B31+1 -> 13 | C32: =IF(D32>0,$F$5,0) -> 0 | D32: =H31 -> 0 | E32: =IF(H31<=E31,H31+G32,$G$5) -> 0 | F32: =E32-G32 -> 0 | G32: =C32*(D32/365)*30 -> 0 | H32: =IF((D32+G32-E32)<0,0,D32+G32-E32) -> 0 | O32: =IF(H32=0,B32,"n.a.") -> 13
B33: =B32+1 -> 14 | C33: =IF(D33>0,$F$5,0) -> 0 | D33: =H32 -> 0 | E33: =IF(H32<=E32,H32+G33,$G$5) -> 0 | F33: =E33-G33 -> 0 | G33: =C33*(D33/365)*30 -> 0 | H33: =IF((D33+G33-E33)<0,0,D33+G33-E33) -> 0 | O33: =IF(H33=0,B33,"n.a.") -> 14
B34: =B33+1 -> 15 | C34: =IF(D34>0,$F$5,0) -> 0 | D34: =H33 -> 0 | E34: =IF(H33<=E33,H33+G34,$G$5) -> 0 | F34: =E34-G34 -> 0 | G34: =C34*(D34/365)*30 -> 0 | H34: =IF((D34+G34-E34)<0,0,D34+G34-E34) -> 0 | O34: =IF(H34=0,B34,"n.a.") -> 15
B35: =B34+1 -> 16 | C35: =IF(D35>0,$F$5,0) -> 0 | D35: =H34 -> 0 | E35: =IF(H34<=E34,H34+G35,$G$5) -> 0 | F35: =E35-G35 -> 0 | G35: =C35*(D35/365)*30 -> 0 | H35: =IF((D35+G35-E35)<0,0,D35+G35-E35) -> 0 | O35: =IF(H35=0,B35,"n.a.") -> 16
B36: =B35+1 -> 17 | C36: =IF(D36>0,$F$5,0) -> 0 | D36: =H35 -> 0 | E36: =IF(H35<=E35,H35+G36,$G$5) -> 0 | F36: =E36-G36 -> 0 | G36: =C36*(D36/365)*30 -> 0 | H36: =IF((D36+G36-E36)<0,0,D36+G36-E36) -> 0 | O36: =IF(H36=0,B36,"n.a.") -> 17
B37: =B36+1 -> 18 | C37: =IF(D37>0,$F$5,0) -> 0 | D37: =H36 -> 0 | E37: =IF(H36<=E36,H36+G37,$G$5) -> 0 | F37: =E37-G37 -> 0 | G37: =C37*(D37/365)*30 -> 0 | H37: =IF((D37+G37-E37)<0,0,D37+G37-E37) -> 0 | O37: =IF(H37=0,B37,"n.a.") -> 18
B38: =B37+1 -> 19 | C38: =IF(D38>0,$F$5,0) -> 0 | D38: =H37 -> 0 | E38: =IF(H37<=E37,H37+G38,$G$5) -> 0 | F38: =E38-G38 -> 0 | G38: =C38*(D38/365)*30 -> 0 | H38: =IF((D38+G38-E38)<0,0,D38+G38-E38) -> 0 | O38: =IF(H38=0,B38,"n.a.") -> 19
B39: =B38+1 -> 20 | C39: =IF(D39>0,$F$5,0) -> 0 | D39: =H38 -> 0 | E39: =IF(H38<=E38,H38+G39,$G$5) -> 0 | F39: =E39-G39 -> 0 | G39: =C39*(D39/365)*30 -> 0 | H39: =IF((D39+G39-E39)<0,0,D39+G39-E39) -> 0 | O39: =IF(H39=0,B39,"n.a.") -> 20
B40: =B39+1 -> 21 | C40: =IF(D40>0,$F$5,0) -> 0 | D40: =H39 -> 0 | E40: =IF(H39<=E39,H39+G40,$G$5) -> 0 | F40: =E40-G40 -> 0 | G40: =C40*(D40/365)*30 -> 0 | H40: =IF((D40+G40-E40)<0,0,D40+G40-E40) -> 0 | O40: =IF(H40=0,B40,"n.a.") -> 21
B41: =B40+1 -> 22 | C41: =IF(D41>0,$F$5,0) -> 0 | D41: =H40 -> 0 | E41: =IF(H40<=E40,H40+G41,$G$5) -> 0 | F41: =E41-G41 -> 0 | G41: =C41*(D41/365)*30 -> 0 | H41: =IF((D41+G41-E41)<0,0,D41+G41-E41) -> 0 | O41: =IF(H41=0,B41,"n.a.") -> 22
B42: =B41+1 -> 23 | C42: =IF(D42>0,$F$5,0) -> 0 | D42: =H41 -> 0 | E42: =IF(H41<=E41,H41+G42,$G$5) -> 0 | F42: =E42-G42 -> 0 | G42: =C42*(D42/365)*30 -> 0 | H42: =IF((D42+G42-E42)<0,0,D42+G42-E42) -> 0 | O42: =IF(H42=0,B42,"n.a.") -> 23
...

Sheet ตาราง-MP-เสนอลด
B1: ตารางผ่อนชำระเบื้องต้น MP (อัตราดอกเบี้ยนำเสนอลด)
B2: ชื่อ | C2: ='1.ลดดอกเบี้ย'!C3 -> 0 | G2: ผ่อนชำระ
B3: App No | C3: ='1.ลดดอกเบี้ย'!C4 -> 0 | F3: อัตราดอกเบี้ย | G3: เท่ากันทุกเดือน
B4: วงเงิน | C4: ='1.ลดดอกเบี้ย'!E8 -> 0 | D4: บาท | E4: ปีที่ 1 | F4: ='2.นำเสนอดอกเบี้ย'!K23 -> 0 | G4: ='1.ลดดอกเบี้ย'!E28 -> 0
B5: ระยะเวลา | C5: ='1.ลดดอกเบี้ย'!E9 -> 0 | D5: ปี | E5: ปีที่ 2 | F5: ='2.นำเสนอดอกเบี้ย'!K24 -> 0 | G5: ='1.ลดดอกเบี้ย'!E29 -> 0 | H5: =SUM(I6:I10)/#REF! -> #REF!
E6: ปีที่ 3 | F6: ='2.นำเสนอดอกเบี้ย'!K25 -> 0 | G6: ='1.ลดดอกเบี้ย'!E30 -> 0 | H6: =F4*12 -> 0
C7: Buffer | D7: 0.01 | E7: ปีที่ 4+ | F7: ='2.นำเสนอดอกเบี้ย'!K26 -> 0 | G7: ='1.ลดดอกเบี้ย'!E31 -> 0 | H7: =F5*12 -> 0
H8: =F6*12 -> 0
H9: =F7*12 -> 0
F10: Int. Yr. 5+ | G10: =F7 -> 0 | H10: =G7 -> 0 | I10: =G10*(#REF!-48) -> #REF!
D11: =12*3 -> 36 | E11: =12*5 -> 60 | F11: =12*7 -> 84 | G11: =12*10 -> 120 | H11: =12*30 -> 360 | I11: =12*15 -> 180
D12: 3 Yrs. | E12: 5 Yrs. | F12: 7 Yrs. | G12: 10 Yrs. | H12: 30 Yrs. | I12: 15 Yrs
B13: Total Int. | D13: =SUM($G$20:$G$55) -> 0 | E13: =SUM($G$20:$G$79) -> 0 | F13: =SUM($G$20:$G$103) -> 0 | G13: =SUM($G$20:$G$139) -> 0 | H13: =SUM($G$20:$G$379) -> 0 | I13: =SUM($G$20:$G$199) -> 0
B14: Average O/S | D14: =AVERAGE($D$20:$D$55) -> 0 | E14: =AVERAGE($D$20:$D$79) -> 0 | F14: =AVERAGE($D$20:$D$103) -> 0 | G14: =AVERAGE($D$20:$D$139) -> 0 | H14: =AVERAGE($D$20:$D$379) -> 0 | I14: =AVERAGE($D$20:$D$199) -> 0
B15: EIR | D15: =D13/D14/(D11/12) -> #DIV/0! | E15: =E13/E14/(E11/12) -> #DIV/0! | F15: =F13/F14/(F11/12) -> #DIV/0! | G15: =G13/G14/(G11/12) -> #DIV/0! | H15: =H13/H14/(H11/12) -> #DIV/0! | I15: =I13/I14/(I11/12) -> #DIV/0!
B17: Average | D17: =AVERAGE($C$20:$C$55) -> 0 | E17: =AVERAGE($C$20:$C$79) -> 0 | F17: =AVERAGE($C$20:$C$103) -> 0 | G17: =AVERAGE($C$20:$C$139) -> 0 | H17: =AVERAGE($C$20:$C$379) -> 0 | I17: =AVERAGE(C20:C199) -> 0
B19: เดือน | C19: อัตราดอกเบี้ย | D19: ยอดคงค้าง | E19: ยอดผ่อนชำระ | F19: ยอดเงินต้น | G19: ยอดดอกเบี้ย | H19: ยอดคงค้าง | I19: LTV | O19: Tenor
B20: 1 | C20: =IF(D20>0,$F$4,0) -> 0 | D20: =C4 -> 0 | E20: =G4 -> 0 | F20: =E20-G20 -> 0 | G20: =C20*(D20/365)*30 -> 0 | H20: =IF((D20+G20-E20)<0,0,D20+G20-E20) -> 0 | O20: =IF(H20=0,B20,"n.a.") -> 1
B21: =B20+1 -> 2 | C21: =IF(D21>0,$F$4,0) -> 0 | D21: =H20 -> 0 | E21: =IF(H20<=E20,H20+G21,$G$4) -> 0 | F21: =E21-G21 -> 0 | G21: =C21*(D21/365)*30 -> 0 | H21: =IF((D21+G21-E21)<0,0,D21+G21-E21) -> 0 | O21: =IF(H21=0,B21,"n.a.") -> 2
B22: =B21+1 -> 3 | C22: =IF(D22>0,$F$4,0) -> 0 | D22: =H21 -> 0 | E22: =IF(H21<=E21,H21+G22,$G$4) -> 0 | F22: =E22-G22 -> 0 | G22: =C22*(D22/365)*30 -> 0 | H22: =IF((D22+G22-E22)<0,0,D22+G22-E22) -> 0 | O22: =IF(H22=0,B22,"n.a.") -> 3
B23: =B22+1 -> 4 | C23: =IF(D23>0,$F$4,0) -> 0 | D23: =H22 -> 0 | E23: =IF(H22<=E22,H22+G23,$G$4) -> 0 | F23: =E23-G23 -> 0 | G23: =C23*(D23/365)*30 -> 0 | H23: =IF((D23+G23-E23)<0,0,D23+G23-E23) -> 0 | O23: =IF(H23=0,B23,"n.a.") -> 4
B24: =B23+1 -> 5 | C24: =IF(D24>0,$F$4,0) -> 0 | D24: =H23 -> 0 | E24: =IF(H23<=E23,H23+G24,$G$4) -> 0 | F24: =E24-G24 -> 0 | G24: =C24*(D24/365)*30 -> 0 | H24: =IF((D24+G24-E24)<0,0,D24+G24-E24) -> 0 | O24: =IF(H24=0,B24,"n.a.") -> 5
B25: =B24+1 -> 6 | C25: =IF(D25>0,$F$4,0) -> 0 | D25: =H24 -> 0 | E25: =IF(H24<=E24,H24+G25,$G$4) -> 0 | F25: =E25-G25 -> 0 | G25: =C25*(D25/365)*30 -> 0 | H25: =IF((D25+G25-E25)<0,0,D25+G25-E25) -> 0 | O25: =IF(H25=0,B25,"n.a.") -> 6
B26: =B25+1 -> 7 | C26: =IF(D26>0,$F$4,0) -> 0 | D26: =H25 -> 0 | E26: =IF(H25<=E25,H25+G26,$G$4) -> 0 | F26: =E26-G26 -> 0 | G26: =C26*(D26/365)*30 -> 0 | H26: =IF((D26+G26-E26)<0,0,D26+G26-E26) -> 0 | O26: =IF(H26=0,B26,"n.a.") -> 7
B27: =B26+1 -> 8 | C27: =IF(D27>0,$F$4,0) -> 0 | D27: =H26 -> 0 | E27: =IF(H26<=E26,H26+G27,$G$4) -> 0 | F27: =E27-G27 -> 0 | G27: =C27*(D27/365)*30 -> 0 | H27: =IF((D27+G27-E27)<0,0,D27+G27-E27) -> 0 | O27: =IF(H27=0,B27,"n.a.") -> 8
B28: =B27+1 -> 9 | C28: =IF(D28>0,$F$4,0) -> 0 | D28: =H27 -> 0 | E28: =IF(H27<=E27,H27+G28,$G$4) -> 0 | F28: =E28-G28 -> 0 | G28: =C28*(D28/365)*30 -> 0 | H28: =IF((D28+G28-E28)<0,0,D28+G28-E28) -> 0 | O28: =IF(H28=0,B28,"n.a.") -> 9
B29: =B28+1 -> 10 | C29: =IF(D29>0,$F$4,0) -> 0 | D29: =H28 -> 0 | E29: =IF(H28<=E28,H28+G29,$G$4) -> 0 | F29: =E29-G29 -> 0 | G29: =C29*(D29/365)*30 -> 0 | H29: =IF((D29+G29-E29)<0,0,D29+G29-E29) -> 0 | O29: =IF(H29=0,B29,"n.a.") -> 10
B30: =B29+1 -> 11 | C30: =IF(D30>0,$F$4,0) -> 0 | D30: =H29 -> 0 | E30: =IF(H29<=E29,H29+G30,$G$4) -> 0 | F30: =E30-G30 -> 0 | G30: =C30*(D30/365)*30 -> 0 | H30: =IF((D30+G30-E30)<0,0,D30+G30-E30) -> 0 | O30: =IF(H30=0,B30,"n.a.") -> 11
B31: =B30+1 -> 12 | C31: =IF(D31>0,$F$4,0) -> 0 | D31: =H30 -> 0 | E31: =IF(H30<=E30,H30+G31,$G$4) -> 0 | F31: =E31-G31 -> 0 | G31: =C31*(D31/365)*30 -> 0 | H31: =IF((D31+G31-E31)<0,0,D31+G31-E31) -> 0 | I31: =H31/$D$5 -> #VALUE! | O31: =IF(H31=0,B31,"n.a.") -> 12
B32: =B31+1 -> 13 | C32: =IF(D32>0,$F$5,0) -> 0 | D32: =H31 -> 0 | E32: =IF(H31<=E31,H31+G32,$G$5) -> 0 | F32: =E32-G32 -> 0 | G32: =C32*(D32/365)*30 -> 0 | H32: =IF((D32+G32-E32)<0,0,D32+G32-E32) -> 0 | O32: =IF(H32=0,B32,"n.a.") -> 13
B33: =B32+1 -> 14 | C33: =IF(D33>0,$F$5,0) -> 0 | D33: =H32 -> 0 | E33: =IF(H32<=E32,H32+G33,$G$5) -> 0 | F33: =E33-G33 -> 0 | G33: =C33*(D33/365)*30 -> 0 | H33: =IF((D33+G33-E33)<0,0,D33+G33-E33) -> 0 | O33: =IF(H33=0,B33,"n.a.") -> 14
B34: =B33+1 -> 15 | C34: =IF(D34>0,$F$5,0) -> 0 | D34: =H33 -> 0 | E34: =IF(H33<=E33,H33+G34,$G$5) -> 0 | F34: =E34-G34 -> 0 | G34: =C34*(D34/365)*30 -> 0 | H34: =IF((D34+G34-E34)<0,0,D34+G34-E34) -> 0 | O34: =IF(H34=0,B34,"n.a.") -> 15
B35: =B34+1 -> 16 | C35: =IF(D35>0,$F$5,0) -> 0 | D35: =H34 -> 0 | E35: =IF(H34<=E34,H34+G35,$G$5) -> 0 | F35: =E35-G35 -> 0 | G35: =C35*(D35/365)*30 -> 0 | H35: =IF((D35+G35-E35)<0,0,D35+G35-E35) -> 0 | O35: =IF(H35=0,B35,"n.a.") -> 16
B36: =B35+1 -> 17 | C36: =IF(D36>0,$F$5,0) -> 0 | D36: =H35 -> 0 | E36: =IF(H35<=E35,H35+G36,$G$5) -> 0 | F36: =E36-G36 -> 0 | G36: =C36*(D36/365)*30 -> 0 | H36: =IF((D36+G36-E36)<0,0,D36+G36-E36) -> 0 | O36: =IF(H36=0,B36,"n.a.") -> 17
B37: =B36+1 -> 18 | C37: =IF(D37>0,$F$5,0) -> 0 | D37: =H36 -> 0 | E37: =IF(H36<=E36,H36+G37,$G$5) -> 0 | F37: =E37-G37 -> 0 | G37: =C37*(D37/365)*30 -> 0 | H37: =IF((D37+G37-E37)<0,0,D37+G37-E37) -> 0 | O37: =IF(H37=0,B37,"n.a.") -> 18
B38: =B37+1 -> 19 | C38: =IF(D38>0,$F$5,0) -> 0 | D38: =H37 -> 0 | E38: =IF(H37<=E37,H37+G38,$G$5) -> 0 | F38: =E38-G38 -> 0 | G38: =C38*(D38/365)*30 -> 0 | H38: =IF((D38+G38-E38)<0,0,D38+G38-E38) -> 0 | O38: =IF(H38=0,B38,"n.a.") -> 19
B39: =B38+1 -> 20 | C39: =IF(D39>0,$F$5,0) -> 0 | D39: =H38 -> 0 | E39: =IF(H38<=E38,H38+G39,$G$5) -> 0 | F39: =E39-G39 -> 0 | G39: =C39*(D39/365)*30 -> 0 | H39: =IF((D39+G39-E39)<0,0,D39+G39-E39) -> 0 | O39: =IF(H39=0,B39,"n.a.") -> 20
B40: =B39+1 -> 21 | C40: =IF(D40>0,$F$5,0) -> 0 | D40: =H39 -> 0 | E40: =IF(H39<=E39,H39+G40,$G$5) -> 0 | F40: =E40-G40 -> 0 | G40: =C40*(D40/365)*30 -> 0 | H40: =IF((D40+G40-E40)<0,0,D40+G40-E40) -> 0 | O40: =IF(H40=0,B40,"n.a.") -> 21
B41: =B40+1 -> 22 | C41: =IF(D41>0,$F$5,0) -> 0 | D41: =H40 -> 0 | E41: =IF(H40<=E40,H40+G41,$G$5) -> 0 | F41: =E41-G41 -> 0 | G41: =C41*(D41/365)*30 -> 0 | H41: =IF((D41+G41-E41)<0,0,D41+G41-E41) -> 0 | O41: =IF(H41=0,B41,"n.a.") -> 22
B42: =B41+1 -> 23 | C42: =IF(D42>0,$F$5,0) -> 0 | D42: =H41 -> 0 | E42: =IF(H41<=E41,H41+G42,$G$5) -> 0 | F42: =E42-G42 -> 0 | G42: =C42*(D42/365)*30 -> 0 | H42: =IF((D42+G42-E42)<0,0,D42+G42-E42) -> 0 | O42: =IF(H42=0,B42,"n.a.") -> 23
...

Sheet pam
D1: com.variance
B2: None | D2: MRTA <2% | E2: MRTA >=2% | O2: Total | P2: Base | Q2: LP
B3: Lock 3Y | C3: BT | D3: 0.8 | E3: 1 | F3: Low | G3: DS1 | H3: Not Pre-Recommend | I3: Yes | J3: วงเงิน HL | K3: บ้านเดี่ยว | L3: เท่ากันทุกเดือน | N3: Fix Rate | O3: =SUM(P3:Q3) -> 0 | R3: FX | U3: %CC confirm by Adrian 12-Nov-24 | AH3: %CC confirm by Adrian 12-Nov-24
B4: Lock 5Y | C4: Focus | D4: 1.2 | E4: 1.25 | F4: Medium | G4: DS2 | H4: Pre-Recommend | I4: No | J4: วงเงิน MP | K4: บ้านแฝด | L4: ขั้นบันได | N4: Float Rate | O4: =SUM(P4:Q4) -> 0 | R4: FL | V4: BT | W4: Focus | X4: 2ndHand | Y4: RBP | Z4: PVL | AA4: Project | AB4: MP | AC4: PP | AD4: Other | AE4: ------- | AI4: BT | AJ4: Focus | AK4: RBP | AL4: PVL | AM4: Project | AN4: MP | AO4: PP | AP4: Other | AQ4: -------
C5: 2ndHand | D5: 1.2 | E5: 1.25 | F5: High | G5: E-Lending | H5: Final Approve | K5: ทาวน์เฮ้าส์ | P5: asof 31.03.26 | Q5: asof 01.04.26 | U5: 1 | V5: 2 | W5: 3 | X5: 4 | Y5: 5 | Z5: 6 | AA5: 7 | AB5: 8 | AC5: 9 | AD5: 10 | AE5: 11 | AF5: Total | AH5: 1 | AI5: 2 | AJ5: 3 | AK5: 4 | AL5: 5 | AM5: 6 | AN5: 7 | AO5: 8 | AP5: 9 | AQ5: 10 | AR5: Total
C6: RBP | D6: 1.2 | E6: 1.25 | F6: Very High | K6: ทาวน์โฮม | U6: Low | V6: =AI6/1.5 -> -0.0013333333 | W6: =AJ6/1.5 -> -0.001 | X6: =AJ6/1.5 -> -0.001 | Y6: =AK6/1.5 -> -0.0013333333 | Z6: =AL6/1.5 -> -0.001 | AA6: =AM6/1.5 -> -0.001 | AB6: =AN6/1.5 -> -0.002 | AC6: =AO6/1.5 -> -0.0046666667 | AD6: =AP6/1.5 -> -0.0013333333 | AE6: =AQ6/1.5 -> 0 | AF6: =AR6/1.5 -> -0.0015333333 | AH6: Low | AI6: -0.002 | AJ6: -0.0015 | AK6: -0.002 | AL6: -0.0015 | AM6: -0.0015 | AN6: -0.003 | AO6: -0.007 | AP6: -0.002 | AQ6: 0 | AR6: -0.0023
C7: PVL | D7: 1.2 | E7: 1.25 | K7: คอนโด | O7: O/N | P7: Y1 | Q7: Y2 | R7: Y3 | S7: LP | U7: Medium | V7: =AI7/1.5 -> -0.0013333333 | W7: =AJ7/1.5 -> -0.0016666667 | X7: =AJ7/1.5 -> -0.0016666667 | Y7: =AK7/1.5 -> -0.0026666667 | Z7: =AL7/1.5 -> -0.001 | AA7: =AM7/1.5 -> -0.0016666667 | AB7: =AN7/1.5 -> -0.004 | AC7: =AO7/1.5 -> -0.0046666667 | AD7: =AP7/1.5 -> -0.004 | AE7: =AQ7/1.5 -> 0 | AF7: =AR7/1.5 -> -0.002 | AH7: Medium | AI7: -0.002 | AJ7: -0.0025 | AK7: -0.004 | AL7: -0.0015 | AM7: -0.0025 | AN7: -0.006 | AO7: -0.007 | AP7: -0.006 | AQ7: 0 | AR7: -0.003
C8: Project | D8: 1.2 | E8: 1.25 | K8: Shop House | N8: FTP | O8: 0.01 | P8: 0.012 | Q8: 0.0155 | R8: 0.017 | S8: 0.0057 | U8: High | V8: =AI8/1.5 -> -0.0033333333 | W8: =AJ8/1.5 -> -0.0033333333 | X8: =AJ8/1.5 -> -0.0033333333 | Y8: =AK8/1.5 -> -0.0053333333 | Z8: =AL8/1.5 -> -0.001 | AA8: =AM8/1.5 -> -0.0033333333 | AB8: =AN8/1.5 -> -0.0086666667 | AC8: =AO8/1.5 -> -0.01 | AD8: =AP8/1.5 -> -0.006 | AE8: =AQ8/1.5 -> 0 | AF8: =AR8/1.5 -> -0.004 | AH8: High | AI8: -0.005 | AJ8: -0.005 | AK8: -0.008 | AL8: -0.0015 | AM8: -0.005 | AN8: -0.013 | AO8: -0.015 | AP8: -0.009 | AQ8: 0 | AR8: -0.006
C9: Other | K9: โกดัง | U9: Very High | V9: =AI9/1.5 -> -0.0066666667 | W9: =AJ9/1.5 -> -0.0066666667 | X9: =AJ9/1.5 -> -0.0066666667 | Y9: =AK9/1.5 -> -0.011333333 | Z9: =AL9/1.5 -> -0.002 | AA9: =AM9/1.5 -> -0.0066666667 | AB9: =AN9/1.5 -> -0.018 | AC9: =AO9/1.5 -> -0.020666667 | AD9: =AP9/1.5 -> -0.012666667 | AE9: =AQ9/1.5 -> 0 | AF9: =AR9/1.5 -> -0.0082 | AH9: Very High | AI9: -0.01 | AJ9: -0.01 | AK9: -0.017 | AL9: -0.003 | AM9: -0.01 | AN9: -0.027 | AO9: -0.031 | AP9: -0.019 | AQ9: 0 | AR9: -0.0123
C10: ------- | K10: โรงงาน | O10: FXFLFL | P10: =P8+S8 -> 0.0177 | Q10: =O8+S8 -> 0.0157 | R10: =O8+S8 -> 0.0157 | S10: =AVERAGE(P10:R10) -> 0.016366667 | U10: Total | V10: =AI10/1.5 -> 0 | W10: =AJ10/1.5 -> 0 | X10: =AJ10/1.5 -> 0 | Y10: =AK10/1.5 -> 0 | Z10: =AL10/1.5 -> 0 | AA10: =AM10/1.5 -> 0 | AB10: =AN10/1.5 -> 0 | AC10: =AO10/1.5 -> 0 | AD10: =AP10/1.5 -> 0 | AE10: =AQ10/1.5 -> 0 | AF10: =AR10/1.5 -> 0
K11: ออฟฟิส | O11: FXFXFL | P11: =Q8+S8 -> 0.0212 | Q11: =Q8+S8 -> 0.0212 | R11: =O8+S8 -> 0.0157 | S11: =AVERAGE(P11:R11) -> 0.019366667
K12: อพาร์ทเม้นท์ | O12: FXFXFX | P12: =R8+S8 -> 0.0227 | Q12: =R8+S8 -> 0.0227 | R12: =R8+S8 -> 0.0227 | S12: =AVERAGE(P12:R12) -> 0.0227 | U12: Index | V12: =HLOOKUP('1.ลดดอกเบี้ย'!C18,pam!$V$4:$AE$5,2,FALSE) -> #N/A
K13: อื่นๆ | O13: FLFXFX | P13: =O8+S8 -> 0.0157 | Q13: =R8+S8 -> 0.0227 | R13: =R8+S8 -> 0.0227 | S13: =AVERAGE(P13:R13) -> 0.020366667
O14: FLFLFX | P14: =O8+S8 -> 0.0157 | Q14: =O8+S8 -> 0.0157 | R14: =R8+S8 -> 0.0227 | S14: =AVERAGE(P14:R14) -> 0.018033333
O15: FLFLFL | P15: =O8+S8 -> 0.0157 | Q15: =O8+S8 -> 0.0157 | R15: =O8+S8 -> 0.0157 | S15: =AVERAGE(P15:R15) -> 0.0157 | V15: Total Y24 | W15: CLD | X15: DSA | Y15: E-lending
O16: FLFXFL | P16: 0.1 | Q16: 0.1 | R16: 0.1 | S16: 0.1 | U16: Salary Base | V16: 73419674 | W16: 51799836 | X16: 20366928 | Y16: 1252910
O17: FXFLFX | P17: 0.1 | Q17: 0.1 | R17: 0.1 | S17: 0.1 | U17: Staff Incentive | V17: 11125092 | W17: 2815200.8 | X17: 6460979.6 | Y17: 1848912
U18: Agent Commission | V18: 40726342 | W18: - | X18: 39906467 | Y18: 819875
U19: Total | V19: 1.2527111e+08 | W19: 54615037 | X19: 66734374 | Y19: 3921697
O21: HL | P21: =VLOOKUP('1.ลดดอกเบี้ย'!C11,pam!N3:R4,5,FALSE)&VLOOKUP('1.ลดดอกเบี้ย'!C12,pam!N3:R4,5,FALSE)&VLOOKUP('1.ลดดอกเบี้ย'!C13,pam!N3:R4,5,FALSE) -> #N/A | Q21: =VLOOKUP(P21,$O$10:$S$18,5,FALSE) -> #N/A | U21: FY24 Loan Vol. | V21: =SUM(W21:Y21) -> 24180.788 | W21: 8925.1129 | X21: 12972.039 | Y21: 2283.6355
O22: MP | P22: =VLOOKUP('1.ลดดอกเบี้ย'!E11,pam!N3:R4,5,FALSE)&VLOOKUP('1.ลดดอกเบี้ย'!E12,pam!N3:R4,5,FALSE)&VLOOKUP('1.ลดดอกเบี้ย'!E13,pam!N3:R4,5,FALSE) -> #N/A | Q22: =VLOOKUP(P22,$O$10:$S$17,5,FALSE) -> #N/A | U22: %CPL | V22: =V19/(V21*1000000) -> 0.005180605 | W22: =W19/(W21*1000000) -> 0.0061192544 | X22: =X19/(X21*1000000) -> 0.0051444783 | Y22: =Y19/(Y21*1000000) -> 0.0017173043

Sheet province
A1: กรุงเทพมหานคร | B1: กระบี่ | C1: กาญจนบุรี | D1: กาฬสินธุ์ | E1: กำแพงเพชร | F1: ขอนแก่น | G1: จันทบุรี | H1: ฉะเชิงเทรา | I1: ชลบุรี | J1: ชัยนาท | K1: ชัยภูมิ | L1: ชุมพร | M1: เชียงราย | N1: เชียงใหม่ | O1: ตรัง | P1: ตราด | Q1: ตาก | R1: นครนายก | S1: นครปฐม | T1: นครพนม | U1: นครราชสีมา | V1: นครศรีธรรมราช | W1: นครสวรรค์ | X1: นนทบุรี | Y1: นราธิวาส | Z1: น่าน | AA1: บุรีรัมย์ | AB1: ปทุมธานี | AC1: ประจวบคีรีขันธ์ | AD1: ปราจีนบุรี | AE1: ปัตตานี | AF1: พระนครศรีอยุธยา | AG1: พังงา | AH1: พัทลุง | AI1: พิจิตร | AJ1: พิษณุโลก | AK1: เพชรบุรี | AL1: เพชรบูรณ์ | AM1: แพร่ | AN1: พะเยา | AO1: ภูเก็ต | AP1: มหาสารคาม | AQ1: มุกดาหาร | AR1: แม่ฮ่องสอน | AS1: ยะลา | AT1: ยโสธร | AU1: ร้อยเอ็ด | AV1: ระนอง | AW1: ระยอง | AX1: ราชบุรี | AY1: ลพบุรี | AZ1: ลำปาง | BA1: ลำพูน | BB1: เลย | BC1: ศีรสะเกษ | BD1: สกลนคร | BE1: สงขลา | BF1: สตูล | BG1: สมุทรปราการ | BH1: สมุทรสงคราม | BI1: สมุทรสาคร | BJ1: สระแก้ว | BK1: สระบุรี | BL1: สิงห์บุรี | BM1: สุโขทัย | BN1: สุพรรณบุรี | BO1: สุราษฎร์ธานี | BP1: สุรินทร์ | BQ1: หนองคาย | BR1: หนองบัวลำภู | BS1: อ่างทอง | BT1: อุดรธานี | BU1: อุทัยธานี | BV1: อุตรดิตถ์ | BW1: อุบลราชธานี | BX1: อำนาจเจริญ
A2: คลองสาน | B2: เมืองกระบี่ | C2: เมืองกาญจนบุรี | D2: เมืองกาฬสินธุ์ | E2: เมืองกำแพงเพชร | F2: เมืองขอนแก่น | G2: เมืองจันทบุรี | H2: เมืองฉะเชิงเทรา | I2: เมืองชลบุรี | J2: เมืองชัยนาท | K2: เมืองชัยภูมิ | L2: เมืองชุมพร | M2: เมืองเชียงราย | N2: เมืองเชียงใหม่ | O2: เมืองตรัง | P2: เมืองตราด | Q2: เมืองตาก | R2: เมืองนครนายก | S2: เมืองนครปฐม | T2: เมืองนครพนม | U2: เมืองนครราชสีมา | V2: เมืองนครศรีธรรมราช | W2: เมืองนครสวรรค์ | X2: เมืองนนทบุรี | Y2: เมืองนราธิวาส | Z2: เมืองน่าน | AA2: เมืองบุรีรัมย์ | AB2: เมืองปทุมธานี | AC2: เมืองประจวบคีรีขันธ์ | AD2: เมืองปราจีนบุรี | AE2: เมืองปัตตานี | AF2: พระนครศรีอยุธยา | AG2: เมืองพังงา | AH2: เมืองพัทลุง | AI2: เมืองพิจิตร | AJ2: เมืองพิษณุโลก | AK2: เมืองเพชรบุรี | AL2: เมืองเพชรบูรณ์ | AM2: เมืองแพร่ | AN2: เมืองพะเยา | AO2: เมืองภูเก็ต | AP2: เมืองมหาสารคาม | AQ2: เมืองมุกดาหาร | AR2: เมืองแม่ฮ่องสอน | AS2: เมืองยะลา | AT2: เมืองยโสธร | AU2: เมืองร้อยเอ็ด | AV2: เมืองระนอง | AW2: เมืองระยอง | AX2: เมืองราชบุรี | AY2: เมืองลพบุรี | AZ2: เมืองลำปาง | BA2: เมืองลำพูน | BB2: เมืองเลย | BC2: เมืองศีรสะเกษ | BD2: เมืองสกลนคร | BE2: เมืองสงขลา | BF2: เมืองสตูล | BG2: เมืองสมุทรปราการ | BH2: เมืองสมุทรสงคราม | BI2: เมืองสมุทรสาคร | BJ2: เมืองสระแก้ว | BK2: เมืองสระบุรี | BL2: เมืองสิงห์บุรี | BM2: เมืองสุโขทัย | BN2: เมืองสุพรรณบุรี | BO2: เมืองสุราษฎร์ธานี | BP2: เมืองสุรินทร์ | BQ2: เมืองหนองคาย | BR2: เมืองหนองบัวลำภู | BS2: เมืองอ่างทอง | BT2: เมืองอุดรธานี | BU2: เมืองอุทัยธานี | BV2: เมืองอุตรดิตถ์ | BW2: เมืองอุบลราชธานี | BX2: เมืองอำนาจเจริญ
A3: คลองเตย | B3: เกาะลันตา | C3: ด่านมะขามเตี้ย | D3: กมลาไสย | E3: ขาณุวรลักษบุรี | F3: กระนวน | G3: แก่งหางแมว | H3: บางคล้า | I3: เกาะสีชัง | J3: มโนรมย์ | K3: เกษตรสมบูรณ์ | L3: ท่าแซะ | M3: ขุนตาล | N3: จอมทอง | O3: กันตัง | P3: เกาะช้าง | Q3: ท่าสองยาง | R3: บ้านนา | S3: กำแพงแสน | T3: ท่าอุเทน | U3: แก้งสนามนาง | V3: ขนอม | W3: เก้าเลี้ยว | X3: ไทรน้อย | Y3: จะแนะ | Z3: เชียงกลาง | AA3: กระสัง | AB3: คลองหลวง | AC3: กุยบุรี | AD3: กบินทร์บุรี | AE3: กะพ้อ | AF3: ท่าเรือ | AG3: กะปง | AH3: กงหรา | AI3: ตะพานหิน | AJ3: นครไทย | AK3: แก่งกระจาน | AL3: เขาค้อ | AM3: เด่นชัย | AN3: จุน | AO3: กะทู้ | AP3: กันทรวิชัย | AQ3: คำชะอี | AR3: ขุนยวม | AS3: กาบัง | AT3: กุดชุม | AU3: เกษตรวิสัย | AV3: กระบุรี | AW3: แกลง | AX3: จอมบึง | AY3: โคกเจริญ | AZ3: เกาะคา | BA3: ทุ่งหัวช้าง | BB3: เชียงคาน | BC3: กันทรลักษ์ | BD3: กุดบาก | BE3: กระแสสินธุ์ | BF3: ควนกาหลง | BG3: บางบ่อ | BH3: บางคณที | BI3: กระทุ่มแบน | BJ3: เขาฉกรรจ์ | BK3: แก่งคอย | BL3: ค่ายบางระจัน | BM3: กงไกรลาศ | BN3: ดอนเจดีย์ | BO3: กาญจนดิษฐ์ | BP3: กาบเชิง | BQ3: เซกา | BR3: นากลาง | BS3: ไชโย | BT3: กู่แก้ว | BU3: ทัพทัน | BV3: ตรอน | BW3: กุดข้าวปุ้น | BX3: ชานุมาน
A4: จอมทอง | B4: เขาพนม | C4: ทองผาภูมิ | D4: กุฉินารายณ์ | E4: คลองขลุง | F4: เขาสวนกวาง | G4: ขลุง | H4: บางน้ำเปรี้ยว | I4: บ่อทอง | J4: วัดสิงห์ | K4: แก้งคร้อ | L4: ทุ่งตะโก | M4: เชียงของ | N4: เชียงดาว | O4: ปะเหลียน | P4: เขาสมิง | Q4: บ้านตาก | R4: ปากพลี | S4: ดอนตูม | T4: ธาตุพนม | U4: ขามทะเลสอ | V4: ฉวาง | W4: โกรกพระ | X4: บางกรวย | Y4: ตากใบ | Z4: ท่าวังผา | AA4: คูเมือง | AB4: ธัญบุรี | AC4: ทับสะแก | AD4: ศรีมโหสถ | AE4: โคกโพธิ์ | AF4: นครหลวง | AG4: เกาะยาว | AH4: เขาชัยสน | AI4: ทับคล้อ | AJ4: ชาติตระการ | AK4: เขาย้อย | AL4: ชนแดน | AM4: ร้องกวาง | AN4: เชียงคำ | AO4: ถลาง | AP4: แกดำ | AQ4: ดงหลวง | AR4: ปางมะผ้า | AS4: กรงปินัง | AT4: ค้อวัง | AU4: จตุรพักตร์พิมาน | AV4: กะเปอร์ | AW4: บ้านค่าย | AX4: ดำเนินสะดวก | AY4: โคกสำโรง | AZ4: งาว | BA4: บ้านโฮ่ง | BB4: ด่านซ้าย | BC4: กันทรารมย์ | BD4: กุสุมาลย์ | BE4: ควนเนียง | BF4: ควนโดน | BG4: บางพลี | BH4: อัมพวา | BI4: บ้านแพ้ว | BJ4: คลองหาด | BK4: ดอนพุด | BL4: ท่าช้าง | BM4: คีรีมาศ | BN4: ด่านช้าง | BO4: เกาะพะงัน | BP4: จอมพระ | BQ4: โซ่พิสัย | BR4: โนนสัง | BS4: ป่าโมก | BT4: กุดจับ | BU4: บ้านไร่ | BV4: ทองแสนขัน | BW4: เขมราฐ | BX4: ปทุมราชวงศา
A5: จตุจักร | B5: คลองท่อม | C5: ท่าม่วง | D5: เขาวง | E5: คลองลาน | F5: โคกโพธิ์ไชย | G5: ท่าใหม่ | H5: บางปะกง | I5: บางละมุง | J5: สรรคบุรี | K5: คอนสวรรค์ | L5: ปะทิว | M5: เชียงแสน | N5: ไชยปราการ | O5: ย่านตาขาว | P5: คลองใหญ่ | Q5: พบพระ | R5: องครักษ์ | S5: นครชัยศรี | T5: นาแก | U5: ขามสะแกแสง | V5: ชะอวด | W5: ชุมแสง | X5: บางบัวทอง | Y5: บาเจาะ | Z5: ทุ่งช้าง | AA5: ชำนิ | AB5: ลาดหลุมแก้ว | AC5: บางสะพาน | AD5: นาดี | AE5: ทุ่งยางแดง | AF5: บางซ้าย | AG5: คุระบุรี | AH5: ควนขนุน | AI5: บางมูลนาก | AJ5: เนินมะปราง | AK5: ชะอำ | AL5: น้ำหนาว | AM5: ลอง | AN5: เชียงม่วน | AP5: โกสุมพิสัย | AQ5: ดอนตาล | AR5: ปาย | AS5: ธารโต | AT5: คำเขื่อนแก้ว | AU5: จังหาร | AV5: ละอุ่น | AW5: บ้านฉาง | AX5: บางแพ | AY5: ชัยบาดาล | AZ5: แจ้ห่ม | BA5: ป่าซาง | BB5: ท่าลี่ | BC5: ขุขันธ์ | BD5: คำตากล้า | BE5: จะนะ | BF5: ท่าแพ | BG5: พระประแดง | BJ5: ตาพระยา | BK5: บ้านหมอ | BL5: บางระจัน | BM5: ทุ่งเสลี่ยม | BN5: เดิมบางนางบวช | BO5: เกาะสมุย | BP5: ชุมพลบุรี | BQ5: ท่าบ่อ | BR5: ศรีบุญเรือง | BS5: โพธิ์ทอง | BT5: กุมภวาปี | BU5: ลานสัก | BV5: ท่าปลา | BW5: เขื่องใน | BX5: พนา
A6: ดุสิต | B6: ปลายพระยา | C6: ท่ามะกา | D6: คำม่วง | E6: ทรายทองวัฒนา | F6: ชำสูง | G6: นายายอาม | H6: บ้านโพธิ์ | I6: บ้านบึง | J6: สรรพยา | K6: คอนสาร | L6: พะโต๊ะ | M6: เทิง | N6: ดอยเต่า | O6: รัษฎา | P6: บ่อไร่ | Q6: แม่ระมาด | S6: บางเลน | T6: นาหว้า | U6: คง | V6: เชียรใหญ่ | W6: ตากฟ้า | X6: บางใหญ่ | Y6: ยี่งอ | Z6: นาน้อย | AA6: นาโพธิ์ | AB6: ลำลูกกา | AC6: บางสะพานน้อย | AD6: บ้านสร้าง | AE6: ปะนาเระ | AF6: บางไทร | AG6: ตะกั่วทุ่ง | AH6: ตะโหมด | AI6: โพทะเล | AJ6: บางกระทุ่ม | AK6: ท่ายาง | AL6: บึงสามพัน | AM6: วังชิ้น | AN6: ดอกคำใต้ | AP6: เชียงยืน | AQ6: นิคมคำสร้อย | AR6: แม่ลาน้อย | AS6: บันนังสตา | AT6: ไทยเจริญ | AU6: ธวัชบุรี | AV6: สุขสำราญ | AW6: ปลวกแดง | AX6: บ้านโป่ง | AY6: ท่าวุ้ง | AZ6: เถิน | BA6: แม่ทา | BB6: นาด้วง | BC6: ขุนหาญ | BD6: เจริญศิลป์ | BE6: เทพา | BF6: ทุ่งหว้า | BG6: พระสมุทรเจดีย์ | BJ6: วังน้ำเย็น | BK6: พระพุทธบาท | BL6: พรหมบุรี | BM6: บ้านด่านลานหอย | BN6: บางปลาม้า | BO6: คีรีรัฐนิคม | BP6: ท่าตูม | BQ6: บึงกาฬ | BR6: สุวรรณคูหา | BS6: วิเศษชัยชาญ | BT6: ไชยวาน | BU6: สว่างอารมณ์ | BV6: น้ำปาด | BW6: โขงเจียม | BX6: เสนางคนิคม
A7: ดอนเมือง | B7: ลำทับ | C7: ไทรโยค | D7: ท่าคันโท | E7: ไทรงาม | F7: ชนบท | G7: โป่งน้ำร้อน | H7: แปลงยาว | I7: พานทอง | J7: หันคา | K7: จัตุรัส | L7: ละแม | M7: ป่าแดด | N7: ดอยหล่อ | O7: สิเกา | P7: แหลมงอบ | Q7: แม่สอด | S7: พุทธมณฑล | T7: บ้านแพง | U7: ครบุรี | V7: ท่าศาลา | W7: ตาคลี | X7: ปากเกร็ด | Y7: ระแงะ | Z7: นาหมื่น | AA7: นางรอง | AB7: สามโคก | AC7: ปราณบุรี | AD7: ประจันตคาม | AE7: มายอ | AF7: บางบาล | AG7: ตะกั่วป่า | AH7: ปากพะยูน | AI7: โพธิ์ประทับช้าง | AJ7: บางระกำ | AK7: บ้านลาด | AL7: วิเชียรบุรี | AM7: สอง | AN7: ปง | AP7: นาเชือก | AQ7: หนองสูง | AR7: แม่สะเรียง | AS7: เบตง | AT7: ทรายมูล | AU7: ปทุมรัตน์ | AW7: วังจันทร์ | AX7: ปากท่อ | AY7: ท่าหลวง | AZ7: แม่ทะ | BA7: ลี้ | BB7: นาแห้ว | BC7: น้ำเกลี้ยง | BD7: เต่างอย | BE7: นาทวี | BF7: ละงู | BG7: บางเสาธง | BJ7: วัฒนานคร | BK7: มวกเหล็ก | BL7: อินทร์บุรี | BM7: ศรีนคร | BN7: ศรีประจันต์ | BO7: เคียนซา | BP7: บัวเชด | BQ7: บึงโขลงหลง | BR7: นาวัง | BS7: สามโก้ | BT7: ทุ่งฝน | BU7: หนองขาหย่าง | BV7: บ้านโคก | BW7: เดชอุดม | BX7: หัวตะพาน
