Workbook
Name Banca: Product[Banca]
Name BT_with_5_year_lock_in_period: Dropdown_Deviate[BT_with_5_year_lock_in_period]
Name Direct_Sales_1: _xlfn.ANCHORARRAY(Dropdown_DS_Zone!$A$2)
Name Direct_Sales_2: _xlfn.ANCHORARRAY(Dropdown_DS_Zone!$B$2)
Name DS1_1_1: Dropdown_DS_Staff!$A$2:$A$100
Name DS1_1_2: Dropdown_DS_Staff!$B$2:$B$100
Name DS1_1_3: Dropdown_DS_Staff!$C$2:$C$100
Name DS1_1_4: Dropdown_DS_Staff!$D$2:$D$100
Name DS1_2_1: Dropdown_DS_Staff!$E$2:$E$100
Name DS1_2_2: Dropdown_DS_Staff!$F$2:$F$100
Name DS1_2_3: Dropdown_DS_Staff!$G$2:$G$100
Name DS1_2_4: Dropdown_DS_Staff!$H$2:$H$100
Name DS1_3_1: Dropdown_DS_Staff!$I$2:$I$100
Name DS1_3_2: Dropdown_DS_Staff!$J$2:$J$100
Name DS1_3_3: Dropdown_DS_Staff!$K$2:$K$100
Name DS1_3_4: Dropdown_DS_Staff!$L$2:$L$100
Name DS1_4_1: Dropdown_DS_Staff!$M$2:$M$100
Name DS1_4_2: Dropdown_DS_Staff!$N$2:$N$100
Name DS1_4_3: Dropdown_DS_Staff!$O$2:$O$100
Name DS1_4_4: Dropdown_DS_Staff!$P$2:$P$100
Name DS1_5_1: Dropdown_DS_Staff!$Q$2:$Q$100
Name DS1_5_2: Dropdown_DS_Staff!$R$2:$R$100
Name DS1_5_3: Dropdown_DS_Staff!$S$2:$S$100
Name DS1_5_4: Dropdown_DS_Staff!$T$2:$T$100
Name DS1_6_1: Dropdown_DS_Staff!$U$2:$U$100
Name DS1_6_2: Dropdown_DS_Staff!$V$2:$V$100
Name DS1_6_3: Dropdown_DS_Staff!$W$2:$W$100
Name DS1_6_4: Dropdown_DS_Staff!$X$2:$X$100
Name DS2_1_1: Dropdown_DS_Staff!$Y$2:$Y$100
Name DS2_1_2: Dropdown_DS_Staff!$Z$2:$Z$100
Name DS2_1_3: Dropdown_DS_Staff!$AA$2:$AA$100
Name DS2_1_4: Dropdown_DS_Staff!$AB$2:$AB$100
Name DS2_1_5: Dropdown_DS_Staff!$AC$2:$AC$100
Name DS2_2_1: Dropdown_DS_Staff!$AD$2:$AD$100
Name DS2_2_2: Dropdown_DS_Staff!$AE$2:$AE$100
Name DS2_2_3: Dropdown_DS_Staff!$AF$2:$AF$100
Name DS2_2_4: Dropdown_DS_Staff!$AG$2:$AG$100
Name DS2_2_5: Dropdown_DS_Staff!$AH$2:$AH$100
Name DS2_3_1: Dropdown_DS_Staff!$AI$2:$AI$100
Name DS2_3_2: Dropdown_DS_Staff!$AJ$2:$AJ$100
Name DS2_3_3: Dropdown_DS_Staff!$AK$2:$AK$100
Name DS2_3_4: Dropdown_DS_Staff!$AL$2:$AL$100
Name DS2_3_5: Dropdown_DS_Staff!$AM$2:$AM$100
Name DS2_4_1: Dropdown_DS_Staff!$AN$2:$AN$100
Name DS2_4_2: Dropdown_DS_Staff!$AO$2:$AO$100
Name DS2_4_3: Dropdown_DS_Staff!$AP$2:$AP$100
Name DS2_4_4: Dropdown_DS_Staff!$AQ$2:$AQ$100
Name DS2_4_5: Dropdown_DS_Staff!$AR$2:$AR$100
Name DS2_5_1: Dropdown_DS_Staff!$AS$2:$AS$100
Name DS2_5_2: Dropdown_DS_Staff!$AT$2:$AT$100
Name DS2_5_3: Dropdown_DS_Staff!$AU$2:$AU$100
Name DS2_5_4: Dropdown_DS_Staff!$AV$2:$AV$100
Name DS2_5_5: Dropdown_DS_Staff!$AW$2:$AW$100
Name Extra_Cash: HLBT_Year[Extra_Cash]
Name HomeLoan_BT_less_than_2_Percent: HLBT_Year[HomeLoan_BT_less_than_2_Percent]
Name HomeLoan_BT_more_than_2_Percent: HLBT_Year[HomeLoan_BT_more_than_2_Percent]
Name HomeLoan_Non_BT: HLBT_Year[HomeLoan_Non_BT]
Name Mortgage_Power_Term: HLBT_Year[Mortgage_Power_Term]
Name MRTA_3_Percent: HLBT_Year[MRTA_3_Percent]
Name MRTA_6_Percent: HLBT_Year[MRTA_6_Percent]

Sheet Detail_Simulation
A2: Channel | B2: Direct_Sales_1
A3: Team | B3: DS1_3_2
F4: =SUM(F$6:F$201) -> 24400000 | K4: =SUM(K$6:K$201) -> 11900000 | L4: =SUM(L$6:L$201) -> 0
A5: No. | B5: Sales ID | C5: Products | D5: Sub Products | E5: Year (Home Loan BT Only) | F5: Amount | G5: Secured_Type | H5: Deviate Range (Secured Loan Only) | I5: Big Loan Size (Secured Loan Only) | J5: Deviate (Secured Loan Only) | K5: Drawdown Calculate | L5: Commission
A6: 1 | B6: 6560479 | C6: Unsecured | E6: 5 | F6: 10000000 | G6: {=_xlfn.IFS( AND($C6="Secured", OR($D6="HomeLoan_BT_more_than_2_Percent", $D6="HomeLoan_BT_less_than_2_Percent"), $E6=""), "", AND($C6="Secured",$E6=""),"others", AND($C6="Secured",$E6=3),"others", AND($C6="Secured",$E6=5),"BT_with_5_year_lock_in_period", TRUE, "")} -> #NAME? | H6: > 0.40% to 0.50% | I6: {=_xlfn.IFS( AND($C6="Secured", OR($D6="HomeLoan_BT_more_than_2_Percent", $D6="HomeLoan_BT_less_than_2_Percent"), OR($E6="", $E6=0)), "Please input Year !!!", AND($C6="Secured", OR($F6="", $F6=0)), "Please input Amount !!!", AND($C6="Secured", $F6<5000000), 1, AND($C6="Secured", $F6>=5000000), 1.1, TRUE, "")} -> #NAME? | J6: {=IFERROR(_xlfn.IFS( $G6="BT_with_5_year_lock_in_period", _xlfn.XLOOKUP($H6, Deviate_Table[Pricing discount], Deviate_Table[BT_with_5_year_lock_in_period]), $G6="others", _xlfn.XLOOKUP($H6, Deviate_Table[Pricing discount], Deviate_Table[others]), TRUE, ""), "Please input Deviate Range !!!")} -> Please input Deviate Range !!! | K6: =IF($C6="Secured",IFERROR($F6*$I6*$J6, ""), $F6) -> 10000000 | L6: {=IFERROR( _xlfn.IFS( D6="HomeLoan_BT_less_than_2_Percent", VLOOKUP(SUMIFS($K:$K, $D:$D, "HomeLoan_BT_more_than_2_Percent", $B:$B, B6)+SUMIFS($K:$K, $D:$D, "HomeLoan_BT_less_than_2_Percent", $B:$B, B6)+SUMIFS($K:$K, $D:$D, "HomeLoan_Non_BT", $B:$B, B6)+SUMIFS($K:$K, $D:$D, "Mortgage_Power_Term", $B:$B, B6), Secured_Commission!$A:$F, 2, 1)*(K6/10^6), D6="HomeLoan_BT_more_than_2_Percent", VLOOKUP(SUMIFS($K:$K, $D:$D, "HomeLoan_BT_more_than_2_Percent", $B:$B, B6)+SUMIFS($K:$K, $D:$D, "HomeLoan_BT_less_than_2_Percent", $B:$B, B6)+SUMIFS($K:$K, $D:$D, "HomeLoan_Non_BT", $B:$B, B6)+SUMIFS($K:$K, $D:$D, "Mortgage_Power_Term", $B:$B, B6), Secured_Commission!$A:$F, 3, 1)*(K6/10^6), D6="HomeLoan_Non_BT", VLOOKUP(SUMIFS($K:$K, $D:$D, "HomeLoan_BT_more_than_2_Percent", $B:$B, B6)+SUMIFS($K:$K, $D:$D, "HomeLoan_BT_less_than_2_Percent", $B:$B, B6)+SUMIFS($K:$K, $D:$D, "HomeLoan_Non_BT", $B:$B, B6)+SUMIFS($K:$K, $D:$D, "Mortgage_Power_Term", $B:$B, B6), Secured_Commission!$A:$F, 4, 1)*(K6/10^6), D6="Mortgage_Power_Term", VLOOKUP(SUMIFS($K:$K, $D:$D, "HomeLoan_BT_more_than_2_Percent", $B:$B, B6)+SUMIFS($K:$K, $D:$D, "HomeLoan_BT_less_than_2_Percent", $B:$B, B6)+SUMIFS($K:$K, $D:$D, "HomeLoan_Non_BT", $B:$B, B6)+SUMIFS($K:$K, $D:$D, "Mortgage_Power_Term", $B:$B, B6), Secured_Commission!$A:$F, 5, 1)*(K6/10^6), D6="Personal_Cash", VLOOKUP(SUMIFS($K:$K, $D:$D, "Personal_Cash", $B:$B, B6), Unsecured_Commission!$A:$B, 2, 1)*K6, OR(D6="MRTA_3_Percent", D6="SOMPO"), K6*0.03, D6="MRTA_6_Percent", K6*0.06), 0)} -> 0
A7: 2 | B7: 6860211 | C7: Secured | F7: 5000000 | G7: {=_xlfn.IFS( AND($C7="Secured", OR($D7="HomeLoan_BT_more_than_2_Percent", $D7="HomeLoan_BT_less_than_2_Percent"), $E7=""), "", AND($C7="Secured",$E7=""),"others", AND($C7="Secured",$E7=3),"others", AND($C7="Secured",$E7=5),"BT_with_5_year_lock_in_period", TRUE, "")} -> #NAME? | H7: <= 0.25% | I7: {=_xlfn.IFS( AND($C7="Secured", OR($D7="HomeLoan_BT_more_than_2_Percent", $D7="HomeLoan_BT_less_than_2_Percent"), OR($E7="", $E7=0)), "Please input Year !!!", AND($C7="Secured", OR($F7="", $F7=0)), "Please input Amount !!!", AND($C7="Secured", $F7<5000000), 1, AND($C7="Secured", $F7>=5000000), 1.1, TRUE, "")} -> #NAME? | J7: {=IFERROR(_xlfn.IFS( $G7="BT_with_5_year_lock_in_period", _xlfn.XLOOKUP($H7, Deviate_Table[Pricing discount], Deviate_Table[BT_with_5_year_lock_in_period]), $G7="others", _xlfn.XLOOKUP($H7, Deviate_Table[Pricing discount], Deviate_Table[others]), TRUE, ""), "Please input Deviate Range !!!")} -> Please input Deviate Range !!! | K7: =IF($C7="Secured",IFERROR($F7*$I7*$J7, ""), $F7) | L7: {=IFERROR( _xlfn.IFS( D7="HomeLoan_BT_less_than_2_Percent", VLOOKUP(SUMIFS($K:$K, $D:$D, "HomeLoan_BT_more_than_2_Percent", $B:$B, B7)+SUMIFS($K:$K, $D:$D, "HomeLoan_BT_less_than_2_Percent", $B:$B, B7)+SUMIFS($K:$K, $D:$D, "HomeLoan_Non_BT", $B:$B, B7)+SUMIFS($K:$K, $D:$D, "Mortgage_Power_Term", $B:$B, B7), Secured_Commission!$A:$F, 2, 1)*(K7/10^6), D7="HomeLoan_BT_more_than_2_Percent", VLOOKUP(SUMIFS($K:$K, $D:$D, "HomeLoan_BT_more_than_2_Percent", $B:$B, B7)+SUMIFS($K:$K, $D:$D, "HomeLoan_BT_less_than_2_Percent", $B:$B, B7)+SUMIFS($K:$K, $D:$D, "HomeLoan_Non_BT", $B:$B, B7)+SUMIFS($K:$K, $D:$D, "Mortgage_Power_Term", $B:$B, B7), Secured_Commission!$A:$F, 3, 1)*(K7/10^6), D7="HomeLoan_Non_BT", VLOOKUP(SUMIFS($K:$K, $D:$D, "HomeLoan_BT_more_than_2_Percent", $B:$B, B7)+SUMIFS($K:$K, $D:$D, "HomeLoan_BT_less_than_2_Percent", $B:$B, B7)+SUMIFS($K:$K, $D:$D, "HomeLoan_Non_BT", $B:$B, B7)+SUMIFS($K:$K, $D:$D, "Mortgage_Power_Term", $B:$B, B7), Secured_Commission!$A:$F, 4, 1)*(K7/10^6), D7="Mortgage_Power_Term", VLOOKUP(SUMIFS($K:$K, $D:$D, "HomeLoan_BT_more_than_2_Percent", $B:$B, B7)+SUMIFS($K:$K, $D:$D, "HomeLoan_BT_less_than_2_Percent", $B:$B, B7)+SUMIFS($K:$K, $D:$D, "HomeLoan_Non_BT", $B:$B, B7)+SUMIFS($K:$K, $D:$D, "Mortgage_Power_Term", $B:$B, B7), Secured_Commission!$A:$F, 5, 1)*(K7/10^6), D7="Personal_Cash", VLOOKUP(SUMIFS($K:$K, $D:$D, "Personal_Cash", $B:$B, B7), Unsecured_Commission!$A:$B, 2, 1)*K7, OR(D7="MRTA_3_Percent", D7="SOMPO"), K7*0.03, D7="MRTA_6_Percent", K7*0.06), 0)} -> 0
A8: 3 | B8: 6860211 | C8: Secured | D8: HomeLoan_BT_less_than_2_Percent | F8: 2000000 | G8: {=_xlfn.IFS( AND($C8="Secured", OR($D8="HomeLoan_BT_more_than_2_Percent", $D8="HomeLoan_BT_less_than_2_Percent"), $E8=""), "", AND($C8="Secured",$E8=""),"others", AND($C8="Secured",$E8=3),"others", AND($C8="Secured",$E8=5),"BT_with_5_year_lock_in_period", TRUE, "")} -> #NAME? | H8: No discount | I8: {=_xlfn.IFS( AND($C8="Secured", OR($D8="HomeLoan_BT_more_than_2_Percent", $D8="HomeLoan_BT_less_than_2_Percent"), OR($E8="", $E8=0)), "Please input Year !!!", AND($C8="Secured", OR($F8="", $F8=0)), "Please input Amount !!!", AND($C8="Secured", $F8<5000000), 1, AND($C8="Secured", $F8>=5000000), 1.1, TRUE, "")} -> #NAME? | J8: {=IFERROR(_xlfn.IFS( $G8="BT_with_5_year_lock_in_period", _xlfn.XLOOKUP($H8, Deviate_Table[Pricing discount], Deviate_Table[BT_with_5_year_lock_in_period]), $G8="others", _xlfn.XLOOKUP($H8, Deviate_Table[Pricing discount], Deviate_Table[others]), TRUE, ""), "Please input Deviate Range !!!")} -> Please input Deviate Range !!! | K8: =IF($C8="Secured",IFERROR($F8*$I8*$J8, ""), $F8) | L8: {=IFERROR( _xlfn.IFS( D8="HomeLoan_BT_less_than_2_Percent", VLOOKUP(SUMIFS($K:$K, $D:$D, "HomeLoan_BT_more_than_2_Percent", $B:$B, B8)+SUMIFS($K:$K, $D:$D, "HomeLoan_BT_less_than_2_Percent", $B:$B, B8)+SUMIFS($K:$K, $D:$D, "HomeLoan_Non_BT", $B:$B, B8)+SUMIFS($K:$K, $D:$D, "Mortgage_Power_Term", $B:$B, B8), Secured_Commission!$A:$F, 2, 1)*(K8/10^6), D8="HomeLoan_BT_more_than_2_Percent", VLOOKUP(SUMIFS($K:$K, $D:$D, "HomeLoan_BT_more_than_2_Percent", $B:$B, B8)+SUMIFS($K:$K, $D:$D, "HomeLoan_BT_less_than_2_Percent", $B:$B, B8)+SUMIFS($K:$K, $D:$D, "HomeLoan_Non_BT", $B:$B, B8)+SUMIFS($K:$K, $D:$D, "Mortgage_Power_Term", $B:$B, B8), Secured_Commission!$A:$F, 3, 1)*(K8/10^6), D8="HomeLoan_Non_BT", VLOOKUP(SUMIFS($K:$K, $D:$D, "HomeLoan_BT_more_than_2_Percent", $B:$B, B8)+SUMIFS($K:$K, $D:$D, "HomeLoan_BT_less_than_2_Percent", $B:$B, B8)+SUMIFS($K:$K, $D:$D, "HomeLoan_Non_BT", $B:$B, B8)+SUMIFS($K:$K, $D:$D, "Mortgage_Power_Term", $B:$B, B8), Secured_Commission!$A:$F, 4, 1)*(K8/10^6), D8="Mortgage_Power_Term", VLOOKUP(SUMIFS($K:$K, $D:$D, "HomeLoan_BT_more_than_2_Percent", $B:$B, B8)+SUMIFS($K:$K, $D:$D, "HomeLoan_BT_less_than_2_Percent", $B:$B, B8)+SUMIFS($K:$K, $D:$D, "HomeLoan_Non_BT", $B:$B, B8)+SUMIFS($K:$K, $D:$D, "Mortgage_Power_Term", $B:$B, B8), Secured_Commission!$A:$F, 5, 1)*(K8/10^6), D8="Personal_Cash", VLOOKUP(SUMIFS($K:$K, $D:$D, "Personal_Cash", $B:$B, B8), Unsecured_Commission!$A:$B, 2, 1)*K8, OR(D8="MRTA_3_Percent", D8="SOMPO"), K8*0.03, D8="MRTA_6_Percent", K8*0.06), 0)} -> 0
A9: 4 | B9: 6860211 | C9: Unsecured | D9: Personal_Cash | F9: 1000000 | G9: {=_xlfn.IFS( AND($C9="Secured", OR($D9="HomeLoan_BT_more_than_2_Percent", $D9="HomeLoan_BT_less_than_2_Percent"), $E9=""), "", AND($C9="Secured",$E9=""),"others", AND($C9="Secured",$E9=3),"others", AND($C9="Secured",$E9=5),"BT_with_5_year_lock_in_period", TRUE, "")} -> #NAME? | I9: {=_xlfn.IFS( AND($C9="Secured", OR($D9="HomeLoan_BT_more_than_2_Percent", $D9="HomeLoan_BT_less_than_2_Percent"), OR($E9="", $E9=0)), "Please input Year !!!", AND($C9="Secured", OR($F9="", $F9=0)), "Please input Amount !!!", AND($C9="Secured", $F9<5000000), 1, AND($C9="Secured", $F9>=5000000), 1.1, TRUE, "")} -> #NAME? | J9: {=IFERROR(_xlfn.IFS( $G9="BT_with_5_year_lock_in_period", _xlfn.XLOOKUP($H9, Deviate_Table[Pricing discount], Deviate_Table[BT_with_5_year_lock_in_period]), $G9="others", _xlfn.XLOOKUP($H9, Deviate_Table[Pricing discount], Deviate_Table[others]), TRUE, ""), "Please input Deviate Range !!!")} -> Please input Deviate Range !!! | K9: =IF($C9="Secured",IFERROR($F9*$I9*$J9, ""), $F9) -> 1000000 | L9: {=IFERROR( _xlfn.IFS( D9="HomeLoan_BT_less_than_2_Percent", VLOOKUP(SUMIFS($K:$K, $D:$D, "HomeLoan_BT_more_than_2_Percent", $B:$B, B9)+SUMIFS($K:$K, $D:$D, "HomeLoan_BT_less_than_2_Percent", $B:$B, B9)+SUMIFS($K:$K, $D:$D, "HomeLoan_Non_BT", $B:$B, B9)+SUMIFS($K:$K, $D:$D, "Mortgage_Power_Term", $B:$B, B9), Secured_Commission!$A:$F, 2, 1)*(K9/10^6), D9="HomeLoan_BT_more_than_2_Percent", VLOOKUP(SUMIFS($K:$K, $D:$D, "HomeLoan_BT_more_than_2_Percent", $B:$B, B9)+SUMIFS($K:$K, $D:$D, "HomeLoan_BT_less_than_2_Percent", $B:$B, B9)+SUMIFS($K:$K, $D:$D, "HomeLoan_Non_BT", $B:$B, B9)+SUMIFS($K:$K, $D:$D, "Mortgage_Power_Term", $B:$B, B9), Secured_Commission!$A:$F, 3, 1)*(K9/10^6), D9="HomeLoan_Non_BT", VLOOKUP(SUMIFS($K:$K, $D:$D, "HomeLoan_BT_more_than_2_Percent", $B:$B, B9)+SUMIFS($K:$K, $D:$D, "HomeLoan_BT_less_than_2_Percent", $B:$B, B9)+SUMIFS($K:$K, $D:$D, "HomeLoan_Non_BT", $B:$B, B9)+SUMIFS($K:$K, $D:$D, "Mortgage_Power_Term", $B:$B, B9), Secured_Commission!$A:$F, 4, 1)*(K9/10^6), D9="Mortgage_Power_Term", VLOOKUP(SUMIFS($K:$K, $D:$D, "HomeLoan_BT_more_than_2_Percent", $B:$B, B9)+SUMIFS($K:$K, $D:$D, "HomeLoan_BT_less_than_2_Percent", $B:$B, B9)+SUMIFS($K:$K, $D:$D, "HomeLoan_Non_BT", $B:$B, B9)+SUMIFS($K:$K, $D:$D, "Mortgage_Power_Term", $B:$B, B9), Secured_Commission!$A:$F, 5, 1)*(K9/10^6), D9="Personal_Cash", VLOOKUP(SUMIFS($K:$K, $D:$D, "Personal_Cash", $B:$B, B9), Unsecured_Commission!$A:$B, 2, 1)*K9, OR(D9="MRTA_3_Percent", D9="SOMPO"), K9*0.03, D9="MRTA_6_Percent", K9*0.06), 0)} -> 0
A10: 5 | B10: 6860211 | C10: Banca | D10: MRTA_6_Percent | F10: 200000 | G10: {=_xlfn.IFS( AND($C10="Secured", OR($D10="HomeLoan_BT_more_than_2_Percent", $D10="HomeLoan_BT_less_than_2_Percent"), $E10=""), "", AND($C10="Secured",$E10=""),"others", AND($C10="Secured",$E10=3),"others", AND($C10="Secured",$E10=5),"BT_with_5_year_lock_in_period", TRUE, "")} -> #NAME? | I10: {=_xlfn.IFS( AND($C10="Secured", OR($D10="HomeLoan_BT_more_than_2_Percent", $D10="HomeLoan_BT_less_than_2_Percent"), OR($E10="", $E10=0)), "Please input Year !!!", AND($C10="Secured", OR($F10="", $F10=0)), "Please input Amount !!!", AND($C10="Secured", $F10<5000000), 1, AND($C10="Secured", $F10>=5000000), 1.1, TRUE, "")} -> #NAME? | J10: {=IFERROR(_xlfn.IFS( $G10="BT_with_5_year_lock_in_period", _xlfn.XLOOKUP($H10, Deviate_Table[Pricing discount], Deviate_Table[BT_with_5_year_lock_in_period]), $G10="others", _xlfn.XLOOKUP($H10, Deviate_Table[Pricing discount], Deviate_Table[others]), TRUE, ""), "Please input Deviate Range !!!")} -> Please input Deviate Range !!! | K10: =IF($C10="Secured",IFERROR($F10*$I10*$J10, ""), $F10) -> 200000 | L10: {=IFERROR( _xlfn.IFS( D10="HomeLoan_BT_less_than_2_Percent", VLOOKUP(SUMIFS($K:$K, $D:$D, "HomeLoan_BT_more_than_2_Percent", $B:$B, B10)+SUMIFS($K:$K, $D:$D, "HomeLoan_BT_less_than_2_Percent", $B:$B, B10)+SUMIFS($K:$K, $D:$D, "HomeLoan_Non_BT", $B:$B, B10)+SUMIFS($K:$K, $D:$D, "Mortgage_Power_Term", $B:$B, B10), Secured_Commission!$A:$F, 2, 1)*(K10/10^6), D10="HomeLoan_BT_more_than_2_Percent", VLOOKUP(SUMIFS($K:$K, $D:$D, "HomeLoan_BT_more_than_2_Percent", $B:$B, B10)+SUMIFS($K:$K, $D:$D, "HomeLoan_BT_less_than_2_Percent", $B:$B, B10)+SUMIFS($K:$K, $D:$D, "HomeLoan_Non_BT", $B:$B, B10)+SUMIFS($K:$K, $D:$D, "Mortgage_Power_Term", $B:$B, B10), Secured_Commission!$A:$F, 3, 1)*(K10/10^6), D10="HomeLoan_Non_BT", VLOOKUP(SUMIFS($K:$K, $D:$D, "HomeLoan_BT_more_than_2_Percent", $B:$B, B10)+SUMIFS($K:$K, $D:$D, "HomeLoan_BT_less_than_2_Percent", $B:$B, B10)+SUMIFS($K:$K, $D:$D, "HomeLoan_Non_BT", $B:$B, B10)+SUMIFS($K:$K, $D:$D, "Mortgage_Power_Term", $B:$B, B10), Secured_Commission!$A:$F, 4, 1)*(K10/10^6), D10="Mortgage_Power_Term", VLOOKUP(SUMIFS($K:$K, $D:$D, "HomeLoan_BT_more_than_2_Percent", $B:$B, B10)+SUMIFS($K:$K, $D:$D, "HomeLoan_BT_less_than_2_Percent", $B:$B, B10)+SUMIFS($K:$K, $D:$D, "HomeLoan_Non_BT", $B:$B, B10)+SUMIFS($K:$K, $D:$D, "Mortgage_Power_Term", $B:$B, B10), Secured_Commission!$A:$F, 5, 1)*(K10/10^6), D10="Personal_Cash", VLOOKUP(SUMIFS($K:$K, $D:$D, "Personal_Cash", $B:$B, B10), Unsecured_Commission!$A:$B, 2, 1)*K10, OR(D10="MRTA_3_Percent", D10="SOMPO"), K10*0.03, D10="MRTA_6_Percent", K10*0.06), 0)} -> 0
A11: 6 | B11: 6860211 | C11: Unsecured | D11: Personal_Cash | F11: 400000 | G11: {=_xlfn.IFS( AND($C11="Secured", OR($D11="HomeLoan_BT_more_than_2_Percent", $D11="HomeLoan_BT_less_than_2_Percent"), $E11=""), "", AND($C11="Secured",$E11=""),"others", AND($C11="Secured",$E11=3),"others", AND($C11="Secured",$E11=5),"BT_with_5_year_lock_in_period", TRUE, "")} -> #NAME? | I11: {=_xlfn.IFS( AND($C11="Secured", OR($D11="HomeLoan_BT_more_than_2_Percent", $D11="HomeLoan_BT_less_than_2_Percent"), OR($E11="", $E11=0)), "Please input Year !!!", AND($C11="Secured", OR($F11="", $F11=0)), "Please input Amount !!!", AND($C11="Secured", $F11<5000000), 1, AND($C11="Secured", $F11>=5000000), 1.1, TRUE, "")} -> #NAME? | J11: {=IFERROR(_xlfn.IFS( $G11="BT_with_5_year_lock_in_period", _xlfn.XLOOKUP($H11, Deviate_Table[Pricing discount], Deviate_Table[BT_with_5_year_lock_in_period]), $G11="others", _xlfn.XLOOKUP($H11, Deviate_Table[Pricing discount], Deviate_Table[others]), TRUE, ""), "Please input Deviate Range !!!")} -> Please input Deviate Range !!! | K11: =IF($C11="Secured",IFERROR($F11*$I11*$J11, ""), $F11) -> 400000 | L11: {=IFERROR( _xlfn.IFS( D11="HomeLoan_BT_less_than_2_Percent", VLOOKUP(SUMIFS($K:$K, $D:$D, "HomeLoan_BT_more_than_2_Percent", $B:$B, B11)+SUMIFS($K:$K, $D:$D, "HomeLoan_BT_less_than_2_Percent", $B:$B, B11)+SUMIFS($K:$K, $D:$D, "HomeLoan_Non_BT", $B:$B, B11)+SUMIFS($K:$K, $D:$D, "Mortgage_Power_Term", $B:$B, B11), Secured_Commission!$A:$F, 2, 1)*(K11/10^6), D11="HomeLoan_BT_more_than_2_Percent", VLOOKUP(SUMIFS($K:$K, $D:$D, "HomeLoan_BT_more_than_2_Percent", $B:$B, B11)+SUMIFS($K:$K, $D:$D, "HomeLoan_BT_less_than_2_Percent", $B:$B, B11)+SUMIFS($K:$K, $D:$D, "HomeLoan_Non_BT", $B:$B, B11)+SUMIFS($K:$K, $D:$D, "Mortgage_Power_Term", $B:$B, B11), Secured_Commission!$A:$F, 3, 1)*(K11/10^6), D11="HomeLoan_Non_BT", VLOOKUP(SUMIFS($K:$K, $D:$D, "HomeLoan_BT_more_than_2_Percent", $B:$B, B11)+SUMIFS($K:$K, $D:$D, "HomeLoan_BT_less_than_2_Percent", $B:$B, B11)+SUMIFS($K:$K, $D:$D, "HomeLoan_Non_BT", $B:$B, B11)+SUMIFS($K:$K, $D:$D, "Mortgage_Power_Term", $B:$B, B11), Secured_Commission!$A:$F, 4, 1)*(K11/10^6), D11="Mortgage_Power_Term", VLOOKUP(SUMIFS($K:$K, $D:$D, "HomeLoan_BT_more_than_2_Percent", $B:$B, B11)+SUMIFS($K:$K, $D:$D, "HomeLoan_BT_less_than_2_Percent", $B:$B, B11)+SUMIFS($K:$K, $D:$D, "HomeLoan_Non_BT", $B:$B, B11)+SUMIFS($K:$K, $D:$D, "Mortgage_Power_Term", $B:$B, B11), Secured_Commission!$A:$F, 5, 1)*(K11/10^6), D11="Personal_Cash", VLOOKUP(SUMIFS($K:$K, $D:$D, "Personal_Cash", $B:$B, B11), Unsecured_Commission!$A:$B, 2, 1)*K11, OR(D11="MRTA_3_Percent", D11="SOMPO"), K11*0.03, D11="MRTA_6_Percent", K11*0.06), 0)} -> 0
A12: 7 | B12: 6860211 | C12: Secured | D12: HomeLoan_BT_less_than_2_Percent | E12: 5 | F12: 5500000 | G12: {=_xlfn.IFS( AND($C12="Secured", OR($D12="HomeLoan_BT_more_than_2_Percent", $D12="HomeLoan_BT_less_than_2_Percent"), $E12=""), "", AND($C12="Secured",$E12=""),"others", AND($C12="Secured",$E12=3),"others", AND($C12="Secured",$E12=5),"BT_with_5_year_lock_in_period", TRUE, "")} -> #NAME? | H12: <= 0.25% | I12: {=_xlfn.IFS( AND($C12="Secured", OR($D12="HomeLoan_BT_more_than_2_Percent", $D12="HomeLoan_BT_less_than_2_Percent"), OR($E12="", $E12=0)), "Please input Year !!!", AND($C12="Secured", OR($F12="", $F12=0)), "Please input Amount !!!", AND($C12="Secured", $F12<5000000), 1, AND($C12="Secured", $F12>=5000000), 1.1, TRUE, "")} -> #NAME? | J12: {=IFERROR(_xlfn.IFS( $G12="BT_with_5_year_lock_in_period", _xlfn.XLOOKUP($H12, Deviate_Table[Pricing discount], Deviate_Table[BT_with_5_year_lock_in_period]), $G12="others", _xlfn.XLOOKUP($H12, Deviate_Table[Pricing discount], Deviate_Table[others]), TRUE, ""), "Please input Deviate Range !!!")} -> Please input Deviate Range !!! | K12: =IF($C12="Secured",IFERROR($F12*$I12*$J12, ""), $F12) | L12: {=IFERROR( _xlfn.IFS( D12="HomeLoan_BT_less_than_2_Percent", VLOOKUP(SUMIFS($K:$K, $D:$D, "HomeLoan_BT_more_than_2_Percent", $B:$B, B12)+SUMIFS($K:$K, $D:$D, "HomeLoan_BT_less_than_2_Percent", $B:$B, B12)+SUMIFS($K:$K, $D:$D, "HomeLoan_Non_BT", $B:$B, B12)+SUMIFS($K:$K, $D:$D, "Mortgage_Power_Term", $B:$B, B12), Secured_Commission!$A:$F, 2, 1)*(K12/10^6), D12="HomeLoan_BT_more_than_2_Percent", VLOOKUP(SUMIFS($K:$K, $D:$D, "HomeLoan_BT_more_than_2_Percent", $B:$B, B12)+SUMIFS($K:$K, $D:$D, "HomeLoan_BT_less_than_2_Percent", $B:$B, B12)+SUMIFS($K:$K, $D:$D, "HomeLoan_Non_BT", $B:$B, B12)+SUMIFS($K:$K, $D:$D, "Mortgage_Power_Term", $B:$B, B12), Secured_Commission!$A:$F, 3, 1)*(K12/10^6), D12="HomeLoan_Non_BT", VLOOKUP(SUMIFS($K:$K, $D:$D, "HomeLoan_BT_more_than_2_Percent", $B:$B, B12)+SUMIFS($K:$K, $D:$D, "HomeLoan_BT_less_than_2_Percent", $B:$B, B12)+SUMIFS($K:$K, $D:$D, "HomeLoan_Non_BT", $B:$B, B12)+SUMIFS($K:$K, $D:$D, "Mortgage_Power_Term", $B:$B, B12), Secured_Commission!$A:$F, 4, 1)*(K12/10^6), D12="Mortgage_Power_Term", VLOOKUP(SUMIFS($K:$K, $D:$D, "HomeLoan_BT_more_than_2_Percent", $B:$B, B12)+SUMIFS($K:$K, $D:$D, "HomeLoan_BT_less_than_2_Percent", $B:$B, B12)+SUMIFS($K:$K, $D:$D, "HomeLoan_Non_BT", $B:$B, B12)+SUMIFS($K:$K, $D:$D, "Mortgage_Power_Term", $B:$B, B12), Secured_Commission!$A:$F, 5, 1)*(K12/10^6), D12="Personal_Cash", VLOOKUP(SUMIFS($K:$K, $D:$D, "Personal_Cash", $B:$B, B12), Unsecured_Commission!$A:$B, 2, 1)*K12, OR(D12="MRTA_3_Percent", D12="SOMPO"), K12*0.03, D12="MRTA_6_Percent", K12*0.06), 0)} -> 0
A13: 8 | B13: 6860015 | C13: Banca | D13: SOMPO | F13: 300000 | G13: {=_xlfn.IFS( AND($C13="Secured", OR($D13="HomeLoan_BT_more_than_2_Percent", $D13="HomeLoan_BT_less_than_2_Percent"), $E13=""), "", AND($C13="Secured",$E13=""),"others", AND($C13="Secured",$E13=3),"others", AND($C13="Secured",$E13=5),"BT_with_5_year_lock_in_period", TRUE, "")} -> #NAME? | I13: {=_xlfn.IFS( AND($C13="Secured", OR($D13="HomeLoan_BT_more_than_2_Percent", $D13="HomeLoan_BT_less_than_2_Percent"), OR($E13="", $E13=0)), "Please input Year !!!", AND($C13="Secured", OR($F13="", $F13=0)), "Please input Amount !!!", AND($C13="Secured", $F13<5000000), 1, AND($C13="Secured", $F13>=5000000), 1.1, TRUE, "")} -> #NAME? | J13: {=IFERROR(_xlfn.IFS( $G13="BT_with_5_year_lock_in_period", _xlfn.XLOOKUP($H13, Deviate_Table[Pricing discount], Deviate_Table[BT_with_5_year_lock_in_period]), $G13="others", _xlfn.XLOOKUP($H13, Deviate_Table[Pricing discount], Deviate_Table[others]), TRUE, ""), "Please input Deviate Range !!!")} -> Please input Deviate Range !!! | K13: =IF($C13="Secured",IFERROR($F13*$I13*$J13, ""), $F13) -> 300000 | L13: {=IFERROR( _xlfn.IFS( D13="HomeLoan_BT_less_than_2_Percent", VLOOKUP(SUMIFS($K:$K, $D:$D, "HomeLoan_BT_more_than_2_Percent", $B:$B, B13)+SUMIFS($K:$K, $D:$D, "HomeLoan_BT_less_than_2_Percent", $B:$B, B13)+SUMIFS($K:$K, $D:$D, "HomeLoan_Non_BT", $B:$B, B13)+SUMIFS($K:$K, $D:$D, "Mortgage_Power_Term", $B:$B, B13), Secured_Commission!$A:$F, 2, 1)*(K13/10^6), D13="HomeLoan_BT_more_than_2_Percent", VLOOKUP(SUMIFS($K:$K, $D:$D, "HomeLoan_BT_more_than_2_Percent", $B:$B, B13)+SUMIFS($K:$K, $D:$D, "HomeLoan_BT_less_than_2_Percent", $B:$B, B13)+SUMIFS($K:$K, $D:$D, "HomeLoan_Non_BT", $B:$B, B13)+SUMIFS($K:$K, $D:$D, "Mortgage_Power_Term", $B:$B, B13), Secured_Commission!$A:$F, 3, 1)*(K13/10^6), D13="HomeLoan_Non_BT", VLOOKUP(SUMIFS($K:$K, $D:$D, "HomeLoan_BT_more_than_2_Percent", $B:$B, B13)+SUMIFS($K:$K, $D:$D, "HomeLoan_BT_less_than_2_Percent", $B:$B, B13)+SUMIFS($K:$K, $D:$D, "HomeLoan_Non_BT", $B:$B, B13)+SUMIFS($K:$K, $D:$D, "Mortgage_Power_Term", $B:$B, B13), Secured_Commission!$A:$F, 4, 1)*(K13/10^6), D13="Mortgage_Power_Term", VLOOKUP(SUMIFS($K:$K, $D:$D, "HomeLoan_BT_more_than_2_Percent", $B:$B, B13)+SUMIFS($K:$K, $D:$D, "HomeLoan_BT_less_than_2_Percent", $B:$B, B13)+SUMIFS($K:$K, $D:$D, "HomeLoan_Non_BT", $B:$B, B13)+SUMIFS($K:$K, $D:$D, "Mortgage_Power_Term", $B:$B, B13), Secured_Commission!$A:$F, 5, 1)*(K13/10^6), D13="Personal_Cash", VLOOKUP(SUMIFS($K:$K, $D:$D, "Personal_Cash", $B:$B, B13), Unsecured_Commission!$A:$B, 2, 1)*K13, OR(D13="MRTA_3_Percent", D13="SOMPO"), K13*0.03, D13="MRTA_6_Percent", K13*0.06), 0)} -> 0
A14: 9 | G14: {=_xlfn.IFS( AND($C14="Secured", OR($D14="HomeLoan_BT_more_than_2_Percent", $D14="HomeLoan_BT_less_than_2_Percent"), $E14=""), "", AND($C14="Secured",$E14=""),"others", AND($C14="Secured",$E14=3),"others", AND($C14="Secured",$E14=5),"BT_with_5_year_lock_in_period", TRUE, "")} | I14: {=_xlfn.IFS( AND($C14="Secured", OR($D14="HomeLoan_BT_more_than_2_Percent", $D14="HomeLoan_BT_less_than_2_Percent"), OR($E14="", $E14=0)), "Please input Year !!!", AND($C14="Secured", OR($F14="", $F14=0)), "Please input Amount !!!", AND($C14="Secured", $F14<5000000), 1, AND($C14="Secured", $F14>=5000000), 1.1, TRUE, "")} | J14: {=IFERROR(_xlfn.IFS( $G14="BT_with_5_year_lock_in_period", _xlfn.XLOOKUP($H14, Deviate_Table[Pricing discount], Deviate_Table[BT_with_5_year_lock_in_period]), $G14="others", _xlfn.XLOOKUP($H14, Deviate_Table[Pricing discount], Deviate_Table[others]), TRUE, ""), "Please input Deviate Range !!!")} | K14: =IF($C14="Secured",IFERROR($F14*$I14*$J14, ""), $F14) -> 0 | L14: {=IFERROR( _xlfn.IFS( D14="HomeLoan_BT_less_than_2_Percent", VLOOKUP(SUMIFS($K:$K, $D:$D, "HomeLoan_BT_more_than_2_Percent", $B:$B, B14)+SUMIFS($K:$K, $D:$D, "HomeLoan_BT_less_than_2_Percent", $B:$B, B14)+SUMIFS($K:$K, $D:$D, "HomeLoan_Non_BT", $B:$B, B14)+SUMIFS($K:$K, $D:$D, "Mortgage_Power_Term", $B:$B, B14), Secured_Commission!$A:$F, 2, 1)*(K14/10^6), D14="HomeLoan_BT_more_than_2_Percent", VLOOKUP(SUMIFS($K:$K, $D:$D, "HomeLoan_BT_more_than_2_Percent", $B:$B, B14)+SUMIFS($K:$K, $D:$D, "HomeLoan_BT_less_than_2_Percent", $B:$B, B14)+SUMIFS($K:$K, $D:$D, "HomeLoan_Non_BT", $B:$B, B14)+SUMIFS($K:$K, $D:$D, "Mortgage_Power_Term", $B:$B, B14), Secured_Commission!$A:$F, 3, 1)*(K14/10^6), D14="HomeLoan_Non_BT", VLOOKUP(SUMIFS($K:$K, $D:$D, "HomeLoan_BT_more_than_2_Percent", $B:$B, B14)+SUMIFS($K:$K, $D:$D, "HomeLoan_BT_less_than_2_Percent", $B:$B, B14)+SUMIFS($K:$K, $D:$D, "HomeLoan_Non_BT", $B:$B, B14)+SUMIFS($K:$K, $D:$D, "Mortgage_Power_Term", $B:$B, B14), Secured_Commission!$A:$F, 4, 1)*(K14/10^6), D14="Mortgage_Power_Term", VLOOKUP(SUMIFS($K:$K, $D:$D, "HomeLoan_BT_more_than_2_Percent", $B:$B, B14)+SUMIFS($K:$K, $D:$D, "HomeLoan_BT_less_than_2_Percent", $B:$B, B14)+SUMIFS($K:$K, $D:$D, "HomeLoan_Non_BT", $B:$B, B14)+SUMIFS($K:$K, $D:$D, "Mortgage_Power_Term", $B:$B, B14), Secured_Commission!$A:$F, 5, 1)*(K14/10^6), D14="Personal_Cash", VLOOKUP(SUMIFS($K:$K, $D:$D, "Personal_Cash", $B:$B, B14), Unsecured_Commission!$A:$B, 2, 1)*K14, OR(D14="MRTA_3_Percent", D14="SOMPO"), K14*0.03, D14="MRTA_6_Percent", K14*0.06), 0)} -> 0
A15: 10 | G15: {=_xlfn.IFS( AND($C15="Secured", OR($D15="HomeLoan_BT_more_than_2_Percent", $D15="HomeLoan_BT_less_than_2_Percent"), $E15=""), "", AND($C15="Secured",$E15=""),"others", AND($C15="Secured",$E15=3),"others", AND($C15="Secured",$E15=5),"BT_with_5_year_lock_in_period", TRUE, "")} | I15: {=_xlfn.IFS( AND($C15="Secured", OR($D15="HomeLoan_BT_more_than_2_Percent", $D15="HomeLoan_BT_less_than_2_Percent"), OR($E15="", $E15=0)), "Please input Year !!!", AND($C15="Secured", OR($F15="", $F15=0)), "Please input Amount !!!", AND($C15="Secured", $F15<5000000), 1, AND($C15="Secured", $F15>=5000000), 1.1, TRUE, "")} | J15: {=IFERROR(_xlfn.IFS( $G15="BT_with_5_year_lock_in_period", _xlfn.XLOOKUP($H15, Deviate_Table[Pricing discount], Deviate_Table[BT_with_5_year_lock_in_period]), $G15="others", _xlfn.XLOOKUP($H15, Deviate_Table[Pricing discount], Deviate_Table[others]), TRUE, ""), "Please input Deviate Range !!!")} | K15: =IF($C15="Secured",IFERROR($F15*$I15*$J15, ""), $F15) -> 0 | L15: {=IFERROR( _xlfn.IFS( D15="HomeLoan_BT_less_than_2_Percent", VLOOKUP(SUMIFS($K:$K, $D:$D, "HomeLoan_BT_more_than_2_Percent", $B:$B, B15)+SUMIFS($K:$K, $D:$D, "HomeLoan_BT_less_than_2_Percent", $B:$B, B15)+SUMIFS($K:$K, $D:$D, "HomeLoan_Non_BT", $B:$B, B15)+SUMIFS($K:$K, $D:$D, "Mortgage_Power_Term", $B:$B, B15), Secured_Commission!$A:$F, 2, 1)*(K15/10^6), D15="HomeLoan_BT_more_than_2_Percent", VLOOKUP(SUMIFS($K:$K, $D:$D, "HomeLoan_BT_more_than_2_Percent", $B:$B, B15)+SUMIFS($K:$K, $D:$D, "HomeLoan_BT_less_than_2_Percent", $B:$B, B15)+SUMIFS($K:$K, $D:$D, "HomeLoan_Non_BT", $B:$B, B15)+SUMIFS($K:$K, $D:$D, "Mortgage_Power_Term", $B:$B, B15), Secured_Commission!$A:$F, 3, 1)*(K15/10^6), D15="HomeLoan_Non_BT", VLOOKUP(SUMIFS($K:$K, $D:$D, "HomeLoan_BT_more_than_2_Percent", $B:$B, B15)+SUMIFS($K:$K, $D:$D, "HomeLoan_BT_less_than_2_Percent", $B:$B, B15)+SUMIFS($K:$K, $D:$D, "HomeLoan_Non_BT", $B:$B, B15)+SUMIFS($K:$K, $D:$D, "Mortgage_Power_Term", $B:$B, B15), Secured_Commission!$A:$F, 4, 1)*(K15/10^6), D15="Mortgage_Power_Term", VLOOKUP(SUMIFS($K:$K, $D:$D, "HomeLoan_BT_more_than_2_Percent", $B:$B, B15)+SUMIFS($K:$K, $D:$D, "HomeLoan_BT_less_than_2_Percent", $B:$B, B15)+SUMIFS($K:$K, $D:$D, "HomeLoan_Non_BT", $B:$B, B15)+SUMIFS($K:$K, $D:$D, "Mortgage_Power_Term", $B:$B, B15), Secured_Commission!$A:$F, 5, 1)*(K15/10^6), D15="Personal_Cash", VLOOKUP(SUMIFS($K:$K, $D:$D, "Personal_Cash", $B:$B, B15), Unsecured_Commission!$A:$B, 2, 1)*K15, OR(D15="MRTA_3_Percent", D15="SOMPO"), K15*0.03, D15="MRTA_6_Percent", K15*0.06), 0)} -> 0
A16: 11 | G16: {=_xlfn.IFS( AND($C16="Secured", OR($D16="HomeLoan_BT_more_than_2_Percent", $D16="HomeLoan_BT_less_than_2_Percent"), $E16=""), "", AND($C16="Secured",$E16=""),"others", AND($C16="Secured",$E16=3),"others", AND($C16="Secured",$E16=5),"BT_with_5_year_lock_in_period", TRUE, "")} | I16: {=_xlfn.IFS( AND($C16="Secured", OR($D16="HomeLoan_BT_more_than_2_Percent", $D16="HomeLoan_BT_less_than_2_Percent"), OR($E16="", $E16=0)), "Please input Year !!!", AND($C16="Secured", OR($F16="", $F16=0)), "Please input Amount !!!", AND($C16="Secured", $F16<5000000), 1, AND($C16="Secured", $F16>=5000000), 1.1, TRUE, "")} | J16: {=IFERROR(_xlfn.IFS( $G16="BT_with_5_year_lock_in_period", _xlfn.XLOOKUP($H16, Deviate_Table[Pricing discount], Deviate_Table[BT_with_5_year_lock_in_period]), $G16="others", _xlfn.XLOOKUP($H16, Deviate_Table[Pricing discount], Deviate_Table[others]), TRUE, ""), "Please input Deviate Range !!!")} | K16: =IF($C16="Secured",IFERROR($F16*$I16*$J16, ""), $F16) -> 0 | L16: {=IFERROR( _xlfn.IFS( D16="HomeLoan_BT_less_than_2_Percent", VLOOKUP(SUMIFS($K:$K, $D:$D, "HomeLoan_BT_more_than_2_Percent", $B:$B, B16)+SUMIFS($K:$K, $D:$D, "HomeLoan_BT_less_than_2_Percent", $B:$B, B16)+SUMIFS($K:$K, $D:$D, "HomeLoan_Non_BT", $B:$B, B16)+SUMIFS($K:$K, $D:$D, "Mortgage_Power_Term", $B:$B, B16), Secured_Commission!$A:$F, 2, 1)*(K16/10^6), D16="HomeLoan_BT_more_than_2_Percent", VLOOKUP(SUMIFS($K:$K, $D:$D, "HomeLoan_BT_more_than_2_Percent", $B:$B, B16)+SUMIFS($K:$K, $D:$D, "HomeLoan_BT_less_than_2_Percent", $B:$B, B16)+SUMIFS($K:$K, $D:$D, "HomeLoan_Non_BT", $B:$B, B16)+SUMIFS($K:$K, $D:$D, "Mortgage_Power_Term", $B:$B, B16), Secured_Commission!$A:$F, 3, 1)*(K16/10^6), D16="HomeLoan_Non_BT", VLOOKUP(SUMIFS($K:$K, $D:$D, "HomeLoan_BT_more_than_2_Percent", $B:$B, B16)+SUMIFS($K:$K, $D:$D, "HomeLoan_BT_less_than_2_Percent", $B:$B, B16)+SUMIFS($K:$K, $D:$D, "HomeLoan_Non_BT", $B:$B, B16)+SUMIFS($K:$K, $D:$D, "Mortgage_Power_Term", $B:$B, B16), Secured_Commission!$A:$F, 4, 1)*(K16/10^6), D16="Mortgage_Power_Term", VLOOKUP(SUMIFS($K:$K, $D:$D, "HomeLoan_BT_more_than_2_Percent", $B:$B, B16)+SUMIFS($K:$K, $D:$D, "HomeLoan_BT_less_than_2_Percent", $B:$B, B16)+SUMIFS($K:$K, $D:$D, "HomeLoan_Non_BT", $B:$B, B16)+SUMIFS($K:$K, $D:$D, "Mortgage_Power_Term", $B:$B, B16), Secured_Commission!$A:$F, 5, 1)*(K16/10^6), D16="Personal_Cash", VLOOKUP(SUMIFS($K:$K, $D:$D, "Personal_Cash", $B:$B, B16), Unsecured_Commission!$A:$B, 2, 1)*K16, OR(D16="MRTA_3_Percent", D16="SOMPO"), K16*0.03, D16="MRTA_6_Percent", K16*0.06), 0)} -> 0
A17: 12 | G17: {=_xlfn.IFS( AND($C17="Secured", OR($D17="HomeLoan_BT_more_than_2_Percent", $D17="HomeLoan_BT_less_than_2_Percent"), $E17=""), "", AND($C17="Secured",$E17=""),"others", AND($C17="Secured",$E17=3),"others", AND($C17="Secured",$E17=5),"BT_with_5_year_lock_in_period", TRUE, "")} | I17: {=_xlfn.IFS( AND($C17="Secured", OR($D17="HomeLoan_BT_more_than_2_Percent", $D17="HomeLoan_BT_less_than_2_Percent"), OR($E17="", $E17=0)), "Please input Year !!!", AND($C17="Secured", OR($F17="", $F17=0)), "Please input Amount !!!", AND($C17="Secured", $F17<5000000), 1, AND($C17="Secured", $F17>=5000000), 1.1, TRUE, "")} | J17: {=IFERROR(_xlfn.IFS( $G17="BT_with_5_year_lock_in_period", _xlfn.XLOOKUP($H17, Deviate_Table[Pricing discount], Deviate_Table[BT_with_5_year_lock_in_period]), $G17="others", _xlfn.XLOOKUP($H17, Deviate_Table[Pricing discount], Deviate_Table[others]), TRUE, ""), "Please input Deviate Range !!!")} | K17: =IF($C17="Secured",IFERROR($F17*$I17*$J17, ""), $F17) -> 0 | L17: {=IFERROR( _xlfn.IFS( D17="HomeLoan_BT_less_than_2_Percent", VLOOKUP(SUMIFS($K:$K, $D:$D, "HomeLoan_BT_more_than_2_Percent", $B:$B, B17)+SUMIFS($K:$K, $D:$D, "HomeLoan_BT_less_than_2_Percent", $B:$B, B17)+SUMIFS($K:$K, $D:$D, "HomeLoan_Non_BT", $B:$B, B17)+SUMIFS($K:$K, $D:$D, "Mortgage_Power_Term", $B:$B, B17), Secured_Commission!$A:$F, 2, 1)*(K17/10^6), D17="HomeLoan_BT_more_than_2_Percent", VLOOKUP(SUMIFS($K:$K, $D:$D, "HomeLoan_BT_more_than_2_Percent", $B:$B, B17)+SUMIFS($K:$K, $D:$D, "HomeLoan_BT_less_than_2_Percent", $B:$B, B17)+SUMIFS($K:$K, $D:$D, "HomeLoan_Non_BT", $B:$B, B17)+SUMIFS($K:$K, $D:$D, "Mortgage_Power_Term", $B:$B, B17), Secured_Commission!$A:$F, 3, 1)*(K17/10^6), D17="HomeLoan_Non_BT", VLOOKUP(SUMIFS($K:$K, $D:$D, "HomeLoan_BT_more_than_2_Percent", $B:$B, B17)+SUMIFS($K:$K, $D:$D, "HomeLoan_BT_less_than_2_Percent", $B:$B, B17)+SUMIFS($K:$K, $D:$D, "HomeLoan_Non_BT", $B:$B, B17)+SUMIFS($K:$K, $D:$D, "Mortgage_Power_Term", $B:$B, B17), Secured_Commission!$A:$F, 4, 1)*(K17/10^6), D17="Mortgage_Power_Term", VLOOKUP(SUMIFS($K:$K, $D:$D, "HomeLoan_BT_more_than_2_Percent", $B:$B, B17)+SUMIFS($K:$K, $D:$D, "HomeLoan_BT_less_than_2_Percent", $B:$B, B17)+SUMIFS($K:$K, $D:$D, "HomeLoan_Non_BT", $B:$B, B17)+SUMIFS($K:$K, $D:$D, "Mortgage_Power_Term", $B:$B, B17), Secured_Commission!$A:$F, 5, 1)*(K17/10^6), D17="Personal_Cash", VLOOKUP(SUMIFS($K:$K, $D:$D, "Personal_Cash", $B:$B, B17), Unsecured_Commission!$A:$B, 2, 1)*K17, OR(D17="MRTA_3_Percent", D17="SOMPO"), K17*0.03, D17="MRTA_6_Percent", K17*0.06), 0)} -> 0
A18: 13 | G18: {=_xlfn.IFS( AND($C18="Secured", OR($D18="HomeLoan_BT_more_than_2_Percent", $D18="HomeLoan_BT_less_than_2_Percent"), $E18=""), "", AND($C18="Secured",$E18=""),"others", AND($C18="Secured",$E18=3),"others", AND($C18="Secured",$E18=5),"BT_with_5_year_lock_in_period", TRUE, "")} | I18: {=_xlfn.IFS( AND($C18="Secured", OR($D18="HomeLoan_BT_more_than_2_Percent", $D18="HomeLoan_BT_less_than_2_Percent"), OR($E18="", $E18=0)), "Please input Year !!!", AND($C18="Secured", OR($F18="", $F18=0)), "Please input Amount !!!", AND($C18="Secured", $F18<5000000), 1, AND($C18="Secured", $F18>=5000000), 1.1, TRUE, "")} | J18: {=IFERROR(_xlfn.IFS( $G18="BT_with_5_year_lock_in_period", _xlfn.XLOOKUP($H18, Deviate_Table[Pricing discount], Deviate_Table[BT_with_5_year_lock_in_period]), $G18="others", _xlfn.XLOOKUP($H18, Deviate_Table[Pricing discount], Deviate_Table[others]), TRUE, ""), "Please input Deviate Range !!!")} | K18: =IF($C18="Secured",IFERROR($F18*$I18*$J18, ""), $F18) -> 0 | L18: {=IFERROR( _xlfn.IFS( D18="HomeLoan_BT_less_than_2_Percent", VLOOKUP(SUMIFS($K:$K, $D:$D, "HomeLoan_BT_more_than_2_Percent", $B:$B, B18)+SUMIFS($K:$K, $D:$D, "HomeLoan_BT_less_than_2_Percent", $B:$B, B18)+SUMIFS($K:$K, $D:$D, "HomeLoan_Non_BT", $B:$B, B18)+SUMIFS($K:$K, $D:$D, "Mortgage_Power_Term", $B:$B, B18), Secured_Commission!$A:$F, 2, 1)*(K18/10^6), D18="HomeLoan_BT_more_than_2_Percent", VLOOKUP(SUMIFS($K:$K, $D:$D, "HomeLoan_BT_more_than_2_Percent", $B:$B, B18)+SUMIFS($K:$K, $D:$D, "HomeLoan_BT_less_than_2_Percent", $B:$B, B18)+SUMIFS($K:$K, $D:$D, "HomeLoan_Non_BT", $B:$B, B18)+SUMIFS($K:$K, $D:$D, "Mortgage_Power_Term", $B:$B, B18), Secured_Commission!$A:$F, 3, 1)*(K18/10^6), D18="HomeLoan_Non_BT", VLOOKUP(SUMIFS($K:$K, $D:$D, "HomeLoan_BT_more_than_2_Percent", $B:$B, B18)+SUMIFS($K:$K, $D:$D, "HomeLoan_BT_less_than_2_Percent", $B:$B, B18)+SUMIFS($K:$K, $D:$D, "HomeLoan_Non_BT", $B:$B, B18)+SUMIFS($K:$K, $D:$D, "Mortgage_Power_Term", $B:$B, B18), Secured_Commission!$A:$F, 4, 1)*(K18/10^6), D18="Mortgage_Power_Term", VLOOKUP(SUMIFS($K:$K, $D:$D, "HomeLoan_BT_more_than_2_Percent", $B:$B, B18)+SUMIFS($K:$K, $D:$D, "HomeLoan_BT_less_than_2_Percent", $B:$B, B18)+SUMIFS($K:$K, $D:$D, "HomeLoan_Non_BT", $B:$B, B18)+SUMIFS($K:$K, $D:$D, "Mortgage_Power_Term", $B:$B, B18), Secured_Commission!$A:$F, 5, 1)*(K18/10^6), D18="Personal_Cash", VLOOKUP(SUMIFS($K:$K, $D:$D, "Personal_Cash", $B:$B, B18), Unsecured_Commission!$A:$B, 2, 1)*K18, OR(D18="MRTA_3_Percent", D18="SOMPO"), K18*0.03, D18="MRTA_6_Percent", K18*0.06), 0)} -> 0
A19: 14 | G19: {=_xlfn.IFS( AND($C19="Secured", OR($D19="HomeLoan_BT_more_than_2_Percent", $D19="HomeLoan_BT_less_than_2_Percent"), $E19=""), "", AND($C19="Secured",$E19=""),"others", AND($C19="Secured",$E19=3),"others", AND($C19="Secured",$E19=5),"BT_with_5_year_lock_in_period", TRUE, "")} | I19: {=_xlfn.IFS( AND($C19="Secured", OR($D19="HomeLoan_BT_more_than_2_Percent", $D19="HomeLoan_BT_less_than_2_Percent"), OR($E19="", $E19=0)), "Please input Year !!!", AND($C19="Secured", OR($F19="", $F19=0)), "Please input Amount !!!", AND($C19="Secured", $F19<5000000), 1, AND($C19="Secured", $F19>=5000000), 1.1, TRUE, "")} | J19: {=IFERROR(_xlfn.IFS( $G19="BT_with_5_year_lock_in_period", _xlfn.XLOOKUP($H19, Deviate_Table[Pricing discount], Deviate_Table[BT_with_5_year_lock_in_period]), $G19="others", _xlfn.XLOOKUP($H19, Deviate_Table[Pricing discount], Deviate_Table[others]), TRUE, ""), "Please input Deviate Range !!!")} | K19: =IF($C19="Secured",IFERROR($F19*$I19*$J19, ""), $F19) -> 0 | L19: {=IFERROR( _xlfn.IFS( D19="HomeLoan_BT_less_than_2_Percent", VLOOKUP(SUMIFS($K:$K, $D:$D, "HomeLoan_BT_more_than_2_Percent", $B:$B, B19)+SUMIFS($K:$K, $D:$D, "HomeLoan_BT_less_than_2_Percent", $B:$B, B19)+SUMIFS($K:$K, $D:$D, "HomeLoan_Non_BT", $B:$B, B19)+SUMIFS($K:$K, $D:$D, "Mortgage_Power_Term", $B:$B, B19), Secured_Commission!$A:$F, 2, 1)*(K19/10^6), D19="HomeLoan_BT_more_than_2_Percent", VLOOKUP(SUMIFS($K:$K, $D:$D, "HomeLoan_BT_more_than_2_Percent", $B:$B, B19)+SUMIFS($K:$K, $D:$D, "HomeLoan_BT_less_than_2_Percent", $B:$B, B19)+SUMIFS($K:$K, $D:$D, "HomeLoan_Non_BT", $B:$B, B19)+SUMIFS($K:$K, $D:$D, "Mortgage_Power_Term", $B:$B, B19), Secured_Commission!$A:$F, 3, 1)*(K19/10^6), D19="HomeLoan_Non_BT", VLOOKUP(SUMIFS($K:$K, $D:$D, "HomeLoan_BT_more_than_2_Percent", $B:$B, B19)+SUMIFS($K:$K, $D:$D, "HomeLoan_BT_less_than_2_Percent", $B:$B, B19)+SUMIFS($K:$K, $D:$D, "HomeLoan_Non_BT", $B:$B, B19)+SUMIFS($K:$K, $D:$D, "Mortgage_Power_Term", $B:$B, B19), Secured_Commission!$A:$F, 4, 1)*(K19/10^6), D19="Mortgage_Power_Term", VLOOKUP(SUMIFS($K:$K, $D:$D, "HomeLoan_BT_more_than_2_Percent", $B:$B, B19)+SUMIFS($K:$K, $D:$D, "HomeLoan_BT_less_than_2_Percent", $B:$B, B19)+SUMIFS($K:$K, $D:$D, "HomeLoan_Non_BT", $B:$B, B19)+SUMIFS($K:$K, $D:$D, "Mortgage_Power_Term", $B:$B, B19), Secured_Commission!$A:$F, 5, 1)*(K19/10^6), D19="Personal_Cash", VLOOKUP(SUMIFS($K:$K, $D:$D, "Personal_Cash", $B:$B, B19), Unsecured_Commission!$A:$B, 2, 1)*K19, OR(D19="MRTA_3_Percent", D19="SOMPO"), K19*0.03, D19="MRTA_6_Percent", K19*0.06), 0)} -> 0
A20: 15 | G20: {=_xlfn.IFS( AND($C20="Secured", OR($D20="HomeLoan_BT_more_than_2_Percent", $D20="HomeLoan_BT_less_than_2_Percent"), $E20=""), "", AND($C20="Secured",$E20=""),"others", AND($C20="Secured",$E20=3),"others", AND($C20="Secured",$E20=5),"BT_with_5_year_lock_in_period", TRUE, "")} | I20: {=_xlfn.IFS( AND($C20="Secured", OR($D20="HomeLoan_BT_more_than_2_Percent", $D20="HomeLoan_BT_less_than_2_Percent"), OR($E20="", $E20=0)), "Please input Year !!!", AND($C20="Secured", OR($F20="", $F20=0)), "Please input Amount !!!", AND($C20="Secured", $F20<5000000), 1, AND($C20="Secured", $F20>=5000000), 1.1, TRUE, "")} | J20: {=IFERROR(_xlfn.IFS( $G20="BT_with_5_year_lock_in_period", _xlfn.XLOOKUP($H20, Deviate_Table[Pricing discount], Deviate_Table[BT_with_5_year_lock_in_period]), $G20="others", _xlfn.XLOOKUP($H20, Deviate_Table[Pricing discount], Deviate_Table[others]), TRUE, ""), "Please input Deviate Range !!!")} | K20: =IF($C20="Secured",IFERROR($F20*$I20*$J20, ""), $F20) -> 0 | L20: {=IFERROR( _xlfn.IFS( D20="HomeLoan_BT_less_than_2_Percent", VLOOKUP(SUMIFS($K:$K, $D:$D, "HomeLoan_BT_more_than_2_Percent", $B:$B, B20)+SUMIFS($K:$K, $D:$D, "HomeLoan_BT_less_than_2_Percent", $B:$B, B20)+SUMIFS($K:$K, $D:$D, "HomeLoan_Non_BT", $B:$B, B20)+SUMIFS($K:$K, $D:$D, "Mortgage_Power_Term", $B:$B, B20), Secured_Commission!$A:$F, 2, 1)*(K20/10^6), D20="HomeLoan_BT_more_than_2_Percent", VLOOKUP(SUMIFS($K:$K, $D:$D, "HomeLoan_BT_more_than_2_Percent", $B:$B, B20)+SUMIFS($K:$K, $D:$D, "HomeLoan_BT_less_than_2_Percent", $B:$B, B20)+SUMIFS($K:$K, $D:$D, "HomeLoan_Non_BT", $B:$B, B20)+SUMIFS($K:$K, $D:$D, "Mortgage_Power_Term", $B:$B, B20), Secured_Commission!$A:$F, 3, 1)*(K20/10^6), D20="HomeLoan_Non_BT", VLOOKUP(SUMIFS($K:$K, $D:$D, "HomeLoan_BT_more_than_2_Percent", $B:$B, B20)+SUMIFS($K:$K, $D:$D, "HomeLoan_BT_less_than_2_Percent", $B:$B, B20)+SUMIFS($K:$K, $D:$D, "HomeLoan_Non_BT", $B:$B, B20)+SUMIFS($K:$K, $D:$D, "Mortgage_Power_Term", $B:$B, B20), Secured_Commission!$A:$F, 4, 1)*(K20/10^6), D20="Mortgage_Power_Term", VLOOKUP(SUMIFS($K:$K, $D:$D, "HomeLoan_BT_more_than_2_Percent", $B:$B, B20)+SUMIFS($K:$K, $D:$D, "HomeLoan_BT_less_than_2_Percent", $B:$B, B20)+SUMIFS($K:$K, $D:$D, "HomeLoan_Non_BT", $B:$B, B20)+SUMIFS($K:$K, $D:$D, "Mortgage_Power_Term", $B:$B, B20), Secured_Commission!$A:$F, 5, 1)*(K20/10^6), D20="Personal_Cash", VLOOKUP(SUMIFS($K:$K, $D:$D, "Personal_Cash", $B:$B, B20), Unsecured_Commission!$A:$B, 2, 1)*K20, OR(D20="MRTA_3_Percent", D20="SOMPO"), K20*0.03, D20="MRTA_6_Percent", K20*0.06), 0)} -> 0
A21: 16 | G21: {=_xlfn.IFS( AND($C21="Secured", OR($D21="HomeLoan_BT_more_than_2_Percent", $D21="HomeLoan_BT_less_than_2_Percent"), $E21=""), "", AND($C21="Secured",$E21=""),"others", AND($C21="Secured",$E21=3),"others", AND($C21="Secured",$E21=5),"BT_with_5_year_lock_in_period", TRUE, "")} | I21: {=_xlfn.IFS( AND($C21="Secured", OR($D21="HomeLoan_BT_more_than_2_Percent", $D21="HomeLoan_BT_less_than_2_Percent"), OR($E21="", $E21=0)), "Please input Year !!!", AND($C21="Secured", OR($F21="", $F21=0)), "Please input Amount !!!", AND($C21="Secured", $F21<5000000), 1, AND($C21="Secured", $F21>=5000000), 1.1, TRUE, "")} | J21: {=IFERROR(_xlfn.IFS( $G21="BT_with_5_year_lock_in_period", _xlfn.XLOOKUP($H21, Deviate_Table[Pricing discount], Deviate_Table[BT_with_5_year_lock_in_period]), $G21="others", _xlfn.XLOOKUP($H21, Deviate_Table[Pricing discount], Deviate_Table[others]), TRUE, ""), "Please input Deviate Range !!!")} | K21: =IF($C21="Secured",IFERROR($F21*$I21*$J21, ""), $F21) -> 0 | L21: {=IFERROR( _xlfn.IFS( D21="HomeLoan_BT_less_than_2_Percent", VLOOKUP(SUMIFS($K:$K, $D:$D, "HomeLoan_BT_more_than_2_Percent", $B:$B, B21)+SUMIFS($K:$K, $D:$D, "HomeLoan_BT_less_than_2_Percent", $B:$B, B21)+SUMIFS($K:$K, $D:$D, "HomeLoan_Non_BT", $B:$B, B21)+SUMIFS($K:$K, $D:$D, "Mortgage_Power_Term", $B:$B, B21), Secured_Commission!$A:$F, 2, 1)*(K21/10^6), D21="HomeLoan_BT_more_than_2_Percent", VLOOKUP(SUMIFS($K:$K, $D:$D, "HomeLoan_BT_more_than_2_Percent", $B:$B, B21)+SUMIFS($K:$K, $D:$D, "HomeLoan_BT_less_than_2_Percent", $B:$B, B21)+SUMIFS($K:$K, $D:$D, "HomeLoan_Non_BT", $B:$B, B21)+SUMIFS($K:$K, $D:$D, "Mortgage_Power_Term", $B:$B, B21), Secured_Commission!$A:$F, 3, 1)*(K21/10^6), D21="HomeLoan_Non_BT", VLOOKUP(SUMIFS($K:$K, $D:$D, "HomeLoan_BT_more_than_2_Percent", $B:$B, B21)+SUMIFS($K:$K, $D:$D, "HomeLoan_BT_less_than_2_Percent", $B:$B, B21)+SUMIFS($K:$K, $D:$D, "HomeLoan_Non_BT", $B:$B, B21)+SUMIFS($K:$K, $D:$D, "Mortgage_Power_Term", $B:$B, B21), Secured_Commission!$A:$F, 4, 1)*(K21/10^6), D21="Mortgage_Power_Term", VLOOKUP(SUMIFS($K:$K, $D:$D, "HomeLoan_BT_more_than_2_Percent", $B:$B, B21)+SUMIFS($K:$K, $D:$D, "HomeLoan_BT_less_than_2_Percent", $B:$B, B21)+SUMIFS($K:$K, $D:$D, "HomeLoan_Non_BT", $B:$B, B21)+SUMIFS($K:$K, $D:$D, "Mortgage_Power_Term", $B:$B, B21), Secured_Commission!$A:$F, 5, 1)*(K21/10^6), D21="Personal_Cash", VLOOKUP(SUMIFS($K:$K, $D:$D, "Personal_Cash", $B:$B, B21), Unsecured_Commission!$A:$B, 2, 1)*K21, OR(D21="MRTA_3_Percent", D21="SOMPO"), K21*0.03, D21="MRTA_6_Percent", K21*0.06), 0)} -> 0
A22: 17 | G22: {=_xlfn.IFS( AND($C22="Secured", OR($D22="HomeLoan_BT_more_than_2_Percent", $D22="HomeLoan_BT_less_than_2_Percent"), $E22=""), "", AND($C22="Secured",$E22=""),"others", AND($C22="Secured",$E22=3),"others", AND($C22="Secured",$E22=5),"BT_with_5_year_lock_in_period", TRUE, "")} | I22: {=_xlfn.IFS( AND($C22="Secured", OR($D22="HomeLoan_BT_more_than_2_Percent", $D22="HomeLoan_BT_less_than_2_Percent"), OR($E22="", $E22=0)), "Please input Year !!!", AND($C22="Secured", OR($F22="", $F22=0)), "Please input Amount !!!", AND($C22="Secured", $F22<5000000), 1, AND($C22="Secured", $F22>=5000000), 1.1, TRUE, "")} | J22: {=IFERROR(_xlfn.IFS( $G22="BT_with_5_year_lock_in_period", _xlfn.XLOOKUP($H22, Deviate_Table[Pricing discount], Deviate_Table[BT_with_5_year_lock_in_period]), $G22="others", _xlfn.XLOOKUP($H22, Deviate_Table[Pricing discount], Deviate_Table[others]), TRUE, ""), "Please input Deviate Range !!!")} | K22: =IF($C22="Secured",IFERROR($F22*$I22*$J22, ""), $F22) -> 0 | L22: {=IFERROR( _xlfn.IFS( D22="HomeLoan_BT_less_than_2_Percent", VLOOKUP(SUMIFS($K:$K, $D:$D, "HomeLoan_BT_more_than_2_Percent", $B:$B, B22)+SUMIFS($K:$K, $D:$D, "HomeLoan_BT_less_than_2_Percent", $B:$B, B22)+SUMIFS($K:$K, $D:$D, "HomeLoan_Non_BT", $B:$B, B22)+SUMIFS($K:$K, $D:$D, "Mortgage_Power_Term", $B:$B, B22), Secured_Commission!$A:$F, 2, 1)*(K22/10^6), D22="HomeLoan_BT_more_than_2_Percent", VLOOKUP(SUMIFS($K:$K, $D:$D, "HomeLoan_BT_more_than_2_Percent", $B:$B, B22)+SUMIFS($K:$K, $D:$D, "HomeLoan_BT_less_than_2_Percent", $B:$B, B22)+SUMIFS($K:$K, $D:$D, "HomeLoan_Non_BT", $B:$B, B22)+SUMIFS($K:$K, $D:$D, "Mortgage_Power_Term", $B:$B, B22), Secured_Commission!$A:$F, 3, 1)*(K22/10^6), D22="HomeLoan_Non_BT", VLOOKUP(SUMIFS($K:$K, $D:$D, "HomeLoan_BT_more_than_2_Percent", $B:$B, B22)+SUMIFS($K:$K, $D:$D, "HomeLoan_BT_less_than_2_Percent", $B:$B, B22)+SUMIFS($K:$K, $D:$D, "HomeLoan_Non_BT", $B:$B, B22)+SUMIFS($K:$K, $D:$D, "Mortgage_Power_Term", $B:$B, B22), Secured_Commission!$A:$F, 4, 1)*(K22/10^6), D22="Mortgage_Power_Term", VLOOKUP(SUMIFS($K:$K, $D:$D, "HomeLoan_BT_more_than_2_Percent", $B:$B, B22)+SUMIFS($K:$K, $D:$D, "HomeLoan_BT_less_than_2_Percent", $B:$B, B22)+SUMIFS($K:$K, $D:$D, "HomeLoan_Non_BT", $B:$B, B22)+SUMIFS($K:$K, $D:$D, "Mortgage_Power_Term", $B:$B, B22), Secured_Commission!$A:$F, 5, 1)*(K22/10^6), D22="Personal_Cash", VLOOKUP(SUMIFS($K:$K, $D:$D, "Personal_Cash", $B:$B, B22), Unsecured_Commission!$A:$B, 2, 1)*K22, OR(D22="MRTA_3_Percent", D22="SOMPO"), K22*0.03, D22="MRTA_6_Percent", K22*0.06), 0)} -> 0
A23: 18 | G23: {=_xlfn.IFS( AND($C23="Secured", OR($D23="HomeLoan_BT_more_than_2_Percent", $D23="HomeLoan_BT_less_than_2_Percent"), $E23=""), "", AND($C23="Secured",$E23=""),"others", AND($C23="Secured",$E23=3),"others", AND($C23="Secured",$E23=5),"BT_with_5_year_lock_in_period", TRUE, "")} | I23: {=_xlfn.IFS( AND($C23="Secured", OR($D23="HomeLoan_BT_more_than_2_Percent", $D23="HomeLoan_BT_less_than_2_Percent"), OR($E23="", $E23=0)), "Please input Year !!!", AND($C23="Secured", OR($F23="", $F23=0)), "Please input Amount !!!", AND($C23="Secured", $F23<5000000), 1, AND($C23="Secured", $F23>=5000000), 1.1, TRUE, "")} | J23: {=IFERROR(_xlfn.IFS( $G23="BT_with_5_year_lock_in_period", _xlfn.XLOOKUP($H23, Deviate_Table[Pricing discount], Deviate_Table[BT_with_5_year_lock_in_period]), $G23="others", _xlfn.XLOOKUP($H23, Deviate_Table[Pricing discount], Deviate_Table[others]), TRUE, ""), "Please input Deviate Range !!!")} | K23: =IF($C23="Secured",IFERROR($F23*$I23*$J23, ""), $F23) -> 0 | L23: {=IFERROR( _xlfn.IFS( D23="HomeLoan_BT_less_than_2_Percent", VLOOKUP(SUMIFS($K:$K, $D:$D, "HomeLoan_BT_more_than_2_Percent", $B:$B, B23)+SUMIFS($K:$K, $D:$D, "HomeLoan_BT_less_than_2_Percent", $B:$B, B23)+SUMIFS($K:$K, $D:$D, "HomeLoan_Non_BT", $B:$B, B23)+SUMIFS($K:$K, $D:$D, "Mortgage_Power_Term", $B:$B, B23), Secured_Commission!$A:$F, 2, 1)*(K23/10^6), D23="HomeLoan_BT_more_than_2_Percent", VLOOKUP(SUMIFS($K:$K, $D:$D, "HomeLoan_BT_more_than_2_Percent", $B:$B, B23)+SUMIFS($K:$K, $D:$D, "HomeLoan_BT_less_than_2_Percent", $B:$B, B23)+SUMIFS($K:$K, $D:$D, "HomeLoan_Non_BT", $B:$B, B23)+SUMIFS($K:$K, $D:$D, "Mortgage_Power_Term", $B:$B, B23), Secured_Commission!$A:$F, 3, 1)*(K23/10^6), D23="HomeLoan_Non_BT", VLOOKUP(SUMIFS($K:$K, $D:$D, "HomeLoan_BT_more_than_2_Percent", $B:$B, B23)+SUMIFS($K:$K, $D:$D, "HomeLoan_BT_less_than_2_Percent", $B:$B, B23)+SUMIFS($K:$K, $D:$D, "HomeLoan_Non_BT", $B:$B, B23)+SUMIFS($K:$K, $D:$D, "Mortgage_Power_Term", $B:$B, B23), Secured_Commission!$A:$F, 4, 1)*(K23/10^6), D23="Mortgage_Power_Term", VLOOKUP(SUMIFS($K:$K, $D:$D, "HomeLoan_BT_more_than_2_Percent", $B:$B, B23)+SUMIFS($K:$K, $D:$D, "HomeLoan_BT_less_than_2_Percent", $B:$B, B23)+SUMIFS($K:$K, $D:$D, "HomeLoan_Non_BT", $B:$B, B23)+SUMIFS($K:$K, $D:$D, "Mortgage_Power_Term", $B:$B, B23), Secured_Commission!$A:$F, 5, 1)*(K23/10^6), D23="Personal_Cash", VLOOKUP(SUMIFS($K:$K, $D:$D, "Personal_Cash", $B:$B, B23), Unsecured_Commission!$A:$B, 2, 1)*K23, OR(D23="MRTA_3_Percent", D23="SOMPO"), K23*0.03, D23="MRTA_6_Percent", K23*0.06), 0)} -> 0
A24: 19 | G24: {=_xlfn.IFS( AND($C24="Secured", OR($D24="HomeLoan_BT_more_than_2_Percent", $D24="HomeLoan_BT_less_than_2_Percent"), $E24=""), "", AND($C24="Secured",$E24=""),"others", AND($C24="Secured",$E24=3),"others", AND($C24="Secured",$E24=5),"BT_with_5_year_lock_in_period", TRUE, "")} | I24: {=_xlfn.IFS( AND($C24="Secured", OR($D24="HomeLoan_BT_more_than_2_Percent", $D24="HomeLoan_BT_less_than_2_Percent"), OR($E24="", $E24=0)), "Please input Year !!!", AND($C24="Secured", OR($F24="", $F24=0)), "Please input Amount !!!", AND($C24="Secured", $F24<5000000), 1, AND($C24="Secured", $F24>=5000000), 1.1, TRUE, "")} | J24: {=IFERROR(_xlfn.IFS( $G24="BT_with_5_year_lock_in_period", _xlfn.XLOOKUP($H24, Deviate_Table[Pricing discount], Deviate_Table[BT_with_5_year_lock_in_period]), $G24="others", _xlfn.XLOOKUP($H24, Deviate_Table[Pricing discount], Deviate_Table[others]), TRUE, ""), "Please input Deviate Range !!!")} | K24: =IF($C24="Secured",IFERROR($F24*$I24*$J24, ""), $F24) -> 0 | L24: {=IFERROR( _xlfn.IFS( D24="HomeLoan_BT_less_than_2_Percent", VLOOKUP(SUMIFS($K:$K, $D:$D, "HomeLoan_BT_more_than_2_Percent", $B:$B, B24)+SUMIFS($K:$K, $D:$D, "HomeLoan_BT_less_than_2_Percent", $B:$B, B24)+SUMIFS($K:$K, $D:$D, "HomeLoan_Non_BT", $B:$B, B24)+SUMIFS($K:$K, $D:$D, "Mortgage_Power_Term", $B:$B, B24), Secured_Commission!$A:$F, 2, 1)*(K24/10^6), D24="HomeLoan_BT_more_than_2_Percent", VLOOKUP(SUMIFS($K:$K, $D:$D, "HomeLoan_BT_more_than_2_Percent", $B:$B, B24)+SUMIFS($K:$K, $D:$D, "HomeLoan_BT_less_than_2_Percent", $B:$B, B24)+SUMIFS($K:$K, $D:$D, "HomeLoan_Non_BT", $B:$B, B24)+SUMIFS($K:$K, $D:$D, "Mortgage_Power_Term", $B:$B, B24), Secured_Commission!$A:$F, 3, 1)*(K24/10^6), D24="HomeLoan_Non_BT", VLOOKUP(SUMIFS($K:$K, $D:$D, "HomeLoan_BT_more_than_2_Percent", $B:$B, B24)+SUMIFS($K:$K, $D:$D, "HomeLoan_BT_less_than_2_Percent", $B:$B, B24)+SUMIFS($K:$K, $D:$D, "HomeLoan_Non_BT", $B:$B, B24)+SUMIFS($K:$K, $D:$D, "Mortgage_Power_Term", $B:$B, B24), Secured_Commission!$A:$F, 4, 1)*(K24/10^6), D24="Mortgage_Power_Term", VLOOKUP(SUMIFS($K:$K, $D:$D, "HomeLoan_BT_more_than_2_Percent", $B:$B, B24)+SUMIFS($K:$K, $D:$D, "HomeLoan_BT_less_than_2_Percent", $B:$B, B24)+SUMIFS($K:$K, $D:$D, "HomeLoan_Non_BT", $B:$B, B24)+SUMIFS($K:$K, $D:$D, "Mortgage_Power_Term", $B:$B, B24), Secured_Commission!$A:$F, 5, 1)*(K24/10^6), D24="Personal_Cash", VLOOKUP(SUMIFS($K:$K, $D:$D, "Personal_Cash", $B:$B, B24), Unsecured_Commission!$A:$B, 2, 1)*K24, OR(D24="MRTA_3_Percent", D24="SOMPO"), K24*0.03, D24="MRTA_6_Percent", K24*0.06), 0)} -> 0
A25: 20 | G25: {=_xlfn.IFS( AND($C25="Secured", OR($D25="HomeLoan_BT_more_than_2_Percent", $D25="HomeLoan_BT_less_than_2_Percent"), $E25=""), "", AND($C25="Secured",$E25=""),"others", AND($C25="Secured",$E25=3),"others", AND($C25="Secured",$E25=5),"BT_with_5_year_lock_in_period", TRUE, "")} | I25: {=_xlfn.IFS( AND($C25="Secured", OR($D25="HomeLoan_BT_more_than_2_Percent", $D25="HomeLoan_BT_less_than_2_Percent"), OR($E25="", $E25=0)), "Please input Year !!!", AND($C25="Secured", OR($F25="", $F25=0)), "Please input Amount !!!", AND($C25="Secured", $F25<5000000), 1, AND($C25="Secured", $F25>=5000000), 1.1, TRUE, "")} | J25: {=IFERROR(_xlfn.IFS( $G25="BT_with_5_year_lock_in_period", _xlfn.XLOOKUP($H25, Deviate_Table[Pricing discount], Deviate_Table[BT_with_5_year_lock_in_period]), $G25="others", _xlfn.XLOOKUP($H25, Deviate_Table[Pricing discount], Deviate_Table[others]), TRUE, ""), "Please input Deviate Range !!!")} | K25: =IF($C25="Secured",IFERROR($F25*$I25*$J25, ""), $F25) -> 0 | L25: {=IFERROR( _xlfn.IFS( D25="HomeLoan_BT_less_than_2_Percent", VLOOKUP(SUMIFS($K:$K, $D:$D, "HomeLoan_BT_more_than_2_Percent", $B:$B, B25)+SUMIFS($K:$K, $D:$D, "HomeLoan_BT_less_than_2_Percent", $B:$B, B25)+SUMIFS($K:$K, $D:$D, "HomeLoan_Non_BT", $B:$B, B25)+SUMIFS($K:$K, $D:$D, "Mortgage_Power_Term", $B:$B, B25), Secured_Commission!$A:$F, 2, 1)*(K25/10^6), D25="HomeLoan_BT_more_than_2_Percent", VLOOKUP(SUMIFS($K:$K, $D:$D, "HomeLoan_BT_more_than_2_Percent", $B:$B, B25)+SUMIFS($K:$K, $D:$D, "HomeLoan_BT_less_than_2_Percent", $B:$B, B25)+SUMIFS($K:$K, $D:$D, "HomeLoan_Non_BT", $B:$B, B25)+SUMIFS($K:$K, $D:$D, "Mortgage_Power_Term", $B:$B, B25), Secured_Commission!$A:$F, 3, 1)*(K25/10^6), D25="HomeLoan_Non_BT", VLOOKUP(SUMIFS($K:$K, $D:$D, "HomeLoan_BT_more_than_2_Percent", $B:$B, B25)+SUMIFS($K:$K, $D:$D, "HomeLoan_BT_less_than_2_Percent", $B:$B, B25)+SUMIFS($K:$K, $D:$D, "HomeLoan_Non_BT", $B:$B, B25)+SUMIFS($K:$K, $D:$D, "Mortgage_Power_Term", $B:$B, B25), Secured_Commission!$A:$F, 4, 1)*(K25/10^6), D25="Mortgage_Power_Term", VLOOKUP(SUMIFS($K:$K, $D:$D, "HomeLoan_BT_more_than_2_Percent", $B:$B, B25)+SUMIFS($K:$K, $D:$D, "HomeLoan_BT_less_than_2_Percent", $B:$B, B25)+SUMIFS($K:$K, $D:$D, "HomeLoan_Non_BT", $B:$B, B25)+SUMIFS($K:$K, $D:$D, "Mortgage_Power_Term", $B:$B, B25), Secured_Commission!$A:$F, 5, 1)*(K25/10^6), D25="Personal_Cash", VLOOKUP(SUMIFS($K:$K, $D:$D, "Personal_Cash", $B:$B, B25), Unsecured_Commission!$A:$B, 2, 1)*K25, OR(D25="MRTA_3_Percent", D25="SOMPO"), K25*0.03, D25="MRTA_6_Percent", K25*0.06), 0)} -> 0
... A201: 196 | G201: {=_xlfn.IFS( AND($C201="Secured", OR($D201="HomeLoan_BT_more_than_2_Percent", $D201="HomeLoan_BT_less_than_2_Percent"), $E201=""), "", AND($C201="Secured",$E201=""),"others", AND($C201="Secured",$E201=3),"others", AND($C201="Secured",$E201=5),"BT_with_5_year_lock_in_period", TRUE, "")} | I201: {=_xlfn.IFS( AND($C201="Secured", OR($D201="HomeLoan_BT_more_than_2_Percent", $D201="HomeLoan_BT_less_than_2_Percent"), OR($E201="", $E201=0)), "Please input Year !!!", AND($C201="Secured", OR($F201="", $F201=0)), "Please input Amount !!!", AND($C201="Secured", $F201<5000000), 1, AND($C201="Secured", $F201>=5000000), 1.1, TRUE, "")} | J201: {=IFERROR(_xlfn.IFS( $G201="BT_with_5_year_lock_in_period", _xlfn.XLOOKUP($H201, Deviate_Table[Pricing discount], Deviate_Table[BT_with_5_year_lock_in_period]), $G201="others", _xlfn.XLOOKUP($H201, Deviate_Table[Pricing discount], Deviate_Table[others]), TRUE, ""), "Please input Deviate Range !!!")} | K201: =IF($C201="Secured",IFERROR($F201*$I201*$J201, ""), $F201) -> 0 | L201: {=IFERROR( _xlfn.IFS( D201="HomeLoan_BT_less_than_2_Percent", VLOOKUP(SUMIFS($K:$K, $D:$D, "HomeLoan_BT_more_than_2_Percent", $B:$B, B201)+SUMIFS($K:$K, $D:$D, "HomeLoan_BT_less_than_2_Percent", $B:$B, B201)+SUMIFS($K:$K, $D:$D, "HomeLoan_Non_BT", $B:$B, B201)+SUMIFS($K:$K, $D:$D, "Mortgage_Power_Term", $B:$B, B201), Secured_Commission!$A:$F, 2, 1)*(K201/10^6), D201="HomeLoan_BT_more_than_2_Percent", VLOOKUP(SUMIFS($K:$K, $D:$D, "HomeLoan_BT_more_than_2_Percent", $B:$B, B201)+SUMIFS($K:$K, $D:$D, "HomeLoan_BT_less_than_2_Percent", $B:$B, B201)+SUMIFS($K:$K, $D:$D, "HomeLoan_Non_BT", $B:$B, B201)+SUMIFS($K:$K, $D:$D, "Mortgage_Power_Term", $B:$B, B201), Secured_Commission!$A:$F, 3, 1)*(K201/10^6), D201="HomeLoan_Non_BT", VLOOKUP(SUMIFS($K:$K, $D:$D, "HomeLoan_BT_more_than_2_Percent", $B:$B, B201)+SUMIFS($K:$K, $D:$D, "HomeLoan_BT_less_than_2_Percent", $B:$B, B201)+SUMIFS($K:$K, $D:$D, "HomeLoan_Non_BT", $B:$B, B201)+SUMIFS($K:$K, $D:$D, "Mortgage_Power_Term", $B:$B, B201), Secured_Commission!$A:$F, 4, 1)*(K201/10^6), D201="Mortgage_Power_Term", VLOOKUP(SUMIFS($K:$K, $D:$D, "HomeLoan_BT_more_than_2_Percent", $B:$B, B201)+SUMIFS($K:$K, $D:$D, "HomeLoan_BT_less_than_2_Percent", $B:$B, B201)+SUMIFS($K:$K, $D:$D, "HomeLoan_Non_BT", $B:$B, B201)+SUMIFS($K:$K, $D:$D, "Mortgage_Power_Term", $B:$B, B201), Secured_Commission!$A:$F, 5, 1)*(K201/10^6), D201="Personal_Cash", VLOOKUP(SUMIFS($K:$K, $D:$D, "Personal_Cash", $B:$B, B201), Unsecured_Commission!$A:$B, 2, 1)*K201, OR(D201="MRTA_3_Percent", D201="SOMPO"), K201*0.03, D201="MRTA_6_Percent", K201*0.06), 0)} -> 0

Sheet Summary_Commission_Simulation
B2: Channel | C2: =Detail_Simulation!$B2 -> Direct_Sales_1
B3: Team | C3: =Detail_Simulation!$B3 -> DS1_3_2
E5: Secured | I5: Unsecured | J5: Banca
D6: =SUBTOTAL(9, D$8:D$41) -> 0 | E6: =SUBTOTAL(9, E$8:E$41) -> 0 | F6: =SUBTOTAL(9, F$8:F$41) -> 0 | G6: =SUBTOTAL(9, G$8:G$41) -> 0 | H6: =SUBTOTAL(9, H$8:H$41) -> 0 | I6: =SUBTOTAL(9, I$8:I$41) -> 0 | J6: =SUBTOTAL(9, J$8:J$41) -> 0 | K6: =SUBTOTAL(9, K$8:K$41) -> 0
B7: No. | C7: Sales ID | D7: Total Commission | E7: HomeLoan_BT (<2%) | F7: HomeLoan_BT (>2%) | G7: HomeLoan Non_BT | H7: MP&PP | I7: PC | J7: MRTA | K7: SOMPO
B8: 1 | C8: {=_xlfn.UNIQUE(_xlfn._xlws.FILTER(Detail_Simulation!$B$6:$B$201, Detail_Simulation!$B$6:$B$201<>0))} -> 6560479 | D8: =SUM(E8,F8,G8,H8,I8,J8,K8) -> 0 | E8: =SUMIFS(Detail_Simulation!$L:$L, Detail_Simulation!$B:$B, $C8, Detail_Simulation!$D:$D, "HomeLoan_BT_less_than_2_Percent") -> 0 | F8: =SUMIFS(Detail_Simulation!$L:$L, Detail_Simulation!$B:$B, $C8, Detail_Simulation!$D:$D, "HomeLoan_BT_more_than_2_Percent") -> 0 | G8: =SUMIFS(Detail_Simulation!$L:$L, Detail_Simulation!$B:$B, $C8, Detail_Simulation!$D:$D, "HomeLoan_Non_BT") -> 0 | H8: =SUMIFS(Detail_Simulation!$L:$L, Detail_Simulation!$B:$B, $C8, Detail_Simulation!$D:$D, "Mortgage_Power_Term") -> 0 | I8: =SUMIFS(Detail_Simulation!$L:$L, Detail_Simulation!$B:$B, $C8, Detail_Simulation!$D:$D, "Personal_Cash") -> 0 | J8: =SUMIFS(Detail_Simulation!$L:$L, Detail_Simulation!$B:$B, $C8, Detail_Simulation!$D:$D, "MRTA_3_Percent")+ SUMIFS(Detail_Simulation!$L:$L, Detail_Simulation!$B:$B, $C8, Detail_Simulation!$D:$D, "MRTA_6_Percent") -> 0 | K8: =SUMIFS(Detail_Simulation!$L:$L, Detail_Simulation!$B:$B, $C8, Detail_Simulation!$D:$D, "SOMPO") -> 0
