Workbook
Name AMP_LIST: #REF!
Name AMP_LIST: #REF!
Name AMP_NAME: #REF!
Name AMP_NAME: #REF!
Name home: Rate!$P$4:$P$9
Name Loan_type: Rate!#REF!
Name Loan_type: Rate!#REF!
Name loan_type_no: Rate!#REF!
Name loan_type_no: Rate!#REF!
Name loay_type_no: Rate!#REF!
Name loay_type_no: Rate!#REF!
Name nonhome: Rate!$Q$4:$Q$6
Name PRV_LIST: #REF!
Name PRV_LIST: #REF!
Name PRV_NAME: #REF!
Name PRV_NAME: #REF!
Name TableProvinces: [1]Province!$A$2:$A$78
Name TUM_NAME: #REF!
Name TUM_NAME: #REF!
Name บ้านที่อยู่อาศัย: Rate!#REF!
Name บ้านที่อยู่อาศัย: Rate!#REF!
Name ไม่ใช่ที่อยู่อาศัย: Rate!#REF!
Name ไม่ใช่ที่อยู่อาศัย: Rate!#REF!

Sheet ประกันอัคคีภัย(มีเล่ม)
C2: คำนวณอัตราเบี้ยประกันอัคคีภัย สำหรับสินเชื่อรายย่อย ธนาคาร ซีไอเอ็มบี ไทย จํากัด (มหาชน)
K7: วันที่ | L7: =NOW() -> 44844.492
B9: ชื่อ-นามสกุล ผู้กู้ | C9: นางสาวทดสอบ
B11: ประเภทสิ่งปลูกสร้าง | C11: อาคารชุดพักอาศัย/คอนโดมิเนียม ชั้น 9
C12: **กรณีประเภทสิ่งปลูกสร้าง นอกเหนือจากที่ระบุ กรุณาติดต่อเจ้าหน้าที่
B14: ทุนประกันภัย | C14: 1960000 | F14: บาท
C16: ** กรณีทุนประกันภัยตั้งแต่ 60 ล้านบาทเป็นต้นไป กรุณาติดต่อเจ้าหน้าที่
C17: ** ระบุราคาประเมินสิ่งปลูกสร้าง ก่อนหักค่าเสื่อมราคา ตามเล่มประเมินของธนาคาร
C18: ** กรณีอาคารชุดพักอาศัย/คอนโดมิเนียม ให้ใช้ราคาประเมินสิ่งปลูกสร้าง
C19: ก่อนหักค่าเสื่อมราคา หรือมูลค่าประกันภัย
B21: เบียประกันภัย (ตามปี)
D22: 1 ปี | E22: 2 ปี | F22: 3 ปี | G22: 4 ปี | H22: 5 ปี | I22: 6 ปี | J22: 7 ปี | K22: 8 ปี | L22: 9 ปี
B23: เบี้ยประภันภัยสุทธิ | D23: =ROUND(($C$14*VLOOKUP($C$11,Rate!$D$3:$N$22,11,FALSE))/100+VLOOKUP($C$11,Rate!$D$3:$M$21,9,FALSE)+VLOOKUP($C$11,Rate!$D$3:$O$21,12,FALSE),0) -> 2201 | E23: =ROUND((($C$14*VLOOKUP($C$11,Rate!$D$3:$N$22,11,FALSE))/100+VLOOKUP($C$11,Rate!$D$3:$M$21,9,FALSE)+VLOOKUP($C$11,Rate!$D$3:$O$21,12,FALSE))*VLOOKUP(2,Rate!$C$28:$D$36,2,FALSE),0) -> 3852 | F23: =ROUND((($C$14*VLOOKUP($C$11,Rate!$D$3:$N$22,11,FALSE))/100+VLOOKUP($C$11,Rate!$D$3:$M$21,9,FALSE)+VLOOKUP($C$11,Rate!$D$3:$O$21,12,FALSE))*VLOOKUP(3,Rate!$C$28:$D$36,2,FALSE),0) -> 5503 | G23: =ROUND((($C$14*VLOOKUP($C$11,Rate!$D$3:$N$22,11,FALSE))/100+VLOOKUP($C$11,Rate!$D$3:$M$21,9,FALSE)+VLOOKUP($C$11,Rate!$D$3:$O$21,12,FALSE))*VLOOKUP(4,Rate!$C$28:$D$36,2,FALSE),0) -> 6317 | H23: =ROUND((($C$14*VLOOKUP($C$11,Rate!$D$3:$N$22,11,FALSE))/100+VLOOKUP($C$11,Rate!$D$3:$M$21,9,FALSE)+VLOOKUP($C$11,Rate!$D$3:$O$21,12,FALSE))*VLOOKUP(5,Rate!$C$28:$D$36,2,FALSE),0) -> 7682 | I23: =IF(OR($C$11="อาคารพาณิชย์/ร้านค้า",$C$11="อาคารสำนักงาน",$C$11="อพาร์ทเม้นท์/แฟลต/หอพัก (คอนกรีต)"),0,ROUND((($C$14*VLOOKUP($C$11,Rate!$D$3:$N$22,11,FALSE))/100+VLOOKUP($C$11,Rate!$D$3:$M$21,9,FALSE)+VLOOKUP($C$11,Rate!$D$3:$O$21,12,FALSE))*VLOOKUP(6,Rate!$C$28:$D$36,2,FALSE),0)) -> 8893 | J23: =IF(OR($C$11="อาคารพาณิชย์/ร้านค้า",$C$11="อาคารสำนักงาน",$C$11="อพาร์ทเม้นท์/แฟลต/หอพัก (คอนกรีต)"),0,ROUND((($C$14*VLOOKUP($C$11,Rate!$D$3:$N$22,11,FALSE))/100+VLOOKUP($C$11,Rate!$D$3:$M$21,9,FALSE)+VLOOKUP($C$11,Rate!$D$3:$O$21,12,FALSE))*VLOOKUP(7,Rate!$C$28:$D$36,2,FALSE),0)) -> 10104 | K23: =IF(OR($C$11="อาคารพาณิชย์/ร้านค้า",$C$11="อาคารสำนักงาน",$C$11="อพาร์ทเม้นท์/แฟลต/หอพัก (คอนกรีต)"),0,ROUND((($C$14*VLOOKUP($C$11,Rate!$D$3:$N$22,11,FALSE))/100+VLOOKUP($C$11,Rate!$D$3:$M$21,9,FALSE)+VLOOKUP($C$11,Rate!$D$3:$O$21,12,FALSE))*VLOOKUP(8,Rate!$C$28:$D$36,2,FALSE),0)) -> 11226 | L23: =IF(OR($C$11="อาคารพาณิชย์/ร้านค้า",$C$11="อาคารสำนักงาน",$C$11="อพาร์ทเม้นท์/แฟลต/หอพัก (คอนกรีต)"),0,ROUND((($C$14*VLOOKUP($C$11,Rate!$D$3:$N$22,11,FALSE))/100+VLOOKUP($C$11,Rate!$D$3:$M$21,9,FALSE)+VLOOKUP($C$11,Rate!$D$3:$O$21,12,FALSE))*VLOOKUP(9,Rate!$C$28:$D$36,2,FALSE),0)) -> 12305
B24: อากรแสตมป์ | D24: =ROUNDUP(D23*0.4%,0) -> 9 | E24: =ROUNDUP(E23*0.4%,0) -> 16 | F24: =ROUNDUP(F23*0.4%,0) -> 23 | G24: =ROUNDUP(G23*0.4%,0) -> 26 | H24: =ROUNDUP(H23*0.4%,0) -> 31 | I24: =ROUNDUP(I23*0.4%,0) -> 36 | J24: =ROUNDUP(J23*0.4%,0) -> 41 | K24: =ROUNDUP(K23*0.4%,0) -> 45 | L24: =ROUNDUP(L23*0.4%,0) -> 50
B25: ภาษี | D25: =ROUND((D23+D24)*7%,2) -> 154.7 | E25: =ROUND((E23+E24)*7%,2) -> 270.76 | F25: =ROUND((F23+F24)*7%,2) -> 386.82 | G25: =ROUND((G23+G24)*7%,2) -> 444.01 | H25: =ROUND((H23+H24)*7%,2) -> 539.91 | I25: =ROUND((I23+I24)*7%,2) -> 625.03 | J25: =ROUND((J23+J24)*7%,2) -> 710.15 | K25: =ROUND((K23+K24)*7%,2) -> 788.97 | L25: =ROUND((L23+L24)*7%,2) -> 864.85
B26: อัตราเบี้ยประกันภัย (รวมภาษีอากร) | D26: =ROUND(SUM(D23:D25),0) -> 2365 | E26: =ROUND(SUM(E23:E25),0) -> 4139 | F26: =ROUND(SUM(F23:F25),0) -> 5913 | G26: =ROUND(SUM(G23:G25),0) -> 6787 | H26: =ROUND(SUM(H23:H25),0) -> 8253 | I26: =ROUND(SUM(I23:I25),0) -> 9554 | J26: =ROUND(SUM(J23:J25),0) -> 10855 | K26: =ROUND(SUM(K23:K25),0) -> 12060 | L26: =ROUND(SUM(L23:L25),0) -> 13220

Sheet ประกันอัคคีภัย(ไม่มีเล่ม)
C2: คำนวณอัตราเบี้ยประกันอัคคีภัย สำหรับสินเชื่อรายย่อย ธนาคาร ซีไอเอ็มบี ไทย จํากัด (มหาชน)
K7: วันที่ | L7: =NOW() -> 44844.492
B9: ชื่อ-นามสกุล ผู้กู้ | C9: นางสาวทดสอบ
B11: ประเภทสิ่งปลูกสร้าง | C11: อาคารชุดพักอาศัย/คอนโดมิเนียม ชั้น 8
C12: **กรณีประเภทสิ่งปลูกสร้าง นอกเหนือจากที่ระบุ กรุณาติดต่อเจ้าหน้าที่
B14: ทุนประกันภัย | C14: =ROUNDUP(VLOOKUP(C11,Rate!$D$3:$M$21,10,FALSE)*$G$14,0) -> 1136166 | E14: บาท | F14: พื้นที่ใช้สอย | G14: 44.5555 | I14: ตร.ม.
C16: ** กรณีทุนประกันภัยตั้งแต่ 60 ล้านบาทเป็นต้นไป กรุณาติดต่อเจ้าหน้าที่
C17: ** ระบุราคาประเมินสิ่งปลูกสร้าง ก่อนหักค่าเสื่อมราคา ตามเล่มประเมินของธนาคาร
C18: ** กรณีอาคารชุดพักอาศัย/คอนโดมิเนียม ให้ใช้ราคาประเมินสิ่งปลูกสร้าง
C19: ก่อนหักค่าเสื่อมราคา หรือมูลค่าประกันภัย
B21: เบียประกันภัย (ตามปี)
D22: 1 ปี | E22: 2 ปี | F22: 3 ปี | G22: 4 ปี | H22: 5 ปี | I22: 6 ปี | J22: 7 ปี | K22: 8 ปี | L22: 9 ปี
B23: เบี้ยประภันภัยสุทธิ | D23: =ROUND(($C$14*VLOOKUP($C$11,Rate!$D$3:$N$22,11,FALSE))/100+VLOOKUP($C$11,Rate!$D$3:$M$21,9,FALSE)+VLOOKUP($C$11,Rate!$D$3:$O$21,12,FALSE),0) -> 1357 | E23: =ROUND((($C$14*VLOOKUP($C$11,Rate!$D$3:$N$22,11,FALSE))/100+VLOOKUP($C$11,Rate!$D$3:$M$21,9,FALSE)+VLOOKUP($C$11,Rate!$D$3:$O$21,12,FALSE))*VLOOKUP(2,Rate!$C$28:$D$36,2,FALSE),0) -> 2374 | F23: =ROUND((($C$14*VLOOKUP($C$11,Rate!$D$3:$N$22,11,FALSE))/100+VLOOKUP($C$11,Rate!$D$3:$M$21,9,FALSE)+VLOOKUP($C$11,Rate!$D$3:$O$21,12,FALSE))*VLOOKUP(3,Rate!$C$28:$D$36,2,FALSE),0) -> 3392 | G23: =ROUND((($C$14*VLOOKUP($C$11,Rate!$D$3:$N$22,11,FALSE))/100+VLOOKUP($C$11,Rate!$D$3:$M$21,9,FALSE)+VLOOKUP($C$11,Rate!$D$3:$O$21,12,FALSE))*VLOOKUP(4,Rate!$C$28:$D$36,2,FALSE),0) -> 3894 | H23: =ROUND((($C$14*VLOOKUP($C$11,Rate!$D$3:$N$22,11,FALSE))/100+VLOOKUP($C$11,Rate!$D$3:$M$21,9,FALSE)+VLOOKUP($C$11,Rate!$D$3:$O$21,12,FALSE))*VLOOKUP(5,Rate!$C$28:$D$36,2,FALSE),0) -> 4735 | I23: =IF(OR($C$11="อาคารพาณิชย์/ร้านค้า",$C$11="อาคารสำนักงาน",$C$11="อพาร์ทเม้นท์/แฟลต/หอพัก (คอนกรีต)"),0,ROUND((($C$14*VLOOKUP($C$11,Rate!$D$3:$N$22,11,FALSE))/100+VLOOKUP($C$11,Rate!$D$3:$M$21,9,FALSE)+VLOOKUP($C$11,Rate!$D$3:$O$21,12,FALSE))*VLOOKUP(6,Rate!$C$28:$D$36,2,FALSE),0)) -> 5481 | J23: =IF(OR($C$11="อาคารพาณิชย์/ร้านค้า",$C$11="อาคารสำนักงาน",$C$11="อพาร์ทเม้นท์/แฟลต/หอพัก (คอนกรีต)"),0,ROUND((($C$14*VLOOKUP($C$11,Rate!$D$3:$N$22,11,FALSE))/100+VLOOKUP($C$11,Rate!$D$3:$M$21,9,FALSE)+VLOOKUP($C$11,Rate!$D$3:$O$21,12,FALSE))*VLOOKUP(7,Rate!$C$28:$D$36,2,FALSE),0)) -> 6227 | K23: =IF(OR($C$11="อาคารพาณิชย์/ร้านค้า",$C$11="อาคารสำนักงาน",$C$11="อพาร์ทเม้นท์/แฟลต/หอพัก (คอนกรีต)"),0,ROUND((($C$14*VLOOKUP($C$11,Rate!$D$3:$N$22,11,FALSE))/100+VLOOKUP($C$11,Rate!$D$3:$M$21,9,FALSE)+VLOOKUP($C$11,Rate!$D$3:$O$21,12,FALSE))*VLOOKUP(8,Rate!$C$28:$D$36,2,FALSE),0)) -> 6919 | L23: =IF(OR($C$11="อาคารพาณิชย์/ร้านค้า",$C$11="อาคารสำนักงาน",$C$11="อพาร์ทเม้นท์/แฟลต/หอพัก (คอนกรีต)"),0,ROUND((($C$14*VLOOKUP($C$11,Rate!$D$3:$N$22,11,FALSE))/100+VLOOKUP($C$11,Rate!$D$3:$M$21,9,FALSE)+VLOOKUP($C$11,Rate!$D$3:$O$21,12,FALSE))*VLOOKUP(9,Rate!$C$28:$D$36,2,FALSE),0)) -> 7584
B24: อากรแสตมป์ | D24: =ROUNDUP(D23*0.4%,0) -> 6 | E24: =ROUNDUP(E23*0.4%,0) -> 10 | F24: =ROUNDUP(F23*0.4%,0) -> 14 | G24: =ROUNDUP(G23*0.4%,0) -> 16 | H24: =ROUNDUP(H23*0.4%,0) -> 19 | I24: =ROUNDUP(I23*0.4%,0) -> 22 | J24: =ROUNDUP(J23*0.4%,0) -> 25 | K24: =ROUNDUP(K23*0.4%,0) -> 28 | L24: =ROUNDUP(L23*0.4%,0) -> 31
B25: ภาษี | D25: =ROUND((D23+D24)*7%,2) -> 95.41 | E25: =ROUND((E23+E24)*7%,2) -> 166.88 | F25: =ROUND((F23+F24)*7%,2) -> 238.42 | G25: =ROUND((G23+G24)*7%,2) -> 273.7 | H25: =ROUND((H23+H24)*7%,2) -> 332.78 | I25: =ROUND((I23+I24)*7%,2) -> 385.21 | J25: =ROUND((J23+J24)*7%,2) -> 437.64 | K25: =ROUND((K23+K24)*7%,2) -> 486.29 | L25: =ROUND((L23+L24)*7%,2) -> 533.05
B26: อัตราเบี้ยประกันภัย (รวมภาษีอากร) | D26: =ROUND(SUM(D23:D25),0) -> 1458 | E26: =ROUND(SUM(E23:E25),0) -> 2551 | F26: =ROUND(SUM(F23:F25),0) -> 3644 | G26: =ROUND(SUM(G23:G25),0) -> 4184 | H26: =ROUND(SUM(H23:H25),0) -> 5087 | I26: =ROUND(SUM(I23:I25),0) -> 5888 | J26: =ROUND(SUM(J23:J25),0) -> 6690 | K26: =ROUND(SUM(K23:K25),0) -> 7433 | L26: =ROUND(SUM(L23:L25),0) -> 8148

Sheet Rate
A1: Type | B1: รหัสภัย | C1: Construction class | D1: ลักษณะของภัย | E1: Rate สูงสุด | F1: Surcharge | G1: Surcharge (storey) | H1: ภัยเพิ่มเติม (Rate)% | K1: Rate กลุ่มภัยธรรมชาติ | L1: กลุ่มภัยธรรมชาติ + additional premium | M1: ราคาประเมินค่าก่อสร้างอาคาร (บาท/ตารางเมตร) | N1: Rate CIMB | O1: กลุ่มภัยธรรมชาติ
H2: ภัยจากน้ำท่วม | I2: ภัยจากลมพายุ | J2: ภัยจากแผ่นดินไหว
A3: Home | B3: 1032, 1074 | C3: 1 | D3: บ้านเดี่ยว (คอนกรีต) | E3: 0.069 | F3: 0.02 | G3: 0 | H3: 0.5 | I3: 0 | J3: 0 | K3: =0.045 -> 0.045 | L3: =IFERROR((H3*50000)/100,0)+IFERROR((I3*100000)/100,0)+IFERROR((J3*100000)/100,0) -> 250 | M3: 13000 | N3: =E3+F3+G3+K3 -> 0.134 | O3: 0
C4: 2 | D4: บ้านเดี่ยว (ครึ่งตึกครึ่งไม้) | E4: 0.157 | F4: 0.055 | G4: 0 | H4: 0.5 | I4: 0 | J4: 0 | K4: =0.045 -> 0.045 | L4: =IFERROR((H4*50000)/100,0)+IFERROR((I4*100000)/100,0)+IFERROR((J4*100000)/100,0) -> 250 | M4: 10000 | N4: =E4+F4+G4+K4 -> 0.257 | O4: 0
C5: 1 | D5: บ้านแฝด/ทาวเฮาส์/ทาวน์โฮม | E5: 0.069 | F5: 0.02 | G5: 0 | H5: 0.5 | I5: 0 | J5: 0 | K5: =0.045 -> 0.045 | L5: =IFERROR((H5*50000)/100,0)+IFERROR((I5*100000)/100,0)+IFERROR((J5*100000)/100,0) -> 250 | M5: 11000 | N5: =E5+F5+G5+K5 -> 0.134 | O5: 0
C6: 1 | D6: อาคารชุดพักอาศัย/คอนโดมิเนียม ชั้น 1-7 | E6: 0.069 | F6: 0.02 | G6: 0 | H6: 0 | I6: 0.1 | J6: 0.1 | K6: 0 | L6: =IFERROR((H6*50000)/100,0)+IFERROR((I6*100000)/100,0)+IFERROR((J6*100000)/100,0) -> 200 | M6: =H28 -> 25500 | N6: =E6+F6+G6+K6 -> 0.089 | O6: 100
C7: 1 | D7: อาคารชุดพักอาศัย/คอนโดมิเนียม ชั้น 8 | E7: 0.069 | F7: 0.02 | G7: =G29 -> 0.004 | H7: 0 | I7: 0.1 | J7: 0.1 | K7: 0 | L7: =IFERROR((H7*50000)/100,0)+IFERROR((I7*100000)/100,0)+IFERROR((J7*100000)/100,0) -> 200 | M7: =H29 -> 25500 | N7: =E7+F7+G7+K7 -> 0.093 | O7: 100
C8: 1 | D8: อาคารชุดพักอาศัย/คอนโดมิเนียม ชั้น 9 | E8: 0.069 | F8: 0.02 | G8: =G30 -> 0.008 | H8: 0 | I8: 0.1 | J8: 0.1 | K8: 0 | L8: =IFERROR((H8*50000)/100,0)+IFERROR((I8*100000)/100,0)+IFERROR((J8*100000)/100,0) -> 200 | M8: =H30 -> 25500 | N8: =E8+F8+G8+K8 -> 0.097 | O8: 100
C9: 1 | D9: อาคารชุดพักอาศัย/คอนโดมิเนียม ชั้น 10 | E9: 0.069 | F9: 0.02 | G9: =G31 -> 0.012 | H9: 0 | I9: 0.1 | J9: 0.1 | K9: 0 | L9: =IFERROR((H9*50000)/100,0)+IFERROR((I9*100000)/100,0)+IFERROR((J9*100000)/100,0) -> 200 | M9: =H31 -> 25500 | N9: =E9+F9+G9+K9 -> 0.101 | O9: 100
C10: 1 | D10: อาคารชุดพักอาศัย/คอนโดมิเนียม ชั้น 11 | E10: 0.069 | F10: 0.02 | G10: =G32 -> 0.016 | H10: 0 | I10: 0.1 | J10: 0.1 | K10: 0 | L10: =IFERROR((H10*50000)/100,0)+IFERROR((I10*100000)/100,0)+IFERROR((J10*100000)/100,0) -> 200 | M10: =H32 -> 25500 | N10: =E10+F10+G10+K10 -> 0.105 | O10: 100
C11: 1 | D11: อาคารชุดพักอาศัย/คอนโดมิเนียม ชั้น 12 | E11: 0.069 | F11: 0.02 | G11: =G33 -> 0.02 | H11: 0 | I11: 0.1 | J11: 0.1 | K11: 0 | L11: =IFERROR((H11*50000)/100,0)+IFERROR((I11*100000)/100,0)+IFERROR((J11*100000)/100,0) -> 200 | M11: =H33 -> 25500 | N11: =E11+F11+G11+K11 -> 0.109 | O11: 100
C12: 1 | D12: อาคารชุดพักอาศัย/คอนโดมิเนียม ชั้น 13 | E12: 0.069 | F12: 0.02 | G12: =G34 -> 0.024 | H12: 0 | I12: 0.1 | J12: 0.1 | K12: 0 | L12: =IFERROR((H12*50000)/100,0)+IFERROR((I12*100000)/100,0)+IFERROR((J12*100000)/100,0) -> 200 | M12: =H34 -> 25500 | N12: =E12+F12+G12+K12 -> 0.113 | O12: 100
C13: 1 | D13: อาคารชุดพักอาศัย/คอนโดมิเนียม ชั้น 14 | E13: 0.069 | F13: 0.02 | G13: =G35 -> 0.028 | H13: 0 | I13: 0.1 | J13: 0.1 | K13: 0 | L13: =IFERROR((H13*50000)/100,0)+IFERROR((I13*100000)/100,0)+IFERROR((J13*100000)/100,0) -> 200 | M13: =H35 -> 25500 | N13: =E13+F13+G13+K13 -> 0.117 | O13: 100
C14: 1 | D14: อาคารชุดพักอาศัย/คอนโดมิเนียม ชั้น 15 | E14: 0.069 | F14: 0.02 | G14: =G36 -> 0.032 | H14: 0 | I14: 0.1 | J14: 0.1 | K14: 0 | L14: =IFERROR((H14*50000)/100,0)+IFERROR((I14*100000)/100,0)+IFERROR((J14*100000)/100,0) -> 200 | M14: =H36 -> 25500 | N14: =E14+F14+G14+K14 -> 0.121 | O14: 100
C15: 1 | D15: อาคารชุดพักอาศัย/คอนโดมิเนียม ชั้น 16 | E15: 0.069 | F15: 0.02 | G15: =G37 -> 0.036 | H15: 0 | I15: 0.1 | J15: 0.1 | K15: 0 | L15: =IFERROR((H15*50000)/100,0)+IFERROR((I15*100000)/100,0)+IFERROR((J15*100000)/100,0) -> 200 | M15: =H37 -> 33500 | N15: =E15+F15+G15+K15 -> 0.125 | O15: 100
C16: 1 | D16: อาคารชุดพักอาศัย/คอนโดมิเนียม ชั้น 17 ขึ้นไป | E16: 0.069 | F16: 0.02 | G16: =G38 -> 0.04 | H16: 0 | I16: 0.1 | J16: 0.1 | K16: 0 | L16: =IFERROR((H16*50000)/100,0)+IFERROR((I16*100000)/100,0)+IFERROR((J16*100000)/100,0) -> 200 | M16: =H38 -> 33500 | N16: =E16+F16+G16+K16 -> 0.129 | O16: 100
C17: 1 | D17: อาคารชุดพักอาศัย/คอนโดมิเนียม ชั้นที่ 30 ขึ้นไป | E17: 0.069 | F17: 0.02 | G17: =G39 -> 0.04 | H17: 0 | I17: 0.1 | J17: 0.1 | K17: 0 | L17: =IFERROR((H17*50000)/100,0)+IFERROR((I17*100000)/100,0)+IFERROR((J17*100000)/100,0) -> 200 | M17: =H39 -> 33500 | N17: =E17+F17+G17+K17 -> 0.129 | O17: 100
C18: 1 | D18: อาคารพาณิชย์/ตึกแถว | E18: 0.069 | F18: 0.02 | G18: 0 | H18: 0.5 | I18: 0 | J18: 0 | K18: =0.045 -> 0.045 | L18: =IFERROR((H18*50000)/100,0)+IFERROR((I18*100000)/100,0)+IFERROR((J18*100000)/100,0) -> 250 | M18: 8500 | N18: =E18+F18+G18+K18 -> 0.134 | O18: 0
A19: Non-home | B19: 1015 | C19: 1 | D19: อาคารพาณิชย์/ร้านค้า | E19: 0.184 | F19: 0.02 | G19: 0 | H19: 0.5 | I19: 0 | J19: 0 | K19: 0.058 | L19: =IFERROR((H19*50000)/100,0)+IFERROR((I19*100000)/100,0)+IFERROR((J19*100000)/100,0) -> 250 | M19: 8500 | N19: =E19+F19+G19+K19 -> 0.262 | O19: 0
B20: 1062 | C20: 1 | D20: อาคารสำนักงาน | E20: 0.086 | F20: 0.02 | G20: 0 | H20: 0.5 | I20: 0 | J20: 0 | K20: 0.058 | L20: =IFERROR((H20*50000)/100,0)+IFERROR((I20*100000)/100,0)+IFERROR((J20*100000)/100,0) -> 250 | M20: 9000 | N20: =E20+F20+G20+K20 -> 0.164 | O20: 0
B21: 1040 | C21: 1 | D21: อพาร์ทเม้นท์/แฟลต/หอพัก (คอนกรีต) | E21: 0.086 | F21: 0.02 | G21: 0 | H21: 0.5 | I21: 0 | J21: 0 | K21: 0.058 | L21: =IFERROR((H21*50000)/100,0)+IFERROR((I21*100000)/100,0)+IFERROR((J21*100000)/100,0) -> 250 | M21: 12000 | N21: =E21+F21+G21+K21 -> 0.164 | O21: 0
F26: Storey
C27: Year | D27: Percentage (%) | F27: Storey | G27: + % Rate | H27: ราคาประเมินค่าก่อสร้างอาคาร (บาท/ตารางเมตร) อาคารชุด | I27: ราคาประเมินค่าก่อสร้างอาคาร (บาท/ตารางเมตร)โรงแรม
C28: 1 | D28: 1 | F28: 1-7 | G28: 0 | H28: 25500 | I28: 19700
C29: 2 | D29: 1.75 | F29: 8 | G29: 0.004 | H29: 25500 | I29: 19700
C30: 3 | D30: 2.5 | F30: 9 | G30: 0.008 | H30: 25500 | I30: 19700
C31: 4 | D31: 2.87 | F31: 10 | G31: 0.012 | H31: 25500 | I31: 19700
C32: 5 | D32: 3.49 | F32: 11 | G32: 0.016 | H32: 25500 | I32: 19700
C33: 6 | D33: 4.04 | F33: 12 | G33: 0.02 | H33: 25500 | I33: 19700
C34: 7 | D34: 4.59 | F34: 13 | G34: 0.024 | H34: 25500 | I34: 19700
C35: 8 | D35: 5.1 | F35: 14 | G35: 0.028 | H35: 25500 | I35: 19700
C36: 9 | D36: 5.59 | F36: 15 | G36: 0.032 | H36: 25500 | I36: 19700
F37: 16 | G37: 0.036 | H37: 33500 | I37: 19700
F38: 17 ชั้นขึ้นไป | G38: 0.04 | H38: 33500 | I38: 19700
F39: 17 ชั้นขึ้นไป | G39: 0.04 | H39: 33500 | I39: 19700
D42: บ้านเดี่ยว (คอนกรีต)
D43: บ้านเดี่ยว (ครึ่งตึกครึ่งไม้)
D44: บ้านแฝด/ทาวเฮาส์/ทาวน์โฮม
D45: อาคารพาณิชย์/ตึกแถว
D46: อาคารพาณิชย์/ร้านค้า
...
