Workbook
Name _Sex11: [1]Home!$M$3
Name _TMO1997: #REF!
Name _TMO1997: #REF!
Name _TMO1997: #REF!
Name _TMO1997: #REF!
Name _TMO1997: #REF!
Name _TMO1997: #REF!
Name _TMO1997: #REF!
Name _TMO1997: #REF!
Name _TMO1997: #REF!
Name _TMO1997: #REF!
Name _TMO1997: #REF!
Name _TMO1997: #REF!
Name _TMO1997: #REF!
Name _TMO1997: #REF!
Name _TMO1997: #REF!
Name _TMO1997: #REF!
Name _TMO1997: #REF!
Name _TMO2008: #REF!
Name _TMO2008: #REF!
Name _TMO2008: #REF!
Name _TMO2008: #REF!
Name _TMO2008: #REF!
Name _TMO2008: #REF!
Name _TMO2008: #REF!
Name _TMO2008: #REF!
Name _TMO2008: #REF!
Name _TMO2008: #REF!
Name _TMO2008: #REF!
Name _TMO2008: #REF!
Name _TMO2008: #REF!
Name _TMO2008: #REF!
Name _TMO2008: #REF!
Name _TMO2008: #REF!
Name _TMO2008: #REF!
Name Age: [1]Home!$M$4
Name camp: #REF!
Name camp: #REF!
Name camp: #REF!
Name camp: #REF!
Name camp: #REF!
Name camp: #REF!
Name camp: #REF!
Name camp: #REF!
Name camp: #REF!
Name camp: #REF!
Name camp: #REF!
Name camp: #REF!
Name CampML: #REF!
Name CampML: #REF!
Name CampML: #REF!
Name CampML: #REF!
Name CampML: #REF!
Name CampML: #REF!
Name CampML: #REF!
Name CampML: #REF!
Name CampML: #REF!
Name CampML: #REF!
Name CampML: #REF!
Name CampML: #REF!

Sheet Secured - Table 1
B1: cr08035 | C1: สินเชื่อบุคคล (ประเภทมีหลักประกัน) | L1: ประกันกู้หลัก
B3: วงเงินสินเชื่อ / อัตราดอกเบี้ย / ยอดผ่อนชำระ/ เบี้ยประกัน/ DIR/สรุปวงเงิน | M3: รายได้ | N3: 20637 | O3: 20668 | P3: 20699 | Q3: 20729 | R3: 20760 | S3: 20790 | T3: 20821 | U3: ชำระงวดจริง | V3: ='eBHomeLoan - Table 1'!N4 -> 281
B4: Home Loan | C4: อายุ | D4: เพศ | E4: คุ้มครองสูงสุด | F4: ระยะเวลาคุ้มครอง (ปี) | G4: อัตราส่วน | H4: ทุนประกัน | I4: MRTA | J4: ระยะเวลากู้สูงสุด | K4: วงเงิน Home Loan 1 | L4: เงินเดือน | M4: 17330 | N4: 17330 | P4: 17330 | Q4: 17330 | R4: 17330 | T4: 18460 | U4: ดอกเบี้ยรวม | V4: ='eBHomeLoan - Table 1'!O4-'eBHomeLoan - Table 1'!G4 -> 2228808.9
B5: กู้หลัก | C5: 30 | D5: หญิง | E5: =IF(C5<=35,30,65-C5) -> 30 | F5: 10 | G5: 55.5 | H5: =K5 -> 2500000 | I5: =G5*H5/1000 -> 138750 | J5: =65-IF(MIN(C5:C7)<=35,35,MIN(C5:C7))&" ปี" -> 30 ปี | K5: 2500000 | L5: เบี้ยเลี้ยง | M5: =SUM(N5:T5)/6 -> 55 | N5: 120 | P5: 120 | Q5: 90 | U5: ประเมิน | V5: 3200
B6: กู้ร่วม 1 | C6: 43 | D6: ชาย | E6: =IF(C6<=35,30,65-C6) -> 22 | F6: 10 | J6: กู้ระยะเวลากู้(ปี) | L6: ค่าล่วงเวลา | M6: =SUM(N6:T6)/6 -> 198.33333 | N6: 649 | P6: 541 | U6: จำนอง | V6: =K8*1/100 -> 26387.5
B7: กู้ร่วม 2 | C7: 43 | D7: ชาย | E7: =IF(C7<=35,30,65-C7) -> 22 | F7: 10 | H7: อัคคีภัยฟรี 3 ปี | J7: =คีย์ข้อมูล!G15 -> 35 | L7: โบนัส | M7: =SUM(N7:S7)/12 -> 2888.3333 | N7: 17330 | S7: 17330 | U7: จ่ายรวม | V7: =V4+V5+V6 -> 2258396.4
B8: ธนาคารอาคารสงเคราะห์ | C8: ยอดคงเหลือ | D8: วงเงินกู้ตามสัญญา | E8: ค่างวด | F8: LTV | H8: รวม MRTA | I8: =SUM(I5:I7) -> 138750 | J8: วงเงินรวม | K8: =K5+I8 -> 2638750 | L8: ค่าโทรศัพท์ | M8: =SUM(N8:S8)/6 -> 50 | Q8: 300
B9: วงเงินบ้าน | C9: 3376000 | D9: 4500000 | E9: 23700 | F9: =C9/D9 -> 0.75022222 | K9: =K8/D16 -> 0.58638889 | L9: เบี้ยเลี้ยงค่าเดินทาง | M9: =SUM(N9:S9)/6 -> 150 | R9: 600 | S9: 300
B10: Mortgage Top UP | C10: อายุ | D10: เพศ | E10: คุ้มครองสูงสุด | F10: ระยะเวลาคุ้มครอง (ปี) | H10: ทุนประกัน | I10: MRTA | J10: ระยะเวลากู้สูงสุด | K10: วงเงิน Home Loan 2 | L10: เงินช่วยเหลือ | M10: =SUM(N10:S10)/6 -> 100 | R10: 300 | S10: 300 | U10: ดอกเบี้ยรวม | V10: ='eBMortgageLoan - Table 1'!O4-'eBMortgageLoan - Table 1'!G4 -> 0
B11: กู้หลัก | C11: =C5 -> 30 | D11: =D5 -> หญิง | E11: =IF(C11=" "," ",IF(B10=I81,IF(C11<=50,15,65-C11),IF(C11<=35,30,65-C11))) -> 30 | F11: 10 | H11: =K11*70/100 -> 0 | I11: =IF(ISERROR(IF(D11="ชาย",(HLOOKUP(F11,OIC_MRTA_bundling!$5:$46,VLOOKUP(C11,OIC_MRTA_bundling!$A$4:$AF$46,32,0),0)*H11),IF(D11="หญิง",(HLOOKUP(F11,OIC_MRTA_bundling!$52:$93,VLOOKUP(C11,OIC_MRTA_bundling!$A$52:$AF$93,32,0),0)*H11))))=TRUE,"",IF(D11="ชาย",(HLOOKUP(F11,OIC_MRTA_bundling!$5:$46,VLOOKUP(C11,OIC_MRTA_bundling!$A$4:$AF$46,32,0),0)*H11),IF(D11="หญิง",(HLOOKUP(F11,OIC_MRTA_bundling!$52:$93,VLOOKUP(C11,OIC_MRTA_bundling!$A$52:$AF$93,32,0),0)*H11)))) -> 0 | J11: =65-IF(MIN(C11:C13)<=35,35,MIN(C11:C13))&" ปี" -> 30 ปี | K11: 0 | L11: ค่าเช่าบ้าน | M11: 10000 | N11: 10000 | O11: 10000 | P11: 10000 | Q11: 10000 | R11: 10000 | S11: 10000 | U11: ชำระงวดจริง | V11: ='eBMortgageLoan - Table 1'!N4 -> 0
B12: กู้ร่วม 1 | J12: ระยะเวลากู้(ปี) | L12: โบนัส ก.พ.56 | M12: =N12/12 -> 5117.75 | N12: 61413
B13: กู้ร่วม 2 | J13: 26 | L13: รับเงินสดจากการออกงานนอกสถานที่ | M13: =SUM(N13:S13)/6 -> 5664.1667 | N13: 6090 | O13: 6822 | P13: 5771 | Q13: 5825 | R13: 6089 | S13: 3388
B14: หลักประกัน บ้านเดี่ยว | C14: LTV สูงสุด 95% ของราคาประเมิน | E14: รายได้ | H14: รวม MRTA | I14: =IF(C19="เงินกู้ปกติ , No MRTA",0,(SUM(I11:I13))) -> 0 | J14: วงเงินรวม | K14: =K11+I14 -> 0 | L14: รวม | M14: =SUM(M4:M13) -> 41553.583
B15: หลักประกัน บ้านเดี่ยว | C15: LTV สูงสุด 95% ของราคาประเมิน | E15: รายได้
B16: ราคาประเมิน = วงเงินกู้ตามสัญญา | D16: 4500000 | E16: เงินเดือน | F16: 53000
B17: เลือกอัตราดอกเบี้ย | E17: Bonus | F17: 0 | H17: คำนวณ DIR | J17: สรุปวงเงิน
B18: Home Loan | C18: ลูกค้า Re-Finance II , No MRTA (waive all fees) | F18: 0 | H18: รายได้รวม | I18: =F19 -> 53000 | J18: Home Loan | K18: =K5 -> 2500000
B19: Mortgage Loan | C19: เงินกู้ปกติ , MRTA | E19: รวม | F19: =SUM(F16:F18) -> 53000 | H19: ภาระใน NCB | I19: =F32 -> 23000 | J19: Mortgage Loan | K19: =K11 -> 0
B20: วันที่ทำสัญญาเงินกู้ ธอส | C20: 30/12/2558 | D20: ( 3 ปีพอดี) | E20: ภาระ | H20: รูปแบบการชำระ | I20: ผ่อนเท่ากันทุกเดือน | J20: MRTA | K20: =I8+I14 -> 138750
B21: ยอดผ่อนต่อเดือน | C21: 54700 | E21: ภาระใน NCB | F21: 23000 | H21: ผ่อน Home Loan | I21: ='ตารางผ่อนวงเงินที่ 1'!F24 -> 6530 | J21: วงเงินรวม | K21: =K18+K19+K20 -> 2638750
B22: อัตราดอกเบี้ยปัจจุบัน | C22: 0.0575 | E22: หักค่างวดบ้านเดิม | F22: 0 | H22: ผ่อน Property Loan | I22: 0 | J22: ผ่อนชำระต่อเดือน | K22: =I21+I22 -> 6530 | CS22: =16000*80/100 -> 12800
F23: 0 | H23: DSR | I23: =(I19+I21+I22)/I18 -> 0.55716981 | J23: LTV | K23: =(K5+K11)/D16 -> 0.55555556
E24: รวม | F24: =SUM(F21:F23) -> 23000 | H24: Net Income | I24: =F19-K22-I19 -> 23470 | J24: MAX LTV | K24: =K21/D16 -> 0.58638889
E32: รวม | F32: =SUM(F21:F23) -> 23000
B33: Home Loan | C33: =C18 -> ลูกค้า Re-Finance II , No MRTA (waive all fees) | E33: Property Loan | F33: =C19 -> เงินกู้ปกติ , MRTA | I33: Mortgage OD
B34: วงเงินกู้ (บาท) | C34: =K8 -> 2638750 | E34: วงเงินกู้ (บาท) | F34: =K14 -> 0 | I34: วงเงินกู้ (บาท) | J34: 0
B35: ระยะเวลากู้ (ปี) | C35: =J7 -> 35 | E35: ระยะเวลากู้ (ปี) | F35: =J13 -> 26 | J35: OD Protection | K35: No OD Protection
C36: อัตราดอกเบี้ย (ต่อปี) | F36: อัตราดอกเบี้ย (ต่อปี) | J36: อัตราดอกเบี้ย (ต่อปี) | K36: อัตราดอกเบี้ย (ต่อปี)
B37: =VLOOKUP($C$33,$L$79:$AY$98,AH$76,FALSE) -> 420 | C37: MRR-4.50% | D37: 0.034 | E37: =VLOOKUP($F$33,$L$104:$AW$108,AH$76,FALSE) -> 420 | F37: MRR-2.00% | H37: 0.069 | J37: =$J$40 -> 0.08 | K37: =$J$40+0.5% -> 0.085
B38: =VLOOKUP($C$33,$L$79:$AY$98,AI$76,FALSE) -> ปีที่ 1 | C38: MRR-2.50% | D38: 0.054 | E38: =VLOOKUP($F$33,$L$104:$AW$108,AI$76,FALSE) -> ปีที่ 1 | F38: =VLOOKUP($F$33,$L$104:$AW$108,AN$76,FALSE) -> MLR-1.25% | H38: =VLOOKUP($F$33,$L$104:$AW$108,AS$76,FALSE) -> 0.079
B39: =VLOOKUP($C$33,$L$79:$AY$98,AJ$76,FALSE) -> ปีที่ 2 | C39: MRR-2.50% | D39: 0.054 | E39: =VLOOKUP($F$33,$L$104:$AW$108,AJ$76,FALSE) | F39: =VLOOKUP($F$33,$L$104:$AW$108,AO$76,FALSE) -> -1 | H39: =VLOOKUP($F$33,$L$104:$AW$108,AT$76,FALSE) -> 0.079 | J39: MOR | K39: MOR+0.5%
B40: =VLOOKUP($C$33,$L$79:$AY$98,AK$76,FALSE) -> ปีที่ 3 | C40: =VLOOKUP($C$33,$L$79:$AY$98,AP$76,FALSE) -> MLR-1.25% | D40: =VLOOKUP($C$33,$L$79:$AY$98,AU$76,FALSE) -> 0.079 | E40: =VLOOKUP($F$33,$L$104:$AW$108,AK$76,FALSE) | F40: =VLOOKUP($F$33,$L$104:$AW$108,AP$76,FALSE) -> -1 | H40: =VLOOKUP($F$33,$L$104:$AW$108,AU$76,FALSE) -> 0.079 | I40: MOR = : | J40: 0.08
B41: =VLOOKUP($C$33,$L$79:$AY$98,AL$76,FALSE) | C41: MRR-1.50% | D41: 0.064 | E41: =VLOOKUP($F$33,$L$104:$AW$108,AL$76,FALSE) | F41: MRR-0.75% | H41: =D44-0.75% -> 0.0715
C42: Grace Period | D42: =VLOOKUP($C$33,$L$79:$AY$98,38,FALSE) -> N | H42: ยอดผ่อนชำระต่อเดือน (บาท) | J42: ยอดผ่อนชำระต่อเดือน (บาท) | K42: ยอดผ่อนชำระต่อเดือน (บาท)
D43: =VLOOKUP($C$33,$L$79:$AY$98,39,FALSE) -> Y
C44: MRR = : | D44: 0.079 | H44: ='eBMortgageLoan - Table 1'!$M$4 -> 0 | J44: =ROUNDUP(J34*(J37/12),-1) -> 0 | K44: =ROUNDUP(J34*(K37/12),-1) -> 0
B48: แบบที่ 1 Option 1 | D48: แบบที่ 2 Option 2 | F48: แบบที่ 3 Option 3 | I48: แบบที่ 4 Option 4
B49: ผ่อนเท่ากันทุกเดือน Flat Rate | D49: ผ่อนเท่ากันทุกเดือน Flat Rate | F49: ผ่อนแบบขั้นบันได Step Rate | I49: ผ่อนแบบขั้นบันได Step Rate
B50: ไม่มี No Grace Period | D50: มี With Grace Period | F50: ไม่มี No Grace Period | I50: มี With Grace Period
B51: ยอดผ่อนชำระต่อเดือน (บาท)
...

Sheet eBHomeLoan - Table 1
D1: ="ตารางคำนวณ "&'Secured - Table 1'!$C$33 -> ตารางคำนวณ ลูกค้า Re-Finance II , No MRTA (waive all fees)
G3: วงเงินกู้ (บาท) | H3: ค่าธรรมเนียม (บาท) | I3: เวลา (เดือน) | J3: อัตราดอกเบี้ย (%) | K3: เงินงวด (บาท) | L3: ผ่อนแบบ ขั้นบันได | M3: เงินงวด (บาท) เผื่อดอกเบี้ย 1% | N3: งวดชำระจริง (งวด) | O3: ยอดชำระรวม (บาท) | P3: ดอกเบี้ยชำระ 3 ปีแรก (บาท)
D4: 1. แบบคงที่ | G4: ='Secured - Table 1'!$C$34 -> 2638750 | I4: ='Secured - Table 1'!$C$35*12 -> 420 | J4: =($J$7*$C$7+$J$8*$C$8+$J$9*$C$9+$J$10*$C$10+$J$11*('Secured - Table 1'!$C$35*12-SUM($C$7:$C$10)))/('Secured - Table 1'!$C$35*12) -> 0.062571429 | K4: =IF(OR($G$7=0,$I$8=0),0,PMT($J4/12,$I4,-$G4)) -> 15504.287 | M4: =IF(OR($G$7=0,$I$8=0),0,ROUNDUP(PMT(($J4+1%)/12,$I4,-$G4),-1)) -> 17340 | N4: =IF(OR($G$7=0,$I$8=0),0,370-COUNTIF(G23:G392,0)) -> 281 | O4: =SUM(H23:H392) -> 4867558.9 | P4: =IF(OR($G$7=0,$I$8=0),0,SUM(F23:F58)) -> 352143.89 | Q4: =O4+3200+3310 -> 4874068.9
D5: 2. แบบคงที่ มี Grace Period | G5: ='Secured - Table 1'!$C$34 -> 2638750 | I5: =I4-12 -> 408 | J5: =($J$7*$C$7+$J$8*$C$8+$J$9*$C$9+$J$10*$C$10+$J$11*('Secured - Table 1'!$C$35*12-SUM($C$7:$C$10)))/('Secured - Table 1'!$C$35*12) -> 0.062571429 | K5: =IF(OR($G$7=0,$I$8=0),0,PMT($J5/12,$I5,-$G5)) -> 15631.962 | M5: =IF(OR($G$7=0,$I$8=0),0,ROUNDUP(PMT(($J5+1%)/12,$I5,-$G5),-1)) -> 17450 | N5: =IF(OR($G$7=0,$I$8=0),0,370-COUNTIF(K35:K392,0)) -> 307 | O5: =SUM(L23:L392) -> 5230710.9 | P5: =IF(OR($G$7=0,$I$8=0),0,SUM(J23:J58)) -> 367317.39
D6: 3. แบบขั้นบันได
A7: 0 | B7: =J7 -> 0.034 | C7: =VLOOKUP('Secured - Table 1'!$C$33,'Secured - Table 1'!$L$79:$AY$98,'Secured - Table 1'!M$76,FALSE) -> 12 | E7: ='Secured - Table 1'!B37 -> 420 | F7: ='Secured - Table 1'!C37 -> MRR-4.50% | G7: ='Secured - Table 1'!$C$34 -> 2638750 | I7: ='Secured - Table 1'!$C$35*12 -> 420 | J7: ='Secured - Table 1'!D37 -> 0.034 | K7: =IF(OR($G$7=0,$I$8=0),0,PMT($J7/12,$I7,-$G7)) -> 10753.372
A8: =SUM(C$7:C7)+1 -> 13 | B8: =J8 -> 0.054 | C8: =VLOOKUP('Secured - Table 1'!$C$33,'Secured - Table 1'!$L$79:$AY$98,'Secured - Table 1'!N$76,FALSE) -> 12 | E8: ='Secured - Table 1'!B38 -> ปีที่ 1 | F8: ='Secured - Table 1'!C38 -> MRR-2.50% | G8: =VLOOKUP(A8,$D$22:$T$392,10,FALSE) -> 2558748.4 | I8: =I7-C7 -> 408 | J8: ='Secured - Table 1'!D38 -> 0.054 | K8: =IF(OR($G$7=0,$I$8=0),0,PMT($J8/12,$I8,-$G8)) -> 13709.41 | Q8: =$V$20 -> % ปรับปรุงค่างวดแบบขั้นบันได | R8: % ค่างวดเพิ่ม | S8: ค่างวดเพิ่ม
A9: =SUM(C$7:C8)+1 -> 25 | B9: =J9 -> 0.054 | C9: =VLOOKUP('Secured - Table 1'!$C$33,'Secured - Table 1'!$L$79:$AY$98,'Secured - Table 1'!O$76,FALSE) -> 12 | E9: ='Secured - Table 1'!B39 -> ปีที่ 2 | F9: ='Secured - Table 1'!C39 -> MRR-2.50% | G9: =VLOOKUP(A9,$D$22:$T$392,10,FALSE) -> 2527679.4 | I9: =I8-C8 -> 396 | J9: ='Secured - Table 1'!D39 -> 0.054 | K9: =IF(OR($G$7=0,$I$8=0),0,PMT($J9/12,$I9,-$G9)) -> 13687.388 | L9: ปีที่ 1 และ 2 | M9: =ROUNDUP($M10/$Q9,-1) -> 14040 | Q9: 1.1
A10: =SUM(C$7:C9)+1 -> 37 | B10: =J10 -> 0.079 | C10: =VLOOKUP('Secured - Table 1'!$C$33,'Secured - Table 1'!$L$79:$AY$98,'Secured - Table 1'!P$76,FALSE) -> 0 | E10: ='Secured - Table 1'!B40 -> ปีที่ 3 | F10: ='Secured - Table 1'!C40 -> MLR-1.25% | G10: =VLOOKUP(A10,$D$22:$T$392,10,FALSE) -> 2477668.4 | I10: =I9-C9 -> 384 | J10: ='Secured - Table 1'!D40 -> 0.079 | K10: =IF(OR($G$7=0,$I$8=0),0,PMT($J10/12,$I10,-$G10)) -> 17738.996 | L10: ปีที่ 3 และ 4 | M10: =ROUNDUP($M$4*$Q10,-1) -> 15440 | Q10: =IF(OR($G$7=0,$I$8=0),0,VLOOKUP($I$8/12,$V$22:$X$52,2)) -> 0.89 | R10: =IF(M9=0,0,M10/M9) -> 1.0997151 | S10: =M10-M9 -> 1400
A11: =SUM(C$7:C10)+1 -> 37 | B11: =J11 -> 0.064 | E11: ='Secured - Table 1'!B41 | F11: ='Secured - Table 1'!C41 -> MRR-1.50% | G11: =VLOOKUP(A11,$D$22:$T$392,10,FALSE) -> 2477668.4 | I11: =I10-C10 -> 384 | J11: ='Secured - Table 1'!D41 -> 0.064 | K11: =IF(OR($G$7=0,$I$8=0),0,PMT($J11/12,$I11,-$G11)) -> 15183.475 | L11: ปีที่ 5 เป็นต้นไป | M11: =IF(OR($G$7=0,$I$8=0),0,ROUNDUP(PMT($J$11/12,$N$4-48,-$M$71),-1)) -> 18400 | N11: =IF(OR($G$7=0,$I$8=0),0,370-COUNTIF(O23:O392,0)) -> 281 | O11: =SUM(P23:P392) -> 4994720 | P11: =IF(OR($G$7=0,$I$8=0),0,SUM(N23:N58)) -> 361158.35 | R11: =IF(M10=0,0,M11/M10) -> 1.1917098 | S11: =M11-M10 -> 2960
D12: 4. แบบขั้นบันได มี Grace Period
A13: =A7 -> 0 | B13: =B7 -> 0.034 | C13: =C7 -> 12 | E13: =E7 -> 420 | F13: =F7 -> MRR-4.50% | G13: ='Secured - Table 1'!$C$34 -> 2638750 | I13: ='Secured - Table 1'!$C$35*12 -> 420 | J13: =J7 -> 0.034 | K13: =IF(OR($G$7=0,$I$8=0),0,$G13*IF($C$13<12,$J$14,$J13)*31/365) -> 7619.8425
A14: =A8 -> 13 | B14: =B8 -> 0.054 | C14: =C8 -> 12 | E14: =E8 -> ปีที่ 1 | F14: =F8 -> MRR-2.50% | G14: =VLOOKUP(A14,$D$22:$T$392,14,FALSE) -> 2637000.4 | I14: =I8 -> 408 | J14: =J8 -> 0.054 | K14: =IF(OR($G$7=0,$I$8=0),0,IF($C$13<12,K13,PMT($J14/12,$I14,-$G14))) -> 14128.673 | L14: ปีที่ 1 | M14: =ROUNDUP($K13,-1) -> 7620 | Q14: =$V$20 -> % ปรับปรุงค่างวดแบบขั้นบันได | R14: % ค่างวดเพิ่ม | S14: ค่างวดเพิ่ม
A15: =A9 -> 25 | B15: =B9 -> 0.054 | C15: =C9 -> 12 | E15: =E9 -> ปีที่ 2 | F15: =F9 -> MRR-2.50% | G15: =VLOOKUP(A15,$D$22:$T$392,14,FALSE) -> 2609156 | I15: =I9 -> 396 | J15: =J9 -> 0.054 | K15: =IF(OR($G$7=0,$I$8=0),0,PMT($J15/12,$I15,-$G15)) -> 14128.584 | L15: ปีที่ 2 และ 3 | M15: =ROUNDUP($M16/$Q15,-1) -> 14130 | Q15: 1.1
A16: =A10 -> 37 | B16: =B10 -> 0.079 | C16: =C10 -> 0 | E16: =E10 -> ปีที่ 3 | F16: =F10 -> MLR-1.25% | G16: =VLOOKUP(A16,$D$22:$T$392,14,FALSE) -> 2579770.2 | I16: =I10 -> 384 | J16: =J10 -> 0.079 | K16: =IF(OR($G$7=0,$I$8=0),0,PMT($J16/12,$I16,-$G16)) -> 18469.999 | L16: ปีที่ 4 และ 5 | M16: =ROUNDUP($M$5*$Q16,-1) -> 15540 | Q16: =IF(OR($G$7=0,$I$8=0),0,VLOOKUP($I$8/12,$V$22:$X$52,3)) -> 0.89 | R16: =IF(M15=0,0,M16/M15) -> 1.0997877 | S16: =M16-M15 -> 1410
A17: =A11 -> 37 | B17: =B11 -> 0.064 | E17: =E11 | F17: =F11 -> MRR-1.50% | G17: =VLOOKUP(A17,$D$22:$T$392,14,FALSE) -> 2579770.2 | I17: =I11 -> 384 | J17: =J11 -> 0.064 | K17: =IF(OR($G$7=0,$I$8=0),0,PMT($J17/12,$I17,-$G17)) -> 15809.168 | L17: ปีที่ 6 เป็นต้นไป | M17: =IF(OR($G$7=0,$I$8=0),0,ROUNDUP(PMT($J17/12,$N$5-60,-$Q$83),-1)) -> 18490 | N17: =IF(OR($G$7=0,$I$8=0),0,370-COUNTIF(S23:S392,0)) -> 307 | O17: =SUM(T23:T392) -> 5367842 | P17: =IF(OR($G$7=0,$I$8=0),0,SUM(R23:R58)) -> 371580.15 | R17: =IF(M16=0,0,M17/M16) -> 1.1898327 | S17: =M17-M16 -> 2950
E20: =D4 -> 1. แบบคงที่ | I20: =D5 -> 2. แบบคงที่ มี Grace Period | M20: =D6 -> 3. แบบขั้นบันได | Q20: =D12 -> 4. แบบขั้นบันได มี Grace Period | V20: % ปรับปรุงค่างวดแบบขั้นบันได
A21: Annual rate | B21: Monthly rate | C21: ปี | D21: งวด | E21: เงินต้นคงเหลือ | F21: ดอกเบี้ยผ่อนชำระ | G21: เงินต้นผ่อนชำระ | H21: เงินงวด | I21: เงินต้นคงเหลือ | J21: ดอกเบี้ยผ่อนชำระ | K21: เงินต้นผ่อนชำระ | L21: เงินงวด | M21: เงินต้นคงเหลือ | N21: ดอกเบี้ยผ่อนชำระ | O21: เงินต้นผ่อนชำระ | P21: เงินงวด | Q21: เงินต้นคงเหลือ | R21: ดอกเบี้ยผ่อนชำระ | S21: เงินต้นผ่อนชำระ | T21: เงินงวด | V21: ระยะเวลา (ปี) | W21: ไม่มี Grace Period | X21: มี Grace Period
C22: 0 | D22: 0 | H22: =-$G$7 -> -2638750 | L22: =-$G$7 -> -2638750 | P22: =-$G$7 -> -2638750 | T22: =-$G$7 -> -2638750 | V22: 0 | W22: 1 | X22: 1.03
A23: =VLOOKUP(D23,$A$7:$B$11,2) -> 0.034 | B23: =A23/12 -> 0.0028333333 | C23: =INT((D23+11)/12) -> 1 | D23: 1 | E23: =$G$7 -> 2638750 | F23: =ROUND(E23*$B23,2) -> 7476.46 | G23: =IF(E23<H23,E23,H23-F23) -> 9863.54 | H23: =IF(E23<$M$4,E23+F23,$M$4) -> 17340 | I23: =$G$7 -> 2638750 | J23: =ROUND(I23*$B23,2) -> 7476.46 | K23: =IF(I23<L23,I23,L23-J23) -> 143.54 | L23: =IF(I23<$M$14,I23+J23,$M$14) -> 7620 | M23: =$G$7 -> 2638750 | N23: =ROUND(M23*$B23,2) -> 7476.46 | O23: =IF(M23<P23,M23,P23-N23) -> 6563.54 | P23: =IF(M23<$M$9,M23+N23,$M$9) -> 14040 | Q23: =$G$7 -> 2638750 | R23: =ROUND(Q23*$B23,2) -> 7476.46 | S23: =IF(Q23<T23,Q23,T23-R23) -> 143.54 | T23: =IF(Q23<$M$14,Q23+R23,$M$14) -> 7620 | V23: 1 | W23: 1 | X23: 1.03
A24: =VLOOKUP(D24,$A$7:$B$11,2) -> 0.034 | B24: =A24/12 -> 0.0028333333 | C24: =INT((D24+11)/12) -> 1 | D24: 2 | E24: =IF(E23<H23,0,E23-G23) -> 2628886.5 | F24: =ROUND(E24*$B24,2) -> 7448.51 | G24: =IF(E24<H24,E24,H24-F24) -> 9891.49 | H24: =IF(E24<$M$4,E24+F24,$M$4) -> 17340 | I24: =IF(I23<L23,0,I23-K23) -> 2638606.5 | J24: =ROUND(I24*$B24,2) -> 7476.05 | K24: =IF(I24<L24,I24,L24-J24) -> 143.95 | L24: =IF(I24<$M$14,I24+J24,$M$14) -> 7620 | M24: =IF(M23<P23,0,M23-O23) -> 2632186.5 | N24: =ROUND(M24*$B24,2) -> 7457.86 | O24: =IF(M24<P24,M24,P24-N24) -> 6582.14 | P24: =IF(M24<$M$9,M24+N24,$M$9) -> 14040 | Q24: =IF(Q23<T23,0,Q23-S23) -> 2638606.5 | R24: =ROUND(Q24*$B24,2) -> 7476.05 | S24: =IF(Q24<T24,Q24,T24-R24) -> 143.95 | T24: =IF(Q24<$M$14,Q24+R24,$M$14) -> 7620 | V24: 2 | W24: 1 | X24: 1.03
A25: =VLOOKUP(D25,$A$7:$B$11,2) -> 0.034 | B25: =A25/12 -> 0.0028333333 | C25: =INT((D25+11)/12) -> 1 | D25: 3 | E25: =IF(E24<H24,0,E24-G24) -> 2618995 | F25: =ROUND(E25*$B25,2) -> 7420.49 | G25: =IF(E25<H25,E25,H25-F25) -> 9919.51 | H25: =IF(E25<$M$4,E25+F25,$M$4) -> 17340 | I25: =IF(I24<L24,0,I24-K24) -> 2638462.5 | J25: =ROUND(I25*$B25,2) -> 7475.64 | K25: =IF(I25<L25,I25,L25-J25) -> 144.36 | L25: =IF(I25<$M$14,I25+J25,$M$14) -> 7620 | M25: =IF(M24<P24,0,M24-O24) -> 2625604.3 | N25: =ROUND(M25*$B25,2) -> 7439.21 | O25: =IF(M25<P25,M25,P25-N25) -> 6600.79 | P25: =IF(M25<$M$9,M25+N25,$M$9) -> 14040 | Q25: =IF(Q24<T24,0,Q24-S24) -> 2638462.5 | R25: =ROUND(Q25*$B25,2) -> 7475.64 | S25: =IF(Q25<T25,Q25,T25-R25) -> 144.36 | T25: =IF(Q25<$M$14,Q25+R25,$M$14) -> 7620 | V25: 3 | W25: 1 | X25: 1.03
A26: =VLOOKUP(D26,$A$7:$B$11,2) -> 0.034 | B26: =A26/12 -> 0.0028333333 | C26: =INT((D26+11)/12) -> 1 | D26: 4 | E26: =IF(E25<H25,0,E25-G25) -> 2609075.5 | F26: =ROUND(E26*$B26,2) -> 7392.38 | G26: =IF(E26<H26,E26,H26-F26) -> 9947.62 | H26: =IF(E26<$M$4,E26+F26,$M$4) -> 17340 | I26: =IF(I25<L25,0,I25-K25) -> 2638318.1 | J26: =ROUND(I26*$B26,2) -> 7475.23 | K26: =IF(I26<L26,I26,L26-J26) -> 144.77 | L26: =IF(I26<$M$14,I26+J26,$M$14) -> 7620 | M26: =IF(M25<P25,0,M25-O25) -> 2619003.5 | N26: =ROUND(M26*$B26,2) -> 7420.51 | O26: =IF(M26<P26,M26,P26-N26) -> 6619.49 | P26: =IF(M26<$M$9,M26+N26,$M$9) -> 14040 | Q26: =IF(Q25<T25,0,Q25-S25) -> 2638318.1 | R26: =ROUND(Q26*$B26,2) -> 7475.23 | S26: =IF(Q26<T26,Q26,T26-R26) -> 144.77 | T26: =IF(Q26<$M$14,Q26+R26,$M$14) -> 7620 | V26: 4 | W26: 1 | X26: 1.03
A27: =VLOOKUP(D27,$A$7:$B$11,2) -> 0.034 | B27: =A27/12 -> 0.0028333333 | C27: =INT((D27+11)/12) -> 1 | D27: 5 | E27: =IF(E26<H26,0,E26-G26) -> 2599127.8 | F27: =ROUND(E27*$B27,2) -> 7364.2 | G27: =IF(E27<H27,E27,H27-F27) -> 9975.8 | H27: =IF(E27<$M$4,E27+F27,$M$4) -> 17340 | I27: =IF(I26<L26,0,I26-K26) -> 2638173.4 | J27: =ROUND(I27*$B27,2) -> 7474.82 | K27: =IF(I27<L27,I27,L27-J27) -> 145.18 | L27: =IF(I27<$M$14,I27+J27,$M$14) -> 7620 | M27: =IF(M26<P26,0,M26-O26) -> 2612384 | N27: =ROUND(M27*$B27,2) -> 7401.75 | O27: =IF(M27<P27,M27,P27-N27) -> 6638.25 | P27: =IF(M27<$M$9,M27+N27,$M$9) -> 14040 | Q27: =IF(Q26<T26,0,Q26-S26) -> 2638173.4 | R27: =ROUND(Q27*$B27,2) -> 7474.82 | S27: =IF(Q27<T27,Q27,T27-R27) -> 145.18 | T27: =IF(Q27<$M$14,Q27+R27,$M$14) -> 7620 | V27: 5 | W27: 1 | X27: 1.03
A28: =VLOOKUP(D28,$A$7:$B$11,2) -> 0.034 | B28: =A28/12 -> 0.0028333333 | C28: =INT((D28+11)/12) -> 1 | D28: 6 | E28: =IF(E27<H27,0,E27-G27) -> 2589152 | F28: =ROUND(E28*$B28,2) -> 7335.93 | G28: =IF(E28<H28,E28,H28-F28) -> 10004.07 | H28: =IF(E28<$M$4,E28+F28,$M$4) -> 17340 | I28: =IF(I27<L27,0,I27-K27) -> 2638028.2 | J28: =ROUND(I28*$B28,2) -> 7474.41 | K28: =IF(I28<L28,I28,L28-J28) -> 145.59 | L28: =IF(I28<$M$14,I28+J28,$M$14) -> 7620 | M28: =IF(M27<P27,0,M27-O27) -> 2605745.8 | N28: =ROUND(M28*$B28,2) -> 7382.95 | O28: =IF(M28<P28,M28,P28-N28) -> 6657.05 | P28: =IF(M28<$M$9,M28+N28,$M$9) -> 14040 | Q28: =IF(Q27<T27,0,Q27-S27) -> 2638028.2 | R28: =ROUND(Q28*$B28,2) -> 7474.41 | S28: =IF(Q28<T28,Q28,T28-R28) -> 145.59 | T28: =IF(Q28<$M$14,Q28+R28,$M$14) -> 7620 | V28: 6 | W28: 1 | X28: 1.03
A29: =VLOOKUP(D29,$A$7:$B$11,2) -> 0.034 | B29: =A29/12 -> 0.0028333333 | C29: =INT((D29+11)/12) -> 1 | D29: 7 | E29: =IF(E28<H28,0,E28-G28) -> 2579148 | F29: =ROUND(E29*$B29,2) -> 7307.59 | G29: =IF(E29<H29,E29,H29-F29) -> 10032.41 | H29: =IF(E29<$M$4,E29+F29,$M$4) -> 17340 | I29: =IF(I28<L28,0,I28-K28) -> 2637882.6 | J29: =ROUND(I29*$B29,2) -> 7474 | K29: =IF(I29<L29,I29,L29-J29) -> 146 | L29: =IF(I29<$M$14,I29+J29,$M$14) -> 7620 | M29: =IF(M28<P28,0,M28-O28) -> 2599088.7 | N29: =ROUND(M29*$B29,2) -> 7364.08 | O29: =IF(M29<P29,M29,P29-N29) -> 6675.92 | P29: =IF(M29<$M$9,M29+N29,$M$9) -> 14040 | Q29: =IF(Q28<T28,0,Q28-S28) -> 2637882.6 | R29: =ROUND(Q29*$B29,2) -> 7474 | S29: =IF(Q29<T29,Q29,T29-R29) -> 146 | T29: =IF(Q29<$M$14,Q29+R29,$M$14) -> 7620 | V29: 7 | W29: 0.98 | X29: 1
A30: =VLOOKUP(D30,$A$7:$B$11,2) -> 0.034 | B30: =A30/12 -> 0.0028333333 | C30: =INT((D30+11)/12) -> 1 | D30: 8 | E30: =IF(E29<H29,0,E29-G29) -> 2569115.6 | F30: =ROUND(E30*$B30,2) -> 7279.16 | G30: =IF(E30<H30,E30,H30-F30) -> 10060.84 | H30: =IF(E30<$M$4,E30+F30,$M$4) -> 17340 | I30: =IF(I29<L29,0,I29-K29) -> 2637736.6 | J30: =ROUND(I30*$B30,2) -> 7473.59 | K30: =IF(I30<L30,I30,L30-J30) -> 146.41 | L30: =IF(I30<$M$14,I30+J30,$M$14) -> 7620 | M30: =IF(M29<P29,0,M29-O29) -> 2592412.8 | N30: =ROUND(M30*$B30,2) -> 7345.17 | O30: =IF(M30<P30,M30,P30-N30) -> 6694.83 | P30: =IF(M30<$M$9,M30+N30,$M$9) -> 14040 | Q30: =IF(Q29<T29,0,Q29-S29) -> 2637736.6 | R30: =ROUND(Q30*$B30,2) -> 7473.59 | S30: =IF(Q30<T30,Q30,T30-R30) -> 146.41 | T30: =IF(Q30<$M$14,Q30+R30,$M$14) -> 7620 | V30: 8 | W30: 0.96 | X30: 0.98
A31: =VLOOKUP(D31,$A$7:$B$11,2) -> 0.034 | B31: =A31/12 -> 0.0028333333 | C31: =INT((D31+11)/12) -> 1 | D31: 9 | E31: =IF(E30<H30,0,E30-G30) -> 2559054.7 | F31: =ROUND(E31*$B31,2) -> 7250.66 | G31: =IF(E31<H31,E31,H31-F31) -> 10089.34 | H31: =IF(E31<$M$4,E31+F31,$M$4) -> 17340 | I31: =IF(I30<L30,0,I30-K30) -> 2637590.2 | J31: =ROUND(I31*$B31,2) -> 7473.17 | K31: =IF(I31<L31,I31,L31-J31) -> 146.83 | L31: =IF(I31<$M$14,I31+J31,$M$14) -> 7620 | M31: =IF(M30<P30,0,M30-O30) -> 2585718 | N31: =ROUND(M31*$B31,2) -> 7326.2 | O31: =IF(M31<P31,M31,P31-N31) -> 6713.8 | P31: =IF(M31<$M$9,M31+N31,$M$9) -> 14040 | Q31: =IF(Q30<T30,0,Q30-S30) -> 2637590.2 | R31: =ROUND(Q31*$B31,2) -> 7473.17 | S31: =IF(Q31<T31,Q31,T31-R31) -> 146.83 | T31: =IF(Q31<$M$14,Q31+R31,$M$14) -> 7620 | V31: 9 | W31: 0.95 | X31: 0.96
A32: =VLOOKUP(D32,$A$7:$B$11,2) -> 0.034 | B32: =A32/12 -> 0.0028333333 | C32: =INT((D32+11)/12) -> 1 | D32: 10 | E32: =IF(E31<H31,0,E31-G31) -> 2548965.4 | F32: =ROUND(E32*$B32,2) -> 7222.07 | G32: =IF(E32<H32,E32,H32-F32) -> 10117.93 | H32: =IF(E32<$M$4,E32+F32,$M$4) -> 17340 | I32: =IF(I31<L31,0,I31-K31) -> 2637443.4 | J32: =ROUND(I32*$B32,2) -> 7472.76 | K32: =IF(I32<L32,I32,L32-J32) -> 147.24 | L32: =IF(I32<$M$14,I32+J32,$M$14) -> 7620 | M32: =IF(M31<P31,0,M31-O31) -> 2579004.2 | N32: =ROUND(M32*$B32,2) -> 7307.18 | O32: =IF(M32<P32,M32,P32-N32) -> 6732.82 | P32: =IF(M32<$M$9,M32+N32,$M$9) -> 14040 | Q32: =IF(Q31<T31,0,Q31-S31) -> 2637443.4 | R32: =ROUND(Q32*$B32,2) -> 7472.76 | S32: =IF(Q32<T32,Q32,T32-R32) -> 147.24 | T32: =IF(Q32<$M$14,Q32+R32,$M$14) -> 7620 | V32: 10 | W32: 0.94 | X32: 0.95
A33: =VLOOKUP(D33,$A$7:$B$11,2) -> 0.034 | B33: =A33/12 -> 0.0028333333 | C33: =INT((D33+11)/12) -> 1 | D33: 11 | E33: =IF(E32<H32,0,E32-G32) -> 2538847.5 | F33: =ROUND(E33*$B33,2) -> 7193.4 | G33: =IF(E33<H33,E33,H33-F33) -> 10146.6 | H33: =IF(E33<$M$4,E33+F33,$M$4) -> 17340 | I33: =IF(I32<L32,0,I32-K32) -> 2637296.1 | J33: =ROUND(I33*$B33,2) -> 7472.34 | K33: =IF(I33<L33,I33,L33-J33) -> 147.66 | L33: =IF(I33<$M$14,I33+J33,$M$14) -> 7620 | M33: =IF(M32<P32,0,M32-O32) -> 2572271.4 | N33: =ROUND(M33*$B33,2) -> 7288.1 | O33: =IF(M33<P33,M33,P33-N33) -> 6751.9 | P33: =IF(M33<$M$9,M33+N33,$M$9) -> 14040 | Q33: =IF(Q32<T32,0,Q32-S32) -> 2637296.1 | R33: =ROUND(Q33*$B33,2) -> 7472.34 | S33: =IF(Q33<T33,Q33,T33-R33) -> 147.66 | T33: =IF(Q33<$M$14,Q33+R33,$M$14) -> 7620 | V33: 11 | W33: 0.93 | X33: 0.94
A34: =VLOOKUP(D34,$A$7:$B$11,2) -> 0.034 | B34: =A34/12 -> 0.0028333333 | C34: =INT((D34+11)/12) -> 1 | D34: 12 | E34: =IF(E33<H33,0,E33-G33) -> 2528700.9 | F34: =ROUND(E34*$B34,2) -> 7164.65 | G34: =IF(E34<H34,E34,H34-F34) -> 10175.35 | H34: =IF(E34<$M$4,E34+F34,$M$4) -> 17340 | I34: =IF(I33<L33,0,I33-K33) -> 2637148.5 | J34: =ROUND(I34*$B34,2) -> 7471.92 | K34: =IF(I34<L34,I34,L34-J34) -> 148.08 | L34: =IF(I34<$M$14,I34+J34,$M$14) -> 7620 | M34: =IF(M33<P33,0,M33-O33) -> 2565519.5 | N34: =ROUND(M34*$B34,2) -> 7268.97 | O34: =IF(M34<P34,M34,P34-N34) -> 6771.03 | P34: =IF(M34<$M$9,M34+N34,$M$9) -> 14040 | Q34: =IF(Q33<T33,0,Q33-S33) -> 2637148.5 | R34: =ROUND(Q34*$B34,2) -> 7471.92 | S34: =IF(Q34<T34,Q34,T34-R34) -> 148.08 | T34: =IF(Q34<$M$14,Q34+R34,$M$14) -> 7620 | V34: 12 | W34: 0.93 | X34: 0.93
A35: =VLOOKUP(D35,$A$7:$B$11,2) -> 0.054 | B35: =A35/12 -> 0.0045 | C35: =INT((D35+11)/12) -> 2 | D35: 13 | E35: =IF(E34<H34,0,E34-G34) -> 2518525.5 | F35: =ROUND(E35*$B35,2) -> 11333.36 | G35: =IF(E35<H35,E35,H35-F35) -> 6006.64 | H35: =IF(E35<$M$4,E35+F35,$M$4) -> 17340 | I35: =IF(I34<L34,0,I34-K34) -> 2637000.4 | J35: =ROUND(I35*$B35,2) -> 11866.5 | K35: =IF(I35<L35,I35,L35-J35) -> 5583.5 | L35: =IF(I35<$M$5,I35+J35,$M$5) -> 17450 | M35: =IF(M34<P34,0,M34-O34) -> 2558748.4 | N35: =ROUND(M35*$B35,2) -> 11514.37 | O35: =IF(M35<P35,M35,P35-N35) -> 2525.63 | P35: =IF(M35<$M$9,M35+N35,$M$9) -> 14040 | Q35: =IF(Q34<T34,0,Q34-S34) -> 2637000.4 | R35: =ROUND(Q35*$B35,2) -> 11866.5 | S35: =IF(Q35<T35,Q35,T35-R35) -> 2263.5 | T35: =IF(Q35<$M$15,Q35+R35,$M$15) -> 14130 | V35: 13 | W35: 0.92 | X35: 0.93
A36: =VLOOKUP(D36,$A$7:$B$11,2) -> 0.054 | B36: =A36/12 -> 0.0045 | C36: =INT((D36+11)/12) -> 2 | D36: 14 | E36: =IF(E35<H35,0,E35-G35) -> 2512518.9 | F36: =ROUND(E36*$B36,2) -> 11306.33 | G36: =IF(E36<H36,E36,H36-F36) -> 6033.67 | H36: =IF(E36<$M$4,E36+F36,$M$4) -> 17340 | I36: =IF(I35<L35,0,I35-K35) -> 2631416.9 | J36: =ROUND(I36*$B36,2) -> 11841.38 | K36: =IF(I36<L36,I36,L36-J36) -> 5608.62 | L36: =IF(I36<$M$5,I36+J36,$M$5) -> 17450 | M36: =IF(M35<P35,0,M35-O35) -> 2556222.8 | N36: =ROUND(M36*$B36,2) -> 11503 | O36: =IF(M36<P36,M36,P36-N36) -> 2537 | P36: =IF(M36<$M$9,M36+N36,$M$9) -> 14040 | Q36: =IF(Q35<T35,0,Q35-S35) -> 2634736.9 | R36: =ROUND(Q36*$B36,2) -> 11856.32 | S36: =IF(Q36<T36,Q36,T36-R36) -> 2273.68 | T36: =IF(Q36<$M$15,Q36+R36,$M$15) -> 14130 | V36: 14 | W36: 0.92 | X36: 0.92
A37: =VLOOKUP(D37,$A$7:$B$11,2) -> 0.054 | B37: =A37/12 -> 0.0045 | C37: =INT((D37+11)/12) -> 2 | D37: 15 | E37: =IF(E36<H36,0,E36-G36) -> 2506485.2 | F37: =ROUND(E37*$B37,2) -> 11279.18 | G37: =IF(E37<H37,E37,H37-F37) -> 6060.82 | H37: =IF(E37<$M$4,E37+F37,$M$4) -> 17340 | I37: =IF(I36<L36,0,I36-K36) -> 2625808.3 | J37: =ROUND(I37*$B37,2) -> 11816.14 | K37: =IF(I37<L37,I37,L37-J37) -> 5633.86 | L37: =IF(I37<$M$5,I37+J37,$M$5) -> 17450 | M37: =IF(M36<P36,0,M36-O36) -> 2553685.8 | N37: =ROUND(M37*$B37,2) -> 11491.59 | O37: =IF(M37<P37,M37,P37-N37) -> 2548.41 | P37: =IF(M37<$M$9,M37+N37,$M$9) -> 14040 | Q37: =IF(Q36<T36,0,Q36-S36) -> 2632463.2 | R37: =ROUND(Q37*$B37,2) -> 11846.08 | S37: =IF(Q37<T37,Q37,T37-R37) -> 2283.92 | T37: =IF(Q37<$M$15,Q37+R37,$M$15) -> 14130 | V37: 15 | W37: 0.91 | X37: 0.92
A38: =VLOOKUP(D38,$A$7:$B$11,2) -> 0.054 | B38: =A38/12 -> 0.0045 | C38: =INT((D38+11)/12) -> 2 | D38: 16 | E38: =IF(E37<H37,0,E37-G37) -> 2500424.4 | F38: =ROUND(E38*$B38,2) -> 11251.91 | G38: =IF(E38<H38,E38,H38-F38) -> 6088.09 | H38: =IF(E38<$M$4,E38+F38,$M$4) -> 17340 | I38: =IF(I37<L37,0,I37-K37) -> 2620174.4 | J38: =ROUND(I38*$B38,2) -> 11790.78 | K38: =IF(I38<L38,I38,L38-J38) -> 5659.22 | L38: =IF(I38<$M$5,I38+J38,$M$5) -> 17450 | M38: =IF(M37<P37,0,M37-O37) -> 2551137.4 | N38: =ROUND(M38*$B38,2) -> 11480.12 | O38: =IF(M38<P38,M38,P38-N38) -> 2559.88 | P38: =IF(M38<$M$9,M38+N38,$M$9) -> 14040 | Q38: =IF(Q37<T37,0,Q37-S37) -> 2630179.3 | R38: =ROUND(Q38*$B38,2) -> 11835.81 | S38: =IF(Q38<T38,Q38,T38-R38) -> 2294.19 | T38: =IF(Q38<$M$15,Q38+R38,$M$15) -> 14130 | V38: 16 | W38: 0.91 | X38: 0.91
A39: =VLOOKUP(D39,$A$7:$B$11,2) -> 0.054 | B39: =A39/12 -> 0.0045 | C39: =INT((D39+11)/12) -> 2 | D39: 17 | E39: =IF(E38<H38,0,E38-G38) -> 2494336.3 | F39: =ROUND(E39*$B39,2) -> 11224.51 | G39: =IF(E39<H39,E39,H39-F39) -> 6115.49 | H39: =IF(E39<$M$4,E39+F39,$M$4) -> 17340 | I39: =IF(I38<L38,0,I38-K38) -> 2614515.2 | J39: =ROUND(I39*$B39,2) -> 11765.32 | K39: =IF(I39<L39,I39,L39-J39) -> 5684.68 | L39: =IF(I39<$M$5,I39+J39,$M$5) -> 17450 | M39: =IF(M38<P38,0,M38-O38) -> 2548577.5 | N39: =ROUND(M39*$B39,2) -> 11468.6 | O39: =IF(M39<P39,M39,P39-N39) -> 2571.4 | P39: =IF(M39<$M$9,M39+N39,$M$9) -> 14040 | Q39: =IF(Q38<T38,0,Q38-S38) -> 2627885.1 | R39: =ROUND(Q39*$B39,2) -> 11825.48 | S39: =IF(Q39<T39,Q39,T39-R39) -> 2304.52 | T39: =IF(Q39<$M$15,Q39+R39,$M$15) -> 14130 | V39: 17 | W39: 0.91 | X39: 0.91 | AD39: ผ
A40: =VLOOKUP(D40,$A$7:$B$11,2) -> 0.054 | B40: =A40/12 -> 0.0045 | C40: =INT((D40+11)/12) -> 2 | D40: 18 | E40: =IF(E39<H39,0,E39-G39) -> 2488220.8 | F40: =ROUND(E40*$B40,2) -> 11196.99 | G40: =IF(E40<H40,E40,H40-F40) -> 6143.01 | H40: =IF(E40<$M$4,E40+F40,$M$4) -> 17340 | I40: =IF(I39<L39,0,I39-K39) -> 2608830.5 | J40: =ROUND(I40*$B40,2) -> 11739.74 | K40: =IF(I40<L40,I40,L40-J40) -> 5710.26 | L40: =IF(I40<$M$5,I40+J40,$M$5) -> 17450 | M40: =IF(M39<P39,0,M39-O39) -> 2546006.1 | N40: =ROUND(M40*$B40,2) -> 11457.03 | O40: =IF(M40<P40,M40,P40-N40) -> 2582.97 | P40: =IF(M40<$M$9,M40+N40,$M$9) -> 14040 | Q40: =IF(Q39<T39,0,Q39-S39) -> 2625580.6 | R40: =ROUND(Q40*$B40,2) -> 11815.11 | S40: =IF(Q40<T40,Q40,T40-R40) -> 2314.89 | T40: =IF(Q40<$M$15,Q40+R40,$M$15) -> 14130 | V40: 18 | W40: 0.9 | X40: 0.91
A41: =VLOOKUP(D41,$A$7:$B$11,2) -> 0.054 | B41: =A41/12 -> 0.0045 | C41: =INT((D41+11)/12) -> 2 | D41: 19 | E41: =IF(E40<H40,0,E40-G40) -> 2482077.8 | F41: =ROUND(E41*$B41,2) -> 11169.35 | G41: =IF(E41<H41,E41,H41-F41) -> 6170.65 | H41: =IF(E41<$M$4,E41+F41,$M$4) -> 17340 | I41: =IF(I40<L40,0,I40-K40) -> 2603120.2 | J41: =ROUND(I41*$B41,2) -> 11714.04 | K41: =IF(I41<L41,I41,L41-J41) -> 5735.96 | L41: =IF(I41<$M$5,I41+J41,$M$5) -> 17450 | M41: =IF(M40<P40,0,M40-O40) -> 2543423.2 | N41: =ROUND(M41*$B41,2) -> 11445.4 | O41: =IF(M41<P41,M41,P41-N41) -> 2594.6 | P41: =IF(M41<$M$9,M41+N41,$M$9) -> 14040 | Q41: =IF(Q40<T40,0,Q40-S40) -> 2623265.7 | R41: =ROUND(Q41*$B41,2) -> 11804.7 | S41: =IF(Q41<T41,Q41,T41-R41) -> 2325.3 | T41: =IF(Q41<$M$15,Q41+R41,$M$15) -> 14130 | V41: 19 | W41: 0.9 | X41: 0.9
A42: =VLOOKUP(D42,$A$7:$B$11,2) -> 0.054 | B42: =A42/12 -> 0.0045 | C42: =INT((D42+11)/12) -> 2 | D42: 20 | E42: =IF(E41<H41,0,E41-G41) -> 2475907.1 | F42: =ROUND(E42*$B42,2) -> 11141.58 | G42: =IF(E42<H42,E42,H42-F42) -> 6198.42 | H42: =IF(E42<$M$4,E42+F42,$M$4) -> 17340 | I42: =IF(I41<L41,0,I41-K41) -> 2597384.3 | J42: =ROUND(I42*$B42,2) -> 11688.23 | K42: =IF(I42<L42,I42,L42-J42) -> 5761.77 | L42: =IF(I42<$M$5,I42+J42,$M$5) -> 17450 | M42: =IF(M41<P41,0,M41-O41) -> 2540828.6 | N42: =ROUND(M42*$B42,2) -> 11433.73 | O42: =IF(M42<P42,M42,P42-N42) -> 2606.27 | P42: =IF(M42<$M$9,M42+N42,$M$9) -> 14040 | Q42: =IF(Q41<T41,0,Q41-S41) -> 2620940.4 | R42: =ROUND(Q42*$B42,2) -> 11794.23 | S42: =IF(Q42<T42,Q42,T42-R42) -> 2335.77 | T42: =IF(Q42<$M$15,Q42+R42,$M$15) -> 14130 | V42: 20 | W42: 0.9 | X42: 0.9
A43: =VLOOKUP(D43,$A$7:$B$11,2) -> 0.054 | B43: =A43/12 -> 0.0045 | C43: =INT((D43+11)/12) -> 2 | D43: 21 | E43: =IF(E42<H42,0,E42-G42) -> 2469708.7 | F43: =ROUND(E43*$B43,2) -> 11113.69 | G43: =IF(E43<H43,E43,H43-F43) -> 6226.31 | H43: =IF(E43<$M$4,E43+F43,$M$4) -> 17340 | I43: =IF(I42<L42,0,I42-K42) -> 2591622.5 | J43: =ROUND(I43*$B43,2) -> 11662.3 | K43: =IF(I43<L43,I43,L43-J43) -> 5787.7 | L43: =IF(I43<$M$5,I43+J43,$M$5) -> 17450 | M43: =IF(M42<P42,0,M42-O42) -> 2538222.3 | N43: =ROUND(M43*$B43,2) -> 11422 | O43: =IF(M43<P43,M43,P43-N43) -> 2618 | P43: =IF(M43<$M$9,M43+N43,$M$9) -> 14040 | Q43: =IF(Q42<T42,0,Q42-S42) -> 2618604.6 | R43: =ROUND(Q43*$B43,2) -> 11783.72 | S43: =IF(Q43<T43,Q43,T43-R43) -> 2346.28 | T43: =IF(Q43<$M$15,Q43+R43,$M$15) -> 14130 | V43: 21 | W43: 0.9 | X43: 0.9
...

Sheet Sheet2
A1: สินเชื่อ | B1: ภาระหนี้คงเหลือ | C1: ยอดผ่อน | D1: ration
B2: 204000 | C2: 7480 | D2: =C2/B2 -> 0.036666667
B3: 50000 | C3: =B3/10 -> 5000 | D3: =C3/B3 -> 0.1
B4: 2600000 | C4: 19000 | D4: =C4/B4 -> 0.0073076923
B6: 250000 | C6: =B6*5% -> 12500
B7: 50000 | C7: 5000
B8: 30000 | C8: 3000
A9: 100000 | B9: 30000 | C9: 3000
C10: =SUM(C6:C9) -> 23500

Sheet NCB
A1: DIR | B1: 0.751 | C1: ใส่เป็นเปอร์เซ็น | E1: กู้หลัก | G1: กู้ร่วม
A2: รายได้รวมที่คีย์เข้าไปในระบบ | B2: 46500 | C2: บาท | E2: 8000 | G2: 15000 | J2: 36000
A3: งวดผ่อนต่อเดือนกับ CIMB | B3: 18820 | C3: บาท | E3: 13000 | G3: 10000
A4: ภาระใน NCB | B4: =(B1*B2)-B3 -> 16101.5 | E4: 500
E5: =SUM(E2:E4) -> 21500 | G5: =SUM(G2:G4) -> 25000
C6: รวม | D6: =E5+G5 -> 46500
E8: 6000
D9: 18820

Sheet eBMortgageLoan - Table 1
D1: ="ตารางคำนวณ "&'Secured - Table 1'!$F$33 -> ตารางคำนวณ เงินกู้ปกติ , MRTA
G3: วงเงินกู้ (บาท) | H3: ค่าธรรมเนียม (บาท) | I3: เวลา (เดือน) | J3: อัตราดอกเบี้ย (%) | K3: เงินงวด (บาท) | L3: ผ่อนแบบ ขั้นบันได | M3: เงินงวด (บาท) เผื่อดอกเบี้ย 1% | N3: งวดชำระจริง (งวด) | O3: ยอดชำระรวม (บาท) | P3: ดอกเบี้ยชำระ 3 ปีแรก (บาท)
D4: 1. แบบคงที่ | G4: ='Secured - Table 1'!$F$34 -> 0 | I4: ='Secured - Table 1'!$F$35*12 -> 312 | J4: =($J$7*$C$7+$J$8*$C$8+$J$9*$C$9+$J$10*$C$10+$J$11*('Secured - Table 1'!$F$35*12-SUM($C$7:$C$10)))/('Secured - Table 1'!$F$35*12) -> 0.071403846 | K4: =IF(OR($G$7=0,$I$8=0),0,PMT($J4/12,$I4,-$G4)) -> 0 | M4: =IF(OR($G$7=0,$I$8=0),0,ROUNDUP(PMT(($J4+1%)/12,$I4,-$G4),-1)) -> 0 | N4: =IF(OR($G$7=0,$I$8=0),0,370-COUNTIF(G23:G392,0)) -> 0 | O4: =SUM(H23:H392) -> 0 | P4: =IF(OR($G$7=0,$I$8=0),0,SUM(F23:F58)) -> 0
D5: 2. แบบคงที่ มี Grace Period | G5: ='Secured - Table 1'!$F$34 -> 0 | I5: =I4-12 -> 300 | J5: =($J$7*$C$7+$J$8*$C$8+$J$9*$C$9+$J$10*$C$10+$J$11*('Secured - Table 1'!$F$35*12-SUM($C$7:$C$10)))/('Secured - Table 1'!$F$35*12) -> 0.071403846 | K5: =IF(OR($G$7=0,$I$8=0),0,PMT($J5/12,$I5,-$G5)) -> 0 | M5: =IF(OR($G$7=0,$I$8=0),0,ROUNDUP(PMT(($J5+1%)/12,$I5,-$G5),-1)) -> 0 | N5: =IF(OR($G$7=0,$I$8=0),0,370-COUNTIF(K35:K392,0)) -> 0 | O5: =SUM(L23:L392) -> 0 | P5: =IF(OR($G$7=0,$I$8=0),0,SUM(J23:J58)) -> 0
D6: 3. แบบขั้นบันได
A7: 0 | B7: =J7 -> 0.069 | C7: =VLOOKUP('Secured - Table 1'!$F$33,'Secured - Table 1'!$L$104:$AW$108,'Secured - Table 1'!M$76,FALSE) -> 12 | E7: ='Secured - Table 1'!E37 -> 420 | F7: ='Secured - Table 1'!F37 -> MRR-2.00% | G7: ='Secured - Table 1'!$F$34 -> 0 | I7: ='Secured - Table 1'!$F$35*12 -> 312 | J7: ='Secured - Table 1'!H37 -> 0.069 | K7: =IF(OR($G$7=0,$I$8=0),0,PMT($J7/12,$I7,-$G7)) -> 0
A8: =SUM(C$7:C7)+1 -> 13 | B8: =J8 -> 0.079 | C8: =VLOOKUP('Secured - Table 1'!$F$33,'Secured - Table 1'!$L$104:$AW$108,'Secured - Table 1'!N$76,FALSE) -> 0 | E8: ='Secured - Table 1'!E38 -> ปีที่ 1 | F8: ='Secured - Table 1'!F38 -> MLR-1.25% | G8: =VLOOKUP(A8,$D$22:$T$392,10,FALSE) -> 0 | I8: =I7-C7 -> 300 | J8: ='Secured - Table 1'!H38 -> 0.079 | K8: =IF(OR($G$7=0,$I$8=0),0,PMT($J8/12,$I8,-$G8)) -> 0 | Q8: =$V$20 -> % ปรับปรุงค่างวดแบบขั้นบันได | R8: % ค่างวดเพิ่ม | S8: ค่างวดเพิ่ม
A9: =SUM(C$7:C8)+1 -> 13 | B9: =J9 -> 0.079 | C9: =VLOOKUP('Secured - Table 1'!$F$33,'Secured - Table 1'!$L$104:$AW$108,'Secured - Table 1'!O$76,FALSE) -> 0 | E9: ='Secured - Table 1'!E39 | F9: ='Secured - Table 1'!F39 -> -1 | G9: =VLOOKUP(A9,$D$22:$T$392,10,FALSE) -> 0 | I9: =I8-C8 -> 300 | J9: ='Secured - Table 1'!H39 -> 0.079 | K9: =IF(OR($G$7=0,$I$8=0),0,PMT($J9/12,$I9,-$G9)) -> 0 | L9: ปีที่ 1 และ 2 | M9: =ROUNDUP($M10/$Q9,-1) -> 0 | Q9: 1.1
A10: =SUM(C$7:C9)+1 -> 13 | B10: =J10 -> 0.079 | C10: =VLOOKUP('Secured - Table 1'!$F$33,'Secured - Table 1'!$L$104:$AW$108,'Secured - Table 1'!P$76,FALSE) -> 0 | E10: ='Secured - Table 1'!E40 | F10: ='Secured - Table 1'!F40 -> -1 | G10: =VLOOKUP(A10,$D$22:$T$392,10,FALSE) -> 0 | I10: =I9-C9 -> 300 | J10: ='Secured - Table 1'!H40 -> 0.079 | K10: =IF(OR($G$7=0,$I$8=0),0,PMT($J10/12,$I10,-$G10)) -> 0 | L10: ปีที่ 3 และ 4 | M10: =ROUNDUP($M$4*$Q10,-1) -> 0 | Q10: =IF(OR($G$7=0,$I$8=0),0,VLOOKUP($I$8/12,$V$22:$X$52,2)) -> 0 | R10: =IF(M9=0,0,M10/M9) -> 0 | S10: =M10-M9 -> 0
A11: =SUM(C$7:C10)+1 -> 13 | B11: =J11 -> 0.0715 | E11: ='Secured - Table 1'!E41 | F11: ='Secured - Table 1'!F41 -> MRR-0.75% | G11: =VLOOKUP(A11,$D$22:$T$392,10,FALSE) -> 0 | I11: =I10-C10 -> 300 | J11: ='Secured - Table 1'!H41 -> 0.0715 | K11: =IF(OR($G$7=0,$I$8=0),0,PMT($J11/12,$I11,-$G11)) -> 0 | L11: ปีที่ 5 เป็นต้นไป | M11: =IF(OR($G$7=0,$I$8=0),0,ROUNDUP(PMT($J$11/12,$N$4-48,-$M$71),-1)) -> 0 | N11: =IF(OR($G$7=0,$I$8=0),0,370-COUNTIF(O23:O392,0)) -> 0 | O11: =SUM(P23:P392) -> 0 | P11: =IF(OR($G$7=0,$I$8=0),0,SUM(N23:N58)) -> 0 | R11: =IF(M10=0,0,M11/M10) -> 0 | S11: =M11-M10 -> 0
D12: 4. แบบขั้นบันได มี Grace Period
A13: =A7 -> 0 | B13: =B7 -> 0.069 | C13: =C7 -> 12 | E13: =E7 -> 420 | F13: =F7 -> MRR-2.00% | G13: ='Secured - Table 1'!$F$34 -> 0 | I13: ='Secured - Table 1'!$F$35*12 -> 312 | J13: =J7 -> 0.069 | K13: =IF(OR($G$7=0,$I$8=0),0,$G13*IF($C$13<12,$J$14,$J13)*31/365) -> 0
A14: =A8 -> 13 | B14: =B8 -> 0.079 | C14: =C8 -> 0 | E14: =E8 -> ปีที่ 1 | F14: =F8 -> MLR-1.25% | G14: =VLOOKUP(A14,$D$22:$T$392,14,FALSE) -> 0 | I14: =I8 -> 300 | J14: =J8 -> 0.079 | K14: =IF(OR($G$7=0,$I$8=0),0,IF($C$13<12,K13,PMT($J14/12,$I14,-$G14))) -> 0 | L14: ปีที่ 1 | M14: =ROUNDUP($K13,-1) -> 0 | Q14: =$V$20 -> % ปรับปรุงค่างวดแบบขั้นบันได | R14: % ค่างวดเพิ่ม | S14: ค่างวดเพิ่ม
A15: =A9 -> 13 | B15: =B9 -> 0.079 | C15: =C9 -> 0 | E15: =E9 | F15: =F9 -> -1 | G15: =VLOOKUP(A15,$D$22:$T$392,14,FALSE) -> 0 | I15: =I9 -> 300 | J15: =J9 -> 0.079 | K15: =IF(OR($G$7=0,$I$8=0),0,PMT($J15/12,$I15,-$G15)) -> 0 | L15: ปีที่ 2 และ 3 | M15: =ROUNDUP($M16/$Q15,-1) -> 0 | Q15: 1.1
A16: =A10 -> 13 | B16: =B10 -> 0.079 | C16: =C10 -> 0 | E16: =E10 | F16: =F10 -> -1 | G16: =VLOOKUP(A16,$D$22:$T$392,14,FALSE) -> 0 | I16: =I10 -> 300 | J16: =J10 -> 0.079 | K16: =IF(OR($G$7=0,$I$8=0),0,PMT($J16/12,$I16,-$G16)) -> 0 | L16: ปีที่ 4 และ 5 | M16: =ROUNDUP($M$5*$Q16,-1) -> 0 | Q16: =IF(OR($G$7=0,$I$8=0),0,VLOOKUP($I$8/12,$V$22:$X$52,3)) -> 0 | R16: =IF(M15=0,0,M16/M15) -> 0 | S16: =M16-M15 -> 0
A17: =A11 -> 13 | B17: =B11 -> 0.0715 | E17: =E11 | F17: =F11 -> MRR-0.75% | G17: =VLOOKUP(A17,$D$22:$T$392,14,FALSE) -> 0 | I17: =I11 -> 300 | J17: =J11 -> 0.0715 | K17: =IF(OR($G$7=0,$I$8=0),0,PMT($J17/12,$I17,-$G17)) -> 0 | L17: ปีที่ 6 เป็นต้นไป | M17: =IF(OR($G$7=0,$I$8=0),0,ROUNDUP(PMT($J17/12,$N$5-60,-$Q$83),-1)) -> 0 | N17: =IF(OR($G$7=0,$I$8=0),0,370-COUNTIF(S23:S392,0)) -> 0 | O17: =SUM(T23:T392) -> 0 | P17: =IF(OR($G$7=0,$I$8=0),0,SUM(R23:R58)) -> 0 | R17: =IF(M16=0,0,M17/M16) -> 0 | S17: =M17-M16 -> 0
E20: =D4 -> 1. แบบคงที่ | I20: =D5 -> 2. แบบคงที่ มี Grace Period | M20: =D6 -> 3. แบบขั้นบันได | Q20: =D12 -> 4. แบบขั้นบันได มี Grace Period | V20: % ปรับปรุงค่างวดแบบขั้นบันได
A21: Annual rate | B21: Monthly rate | C21: ปี | D21: งวด | E21: เงินต้นคงเหลือ | F21: ดอกเบี้ยผ่อนชำระ | G21: เงินต้นผ่อนชำระ | H21: เงินงวด | I21: เงินต้นคงเหลือ | J21: ดอกเบี้ยผ่อนชำระ | K21: เงินต้นผ่อนชำระ | L21: เงินงวด | M21: เงินต้นคงเหลือ | N21: ดอกเบี้ยผ่อนชำระ | O21: เงินต้นผ่อนชำระ | P21: เงินงวด | Q21: เงินต้นคงเหลือ | R21: ดอกเบี้ยผ่อนชำระ | S21: เงินต้นผ่อนชำระ | T21: เงินงวด | V21: ระยะเวลา (ปี) | W21: ไม่มี Grace Period | X21: มี Grace Period
C22: 0 | D22: 0 | H22: =-$G$7 -> 0 | L22: =-$G$7 -> 0 | P22: =-$G$7 -> 0 | T22: =-$G$7 -> 0 | V22: 0 | W22: 1 | X22: 1.03
A23: =VLOOKUP(D23,$A$7:$B$11,2) -> 0.069 | B23: =A23/12 -> 0.00575 | C23: =INT((D23+11)/12) -> 1 | D23: 1 | E23: =$G$7 -> 0 | F23: =ROUND(E23*$B23,2) -> 0 | G23: =IF(E23<H23,E23,H23-F23) -> 0 | H23: =IF(E23<$M$4,E23+F23,$M$4) -> 0 | I23: =$G$7 -> 0 | J23: =ROUND(I23*$B23,2) -> 0 | K23: =IF(I23<L23,I23,L23-J23) -> 0 | L23: =IF(I23<$M$14,I23+J23,$M$14) -> 0 | M23: =$G$7 -> 0 | N23: =ROUND(M23*$B23,2) -> 0 | O23: =IF(M23<P23,M23,P23-N23) -> 0 | P23: =IF(M23<$M$9,M23+N23,$M$9) -> 0 | Q23: =$G$7 -> 0 | R23: =ROUND(Q23*$B23,2) -> 0 | S23: =IF(Q23<T23,Q23,T23-R23) -> 0 | T23: =IF(Q23<$M$14,Q23+R23,$M$14) -> 0 | V23: 1 | W23: 1 | X23: 1.03
A24: =VLOOKUP(D24,$A$7:$B$11,2) -> 0.069 | B24: =A24/12 -> 0.00575 | C24: =INT((D24+11)/12) -> 1 | D24: 2 | E24: =IF(E23<H23,0,E23-G23) -> 0 | F24: =ROUND(E24*$B24,2) -> 0 | G24: =IF(E24<H24,E24,H24-F24) -> 0 | H24: =IF(E24<$M$4,E24+F24,$M$4) -> 0 | I24: =IF(I23<L23,0,I23-K23) -> 0 | J24: =ROUND(I24*$B24,2) -> 0 | K24: =IF(I24<L24,I24,L24-J24) -> 0 | L24: =IF(I24<$M$14,I24+J24,$M$14) -> 0 | M24: =IF(M23<P23,0,M23-O23) -> 0 | N24: =ROUND(M24*$B24,2) -> 0 | O24: =IF(M24<P24,M24,P24-N24) -> 0 | P24: =IF(M24<$M$9,M24+N24,$M$9) -> 0 | Q24: =IF(Q23<T23,0,Q23-S23) -> 0 | R24: =ROUND(Q24*$B24,2) -> 0 | S24: =IF(Q24<T24,Q24,T24-R24) -> 0 | T24: =IF(Q24<$M$14,Q24+R24,$M$14) -> 0 | V24: 2 | W24: 1 | X24: 1.03
A25: =VLOOKUP(D25,$A$7:$B$11,2) -> 0.069 | B25: =A25/12 -> 0.00575 | C25: =INT((D25+11)/12) -> 1 | D25: 3 | E25: =IF(E24<H24,0,E24-G24) -> 0 | F25: =ROUND(E25*$B25,2) -> 0 | G25: =IF(E25<H25,E25,H25-F25) -> 0 | H25: =IF(E25<$M$4,E25+F25,$M$4) -> 0 | I25: =IF(I24<L24,0,I24-K24) -> 0 | J25: =ROUND(I25*$B25,2) -> 0 | K25: =IF(I25<L25,I25,L25-J25) -> 0 | L25: =IF(I25<$M$14,I25+J25,$M$14) -> 0 | M25: =IF(M24<P24,0,M24-O24) -> 0 | N25: =ROUND(M25*$B25,2) -> 0 | O25: =IF(M25<P25,M25,P25-N25) -> 0 | P25: =IF(M25<$M$9,M25+N25,$M$9) -> 0 | Q25: =IF(Q24<T24,0,Q24-S24) -> 0 | R25: =ROUND(Q25*$B25,2) -> 0 | S25: =IF(Q25<T25,Q25,T25-R25) -> 0 | T25: =IF(Q25<$M$14,Q25+R25,$M$14) -> 0 | V25: 3 | W25: 1 | X25: 1.03
A26: =VLOOKUP(D26,$A$7:$B$11,2) -> 0.069 | B26: =A26/12 -> 0.00575 | C26: =INT((D26+11)/12) -> 1 | D26: 4 | E26: =IF(E25<H25,0,E25-G25) -> 0 | F26: =ROUND(E26*$B26,2) -> 0 | G26: =IF(E26<H26,E26,H26-F26) -> 0 | H26: =IF(E26<$M$4,E26+F26,$M$4) -> 0 | I26: =IF(I25<L25,0,I25-K25) -> 0 | J26: =ROUND(I26*$B26,2) -> 0 | K26: =IF(I26<L26,I26,L26-J26) -> 0 | L26: =IF(I26<$M$14,I26+J26,$M$14) -> 0 | M26: =IF(M25<P25,0,M25-O25) -> 0 | N26: =ROUND(M26*$B26,2) -> 0 | O26: =IF(M26<P26,M26,P26-N26) -> 0 | P26: =IF(M26<$M$9,M26+N26,$M$9) -> 0 | Q26: =IF(Q25<T25,0,Q25-S25) -> 0 | R26: =ROUND(Q26*$B26,2) -> 0 | S26: =IF(Q26<T26,Q26,T26-R26) -> 0 | T26: =IF(Q26<$M$14,Q26+R26,$M$14) -> 0 | V26: 4 | W26: 1 | X26: 1.03
A27: =VLOOKUP(D27,$A$7:$B$11,2) -> 0.069 | B27: =A27/12 -> 0.00575 | C27: =INT((D27+11)/12) -> 1 | D27: 5 | E27: =IF(E26<H26,0,E26-G26) -> 0 | F27: =ROUND(E27*$B27,2) -> 0 | G27: =IF(E27<H27,E27,H27-F27) -> 0 | H27: =IF(E27<$M$4,E27+F27,$M$4) -> 0 | I27: =IF(I26<L26,0,I26-K26) -> 0 | J27: =ROUND(I27*$B27,2) -> 0 | K27: =IF(I27<L27,I27,L27-J27) -> 0 | L27: =IF(I27<$M$14,I27+J27,$M$14) -> 0 | M27: =IF(M26<P26,0,M26-O26) -> 0 | N27: =ROUND(M27*$B27,2) -> 0 | O27: =IF(M27<P27,M27,P27-N27) -> 0 | P27: =IF(M27<$M$9,M27+N27,$M$9) -> 0 | Q27: =IF(Q26<T26,0,Q26-S26) -> 0 | R27: =ROUND(Q27*$B27,2) -> 0 | S27: =IF(Q27<T27,Q27,T27-R27) -> 0 | T27: =IF(Q27<$M$14,Q27+R27,$M$14) -> 0 | V27: 5 | W27: 1 | X27: 1.03
A28: =VLOOKUP(D28,$A$7:$B$11,2) -> 0.069 | B28: =A28/12 -> 0.00575 | C28: =INT((D28+11)/12) -> 1 | D28: 6 | E28: =IF(E27<H27,0,E27-G27) -> 0 | F28: =ROUND(E28*$B28,2) -> 0 | G28: =IF(E28<H28,E28,H28-F28) -> 0 | H28: =IF(E28<$M$4,E28+F28,$M$4) -> 0 | I28: =IF(I27<L27,0,I27-K27) -> 0 | J28: =ROUND(I28*$B28,2) -> 0 | K28: =IF(I28<L28,I28,L28-J28) -> 0 | L28: =IF(I28<$M$14,I28+J28,$M$14) -> 0 | M28: =IF(M27<P27,0,M27-O27) -> 0 | N28: =ROUND(M28*$B28,2) -> 0 | O28: =IF(M28<P28,M28,P28-N28) -> 0 | P28: =IF(M28<$M$9,M28+N28,$M$9) -> 0 | Q28: =IF(Q27<T27,0,Q27-S27) -> 0 | R28: =ROUND(Q28*$B28,2) -> 0 | S28: =IF(Q28<T28,Q28,T28-R28) -> 0 | T28: =IF(Q28<$M$14,Q28+R28,$M$14) -> 0 | V28: 6 | W28: 1 | X28: 1.03
A29: =VLOOKUP(D29,$A$7:$B$11,2) -> 0.069 | B29: =A29/12 -> 0.00575 | C29: =INT((D29+11)/12) -> 1 | D29: 7 | E29: =IF(E28<H28,0,E28-G28) -> 0 | F29: =ROUND(E29*$B29,2) -> 0 | G29: =IF(E29<H29,E29,H29-F29) -> 0 | H29: =IF(E29<$M$4,E29+F29,$M$4) -> 0 | I29: =IF(I28<L28,0,I28-K28) -> 0 | J29: =ROUND(I29*$B29,2) -> 0 | K29: =IF(I29<L29,I29,L29-J29) -> 0 | L29: =IF(I29<$M$14,I29+J29,$M$14) -> 0 | M29: =IF(M28<P28,0,M28-O28) -> 0 | N29: =ROUND(M29*$B29,2) -> 0 | O29: =IF(M29<P29,M29,P29-N29) -> 0 | P29: =IF(M29<$M$9,M29+N29,$M$9) -> 0 | Q29: =IF(Q28<T28,0,Q28-S28) -> 0 | R29: =ROUND(Q29*$B29,2) -> 0 | S29: =IF(Q29<T29,Q29,T29-R29) -> 0 | T29: =IF(Q29<$M$14,Q29+R29,$M$14) -> 0 | V29: 7 | W29: 0.98 | X29: 1
A30: =VLOOKUP(D30,$A$7:$B$11,2) -> 0.069 | B30: =A30/12 -> 0.00575 | C30: =INT((D30+11)/12) -> 1 | D30: 8 | E30: =IF(E29<H29,0,E29-G29) -> 0 | F30: =ROUND(E30*$B30,2) -> 0 | G30: =IF(E30<H30,E30,H30-F30) -> 0 | H30: =IF(E30<$M$4,E30+F30,$M$4) -> 0 | I30: =IF(I29<L29,0,I29-K29) -> 0 | J30: =ROUND(I30*$B30,2) -> 0 | K30: =IF(I30<L30,I30,L30-J30) -> 0 | L30: =IF(I30<$M$14,I30+J30,$M$14) -> 0 | M30: =IF(M29<P29,0,M29-O29) -> 0 | N30: =ROUND(M30*$B30,2) -> 0 | O30: =IF(M30<P30,M30,P30-N30) -> 0 | P30: =IF(M30<$M$9,M30+N30,$M$9) -> 0 | Q30: =IF(Q29<T29,0,Q29-S29) -> 0 | R30: =ROUND(Q30*$B30,2) -> 0 | S30: =IF(Q30<T30,Q30,T30-R30) -> 0 | T30: =IF(Q30<$M$14,Q30+R30,$M$14) -> 0 | V30: 8 | W30: 0.96 | X30: 0.98
A31: =VLOOKUP(D31,$A$7:$B$11,2) -> 0.069 | B31: =A31/12 -> 0.00575 | C31: =INT((D31+11)/12) -> 1 | D31: 9 | E31: =IF(E30<H30,0,E30-G30) -> 0 | F31: =ROUND(E31*$B31,2) -> 0 | G31: =IF(E31<H31,E31,H31-F31) -> 0 | H31: =IF(E31<$M$4,E31+F31,$M$4) -> 0 | I31: =IF(I30<L30,0,I30-K30) -> 0 | J31: =ROUND(I31*$B31,2) -> 0 | K31: =IF(I31<L31,I31,L31-J31) -> 0 | L31: =IF(I31<$M$14,I31+J31,$M$14) -> 0 | M31: =IF(M30<P30,0,M30-O30) -> 0 | N31: =ROUND(M31*$B31,2) -> 0 | O31: =IF(M31<P31,M31,P31-N31) -> 0 | P31: =IF(M31<$M$9,M31+N31,$M$9) -> 0 | Q31: =IF(Q30<T30,0,Q30-S30) -> 0 | R31: =ROUND(Q31*$B31,2) -> 0 | S31: =IF(Q31<T31,Q31,T31-R31) -> 0 | T31: =IF(Q31<$M$14,Q31+R31,$M$14) -> 0 | V31: 9 | W31: 0.95 | X31: 0.96
A32: =VLOOKUP(D32,$A$7:$B$11,2) -> 0.069 | B32: =A32/12 -> 0.00575 | C32: =INT((D32+11)/12) -> 1 | D32: 10 | E32: =IF(E31<H31,0,E31-G31) -> 0 | F32: =ROUND(E32*$B32,2) -> 0 | G32: =IF(E32<H32,E32,H32-F32) -> 0 | H32: =IF(E32<$M$4,E32+F32,$M$4) -> 0 | I32: =IF(I31<L31,0,I31-K31) -> 0 | J32: =ROUND(I32*$B32,2) -> 0 | K32: =IF(I32<L32,I32,L32-J32) -> 0 | L32: =IF(I32<$M$14,I32+J32,$M$14) -> 0 | M32: =IF(M31<P31,0,M31-O31) -> 0 | N32: =ROUND(M32*$B32,2) -> 0 | O32: =IF(M32<P32,M32,P32-N32) -> 0 | P32: =IF(M32<$M$9,M32+N32,$M$9) -> 0 | Q32: =IF(Q31<T31,0,Q31-S31) -> 0 | R32: =ROUND(Q32*$B32,2) -> 0 | S32: =IF(Q32<T32,Q32,T32-R32) -> 0 | T32: =IF(Q32<$M$14,Q32+R32,$M$14) -> 0 | V32: 10 | W32: 0.94 | X32: 0.95
A33: =VLOOKUP(D33,$A$7:$B$11,2) -> 0.069 | B33: =A33/12 -> 0.00575 | C33: =INT((D33+11)/12) -> 1 | D33: 11 | E33: =IF(E32<H32,0,E32-G32) -> 0 | F33: =ROUND(E33*$B33,2) -> 0 | G33: =IF(E33<H33,E33,H33-F33) -> 0 | H33: =IF(E33<$M$4,E33+F33,$M$4) -> 0 | I33: =IF(I32<L32,0,I32-K32) -> 0 | J33: =ROUND(I33*$B33,2) -> 0 | K33: =IF(I33<L33,I33,L33-J33) -> 0 | L33: =IF(I33<$M$14,I33+J33,$M$14) -> 0 | M33: =IF(M32<P32,0,M32-O32) -> 0 | N33: =ROUND(M33*$B33,2) -> 0 | O33: =IF(M33<P33,M33,P33-N33) -> 0 | P33: =IF(M33<$M$9,M33+N33,$M$9) -> 0 | Q33: =IF(Q32<T32,0,Q32-S32) -> 0 | R33: =ROUND(Q33*$B33,2) -> 0 | S33: =IF(Q33<T33,Q33,T33-R33) -> 0 | T33: =IF(Q33<$M$14,Q33+R33,$M$14) -> 0 | V33: 11 | W33: 0.93 | X33: 0.94
A34: =VLOOKUP(D34,$A$7:$B$11,2) -> 0.069 | B34: =A34/12 -> 0.00575 | C34: =INT((D34+11)/12) -> 1 | D34: 12 | E34: =IF(E33<H33,0,E33-G33) -> 0 | F34: =ROUND(E34*$B34,2) -> 0 | G34: =IF(E34<H34,E34,H34-F34) -> 0 | H34: =IF(E34<$M$4,E34+F34,$M$4) -> 0 | I34: =IF(I33<L33,0,I33-K33) -> 0 | J34: =ROUND(I34*$B34,2) -> 0 | K34: =IF(I34<L34,I34,L34-J34) -> 0 | L34: =IF(I34<$M$14,I34+J34,$M$14) -> 0 | M34: =IF(M33<P33,0,M33-O33) -> 0 | N34: =ROUND(M34*$B34,2) -> 0 | O34: =IF(M34<P34,M34,P34-N34) -> 0 | P34: =IF(M34<$M$9,M34+N34,$M$9) -> 0 | Q34: =IF(Q33<T33,0,Q33-S33) -> 0 | R34: =ROUND(Q34*$B34,2) -> 0 | S34: =IF(Q34<T34,Q34,T34-R34) -> 0 | T34: =IF(Q34<$M$14,Q34+R34,$M$14) -> 0 | V34: 12 | W34: 0.93 | X34: 0.93
A35: =VLOOKUP(D35,$A$7:$B$11,2) -> 0.0715 | B35: =A35/12 -> 0.0059583333 | C35: =INT((D35+11)/12) -> 2 | D35: 13 | E35: =IF(E34<H34,0,E34-G34) -> 0 | F35: =ROUND(E35*$B35,2) -> 0 | G35: =IF(E35<H35,E35,H35-F35) -> 0 | H35: =IF(E35<$M$4,E35+F35,$M$4) -> 0 | I35: =IF(I34<L34,0,I34-K34) -> 0 | J35: =ROUND(I35*$B35,2) -> 0 | K35: =IF(I35<L35,I35,L35-J35) -> 0 | L35: =IF(I35<$M$5,I35+J35,$M$5) -> 0 | M35: =IF(M34<P34,0,M34-O34) -> 0 | N35: =ROUND(M35*$B35,2) -> 0 | O35: =IF(M35<P35,M35,P35-N35) -> 0 | P35: =IF(M35<$M$9,M35+N35,$M$9) -> 0 | Q35: =IF(Q34<T34,0,Q34-S34) -> 0 | R35: =ROUND(Q35*$B35,2) -> 0 | S35: =IF(Q35<T35,Q35,T35-R35) -> 0 | T35: =IF(Q35<$M$15,Q35+R35,$M$15) -> 0 | V35: 13 | W35: 0.92 | X35: 0.93
A36: =VLOOKUP(D36,$A$7:$B$11,2) -> 0.0715 | B36: =A36/12 -> 0.0059583333 | C36: =INT((D36+11)/12) -> 2 | D36: 14 | E36: =IF(E35<H35,0,E35-G35) -> 0 | F36: =ROUND(E36*$B36,2) -> 0 | G36: =IF(E36<H36,E36,H36-F36) -> 0 | H36: =IF(E36<$M$4,E36+F36,$M$4) -> 0 | I36: =IF(I35<L35,0,I35-K35) -> 0 | J36: =ROUND(I36*$B36,2) -> 0 | K36: =IF(I36<L36,I36,L36-J36) -> 0 | L36: =IF(I36<$M$5,I36+J36,$M$5) -> 0 | M36: =IF(M35<P35,0,M35-O35) -> 0 | N36: =ROUND(M36*$B36,2) -> 0 | O36: =IF(M36<P36,M36,P36-N36) -> 0 | P36: =IF(M36<$M$9,M36+N36,$M$9) -> 0 | Q36: =IF(Q35<T35,0,Q35-S35) -> 0 | R36: =ROUND(Q36*$B36,2) -> 0 | S36: =IF(Q36<T36,Q36,T36-R36) -> 0 | T36: =IF(Q36<$M$15,Q36+R36,$M$15) -> 0 | V36: 14 | W36: 0.92 | X36: 0.92
A37: =VLOOKUP(D37,$A$7:$B$11,2) -> 0.0715 | B37: =A37/12 -> 0.0059583333 | C37: =INT((D37+11)/12) -> 2 | D37: 15 | E37: =IF(E36<H36,0,E36-G36) -> 0 | F37: =ROUND(E37*$B37,2) -> 0 | G37: =IF(E37<H37,E37,H37-F37) -> 0 | H37: =IF(E37<$M$4,E37+F37,$M$4) -> 0 | I37: =IF(I36<L36,0,I36-K36) -> 0 | J37: =ROUND(I37*$B37,2) -> 0 | K37: =IF(I37<L37,I37,L37-J37) -> 0 | L37: =IF(I37<$M$5,I37+J37,$M$5) -> 0 | M37: =IF(M36<P36,0,M36-O36) -> 0 | N37: =ROUND(M37*$B37,2) -> 0 | O37: =IF(M37<P37,M37,P37-N37) -> 0 | P37: =IF(M37<$M$9,M37+N37,$M$9) -> 0 | Q37: =IF(Q36<T36,0,Q36-S36) -> 0 | R37: =ROUND(Q37*$B37,2) -> 0 | S37: =IF(Q37<T37,Q37,T37-R37) -> 0 | T37: =IF(Q37<$M$15,Q37+R37,$M$15) -> 0 | V37: 15 | W37: 0.91 | X37: 0.92
A38: =VLOOKUP(D38,$A$7:$B$11,2) -> 0.0715 | B38: =A38/12 -> 0.0059583333 | C38: =INT((D38+11)/12) -> 2 | D38: 16 | E38: =IF(E37<H37,0,E37-G37) -> 0 | F38: =ROUND(E38*$B38,2) -> 0 | G38: =IF(E38<H38,E38,H38-F38) -> 0 | H38: =IF(E38<$M$4,E38+F38,$M$4) -> 0 | I38: =IF(I37<L37,0,I37-K37) -> 0 | J38: =ROUND(I38*$B38,2) -> 0 | K38: =IF(I38<L38,I38,L38-J38) -> 0 | L38: =IF(I38<$M$5,I38+J38,$M$5) -> 0 | M38: =IF(M37<P37,0,M37-O37) -> 0 | N38: =ROUND(M38*$B38,2) -> 0 | O38: =IF(M38<P38,M38,P38-N38) -> 0 | P38: =IF(M38<$M$9,M38+N38,$M$9) -> 0 | Q38: =IF(Q37<T37,0,Q37-S37) -> 0 | R38: =ROUND(Q38*$B38,2) -> 0 | S38: =IF(Q38<T38,Q38,T38-R38) -> 0 | T38: =IF(Q38<$M$15,Q38+R38,$M$15) -> 0 | V38: 16 | W38: 0.91 | X38: 0.91
A39: =VLOOKUP(D39,$A$7:$B$11,2) -> 0.0715 | B39: =A39/12 -> 0.0059583333 | C39: =INT((D39+11)/12) -> 2 | D39: 17 | E39: =IF(E38<H38,0,E38-G38) -> 0 | F39: =ROUND(E39*$B39,2) -> 0 | G39: =IF(E39<H39,E39,H39-F39) -> 0 | H39: =IF(E39<$M$4,E39+F39,$M$4) -> 0 | I39: =IF(I38<L38,0,I38-K38) -> 0 | J39: =ROUND(I39*$B39,2) -> 0 | K39: =IF(I39<L39,I39,L39-J39) -> 0 | L39: =IF(I39<$M$5,I39+J39,$M$5) -> 0 | M39: =IF(M38<P38,0,M38-O38) -> 0 | N39: =ROUND(M39*$B39,2) -> 0 | O39: =IF(M39<P39,M39,P39-N39) -> 0 | P39: =IF(M39<$M$9,M39+N39,$M$9) -> 0 | Q39: =IF(Q38<T38,0,Q38-S38) -> 0 | R39: =ROUND(Q39*$B39,2) -> 0 | S39: =IF(Q39<T39,Q39,T39-R39) -> 0 | T39: =IF(Q39<$M$15,Q39+R39,$M$15) -> 0 | V39: 17 | W39: 0.91 | X39: 0.91
A40: =VLOOKUP(D40,$A$7:$B$11,2) -> 0.0715 | B40: =A40/12 -> 0.0059583333 | C40: =INT((D40+11)/12) -> 2 | D40: 18 | E40: =IF(E39<H39,0,E39-G39) -> 0 | F40: =ROUND(E40*$B40,2) -> 0 | G40: =IF(E40<H40,E40,H40-F40) -> 0 | H40: =IF(E40<$M$4,E40+F40,$M$4) -> 0 | I40: =IF(I39<L39,0,I39-K39) -> 0 | J40: =ROUND(I40*$B40,2) -> 0 | K40: =IF(I40<L40,I40,L40-J40) -> 0 | L40: =IF(I40<$M$5,I40+J40,$M$5) -> 0 | M40: =IF(M39<P39,0,M39-O39) -> 0 | N40: =ROUND(M40*$B40,2) -> 0 | O40: =IF(M40<P40,M40,P40-N40) -> 0 | P40: =IF(M40<$M$9,M40+N40,$M$9) -> 0 | Q40: =IF(Q39<T39,0,Q39-S39) -> 0 | R40: =ROUND(Q40*$B40,2) -> 0 | S40: =IF(Q40<T40,Q40,T40-R40) -> 0 | T40: =IF(Q40<$M$15,Q40+R40,$M$15) -> 0 | V40: 18 | W40: 0.9 | X40: 0.91
A41: =VLOOKUP(D41,$A$7:$B$11,2) -> 0.0715 | B41: =A41/12 -> 0.0059583333 | C41: =INT((D41+11)/12) -> 2 | D41: 19 | E41: =IF(E40<H40,0,E40-G40) -> 0 | F41: =ROUND(E41*$B41,2) -> 0 | G41: =IF(E41<H41,E41,H41-F41) -> 0 | H41: =IF(E41<$M$4,E41+F41,$M$4) -> 0 | I41: =IF(I40<L40,0,I40-K40) -> 0 | J41: =ROUND(I41*$B41,2) -> 0 | K41: =IF(I41<L41,I41,L41-J41) -> 0 | L41: =IF(I41<$M$5,I41+J41,$M$5) -> 0 | M41: =IF(M40<P40,0,M40-O40) -> 0 | N41: =ROUND(M41*$B41,2) -> 0 | O41: =IF(M41<P41,M41,P41-N41) -> 0 | P41: =IF(M41<$M$9,M41+N41,$M$9) -> 0 | Q41: =IF(Q40<T40,0,Q40-S40) -> 0 | R41: =ROUND(Q41*$B41,2) -> 0 | S41: =IF(Q41<T41,Q41,T41-R41) -> 0 | T41: =IF(Q41<$M$15,Q41+R41,$M$15) -> 0 | V41: 19 | W41: 0.9 | X41: 0.9
A42: =VLOOKUP(D42,$A$7:$B$11,2) -> 0.0715 | B42: =A42/12 -> 0.0059583333 | C42: =INT((D42+11)/12) -> 2 | D42: 20 | E42: =IF(E41<H41,0,E41-G41) -> 0 | F42: =ROUND(E42*$B42,2) -> 0 | G42: =IF(E42<H42,E42,H42-F42) -> 0 | H42: =IF(E42<$M$4,E42+F42,$M$4) -> 0 | I42: =IF(I41<L41,0,I41-K41) -> 0 | J42: =ROUND(I42*$B42,2) -> 0 | K42: =IF(I42<L42,I42,L42-J42) -> 0 | L42: =IF(I42<$M$5,I42+J42,$M$5) -> 0 | M42: =IF(M41<P41,0,M41-O41) -> 0 | N42: =ROUND(M42*$B42,2) -> 0 | O42: =IF(M42<P42,M42,P42-N42) -> 0 | P42: =IF(M42<$M$9,M42+N42,$M$9) -> 0 | Q42: =IF(Q41<T41,0,Q41-S41) -> 0 | R42: =ROUND(Q42*$B42,2) -> 0 | S42: =IF(Q42<T42,Q42,T42-R42) -> 0 | T42: =IF(Q42<$M$15,Q42+R42,$M$15) -> 0 | V42: 20 | W42: 0.9 | X42: 0.9
A43: =VLOOKUP(D43,$A$7:$B$11,2) -> 0.0715 | B43: =A43/12 -> 0.0059583333 | C43: =INT((D43+11)/12) -> 2 | D43: 21 | E43: =IF(E42<H42,0,E42-G42) -> 0 | F43: =ROUND(E43*$B43,2) -> 0 | G43: =IF(E43<H43,E43,H43-F43) -> 0 | H43: =IF(E43<$M$4,E43+F43,$M$4) -> 0 | I43: =IF(I42<L42,0,I42-K42) -> 0 | J43: =ROUND(I43*$B43,2) -> 0 | K43: =IF(I43<L43,I43,L43-J43) -> 0 | L43: =IF(I43<$M$5,I43+J43,$M$5) -> 0 | M43: =IF(M42<P42,0,M42-O42) -> 0 | N43: =ROUND(M43*$B43,2) -> 0 | O43: =IF(M43<P43,M43,P43-N43) -> 0 | P43: =IF(M43<$M$9,M43+N43,$M$9) -> 0 | Q43: =IF(Q42<T42,0,Q42-S42) -> 0 | R43: =ROUND(Q43*$B43,2) -> 0 | S43: =IF(Q43<T43,Q43,T43-R43) -> 0 | T43: =IF(Q43<$M$15,Q43+R43,$M$15) -> 0 | V43: 21 | W43: 0.9 | X43: 0.9
...

Sheet Sheet6

Sheet คีย์ข้อมูล
A2: ผู้กู้หลัก | B2: อายุ | C2: =69-39 -> 30 | D2: ปี | E2: เพศ | F2: ชาย | G2: ผู้กู้ร่วม 1 | H2: อายุ | I2: =67-27 -> 40 | J2: ปี | K2: เพศ | L2: หญิง | M2: ผู้กู้ร่วม 2 | N2: อายุ | O2: 30 | P2: ปี | Q2: เพศ | R2: หญิง | T2: ราคาซื้อขาย | U2: ราคาประเมิน
A3: รายได้ | P3: สรุปวงเงิน | T3: 2540000 | U3: 2201680
A4: SL | B4: 30000 | C4: บาท | G4: ประจำ | I4: บาท | M4: ประจำ | N4: 0 | O4: บาท | P4: วงเงินที่ 1 | T4: LTV | U4: LTV
C5: บาท | G5: อื่นๆ | I5: บาท | M5: อื่นๆ | N5: 0 | O5: บาท | P5: HL | S5: =B15 -> 1000000 | T5: =S5/T3 -> 0.39370079 | U5: =S5/U3 -> 0.45419861
A6: รวม | B6: =B4+B5 -> 30000 | C6: บาท | G6: รวม | H6: =H4+H5 -> 0 | I6: บาท | M6: รวม | N6: =N4+N5 -> 0 | O6: บาท | P6: HL+ประกัน | S6: =B21 -> 1020980 | T6: =S6/T3 -> 0.40196063 | U6: =S6/U3 -> 0.4637277
A7: ภาระผ่อนสินเชื่อ (อย่าลืมใส่ภาระผ่อนสินเชื่อทั้งในและนอก NCB) | P7: วงเงินที่ 2
C8: บาท | I8: บาท | M8: ตาม NCB | N8: 0 | O8: บาท | P8: MP | S8: =B24 -> 0 | T8: =S8/T3 -> 0 | U8: =S8/U3 -> 0
C9: บาท | H9: 0 | I9: บาท | M9: นอกNCB | N9: 0 | O9: บาท | P9: MP+ประกัน | S9: =B30 -> 0 | T9: =S9/T3 -> 0 | U9: =S9/U3 -> 0
A10: รวม | B10: =B8+B9 -> 0 | C10: บาท | G10: รวม | H10: =H8+H9 -> 0 | I10: บาท | L10: Medium | M10: รวม | N10: =N8+N9 -> 0 | O10: บาท | P10: วงเงินรวม
A11: รายได้รวม | H11: =B6+H6+N6 -> 30000 | I11: บาท | J11: ควรมีรายได้ | L11: Limit DSR | M11: DSR | N11: =(H13+H12)/H11 -> 0.21766667 | P11: HL+MP | S11: =S5+S8 -> 1000000 | T11: =S11/T3 -> 0.39370079 | U11: =S11/U3 -> 0.45419861
A12: ภาระผ่อนสินเชื่อรวม | H12: =B10+H10+N10 -> 0 | I12: บาท | J12: =IF(N11>L12,((H12+H13)/L12),0) -> 0 | L12: 0.7 | M12: Net Income | N12: =H11-H12-H13 -> 23470 | O12: บาท | P12: HL+MP+ประกัน | S12: =B21+B30 -> 1020980 | T12: =S12/T3 -> 0.40196063 | U12: =S12/U3 -> 0.4637277
A13: ค่างวดผ่อน CIMB รวม | H13: =G30+G21 -> 6530 | I13: บาท | J13: =IF(N11>L12,((H12+H13)/L12-H11),0) -> 0 | L13: << เพิ่มอีก | M13: Net Income ต้อง > 7,500 บาท | Y13: MRTA | AB13: MRTA+
A14: วงเงินที่ 1 | L14: ระยะเวลา | M14: อัตราดอกเบี้ย | N14: % | X14: HL | Y14: ชาย | Z14: หญิง | AA14: เลือกเพศ | AB14: ชาย | AC14: หญิง | AD14: เลือกเพศ
A15: วงเงินที่ 1 | B15: 1000000 | C15: บาท | E15: ระยะเวลากู้ | G15: 35 | H15: ปี(ถ้าเลยวันเกิดกู้หลักระยะเวลากู้ -1) | L15: เดือนที่ 1-3 | N15: 0.0329 | X15: 1 | Y15: =VLOOKUP(G17,'อัตรา mrta'!$A$6:$AR$36,C2-18,0) -> 0.01642 | Z15: =VLOOKUP(G17,'อัตรา mrta'!$A$41:$AR$71,C2-18,0) -> 0.00568 | AA15: =IF(F2="หญิง",Z15,Y15) -> 0.01642 | AB15: =VLOOKUP(G17,'อัตรา mrta+'!$A$6:$AR$36,C2-18,0) -> 0.02098 | AC15: =VLOOKUP(G17,'อัตรา mrta+'!$A$41:$AR$71,C2-18,0) -> 0.01024 | AD15: =IF(F2="หญิง",AC15,AB15) -> 0.02098 | AE15: =IF(J17="NoMRTA",0,IF(J17="MRTA",AA15,AD15)) -> 0.02098
B16: เบี้ยประกัน | G16: ปี | H16: ทุนประกัน(บาท) | I16: อัตรา | J16: ประกัน | K16: % | L16: เดือนที่ 4-12 | N16: 0.0329 | X16: 2 | Y16: =VLOOKUP(G18,'อัตรา mrta'!$A$6:$AR$36,I2-18,0) -> 0.02132 | Z16: =VLOOKUP(G18,'อัตรา mrta'!$A$41:$AR$71,I2-18,0) -> 0.00828 | AA16: =IF(L2="หญิง",Z16,Y16) -> 0.00828 | AB16: =VLOOKUP(G18,'อัตรา mrta+'!$A$6:$AR$36,I2-18,0) -> 0.02507 | AC16: =VLOOKUP(G18,'อัตรา mrta+'!$A$41:$AR$71,I2-18,0) -> 0.01203 | AD16: =IF(L2="หญิง",AC16,AB16) -> 0.01203
A17: ผู้กู้หลัก | B17: =H17*I17 -> 20980 | C17: บาท | E17: ระยะเวลาคุ้มครอง | G17: 10 | H17: =$B$15*K17 -> 1000000 | I17: =IF(J17="NoMRTA",0,IF(J17="MRTA",AA15,AD15)) -> 0.02098 | J17: MRTA+ | K17: 1 | L17: ปีที่ 2 | N17: 0.0329 | X17: 3 | Y17: =VLOOKUP(G19,'อัตรา mrta'!$A$6:$AR$36,O2-18,0) -> 0.01263 | Z17: =VLOOKUP(G19,'อัตรา mrta'!$A$41:$AR$71,O2-18,0) -> 0.00434 | AA17: =IF(R2="หญิง",Z17,Y17) -> 0.00434 | AB17: =VLOOKUP(G19,'อัตรา mrta+'!$A$6:$AR$36,O2-18,0) -> 0.01638 | AC17: =VLOOKUP(G19,'อัตรา mrta+'!$A$41:$AR$71,O2-18,0) -> 0.00809 | AD17: =IF(R2="หญิง",AC17,AB17) -> 0.00809
A18: ผู้กู้ร่วม 1 | B18: =H18*I18 -> 0 | C18: บาท | E18: ระยะเวลาคุ้มครอง | G18: 8 | H18: =$B$15*K18 -> 1000000 | I18: =IF(J18="NoMRTA",0,IF(J18="MRTA",AA16,AD16)) -> 0 | J18: NoMRTA | K18: 1 | L18: ปีที่ 3 | N18: 0.0329 | S18: 8.525 | X18: 4 | Y18: =VLOOKUP(G26,'อัตรา mrta'!$A$6:$AR$36,C2-18,0) -> 0.01642 | Z18: =VLOOKUP(G26,'อัตรา mrta'!$A$41:$AR$71,C2-18,0) -> 0.00568 | AA18: =IF(F2="หญิง",Z18,Y18) -> 0.01642 | AB18: =VLOOKUP(G26,'อัตรา mrta+'!$A$6:$AR$36,C2-18,0) -> 0.02098 | AC18: =VLOOKUP(G26,'อัตรา mrta+'!$A$41:$AR$71,C2-18,0) -> 0.01024 | AD18: =IF(F2="หญิง",AC18,AB18) -> 0.02098
A19: ผู้กู้ร่วม 2 | B19: =H19*I19 -> 0 | C19: บาท | E19: ระยะเวลาคุ้มครอง | G19: 8 | H19: =$B$15*K19 -> 1000000 | I19: =IF(J19="NoMRTA",0,IF(J19="MRTA",AA17,AD17)) -> 0 | J19: NoMRTA | K19: 1 | L19: หลังจากนั้น | N19: 0.06525 | X19: 5 | Y19: =VLOOKUP(G27,'อัตรา mrta'!$A$6:$AR$36,I2-18,0) -> 0.02813 | Z19: =VLOOKUP(G27,'อัตรา mrta'!$A$41:$AR$71,I2-18,0) -> 0.01106 | AA19: =IF(L2="หญิง",Z19,Y19) -> 0.01106 | AB19: =VLOOKUP(G27,'อัตรา mrta+'!$A$6:$AR$36,I2-18,0) -> 0.03269 | AC19: =VLOOKUP(G27,'อัตรา mrta+'!$A$41:$AR$71,I2-18,0) -> 0.01562 | AD19: =IF(L2="หญิง",AC19,AB19) -> 0.01562
